Workbook

Sheet COMISIONES
A1: VENDEDOR | B1: SUCURSAL | C1: BULTOS | D1: UNIDAD DE MEDIDA | E1: IMPORTE | F1: COMISIÓN POR IMPORTE FIJO | G1: COMISIÓN POR PORCENTAJE | H1: COMISIÓN TOTAL
A2: 0 - TODOS LOS VENDEDORES | B2: 0 | C2: 9307.0964 | D2: 35869.189 | E2: 1.6072063e+08 | F2: 0 | G2: 95503.988 | H2: 95504.07
A3: 1 - VERA ERNESTO | B3: 1 | C3: 101.64787 | D3: 202.01234 | E3: 3183466.3 | F3: 0 | G3: 95503.988 | H3: 95504.07
A4: 2 - OJEDA NORBERTO | B4: 1 | C4: 40.25248 | D4: 73.44925 | E4: 1422600.4 | F4: 0 | G4: 0 | H4: 0
A5: 3 - VIDAL NAHUEL | B5: 1 | C5: 159.59629 | D5: 1736.7712 | E5: 4354861.9 | F5: 0 | G5: 0 | H5: 0
A6: 4 - TUR SPRINGER FERNANDO | B6: 1 | C6: 144.0997 | D6: 130.11894 | E6: 3440020.8 | F6: 0 | G6: 0 | H6: 0
A7: 5 - SCHELOVER RAUL | B7: 1 | C7: 200.38341 | D7: 755.98143 | E7: 3946966.7 | F7: 0 | G7: 0 | H7: 0
A8: 7 - VALLEJOS EDUARDO | B8: 1 | C8: 319 | D8: 1573.9 | E8: 9048937.8 | F8: 0 | G8: 0 | H8: 0
A9: 8 - RAVAROTTO EMANUEL | B9: 1 | C9: 28.883333 | D9: 74.419167 | E9: 665204.35 | F9: 0 | G9: 0 | H9: 0
A10: 9 - ESTIGARRIBIA DAVID | B10: 1 | C10: 33.897917 | D10: 146.03287 | E10: 1470728.8 | F10: 0 | G10: 0 | H10: 0
A11: 10 - BRITEZ EMMANUEL | B11: 1 | C11: 47.479921 | D11: 133.234 | E11: 1145490.6 | F11: 0 | G11: 0 | H11: 0
A12: 11 - SANCHEZ RICARDO | B12: 1 | C12: 174.80099 | D12: 535.745 | E12: 3158440.5 | F12: 0 | G12: 0 | H12: 0
A13: 12 - GUTIERREZ MARCOS DAVID | B13: 1 | C13: 132.30618 | D13: 567.20567 | E13: 2324352.4 | F13: 0 | G13: 0 | H13: 0
... A43: 123 - TORRES ROLANDO | B43: 1 | C43: 69 | D43: 49.02 | E43: 2627111.6 | F43: 0 | G43: 0 | H43: 0

Sheet AVANCE
A1: SUPERVISOR | B1: VENDEDOR | C1: OBJETIVO | D1: FACTURACION ACUMULADA | E1: FACTURACION N-1 | F1: FACTURACION DEL DIA | G1: AVANCE VS OBJETIVO | H1: PROYECCION | I1: CUMPLIMIENTO PROYECTADO | J1: MEDIA REAL | K1: MEDIA NECESARIA | L1: COBRO
A2: MARTIN PREVENTA | B2: 20 - FLORES JAVIER | C2: 32279077 | D2: =IFERROR(+VLOOKUP(B2,COMISIONES!A:E,5,FALSE),"0")*1 -> 5630523.5 | E2: 197724.01 | F2: 33086054 | G2: =+D2/C2 -> 0.17443261 | H2: =+D2/$N$3*$N$4 -> 73196805 | I2: =+H2/C2 -> 2.2676239 | J2: =+D2/$N$3 -> 2815261.7 | K2: =+(C2-D2)/$N$2 -> 1110356.4 | L2: {=+_xlfn.IFS(I2>114%,H2*0.02,I2>109%,H2*0.015,I2>104%,H2*0.0125,I2>99%,H2*0.01,I2<99%,H2*0)} -> 1463936.1 | M2: DIAS DE TRABAJO RESTANTES | N2: 24
B3: 19 - GONZALEZ MARCELO | C3: 30982728 | D3: =IFERROR(+VLOOKUP(B3,COMISIONES!A:E,5,FALSE),"0")*1 -> 3246306.4 | E3: 1795361.9 | F3: 31757296 | G3: =+D3/C3 -> 0.10477794 | H3: =+D3/$N$3*$N$4 -> 42201983 | I3: =+H3/C3 -> 1.3621132 | J3: =+D3/$N$3 -> 1623153.2 | K3: =+(C3-D3)/$N$2 -> 1155684.2 | L3: {=+_xlfn.IFS(I3>114%,H3*0.02,I3>109%,H3*0.015,I3>104%,H3*0.0125,I3>99%,H3*0.01,I3<99%,H3*0)} -> 844039.66 | M3: DIAS TRABAJADOS | N3: =N4-N2 -> 2
B4: 16 - GOMEZ MATÍAS | C4: 28390031 | D4: =IFERROR(+VLOOKUP(B4,COMISIONES!A:E,5,FALSE),"0")*1 -> 2772280.6 | E4: 1264552.9 | F4: 29099782 | G4: =+D4/C4 -> 0.09764979 | H4: =+D4/$N$3*$N$4 -> 36039648 | I4: =+H4/C4 -> 1.2694473 | J4: =+D4/$N$3 -> 1386140.3 | K4: =+(C4-D4)/$N$2 -> 1067406.3 | L4: {=+_xlfn.IFS(I4>114%,H4*0.02,I4>109%,H4*0.015,I4>104%,H4*0.0125,I4>99%,H4*0.01,I4<99%,H4*0)} -> 720792.95 | M4: DIAS DE TRABAJO MES | N4: 26
B5: 12 - GUTIERREZ MARCOS DAVID | C5: 28390031 | D5: =IFERROR(+VLOOKUP(B5,COMISIONES!A:E,5,FALSE),"0")*1 -> 2324352.4 | E5: 554218.39 | F5: 29099782 | G5: =+D5/C5 -> 0.081872134 | H5: =+D5/$N$3*$N$4 -> 30216582 | I5: =+H5/C5 -> 1.0643377 | J5: =+D5/$N$3 -> 1162176.2 | K5: =+(C5-D5)/$N$2 -> 1086070 | L5: {=+_xlfn.IFS(I5>114%,H5*0.02,I5>109%,H5*0.015,I5>104%,H5*0.0125,I5>99%,H5*0.01,I5<99%,H5*0)} -> 377707.27
B6: 11 - SANCHEZ RICARDO | C6: 23528725 | D6: =IFERROR(+VLOOKUP(B6,COMISIONES!A:E,5,FALSE),"0")*1 -> 3158440.5 | E6: 2024283.5 | F6: 24116943 | G6: =+D6/C6 -> 0.13423764 | H6: =+D6/$N$3*$N$4 -> 41059727 | I6: =+H6/C6 -> 1.7450894 | J6: =+D6/$N$3 -> 1579220.3 | K6: =+(C6-D6)/$N$2 -> 848761.83 | L6: {=+_xlfn.IFS(I6>114%,H6*0.02,I6>109%,H6*0.015,I6>104%,H6*0.0125,I6>99%,H6*0.01,I6<99%,H6*0)} -> 821194.53
B7: 8 - RAVAROTTO EMANUEL | C7: 27741857 | D7: =IFERROR(+VLOOKUP(B7,COMISIONES!A:E,5,FALSE),"0")*1 -> 665204.35 | E7: 401287.85 | F7: 28435403 | G7: =+D7/C7 -> 0.023978364 | H7: =+D7/$N$3*$N$4 -> 8647656.5 | I7: =+H7/C7 -> 0.31171873 | J7: =+D7/$N$3 -> 332602.17 | K7: =+(C7-D7)/$N$2 -> 1128193.9 | L7: {=+_xlfn.IFS(I7>114%,H7*0.02,I7>109%,H7*0.015,I7>104%,H7*0.0125,I7>99%,H7*0.01,I7<99%,H7*0)} -> 0
B8: 5 - SCHELOVER RAUL | C8: 35831071 | D8: =IFERROR(+VLOOKUP(B8,COMISIONES!A:E,5,FALSE),"0")*1 -> 3946966.7 | E8: 2033398.5 | F8: 36726848 | G8: =+D8/C8 -> 0.11015486 | H8: =+D8/$N$3*$N$4 -> 51310567 | I8: =+H8/C8 -> 1.4320132 | J8: =+D8/$N$3 -> 1973483.4 | K8: =+(C8-D8)/$N$2 -> 1328504.4 | L8: {=+_xlfn.IFS(I8>114%,H8*0.02,I8>109%,H8*0.015,I8>104%,H8*0.0125,I8>99%,H8*0.01,I8<99%,H8*0)} -> 1026211.3
B9: 4 - TUR SPRINGER FERNANDO | C9: 35831071 | D9: =IFERROR(+VLOOKUP(B9,COMISIONES!A:E,5,FALSE),"0")*1 -> 3440020.8 | E9: 1533394.8 | F9: 36726848 | G9: =+D9/C9 -> 0.09600664 | H9: =+D9/$N$3*$N$4 -> 44720270 | I9: =+H9/C9 -> 1.2480863 | J9: =+D9/$N$3 -> 1720010.4 | K9: =+(C9-D9)/$N$2 -> 1349627.1 | L9: {=+_xlfn.IFS(I9>114%,H9*0.02,I9>109%,H9*0.015,I9>104%,H9*0.0125,I9>99%,H9*0.01,I9<99%,H9*0)} -> 894405.4
C10: 2.4297459e+08 | D10: =+SUM(D2:D9) -> 25184095 | E10: 9804221.9 | F10: 2.4904896e+08 | G10: =+D10/C10 -> 0.10364909 | H10: =+D10/$N$3*$N$4 -> 3.2739324e+08 | I10: =+H10/C10 -> 1.3474382 | J10: =+D10/$N$3 -> 12592048 | K10: =+(C10-D10)/$N$2 -> 9074604
A11: MARTIN | B11: 22 - ALMIRON NICOLAS | C11: 96971948 | D11: =IFERROR(+VLOOKUP(B11,COMISIONES!A:E,5,FALSE),"0")*1 -> 5511113.9 | E11: 2321605.5 | F11: 99396247 | G11: =+D11/C11 -> 0.056832043 | H11: =+D11/$N$3*$N$4 -> 71644481 | I11: =+H11/C11 -> 0.73881656 | J11: =+D11/$N$3 -> 2755557 | K11: =+(C11-D11)/$N$2 -> 3810868.1 | L11: {=+_xlfn.IFS(I11>114%,H11*0.0125,I11>109%,H11*0.01,I11>104%,H11*0.0075,I11>99%,H11*0.005,I11<99%,H11*0)} -> 0
B12: 15 - GALARZA GERARDO | C12: 1.2836392e+08 | D12: =IFERROR(+VLOOKUP(B12,COMISIONES!A:E,5,FALSE),"0")*1 -> 3123900 | E12: 1461699.3 | F12: 1.3157301e+08 | G12: =+D12/C12 -> 0.024336279 | H12: =+D12/$N$3*$N$4 -> 40610700 | I12: =+H12/C12 -> 0.31637162 | J12: =+D12/$N$3 -> 1561950 | K12: =+(C12-D12)/$N$2 -> 5218334 | L12: {=+_xlfn.IFS(I12>114%,H12*0.0125,I12>109%,H12*0.01,I12>104%,H12*0.0075,I12>99%,H12*0.005,I12<99%,H12*0)} -> 0 | M12: AUMENTO OBJ | N12: 0.02
B13: 52 - MARSALL NICOLAS | C13: 42449057 | D13: =IFERROR(+VLOOKUP(B13,COMISIONES!A:E,5,FALSE),"0")*1 -> 3697110.3 | E13: 92221.682 | F13: 43510284 | G13: =+D13/C13 -> 0.087095228 | H13: =+D13/$N$3*$N$4 -> 48062434 | I13: =+H13/C13 -> 1.132238 | J13: =+D13/$N$3 -> 1848555.2 | K13: =+(C13-D13)/$N$2 -> 1614664.5 | L13: {=+_xlfn.IFS(I13>109%,H13*0.015,I13>104%,H13*0.0125,I13>99%,H13*0.01,I13<99%,H13*0)} -> 720936.52
B14: 53 - SANDOVAL RODRIGO | C14: 42449057 | D14: =IFERROR(+VLOOKUP(B14,COMISIONES!A:E,5,FALSE),"0")*1 -> 3131426.5 | E14: 2876584.6 | F14: 43510284 | G14: =+D14/C14 -> 0.073769046 | H14: =+D14/$N$3*$N$4 -> 40708544 | I14: =+H14/C14 -> 0.9589976 | J14: =+D14/$N$3 -> 1565713.2 | K14: =+(C14-D14)/$N$2 -> 1638234.6 | L14: {=+_xlfn.IFS(I14>109%,H14*0.015,I14>104%,H14*0.0125,I14>99%,H14*0.01,I14<99%,H14*0)} -> 0
C15: 3.4186488e+08 | D15: =+SUM(D11:D14) -> 15463551 | E15: 6752111.2 | F15: 3.1798983e+08 | G15: =+D15/C15 -> 0.045232931 | H15: =+D15/$N$3*$N$4 -> 2.0102616e+08 | I15: =+H15/C15 -> 0.58802811 | J15: =+D15/$N$3 -> 7731775.4 | K15: =+(C15-D15)/$N$2 -> 13600055
A16: CRISTIAN | B16: 2 - OJEDA NORBERTO | C16: 28430000 | D16: =IFERROR(+VLOOKUP(B16,COMISIONES!A:E,5,FALSE),"0")*1 -> 1422600.4 | E16: 741155.96 | F16: =+D16-E16 -> 681444.41 | G16: =+D16/C16 -> 0.050038704 | H16: =+D16/$N$3*$N$4 -> 18493805 | I16: =+H16/C16 -> 0.65050316 | J16: =+D16/$N$3 -> 711300.18 | K16: =+(C16-D16)/$N$2 -> 1125308.3 | L16: {=+_xlfn.IFS(I16>114%,H16*0.02,I16>109%,H16*0.015,I16>104%,H16*0.0125,I16>99%,H16*0.01,I16<99%,H16*0)} -> 0
B17: 3 - VIDAL NAHUEL | C17: 25000000 | D17: =IFERROR(+VLOOKUP(B17,COMISIONES!A:E,5,FALSE),"0")*1 -> 4354861.9 | E17: 3175848.5 | F17: =+D17-E17 -> 1179013.4 | G17: =+D17/C17 -> 0.17419447 | H17: =+D17/$N$3*$N$4 -> 56613204 | I17: =+H17/C17 -> 2.2645282 | J17: =+D17/$N$3 -> 2177430.9 | K17: =+(C17-D17)/$N$2 -> 860214.09 | L17: {=+_xlfn.IFS(I17>114%,H17*0.02,I17>109%,H17*0.015,I17>104%,H17*0.0125,I17>99%,H17*0.01,I17<99%,H17*0)} -> 1132264.1
B18: 18 - HERRERA PABLO | C18: 25500000 | D18: =IFERROR(+VLOOKUP(B18,COMISIONES!A:E,5,FALSE),"0")*1 -> 2195813.5 | E18: 1106384.1 | F18: =+D18-E18 -> 1089429.4 | G18: =+D18/C18 -> 0.086110335 | H18: =+D18/$N$3*$N$4 -> 28545576 | I18: =+H18/C18 -> 1.1194344 | J18: =+D18/$N$3 -> 1097906.8 | K18: =+(C18-D18)/$N$2 -> 971007.77 | L18: {=+_xlfn.IFS(I18>114%,H18*0.02,I18>109%,H18*0.015,I18>104%,H18*0.0125,I18>99%,H18*0.01,I18<99%,H18*0)} -> 428183.64
B19: 21 - CATAN MATIAS | C19: 35200000 | D19: =IFERROR(+VLOOKUP(B19,COMISIONES!A:E,5,FALSE),"0")*1 -> 2509697 | E19: 1592632.1 | F19: =+D19-E19 -> 917064.9 | G19: =+D19/C19 -> 0.07129821 | H19: =+D19/$N$3*$N$4 -> 32626061 | I19: =+H19/C19 -> 0.92687673 | J19: =+D19/$N$3 -> 1254848.5 | K19: =+(C19-D19)/$N$2 -> 1362096 | L19: {=+_xlfn.IFS(I19>114%,H19*0.02,I19>109%,H19*0.015,I19>104%,H19*0.0125,I19>99%,H19*0.01,I19<99%,H19*0)} -> 0
B20: 23 - DELGADO JOSÉ | C20: 26100000 | D20: =IFERROR(+VLOOKUP(B20,COMISIONES!A:E,5,FALSE),"0")*1 -> 2318490.8 | E20: 959278.13 | F20: =+D20-E20 -> 1359212.7 | G20: =+D20/C20 -> 0.088831067 | H20: =+D20/$N$3*$N$4 -> 30140381 | I20: =+H20/C20 -> 1.1548039 | J20: =+D20/$N$3 -> 1159245.4 | K20: =+(C20-D20)/$N$2 -> 990896.21 | L20: {=+_xlfn.IFS(I20>114%,H20*0.02,I20>109%,H20*0.015,I20>104%,H20*0.0125,I20>99%,H20*0.01,I20<99%,H20*0)} -> 602807.62
B21: 31 - RENZO RAMOS | C21: 32600000 | D21: =IFERROR(+VLOOKUP(B21,COMISIONES!A:E,5,FALSE),"0")*1 -> 2857508.4 | E21: 928553.23 | F21: =+D21-E21 -> 1928955.2 | G21: =+D21/C21 -> 0.087653632 | H21: =+D21/$N$3*$N$4 -> 37147609 | I21: =+H21/C21 -> 1.1394972 | J21: =+D21/$N$3 -> 1428754.2 | K21: =+(C21-D21)/$N$2 -> 1239270.5 | L21: {=+_xlfn.IFS(I21>114%,H21*0.02,I21>109%,H21*0.015,I21>104%,H21*0.0125,I21>99%,H21*0.01,I21<99%,H21*0)} -> 557214.14
B22: 44 - MONGES CESAR LUIS | C22: 28200000 | D22: =IFERROR(+VLOOKUP(B22,COMISIONES!A:E,5,FALSE),"0")*1 -> 2290915.2 | E22: 1211206.3 | F22: =+D22-E22 -> 1079708.9 | G22: =+D22/C22 -> 0.081238129 | H22: =+D22/$N$3*$N$4 -> 29781898 | I22: =+H22/C22 -> 1.0560957 | J22: =+D22/$N$3 -> 1145457.6 | K22: =+(C22-D22)/$N$2 -> 1079545.2 | L22: {=+_xlfn.IFS(I22>114%,H22*0.02,I22>109%,H22*0.015,I22>104%,H22*0.0125,I22>99%,H22*0.01,I22<99%,H22*0)} -> 372273.72
B23: 54 - BARTSCHAT EMILIANO NAHUEL | C23: 36600000 | D23: =IFERROR(+VLOOKUP(B23,COMISIONES!A:E,5,FALSE),"0")*1 -> 2921309 | E23: 859233.11 | F23: =+D23-E23 -> 2062075.9 | G23: =+D23/C23 -> 0.079817185 | H23: =+D23/$N$3*$N$4 -> 37977017 | I23: =+H23/C23 -> 1.0376234 | J23: =+D23/$N$3 -> 1460654.5 | K23: =+(C23-D23)/$N$2 -> 1403278.8 | L23: {=+_xlfn.IFS(I23>114%,H23*0.02,I23>109%,H23*0.015,I23>104%,H23*0.0125,I23>99%,H23*0.01,I23<99%,H23*0)} -> 379770.17
C24: 237630000 | D24: =+SUM(D16:D23) -> 20871196 | E24: 10574291 | F24: =+D24-E24 -> 10296905 | G24: =+D24/C24 -> 0.087830645 | H24: =+D24/$N$3*$N$4 -> 2.7132555e+08 | I24: =+H24/C24 -> 1.1417984 | J24: =+D24/$N$3 -> 10435598 | K24: =+(C24-D24)/$N$2 -> 9031616.8
A25: GONZALO | B25: 32 - CABRAL GONZALO | C25: 84027142 | D25: =IFERROR(+VLOOKUP(B25,COMISIONES!A:E,5,FALSE),"0")*1 -> 5603369 | E25: 3206664.6 | F25: =+D25-E25 -> 2396704.4 | G25: =+D25/C25 -> 0.066685226 | H25: =+D25/$N$3*$N$4 -> 72843797 | I25: =+H25/C25 -> 0.86690794 | J25: =+D25/$N$3 -> 2801684.5 | K25: =+(C25-D25)/$N$2 -> 3267657.2 | L25: {=+_xlfn.IFS(I25>114%,H25*0.0125,I25>109%,H25*0.01,I25>104%,H25*0.0075,I25>99%,H25*0.005,I25<99%,H25*0)} -> 0
B26: 36 - COSARINSKI DIEGO | C26: 21525000 | D26: =IFERROR(+VLOOKUP(B26,COMISIONES!A:E,5,FALSE),"0")*1 -> 1210633.6 | E26: 613066.82 | F26: =+D26-E26 -> 597566.74 | G26: =+D26/C26 -> 0.056243139 | H26: =+D26/$N$3*$N$4 -> 15738236 | I26: =+H26/C26 -> 0.73116081 | J26: =+D26/$N$3 -> 605316.78 | K26: =+(C26-D26)/$N$2 -> 846431.93 | L26: {=+_xlfn.IFS(I26>114%,H26*0.02,I26>109%,H26*0.015,I26>104%,H26*0.0125,I26>99%,H26*0.01,I26<99%,H26*0)} -> 0
B27: 9 - ESTIGARRIBIA DAVID | C27: 26383192 | D27: =IFERROR(+VLOOKUP(B27,COMISIONES!A:E,5,FALSE),"0")*1 -> 1470728.8 | E27: 988543.02 | F27: =+D27-E27 -> 482185.79 | G27: =+D27/C27 -> 0.055744915 | H27: =+D27/$N$3*$N$4 -> 19119475 | I27: =+H27/C27 -> 0.72468389 | J27: =+D27/$N$3 -> 735364.41 | K27: =+(C27-D27)/$N$2 -> 1038019.3 | L27: {=+_xlfn.IFS(I27>114%,H27*0.02,I27>109%,H27*0.015,I27>104%,H27*0.0125,I27>99%,H27*0.01,I27<99%,H27*0)} -> 0
B28: 40 - IBARROLA JORGE | C28: 39189035 | D28: =IFERROR(+VLOOKUP(B28,COMISIONES!A:E,5,FALSE),"0")*1 -> 2156343.8 | E28: 1302532 | F28: =+D28-E28 -> 853811.84 | G28: =+D28/C28 -> 0.055024162 | H28: =+D28/$N$3*$N$4 -> 28032470 | I28: =+H28/C28 -> 0.71531411 | J28: =+D28/$N$3 -> 1078171.9 | K28: =+(C28-D28)/$N$2 -> 1543028.8 | L28: {=+_xlfn.IFS(I28>114%,H28*0.02,I28>109%,H28*0.015,I28>104%,H28*0.0125,I28>99%,H28*0.01,I28<99%,H28*0)} -> 0
B29: 27 - GOMEZ ADRIÁN | C29: 26050631 | D29: =IFERROR(+VLOOKUP(B29,COMISIONES!A:E,5,FALSE),"0")*1 -> 2307023.2 | E29: 1114483.6 | F29: =+D29-E29 -> 1192539.6 | G29: =+D29/C29 -> 0.088559203 | H29: =+D29/$N$3*$N$4 -> 29991301 | I29: =+H29/C29 -> 1.1512696 | J29: =+D29/$N$3 -> 1153511.6 | K29: =+(C29-D29)/$N$2 -> 989317 | L29: {=+_xlfn.IFS(I29>114%,H29*0.02,I29>109%,H29*0.015,I29>104%,H29*0.0125,I29>99%,H29*0.01,I29<99%,H29*0)} -> 599826.02
B30: 10 - BRITEZ EMMANUEL | C30: 25830000 | D30: =IFERROR(+VLOOKUP(B30,COMISIONES!A:E,5,FALSE),"0")*1 -> 1145490.6 | E30: 756625.92 | F30: =+D30-E30 -> 388864.67 | G30: =+D30/C30 -> 0.044347294 | H30: =+D30/$N$3*$N$4 -> 14891378 | I30: =+H30/C30 -> 0.57651482 | J30: =+D30/$N$3 -> 572745.3 | K30: =+(C30-D30)/$N$2 -> 1028521.2 | L30: {=+_xlfn.IFS(I30>114%,H30*0.02,I30>109%,H30*0.015,I30>104%,H30*0.0125,I30>99%,H30*0.01,I30<99%,H30*0)} -> 0
B31: 28 - GOMEZ PABLO | C31: 27159169 | D31: =IFERROR(+VLOOKUP(B31,COMISIONES!A:E,5,FALSE),"0")*1 -> 1606565 | E31: 895356.64 | F31: =+D31-E31 -> 711208.32 | G31: =+D31/C31 -> 0.059153687 | H31: =+D31/$N$3*$N$4 -> 20885345 | I31: =+H31/C31 -> 0.76899793 | J31: =+D31/$N$3 -> 803282.48 | K31: =+(C31-D31)/$N$2 -> 1064691.8 | L31: {=+_xlfn.IFS(I31>114%,H31*0.02,I31>109%,H31*0.015,I31>104%,H31*0.0125,I31>99%,H31*0.01,I31<99%,H31*0)} -> 0
B32: 33 - NICOLAS AZULA | C32: 21525000 | D32: =IFERROR(+VLOOKUP(B32,COMISIONES!A:E,5,FALSE),"0")*1 -> 1415676.5 | E32: 1007466.4 | F32: =+D32-E32 -> 408210.09 | G32: =+D32/C32 -> 0.065768944 | H32: =+D32/$N$3*$N$4 -> 18403795 | I32: =+H32/C32 -> 0.85499627 | J32: =+D32/$N$3 -> 707838.26 | K32: =+(C32-D32)/$N$2 -> 837888.48 | L32: {=+_xlfn.IFS(I32>114%,H32*0.02,I32>109%,H32*0.015,I32>104%,H32*0.0125,I32>99%,H32*0.01,I32<99%,H32*0)} -> 0
B33: 37 - PEREZ ESQUIVEL BRUNO NICOLAS | C33: 25274655 | D33: =IFERROR(+VLOOKUP(B33,COMISIONES!A:E,5,FALSE),"0")*1 -> 512291.09 | E33: 372346.89 | F33: =+D33-E33 -> 139944.2 | G33: =+D33/C33 -> 0.020268965 | H33: =+D33/$N$3*$N$4 -> 6659784.2 | I33: =+H33/C33 -> 0.26349654 | J33: =+D33/$N$3 -> 256145.55 | K33: =+(C33-D33)/$N$2 -> 1031765.2 | L33: {=+_xlfn.IFS(I33>114%,H33*0.02,I33>109%,H33*0.015,I33>104%,H33*0.0125,I33>99%,H33*0.01,I33<99%,H33*0)} -> 0
B34: 24 - MARTINEZ JORGE NICOLAS | C34: 25865875 | D34: =IFERROR(+VLOOKUP(B34,COMISIONES!A:E,5,FALSE),"0")*1 -> 1843966.6 | E34: 929596.92 | F34: =+D34-E34 -> 914369.64 | G34: =+D34/C34 -> 0.071289549 | H34: =+D34/$N$3*$N$4 -> 23971565 | I34: =+H34/C34 -> 0.92676414 | J34: =+D34/$N$3 -> 921983.28 | K34: =+(C34-D34)/$N$2 -> 1000912.9 | L34: {=+_xlfn.IFS(I34>114%,H34*0.02,I34>109%,H34*0.015,I34>104%,H34*0.0125,I34>99%,H34*0.01,I34<99%,H34*0)} -> 0
B35: 7 - VALLEJOS EDUARDO | C35: 1.2506204e+08 | D35: =IFERROR(+VLOOKUP(B35,COMISIONES!A:E,5,FALSE),"0")*1 -> 9048937.8 | E35: 2114567.1 | F35: =+D35-E35 -> 6934370.7 | G35: =+D35/C35 -> 0.072355589 | H35: =+D35/$N$3*$N$4 -> 1.1763619e+08 | I35: =+H35/C35 -> 0.94062266 | J35: =+D35/$N$3 -> 4524468.9 | K35: =+(C35-D35)/$N$2 -> 4833879.4 | L35: {=+_xlfn.IFS(I35>114%,H35*0.0125,I35>109%,H35*0.01,I35>104%,H35*0.0075,I35>99%,H35*0.005,I35<99%,H35*0)} -> 0
B36: 57 - ROUBINEAU SEBASTIAN | C36: 36592500 | D36: =IFERROR(+VLOOKUP(B36,COMISIONES!A:E,5,FALSE),"0")*1 -> 941292.3 | E36: 100345.76 | F36: =+D36-E36 -> 840946.55 | G36: =+D36/C36 -> 0.02572364 | H36: =+D36/$N$3*$N$4 -> 12236800 | I36: =+H36/C36 -> 0.33440732 | J36: =+D36/$N$3 -> 470646.15 | K36: =+(C36-D36)/$N$2 -> 1485467 | L36: {=+_xlfn.IFS(I36>109%,H36*0.015,I36>104%,H36*0.0125,I36>99%,H36*0.01,I36<99%,H36*0)} -> 0
B37: 1 - VERA ERNESTO | C37: 37270463 | D37: =IFERROR(+VLOOKUP(B37,COMISIONES!A:E,5,FALSE),"0")*1 -> 3183466.3 | E37: 1828232.5 | F37: =+D37-E37 -> 1355233.8 | G37: =+D37/C37 -> 0.085415258 | H37: =+D37/$N$3*$N$4 -> 41385061 | I37: =+H37/C37 -> 1.1103984 | J37: =+D37/$N$3 -> 1591733.1 | K37: =+(C37-D37)/$N$2 -> 1420291.5 | L37: {=+_xlfn.IFS(I37>114%,H37*0.02,I37>109%,H37*0.015,I37>104%,H37*0.0125,I37>99%,H37*0.01,I37<99%,H37*0)} -> 620775.92
C38: 5.2175471e+08 | D38: =+SUM(D25:D37) -> 32445785 | E38: 15229828 | F38: =+D38-E38 -> 17215956 | G38: =+D38/C38 -> 0.062185897 | H38: =+D38/$N$3*$N$4 -> 4.217952e+08 | I38: =+H38/C38 -> 0.80841666 | J38: =+D38/$N$3 -> 16222892 | K38: =+(C38-D38)/$N$2 -> 20387872
A39: MAXI | B39: 58 - BLADIMIR LEZCANO | C39: 35000000 | D39: =IFERROR(+VLOOKUP(B39,COMISIONES!A:E,5,FALSE),"0")*1 -> 0 | E39: 0 | F39: =+D39-E39 -> 0 | G39: =+D39/C39 -> 0 | H39: =+D39/$N$3*$N$4 -> 0 | I39: =+H39/C39 -> 0 | J39: =+D39/$N$3 -> 0 | K39: =+(C39-D39)/$N$2 -> 1458333.3 | L39: {=+_xlfn.IFS(I39>114%,H39*0.02,I39>109%,H39*0.015,I39>104%,H39*0.0125,I39>99%,H39*0.01,I39<99%,H39*0)} -> 0
B40: 59 - LEIVA SILVIO | C40: 30000000 | D40: =IFERROR(+VLOOKUP(B40,COMISIONES!A:E,5,FALSE),"0")*1 -> 0 | E40: 0 | F40: =+D40-E40 -> 0 | G40: =+D40/C40 -> 0 | H40: =+D40/$N$3*$N$4 -> 0 | I40: =+H40/C40 -> 0 | J40: =+D40/$N$3 -> 0 | K40: =+(C40-D40)/$N$2 -> 1250000 | L40: {=+_xlfn.IFS(I40>114%,H40*0.02,I40>109%,H40*0.015,I40>104%,H40*0.0125,I40>99%,H40*0.01,I40<99%,H40*0)} -> 0
...

Sheet COBERTURA
A1: SUPERVISOR | C1: VENDEDOR | D1: COBERTURA TOTAL | E1: DIA ANTERIOR | F1: INCREMENTO DIARIO | G1: CARTERA TOTAL | H1: CCC | I1: CCC FALTANTE 85% | P1: Cod vdor | R1: Cobertura x Un de negocio
A2: MARTIN (SUPERVISOR) | B2: 22 | C2: =+AVANCE!B11 -> 22 - ALMIRON NICOLAS | D2: =H2/G2 -> 0.12 | E2: 33 | F2: =+H2-E2 -> -24 | G2: =VLOOKUP(B2,'Base Cobertura'!$A:$C,3,FALSE) -> 75 | H2: =VLOOKUP(B2,'Base Cobertura'!$A:$C,2,FALSE) -> 9 | I2: =(+G2*$M$2)-H2 -> 54.75 | J2: bien | K2: bien | L2: OBJETIVO | M2: 0.85 | P2: 25 | Q2: =VLOOKUP(P2,$B:$C,2,FALSE) -> 25 - KALATAKI GUSTAVO | R2: =VLOOKUP(P2,$B:$C,2,FALSE) -> 25 - KALATAKI GUSTAVO | S2: CCC | T2: CARTERA TOTAL | U2: % ALCANZADO
B3: 49 | C3: =+AVANCE!#REF! -> #REF! | D3: =H3/G3 -> 0 | E3: 1 | F3: =+H3-E3 -> -1 | G3: =VLOOKUP(B3,'Base Cobertura'!$A:$C,3,FALSE) -> 243 | H3: =VLOOKUP(B3,'Base Cobertura'!$A:$C,2,FALSE) -> 0 | I3: =(+G3*$M$2)-H3 -> 206.55 | J3: mal | K3: chaca | P3: {=+_xlfn._xlws.FILTER('Base Cobertura'!E:I,'Base Cobertura'!E:E=COBERTURA!P2)} -> 25 | Q3: 25 | R3: 147 - ALMACEN | S3: 0 | T3: 172 | U3: =+S3/T3 -> 0
B4: 20 | C4: =+AVANCE!B2 -> 20 - FLORES JAVIER | D4: =H4/G4 -> 0.1277533 | E4: 126 | F4: =+H4-E4 -> -97 | G4: =VLOOKUP(B4,'Base Cobertura'!$A:$C,3,FALSE) -> 227 | H4: =VLOOKUP(B4,'Base Cobertura'!$A:$C,2,FALSE) -> 29 | I4: =(+G4*$M$2)-H4 -> 163.95 | J4: re bien | K4: muy bien | P4: 25 | Q4: 0 | R4: 147 - Articulos Sin Asociar Agrupacion | S4: 0 | T4: 172 | U4: =+S4/T4 -> 0
B5: 15 | C5: =+AVANCE!B12 -> 15 - GALARZA GERARDO | D5: =H5/G5 -> 0.061538462 | E5: 21 | F5: =+H5-E5 -> -17 | G5: =VLOOKUP(B5,'Base Cobertura'!$A:$C,3,FALSE) -> 65 | H5: =VLOOKUP(B5,'Base Cobertura'!$A:$C,2,FALSE) -> 4 | I5: =(+G5*$M$2)-H5 -> 51.25 | K5: muy bien | P5: 25 | Q5: 0 | R5: 147 - BEBIDAS | S5: 0 | T5: 172 | U5: =+S5/T5 -> 0
B6: 19 | C6: =+AVANCE!B3 -> 19 - GONZALEZ MARCELO | D6: =H6/G6 -> 0.11057692 | E6: 100 | F6: =+H6-E6 -> -77 | G6: =VLOOKUP(B6,'Base Cobertura'!$A:$C,3,FALSE) -> 208 | H6: =VLOOKUP(B6,'Base Cobertura'!$A:$C,2,FALSE) -> 23 | I6: =(+G6*$M$2)-H6 -> 153.8 | J6: apretarlo | K6: apretarlo | P6: 25 | Q6: 0 | R6: 147 - CHOCOLATE | S6: 0 | T6: 172 | U6: =+S6/T6 -> 0
B7: 16 | C7: =+AVANCE!B4 -> 16 - GOMEZ MATÍAS | D7: =H7/G7 -> 0.11055276 | E7: 81 | F7: =+H7-E7 -> -59 | G7: =VLOOKUP(B7,'Base Cobertura'!$A:$C,3,FALSE) -> 199 | H7: =VLOOKUP(B7,'Base Cobertura'!$A:$C,2,FALSE) -> 22 | I7: =(+G7*$M$2)-H7 -> 147.15 | J7: apretarlo | K7: apretarlo | P7: 25 | Q7: 0 | R7: 147 - GALLETITAS | S7: 0 | T7: 172 | U7: =+S7/T7 -> 0
B8: 12 | C8: =+AVANCE!B5 -> 12 - GUTIERREZ MARCOS DAVID | D8: =H8/G8 -> 0.11214953 | E8: 89 | F8: =+H8-E8 -> -65 | G8: =VLOOKUP(B8,'Base Cobertura'!$A:$C,3,FALSE) -> 214 | H8: =VLOOKUP(B8,'Base Cobertura'!$A:$C,2,FALSE) -> 24 | I8: =(+G8*$M$2)-H8 -> 157.9 | J8: bien | K8: apretarlo | P8: 25 | Q8: 0 | R8: 147 - GOLOSINAS | S8: 0 | T8: 172 | U8: =+S8/T8 -> 0
B9: 11 | C9: =+AVANCE!B6 -> 11 - SANCHEZ RICARDO | D9: =H9/G9 -> 0.18934911 | E9: 92 | F9: =+H9-E9 -> -60 | G9: =VLOOKUP(B9,'Base Cobertura'!$A:$C,3,FALSE) -> 169 | H9: =VLOOKUP(B9,'Base Cobertura'!$A:$C,2,FALSE) -> 32 | I9: =(+G9*$M$2)-H9 -> 111.65 | J9: bien | K9: apretarlo con ema | P9: 25 | Q9: 0 | R9: 147 - MASCOTAS | S9: 0 | T9: 172 | U9: =+S9/T9 -> 0
B10: 8 | C10: =+AVANCE!B7 -> 8 - RAVAROTTO EMANUEL | D10: =H10/G10 -> 0.041025641 | E10: 64 | F10: =+H10-E10 -> -56 | G10: =VLOOKUP(B10,'Base Cobertura'!$A:$C,3,FALSE) -> 195 | H10: =VLOOKUP(B10,'Base Cobertura'!$A:$C,2,FALSE) -> 8 | I10: =(+G10*$M$2)-H10 -> 157.75 | J10: apretarlo | K10: apretarlo | P10: 25 | Q10: 0 | R10: 147 - NO PERECEDEROS | S10: 0 | T10: 172 | U10: =+S10/T10 -> 0
B11: 52 | C11: =+AVANCE!B13 -> 52 - MARSALL NICOLAS | D11: =H11/G11 -> 0.019607843 | E11: 19 | F11: =+H11-E11 -> -17 | G11: =VLOOKUP(B11,'Base Cobertura'!$A:$C,3,FALSE) -> 102 | H11: =VLOOKUP(B11,'Base Cobertura'!$A:$C,2,FALSE) -> 2 | I11: =(+G11*$M$2)-H11 -> 84.7 | J11: verlo | P11: 25 | Q11: 0 | R11: 147 - PILAS | S11: 0 | T11: 172 | U11: =+S11/T11 -> 0
B12: 53 | C12: =+AVANCE!B14 -> 53 - SANDOVAL RODRIGO | D12: =H12/G12 -> 0.047619048 | E12: 24 | F12: =+H12-E12 -> -19 | G12: =VLOOKUP(B12,'Base Cobertura'!$A:$C,3,FALSE) -> 105 | H12: =VLOOKUP(B12,'Base Cobertura'!$A:$C,2,FALSE) -> 5 | I12: =(+G12*$M$2)-H12 -> 84.25 | J12: verlo
B13: 5 | C13: =+AVANCE!B8 -> 5 - SCHELOVER RAUL | D13: =H13/G13 -> 0.13793103 | E13: 144 | F13: =+H13-E13 -> -108 | G13: =VLOOKUP(B13,'Base Cobertura'!$A:$C,3,FALSE) -> 261 | H13: =VLOOKUP(B13,'Base Cobertura'!$A:$C,2,FALSE) -> 36 | I13: =(+G13*$M$2)-H13 -> 185.85 | J13: re bien | K13: muy bien
B14: 4 | C14: =+AVANCE!B9 -> 4 - TUR SPRINGER FERNANDO | D14: =H14/G14 -> 0.1043956 | E14: 85 | F14: =+H14-E14 -> -66 | G14: =VLOOKUP(B14,'Base Cobertura'!$A:$C,3,FALSE) -> 182 | H14: =VLOOKUP(B14,'Base Cobertura'!$A:$C,2,FALSE) -> 19 | I14: =(+G14*$M$2)-H14 -> 135.7 | J14: bien | K14: muy bien
F15: =+SUM(F2:F14) -> -666 | G15: =+SUM(G2:G14) -> 2245 | H15: =+SUM(H2:H14) -> 213
A16: CRISTIAN (SUPERVISOR) | B16: 31 | C16: =+AVANCE!B21 -> 31 - RENZO RAMOS | D16: =H16/G16 -> 0.10559006 | E16: 90 | F16: =+H16-E16 -> -73 | G16: =VLOOKUP(B16,'Base Cobertura'!$A:$C,3,FALSE) -> 161 | H16: =VLOOKUP(B16,'Base Cobertura'!$A:$C,2,FALSE) -> 17 | I16: =(+G16*$M$2)-H16 -> 119.85 | J16: bien | K16: bien
B17: 54 | C17: =+AVANCE!B23 -> 54 - BARTSCHAT EMILIANO NAHUEL | D17: =H17/G17 -> 0.060913706 | E17: 92 | F17: =+H17-E17 -> -80 | G17: =VLOOKUP(B17,'Base Cobertura'!$A:$C,3,FALSE) -> 197 | H17: =VLOOKUP(B17,'Base Cobertura'!$A:$C,2,FALSE) -> 12 | I17: =(+G17*$M$2)-H17 -> 155.45 | J17: bien | K17: chaca
B18: 21 | C18: =+AVANCE!B19 -> 21 - CATAN MATIAS | D18: =H18/G18 -> 0.11695906 | E18: 88 | F18: =+H18-E18 -> -68 | G18: =VLOOKUP(B18,'Base Cobertura'!$A:$C,3,FALSE) -> 171 | H18: =VLOOKUP(B18,'Base Cobertura'!$A:$C,2,FALSE) -> 20 | I18: =(+G18*$M$2)-H18 -> 125.35 | J18: apretarlo | K18: bien
B19: 23 | C19: =+AVANCE!B20 -> 23 - DELGADO JOSÉ | D19: =H19/G19 -> 0.17532468 | E19: 95 | F19: =+H19-E19 -> -68 | G19: =VLOOKUP(B19,'Base Cobertura'!$A:$C,3,FALSE) -> 154 | H19: =VLOOKUP(B19,'Base Cobertura'!$A:$C,2,FALSE) -> 27 | I19: =(+G19*$M$2)-H19 -> 103.9 | J19: apretarlo | K19: muy bien
B20: 18 | C20: =+AVANCE!B18 -> 18 - HERRERA PABLO | D20: =H20/G20 -> 0.12777778 | E20: 83 | F20: =+H20-E20 -> -60 | G20: =VLOOKUP(B20,'Base Cobertura'!$A:$C,3,FALSE) -> 180 | H20: =VLOOKUP(B20,'Base Cobertura'!$A:$C,2,FALSE) -> 23 | I20: =(+G20*$M$2)-H20 -> 130 | J20: bien | K20: bien
B21: 44 | C21: =+AVANCE!B22 -> 44 - MONGES CESAR LUIS | D21: =H21/G21 -> 0.11627907 | E21: 64 | F21: =+H21-E21 -> -44 | G21: =VLOOKUP(B21,'Base Cobertura'!$A:$C,3,FALSE) -> 172 | H21: =VLOOKUP(B21,'Base Cobertura'!$A:$C,2,FALSE) -> 20 | I21: =(+G21*$M$2)-H21 -> 126.2 | J21: apretarlo | K21: muy bien
B22: 56 | C22: =+AVANCE!B42 -> 56 - JUAN ANDRES SANCHEZ | D22: =H22/G22 -> 0.1928934 | E22: 66 | F22: =+H22-E22 -> -28 | G22: =VLOOKUP(B22,'Base Cobertura'!$A:$C,3,FALSE) -> 197 | H22: =VLOOKUP(B22,'Base Cobertura'!$A:$C,2,FALSE) -> 38 | I22: =(+G22*$M$2)-H22 -> 129.45 | J22: apretarlo | K22: apretar/charlar
B23: 2 | C23: =+AVANCE!B16 -> 2 - OJEDA NORBERTO | D23: =H23/G23 -> 0.18644068 | E23: 70 | F23: =+H23-E23 -> -48 | G23: =VLOOKUP(B23,'Base Cobertura'!$A:$C,3,FALSE) -> 118 | H23: =VLOOKUP(B23,'Base Cobertura'!$A:$C,2,FALSE) -> 22 | I23: =(+G23*$M$2)-H23 -> 78.3 | J23: apretarlo | K23: apretar
B24: 3 | C24: =+AVANCE!B17 -> 3 - VIDAL NAHUEL | D24: =H24/G24 -> 0.17647059 | E24: 79 | F24: =+H24-E24 -> -49 | G24: =VLOOKUP(B24,'Base Cobertura'!$A:$C,3,FALSE) -> 170 | H24: =VLOOKUP(B24,'Base Cobertura'!$A:$C,2,FALSE) -> 30 | I24: =(+G24*$M$2)-H24 -> 114.5 | J24: abrazo | K24: muy bien
F25: =+SUM(F16:F24) -> -518 | G25: =+SUM(G16:G24) -> 1520 | H25: =+SUM(H16:H24) -> 209
A26: GONZALO (SUPERVISOR) | B26: 32 | C26: =+AVANCE!B25 -> 32 - CABRAL GONZALO | D26: =H26/G26 -> 0.034482759 | E26: 20 | F26: =+H26-E26 -> -18 | G26: =VLOOKUP(B26,'Base Cobertura'!$A:$C,3,FALSE) -> 58 | H26: =VLOOKUP(B26,'Base Cobertura'!$A:$C,2,FALSE) -> 2 | I26: =(+G26*$M$2)-H26 -> 47.3 | J26: bien | K26: apretar
B27: 36 | C27: =+AVANCE!B26 -> 36 - COSARINSKI DIEGO | D27: =H27/G27 -> 0.08125 | E27: 68 | F27: =+H27-E27 -> -55 | G27: =VLOOKUP(B27,'Base Cobertura'!$A:$C,3,FALSE) -> 160 | H27: =VLOOKUP(B27,'Base Cobertura'!$A:$C,2,FALSE) -> 13 | I27: =(+G27*$M$2)-H27 -> 123 | J27: apretarlo | K27: apretar
B28: 9 | C28: =+AVANCE!B27 -> 9 - ESTIGARRIBIA DAVID | D28: =H28/G28 -> 0.1025641 | E28: 80 | F28: =+H28-E28 -> -64 | G28: =VLOOKUP(B28,'Base Cobertura'!$A:$C,3,FALSE) -> 156 | H28: =VLOOKUP(B28,'Base Cobertura'!$A:$C,2,FALSE) -> 16 | I28: =(+G28*$M$2)-H28 -> 116.6 | J28: apretarlo | K28: bien
B29: 40 | C29: =+AVANCE!B28 -> 40 - IBARROLA JORGE | D29: =H29/G29 -> 0.064 | E29: 68 | F29: =+H29-E29 -> -52 | G29: =VLOOKUP(B29,'Base Cobertura'!$A:$C,3,FALSE) -> 250 | H29: =VLOOKUP(B29,'Base Cobertura'!$A:$C,2,FALSE) -> 16 | I29: =(+G29*$M$2)-H29 -> 196.5 | J29: apretarlo | K29: apretar
B30: 27 | C30: =+AVANCE!B29 -> 27 - GOMEZ ADRIÁN | D30: =H30/G30 -> 0.17293233 | E30: 73 | F30: =+H30-E30 -> -50 | G30: =VLOOKUP(B30,'Base Cobertura'!$A:$C,3,FALSE) -> 133 | H30: =VLOOKUP(B30,'Base Cobertura'!$A:$C,2,FALSE) -> 23 | I30: =(+G30*$M$2)-H30 -> 90.05 | J30: bien | K30: apretar
B31: 10 | C31: =+AVANCE!B30 -> 10 - BRITEZ EMMANUEL | D31: =H31/G31 -> 0.10382514 | E31: 40 | F31: =+H31-E31 -> -21 | G31: =VLOOKUP(B31,'Base Cobertura'!$A:$C,3,FALSE) -> 183 | H31: =VLOOKUP(B31,'Base Cobertura'!$A:$C,2,FALSE) -> 19 | I31: =(+G31*$M$2)-H31 -> 136.55 | J31: apretarlo | K31: apretar
B32: 28 | C32: =+AVANCE!B31 -> 28 - GOMEZ PABLO | D32: =H32/G32 -> 0.11309524 | E32: 67 | F32: =+H32-E32 -> -48 | G32: =VLOOKUP(B32,'Base Cobertura'!$A:$C,3,FALSE) -> 168 | H32: =VLOOKUP(B32,'Base Cobertura'!$A:$C,2,FALSE) -> 19 | I32: =(+G32*$M$2)-H32 -> 123.8 | J32: apretarlo | K32: apretar
B33: 33 | C33: =+AVANCE!B32 -> 33 - NICOLAS AZULA | D33: =H33/G33 -> 0.17365269 | E33: 66 | F33: =+H33-E33 -> -37 | G33: =VLOOKUP(B33,'Base Cobertura'!$A:$C,3,FALSE) -> 167 | H33: =VLOOKUP(B33,'Base Cobertura'!$A:$C,2,FALSE) -> 29 | I33: =(+G33*$M$2)-H33 -> 112.95 | J33: apretarlo | K33: apretar
B34: 37 | C34: =+AVANCE!B33 -> 37 - PEREZ ESQUIVEL BRUNO NICOLAS | D34: =H34/G34 -> 0.056338028 | E34: 82 | F34: =+H34-E34 -> -74 | G34: =VLOOKUP(B34,'Base Cobertura'!$A:$C,3,FALSE) -> 142 | H34: =VLOOKUP(B34,'Base Cobertura'!$A:$C,2,FALSE) -> 8 | I34: =(+G34*$M$2)-H34 -> 112.7 | J34: bien | K34: apretar
B35: 24 | C35: =+AVANCE!B34 -> 24 - MARTINEZ JORGE NICOLAS | D35: =H35/G35 -> 0.08988764 | E35: 81 | F35: =+H35-E35 -> -65 | G35: =VLOOKUP(B35,'Base Cobertura'!$A:$C,3,FALSE) -> 178 | H35: =VLOOKUP(B35,'Base Cobertura'!$A:$C,2,FALSE) -> 16 | I35: =(+G35*$M$2)-H35 -> 135.3 | J35: apretarlo | K35: apretar
B36: 7 | C36: =+AVANCE!B35 -> 7 - VALLEJOS EDUARDO | D36: =H36/G36 -> 0.017391304 | E36: 0 | F36: =+H36-E36 -> 2 | G36: =VLOOKUP(B36,'Base Cobertura'!$A:$C,3,FALSE) -> 115 | H36: =VLOOKUP(B36,'Base Cobertura'!$A:$C,2,FALSE) -> 2 | I36: =(+G36*$M$2)-H36 -> 95.75 | J36: apretarlo
B37: 57 | C37: =+AVANCE!B36 -> 57 - ROUBINEAU SEBASTIAN | D37: =H37/G37 -> 0.0095238095 | E37: 17 | F37: =+H37-E37 -> -16 | G37: =VLOOKUP(B37,'Base Cobertura'!$A:$C,3,FALSE) -> 105 | H37: =VLOOKUP(B37,'Base Cobertura'!$A:$C,2,FALSE) -> 1 | I37: =(+G37*$M$2)-H37 -> 88.25 | J37: verlo
B38: 1 | C38: =+AVANCE!B37 -> 1 - VERA ERNESTO | D38: =H38/G38 -> 0.13385827 | E38: 60 | F38: =+H38-E38 -> -43 | G38: =VLOOKUP(B38,'Base Cobertura'!$A:$C,3,FALSE) -> 127 | H38: =VLOOKUP(B38,'Base Cobertura'!$A:$C,2,FALSE) -> 17 | I38: =(+G38*$M$2)-H38 -> 90.95 | J38: bien | K38: bien
F39: =+SUM(F26:F38) -> -541 | G39: =+SUM(G26:G38) -> 1942 | H39: =+SUM(H26:H38) -> 181
A40: MAXI (SUPERVISOR) | B40: 58 | C40: 58 - BLADIMIR LEZCANO | D40: =H40/G40 -> 0 | E40: 60 | F40: =+H40-E40 -> -60 | G40: =VLOOKUP(B40,'Base Cobertura'!$A:$C,3,FALSE) -> 122 | H40: =VLOOKUP(B40,'Base Cobertura'!$A:$C,2,FALSE) -> 0 | I40: =(+G40*$M$2)-H40 -> 103.7
...

Sheet Venta C
B1: VENDEDOR/ SUPERVISOR | C1: Venta NETA ARTICULOS C
A2: 20 | B2: 20 - FLORES JAVIER | C2: =IFERROR(VLOOKUP(A2,'Base venta C'!$E:$P,12,FALSE),"0")*1 -> 343887.46
A3: 19 | B3: 19 - GONZALEZ MARCELO | C3: =IFERROR(VLOOKUP(A3,'Base venta C'!$E:$P,12,FALSE),"0")*1 -> 365262.82
A4: 16 | B4: 16 - GOMEZ MATÍAS | C4: =IFERROR(VLOOKUP(A4,'Base venta C'!$E:$P,12,FALSE),"0")*1 -> 271002.4
A5: 12 | B5: 12 - GUTIERREZ MARCOS DAVID | C5: =IFERROR(VLOOKUP(A5,'Base venta C'!$E:$P,12,FALSE),"0")*1 -> 284624.48
A6: 11 | B6: 11 - ZACARIAS DAVID | C6: =IFERROR(VLOOKUP(A6,'Base venta C'!$E:$P,12,FALSE),"0")*1 -> 166886.05
A7: 8 | B7: 8 - RAVAROTTO EMANUEL | C7: =IFERROR(VLOOKUP(A7,'Base venta C'!$E:$P,12,FALSE),"0")*1 -> 284846.64
A8: 5 | B8: 5 - SCHELOVER RAUL | C8: =IFERROR(VLOOKUP(A8,'Base venta C'!$E:$P,12,FALSE),"0")*1 -> 322216.7
A9: 4 | B9: 4 - TUR SPRINGER FERNANDO | C9: =IFERROR(VLOOKUP(A9,'Base venta C'!$E:$P,12,FALSE),"0")*1 -> 875228.78
B10: MARTIN (SUPERVISOR) PREVENTA
A11: 22 | B11: 22 - ALMIRON NICOLAS | C11: =IFERROR(VLOOKUP(A11,'Base venta C'!$E:$P,12,FALSE),"0")*1 -> 270784.37
A12: 49 | B12: 49 - ESCOBAR RAÚL | C12: =IFERROR(VLOOKUP(A12,'Base venta C'!$E:$P,12,FALSE),"0")*1 -> 76349.44
A13: 15 | B13: 15 - GALARZA GERARDO | C13: =IFERROR(VLOOKUP(A13,'Base venta C'!$E:$P,12,FALSE),"0")*1 -> 1329007.3
A14: 52 | B14: 52 - MARSALL NICOLAS | C14: =IFERROR(VLOOKUP(A14,'Base venta C'!$E:$P,12,FALSE),"0")*1 -> 155315.73
A15: 53 | B15: 53 - SANDOVAL RODRIGO | C15: =IFERROR(VLOOKUP(A15,'Base venta C'!$E:$P,12,FALSE),"0")*1 -> 833691.44
B16: MARTIN (SUPERVISOR)
A17: 2 | B17: 2 - OJEDA NORBERTO | C17: =IFERROR(VLOOKUP(A17,'Base venta C'!$E:$P,12,FALSE),"0")*1 -> 355809.05
A18: 3 | B18: 3 - VIDAL NAHUEL | C18: =IFERROR(VLOOKUP(A18,'Base venta C'!$E:$P,12,FALSE),"0")*1 -> 461503.95
A19: 18 | B19: 18 - HERRERA PABLO | C19: =IFERROR(VLOOKUP(A19,'Base venta C'!$E:$P,12,FALSE),"0")*1 -> 465462.81
A20: 21 | B20: 21 - CATAN MATIAS | C20: =IFERROR(VLOOKUP(A20,'Base venta C'!$E:$P,12,FALSE),"0")*1 -> 300786.17
A21: 23 | B21: 23 - DELGADO JOSÉ | C21: =IFERROR(VLOOKUP(A21,'Base venta C'!$E:$P,12,FALSE),"0")*1 -> 517438.51
A22: 31 | B22: 31 - BARTSCHAT EMILIANO NAHUEL | C22: =IFERROR(VLOOKUP(A22,'Base venta C'!$E:$P,12,FALSE),"0")*1 -> 346898.23
A23: 44 | B23: 44 - MONGE CÉSAR LUIS | C23: =IFERROR(VLOOKUP(A23,'Base venta C'!$E:$P,12,FALSE),"0")*1 -> 475747.4
A24: 54 | B24: 54 - CAÑETE DIEGO | C24: =IFERROR(VLOOKUP(A24,'Base venta C'!$E:$P,12,FALSE),"0")*1 -> 394891.73
A25: 56 | B25: 56 - JUAN ANDRES SANCHEZ | C25: =IFERROR(VLOOKUP(A25,'Base venta C'!$E:$P,12,FALSE),"0")*1 -> 254599.35
B26: CRISTIAN (SUPERVISOR)
A27: 32 | B27: 32 - BLANCO FERNANDO | C27: =IFERROR(VLOOKUP(A27,'Base venta C'!$E:$P,12,FALSE),"0")*1 -> 357064.39
A28: 36 | B28: 36 - STELLA MARIS CANO | C28: =IFERROR(VLOOKUP(A28,'Base venta C'!$E:$P,12,FALSE),"0")*1 -> 228911.14
A29: 9 | B29: 9 - ESTIGARRIBIA DAVID | C29: =IFERROR(VLOOKUP(A29,'Base venta C'!$E:$P,12,FALSE),"0")*1 -> 449396.93
A30: 40 | B30: 40 - GARCIA BOGARIN SANTIAGO | C30: =IFERROR(VLOOKUP(A30,'Base venta C'!$E:$P,12,FALSE),"0")*1 -> 259074.86
A31: 27 | B31: 27 - GOMEZ ADRIÁN | C31: =IFERROR(VLOOKUP(A31,'Base venta C'!$E:$P,12,FALSE),"0")*1 -> 315929.47
A32: 10 | B32: 10 - SEGOVIA JUAN CRUZ | C32: =IFERROR(VLOOKUP(A32,'Base venta C'!$E:$P,12,FALSE),"0")*1 -> 385757.33
A33: 28 | B33: 28 - GOMEZ PABLO | C33: =IFERROR(VLOOKUP(A33,'Base venta C'!$E:$P,12,FALSE),"0")*1 -> 216785.26
A34: 33 | B34: 33 - NICOLAS AZULA | C34: =IFERROR(VLOOKUP(A34,'Base venta C'!$E:$P,12,FALSE),"0")*1 -> 218111.24
A35: 37 | B35: 37 - PEREZ ESQUIVEL BRUNO NICOLAS | C35: =IFERROR(VLOOKUP(A35,'Base venta C'!$E:$P,12,FALSE),"0")*1 -> 160532.76
A36: 24 | B36: 24 - DELGADO HERNAN GABRIEL | C36: =IFERROR(VLOOKUP(A36,'Base venta C'!$E:$P,12,FALSE),"0")*1 -> 294217.66
A37: 7 | B37: 7 - VALLEJOS EDUARDO | C37: =IFERROR(VLOOKUP(A37,'Base venta C'!$E:$P,12,FALSE),"0")*1 -> 264122.85
A38: 57 | B38: 57 - ZARATE NICOLAS | C38: =IFERROR(VLOOKUP(A38,'Base venta C'!$E:$P,12,FALSE),"0")*1 -> 62179.29
A39: 1 | B39: 1 - VERA ERNESTO | C39: =IFERROR(VLOOKUP(A39,'Base venta C'!$E:$P,12,FALSE),"0")*1 -> 1671221.4
B40: GONZALO (SUPERVISOR)
...

Sheet Base Cobertura
A1: COBERTURAMESENCURSO | F1: COBERTURAUNIDADDENEGOCIO
A2: Nro Vendedor | B2: CCC x Bultos | C2: Cartera Clientes | F2: Nro Vendedor | G2: Agrupacion | H2: CCC x Bultos | I2: Cartera Clientes
B3: 1 | C3: 3478 | G3: 147 - ALMACEN | H3: 1 | I3: 3478
A4: 1 | B4: 17 | C4: 127 | G4: 147 - Articulos Sin Asociar Agrupacion | I4: 3478
A5: 10 | B5: 19 | C5: 183 | G5: 147 - BEBIDAS | I5: 3478
A6: 100 | B6: 14 | C6: 2030 | G6: 147 - CHOCOLATE | I6: 3478
A7: 11 | B7: 32 | C7: 169 | G7: 147 - GALLETITAS | I7: 3478
A8: 12 | B8: 24 | C8: 214 | G8: 147 - GOLOSINAS | H8: 1 | I8: 3478
A9: 123 | B9: 16 | C9: 491 | G9: 147 - MASCOTAS | H9: 1 | I9: 3478
A10: 15 | B10: 4 | C10: 65 | G10: 147 - NO PERECEDEROS | I10: 3478
A11: 16 | B11: 22 | C11: 199 | G11: 147 - PILAS | I11: 3478
A12: 18 | B12: 23 | C12: 180 | E12: =+F12 -> 1 | F12: 1 | G12: 147 - ALMACEN | H12: 5 | I12: 127
A13: 19 | B13: 23 | C13: 208 | E13: =+$E$12 -> 1 | G13: 147 - Articulos Sin Asociar Agrupacion | H13: 6 | I13: 127
A14: 2 | B14: 22 | C14: 118 | E14: =+$E$12 -> 1 | G14: 147 - BEBIDAS | H14: 8 | I14: 127
A15: 20 | B15: 29 | C15: 227 | E15: =+$E$12 -> 1 | G15: 147 - CHOCOLATE | H15: 8 | I15: 127
A16: 21 | B16: 20 | C16: 171 | E16: =+$E$12 -> 1 | G16: 147 - GALLETITAS | H16: 9 | I16: 127
A17: 22 | B17: 9 | C17: 75 | E17: =+$E$12 -> 1 | G17: 147 - GOLOSINAS | H17: 11 | I17: 127
A18: 23 | B18: 27 | C18: 154 | E18: =+$E$12 -> 1 | G18: 147 - MASCOTAS | H18: 3 | I18: 127
A19: 24 | B19: 16 | C19: 178 | E19: =+$E$12 -> 1 | G19: 147 - NO PERECEDEROS | H19: 4 | I19: 127
A20: 25 | C20: 172 | E20: =+$E$12 -> 1 | G20: 147 - PILAS | H20: 5 | I20: 127
A21: 26 | C21: 166 | E21: =+$F$21 -> 10 | F21: 10 | G21: 147 - ALMACEN | H21: 2 | I21: 183
A22: 27 | B22: 23 | C22: 133 | E22: =+$F$21 -> 10 | G22: 147 - Articulos Sin Asociar Agrupacion | H22: 2 | I22: 183
A23: 28 | B23: 19 | C23: 168 | E23: =+$F$21 -> 10 | G23: 147 - BEBIDAS | H23: 6 | I23: 183
A24: 3 | B24: 30 | C24: 170 | E24: =+$F$21 -> 10 | G24: 147 - CHOCOLATE | H24: 9 | I24: 183
A25: 30 | B25: 5 | C25: 139 | E25: =+$F$21 -> 10 | G25: 147 - GALLETITAS | H25: 10 | I25: 183
A26: 31 | B26: 17 | C26: 161 | E26: =+$F$21 -> 10 | G26: 147 - GOLOSINAS | H26: 5 | I26: 183
A27: 32 | B27: 2 | C27: 58 | E27: =+$F$21 -> 10 | G27: 147 - MASCOTAS | H27: 3 | I27: 183
A28: 33 | B28: 29 | C28: 167 | E28: =+$F$21 -> 10 | G28: 147 - NO PERECEDEROS | H28: 1 | I28: 183
A29: 36 | B29: 13 | C29: 160 | E29: =+$F$21 -> 10 | G29: 147 - PILAS | H29: 1 | I29: 183
A30: 37 | B30: 8 | C30: 142 | E30: =+$F$30 -> 100 | F30: 100 | G30: 147 - ALMACEN | H30: 5 | I30: 2030
A31: 4 | B31: 19 | C31: 182 | E31: =+$F$30 -> 100 | G31: 147 - Articulos Sin Asociar Agrupacion | H31: 3 | I31: 2030
A32: 40 | B32: 16 | C32: 250 | E32: =+$F$30 -> 100 | G32: 147 - BEBIDAS | H32: 2 | I32: 2030
A33: 42 | C33: 52 | E33: =+$F$30 -> 100 | G33: 147 - CHOCOLATE | H33: 4 | I33: 2030
A34: 43 | C34: 93 | E34: =+$F$30 -> 100 | G34: 147 - GALLETITAS | H34: 7 | I34: 2030
A35: 44 | B35: 20 | C35: 172 | E35: =+$F$30 -> 100 | G35: 147 - GOLOSINAS | H35: 5 | I35: 2030
A36: 49 | C36: 243 | E36: =+$F$30 -> 100 | G36: 147 - MASCOTAS | H36: 2 | I36: 2030
A37: 5 | B37: 36 | C37: 261 | E37: =+$F$30 -> 100 | G37: 147 - NO PERECEDEROS | H37: 1 | I37: 2030
A38: 52 | B38: 2 | C38: 102 | E38: =+$F$30 -> 100 | G38: 147 - PILAS | H38: 1 | I38: 2030
A39: 53 | B39: 5 | C39: 105 | E39: =+$F$39 -> 11 | F39: 11 | G39: 147 - ALMACEN | H39: 5 | I39: 169
A40: 54 | B40: 12 | C40: 197 | E40: =+$F$39 -> 11 | G40: 147 - Articulos Sin Asociar Agrupacion | H40: 5 | I40: 169
...

Sheet Base venta C
A1: Periodos | B1: Cod. Período | C1: Descripción Período | D1: Vendedor según comprobante | E1: Código | F1: Descripción | G1: Rotacion a-b-c | H1: Código | I1: Descripción | J1: P.P.P. Neto | K1: P.P.P. Final | L1: Cantidades CON Cargo | M1: Cantidades SIN Cargo | N1: Cantidades Totales | O1: Pesos Totales | P1: Importes Netos | Q1: Importes Finales | R1: Cantidad de Facturas | S1: Bultos Promedio | T1: Cantidades en Combos
A2: (001) MAR 2026 | B2: 1 | C2: 46082 | D2: Suc: 001 (000001) VERA ERNESTO | E2: 1 | F2: VERA ERNESTO | G2: (1382) ROTACION C INCENTIVO | H2: 1382 | I2: ROTACION C INCENTIVO | J2: 98746.145 | K2: 122432.8 | L2: 14.2607 | M2: 2.6637 | N2: 16.9244 | O2: 0 | P2: 1671221.4 | Q2: 2072104.4 | R2: 128 | S2: 0.13 | T2: 0
A3: (001) MAR 2026 | B3: 1 | C3: 46082 | D3: Suc: 001 (000002) OJEDA NORBERTO | E3: 2 | F3: OJEDA NORBERTO | G3: (1382) ROTACION C INCENTIVO | H3: 1382 | I3: ROTACION C INCENTIVO | J3: 11815.421 | K3: 14554.453 | L3: 25.5498 | M3: 4.5642 | N3: 30.114 | O3: 0 | P3: 355809.05 | Q3: 438292.15 | R3: 73 | S3: 0.41 | T3: 0
A4: (001) MAR 2026 | B4: 1 | C4: 46082 | D4: Suc: 001 (000003) VIDAL NAHUEL | E4: 3 | F4: VIDAL NAHUEL | G4: (1382) ROTACION C INCENTIVO | H4: 1382 | I4: ROTACION C INCENTIVO | J4: 12029.634 | K4: 14825.838 | L4: 27.3731 | M4: 10.9908 | N4: 38.3639 | O4: 0 | P4: 461503.95 | Q4: 568777.28 | R4: 79 | S4: 0.49 | T4: 0
A5: (001) MAR 2026 | B5: 1 | C5: 46082 | D5: Suc: 001 (000004) TUR SPRINGER FERNANDO | E5: 4 | F5: TUR SPRINGER FERNANDO | G5: (1382) ROTACION C INCENTIVO | H5: 1382 | I5: ROTACION C INCENTIVO | J5: 17624.902 | K5: 21774.702 | L5: 44.3529 | M5: 5.3058 | N5: 49.6586 | O5: 0 | P5: 875228.78 | Q5: 1081302.2 | R5: 100 | S5: 0.5 | T5: 0
A6: (001) MAR 2026 | B6: 1 | C6: 46082 | D6: Suc: 001 (000005) SCHELOVER RAUL | E6: 5 | F6: SCHELOVER RAUL | G6: (1382) ROTACION C INCENTIVO | H6: 1382 | I6: ROTACION C INCENTIVO | J6: 26707.909 | K6: 32656.222 | L6: 7.0172 | M6: 5.0472 | N6: 12.0645 | O6: 0 | P6: 322216.7 | Q6: 393979.93 | R6: 70 | S6: 0.17 | T6: 0
A7: (001) MAR 2026 | B7: 1 | C7: 46082 | D7: Suc: 001 (000007) VALLEJOS EDUARDO | E7: 7 | F7: VALLEJOS EDUARDO | G7: (1382) ROTACION C INCENTIVO | H7: 1382 | I7: ROTACION C INCENTIVO | J7: 6772.381 | K7: 8382.717 | L7: 39 | M7: 0 | N7: 39 | O7: 0 | P7: 264122.85 | Q7: 326925.97 | R7: 1 | S7: 39 | T7: 0
A8: (001) MAR 2026 | B8: 1 | C8: 46082 | D8: Suc: 001 (000008) RAVAROTTO EMANUEL | E8: 8 | F8: RAVAROTTO EMANUEL | G8: (1382) ROTACION C INCENTIVO | H8: 1382 | I8: ROTACION C INCENTIVO | J8: 18047.967 | K8: 22290.443 | L8: 8.0508 | M8: 7.7319 | N8: 15.7828 | O8: 0 | P8: 284846.64 | Q8: 351804.59 | R8: 61 | S8: 0.26 | T8: 0
A9: (001) MAR 2026 | B9: 1 | C9: 46082 | D9: Suc: 001 (000009) ESTIGARRIBIA DAVID | E9: 9 | F9: ESTIGARRIBIA DAVID | G9: (1382) ROTACION C INCENTIVO | H9: 1382 | I9: ROTACION C INCENTIVO | J9: 9288.078 | K9: 11426.613 | L9: 40.549 | M9: 7.8353 | N9: 48.3843 | O9: 0 | P9: 449396.93 | Q9: 552868.39 | R9: 85 | S9: 0.57 | T9: 0
A10: (001) MAR 2026 | B10: 1 | C10: 46082 | D10: Suc: 001 (000010) SEGOVIA JUAN CRUZ | E10: 10 | F10: SEGOVIA JUAN CRUZ | G10: (1382) ROTACION C INCENTIVO | H10: 1382 | I10: ROTACION C INCENTIVO | J10: 19423.102 | K10: 23755.08 | L10: 16.26 | M10: 3.6008 | N10: 19.8607 | O10: 0 | P10: 385757.33 | Q10: 471793.64 | R10: 61 | S10: 0.33 | T10: 0
A11: (001) MAR 2026 | B11: 1 | C11: 46082 | D11: Suc: 001 (000011) ZACARIAS DAVID | E11: 11 | F11: ZACARIAS DAVID | G11: (1382) ROTACION C INCENTIVO | H11: 1382 | I11: ROTACION C INCENTIVO | J11: 19880.77 | K11: 24580.662 | L11: 6.225 | M11: 2.1693 | N11: 8.3943 | O11: 0 | P11: 166886.05 | Q11: 206338.57 | R11: 53 | S11: 0.16 | T11: 0
A12: (001) MAR 2026 | B12: 1 | C12: 46082 | D12: Suc: 001 (000012) GUTIERREZ MARCOS DAVID | E12: 12 | F12: GUTIERREZ MARCOS DAVID | G12: (1382) ROTACION C INCENTIVO | H12: 1382 | I12: ROTACION C INCENTIVO | J12: 21003.651 | K12: 25910.202 | L12: 6.2833 | M12: 7.2679 | N12: 13.5512 | O12: 0 | P12: 284624.48 | Q12: 351114.08 | R12: 65 | S12: 0.21 | T12: 0
A13: (001) MAR 2026 | B13: 1 | C13: 46082 | D13: Suc: 001 (000015) GALARZA GERARDO | E13: 15 | F13: GALARZA GERARDO | G13: (1382) ROTACION C INCENTIVO | H13: 1382 | I13: ROTACION C INCENTIVO | J13: 39203.754 | K13: 49427.271 | L13: 33.6667 | M13: 0.2333 | N13: 33.9 | O13: 0 | P13: 1329007.3 | Q13: 1675584.5 | R13: 10 | S13: 3.39 | T13: 0
... A45: (001) MAR 2026 | B45: 1 | C45: 46082 | D45: Suc: 001 (000123) TORRES ROLANDO | E45: 123 | F45: TORRES ROLANDO | G45: (1382) ROTACION C INCENTIVO | H45: 1382 | I45: ROTACION C INCENTIVO | J45: 52587.592 | K45: 64949.011 | L45: 26.325 | M45: 0.1667 | N45: 26.4917 | O45: 0 | P45: 1393132.9 | Q45: 1720607.6 | R45: 13 | S45: 2.04 | T45: 0

Sheet Promedio Horas
A1: Cod | B1: Vendedor | D1: Promedio Mensual
A2: V2 | B2: OJEDA NORBERTO | D2: 0.21185359
A3: V3 | B3: VIDAL NAHUEL | D3: 0.27407998
A4: V18 | B4: HERRERA PABLO | D4: 0.26547164
A5: V21 | B5: CATAN MATIAS | D5: 0.25571852
A6: V23 | B6: DELGADO JOSÉ | D6: 0.23859954
A7: V31 | B7: RENZO RAMOS | D7: 0.26923698
A8: V44 | B8: MONGES CESAR LUIS | D8: 0.24571528
A9: V54 | B9: BARTSCHAT EMILIANO NAHUEL | D9: 0.26156713
A10: V56 | B10: JUAN ANDRES SANCHEZ | D10: 0.11846547
A11: V4 | B11: TUR SPRINGER FERNANDO | D11: 0.26648634
A12: V5 | B12: SCHELOVER RAUL | D12: 0.29533958
A13: V8 | B13: RAVAROTTO EMANUEL | D13: 0.2281559
... A36: V57 | B36: ROUBINEAU SEBASTIAN | D36: 0.14208492

Sheet Historico Enero
A1: VENDEDOR/ SUPERVISOR | B1: OBJETIVO | C1: FACTURACION ACUMULADA | D1: FACTURACION N-1 | E1: FACTURACION DEL DIA | F1: AVANCE VS OBJETIVO | G1: PROYECCION | H1: CUMPLIMIENTO PROYECTADO | I1: MEDIA REAL | J1: MEDIA NECESARIA | K1: COBRO | N1: VENDEDOR/ SUPERVISOR | O1: COBERTURA TOTAL | P1: DIA ANTERIOR | Q1: INCREMENTO DIARIO | R1: CARTERA TOTAL | S1: CCC | T1: CCC FALTANTE 85%
A2: 20 - FLORES JAVIER | B2: 28001295 | C2: 32969064 | D2: 0 | E2: 32969064 | F2: 1.1774121 | G2: 32969064 | H2: 1.1774121 | I2: 1268040.9 | J2: #DIV/0! | K2: 659381.28 | M2: 22 | N2: 22 - ALMIRON NICOLAS | O2: 0.79411765 | P2: 33 | Q2: 21 | R2: 68 | S2: 54 | T2: 3.8
A3: 19 - GONZALEZ MARCELO | B3: 26876745 | C3: 29130365 | D3: 0 | E3: 29130365 | F3: 1.0838502 | G3: 29130365 | H3: 1.0838502 | I3: 1120398.6 | J3: #DIV/0! | K3: 364129.56 | M3: 49 | N3: 49 - ESCOBAR RAÚL | O3: 0.45493562 | P3: 1 | Q3: 105 | R3: 233 | S3: 106 | T3: 92.05
A4: 16 - GOMEZ MATÍAS | B4: 24627645 | C4: 20258834 | D4: 0 | E4: 20258834 | F4: 0.82260539 | G4: 20258834 | H4: 0.82260539 | I4: 779185.91 | J4: #DIV/0! | K4: 0 | M4: 20 | N4: 20 - FLORES JAVIER | O4: 0.91891892 | P4: 126 | Q4: 78 | R4: 222 | S4: 204 | T4: -15.3
A5: 12 - GUTIERREZ MARCOS DAVID | B5: 24627645 | C5: 26537938 | D5: 0 | E5: 26537938 | F5: 1.077567 | G5: 26537938 | H5: 1.077567 | I5: 1020689.9 | J5: #DIV/0! | K5: 331724.23 | M5: 15 | N5: 15 - GALARZA GERARDO | O5: 0.78461538 | P5: 21 | Q5: 30 | R5: 65 | S5: 51 | T5: 4.25
A6: 11 - ZACARIAS DAVID | B6: 20410582 | C6: 17576103 | D6: 0 | E6: 17576103 | F6: 0.86112695 | G6: 17576103 | H6: 0.86112695 | I6: 676003.95 | J6: #DIV/0! | K6: 0 | M6: 19 | N6: 19 - GONZALEZ MARCELO | O6: 0.85784314 | P6: 100 | Q6: 75 | R6: 204 | S6: 175 | T6: -1.6
A7: 8 - RAVAROTTO EMANUEL | B7: 24065370 | C7: 24383409 | D7: 0 | E7: 24383409 | F7: 1.0132156 | G7: 24383409 | H7: 1.0132156 | I7: 937823.42 | J7: #DIV/0! | K7: 243834.09 | M7: 16 | N7: 16 - GOMEZ MATÍAS | O7: 0.87309645 | P7: 81 | Q7: 91 | R7: 197 | S7: 172 | T7: -4.55
A8: 5 - SCHELOVER RAUL | B8: 31082562 | C8: 32899445 | D8: 0 | E8: 32899445 | F8: 1.0584534 | G8: 32899445 | H8: 1.0584534 | I8: 1265363.3 | J8: #DIV/0! | K8: 411243.06 | M8: 12 | N8: 12 - GUTIERREZ MARCOS DAVID | O8: 0.89952153 | P8: 89 | Q8: 99 | R8: 209 | S8: 188 | T8: -10.35
A9: 4 - TUR SPRINGER FERNANDO | B9: 31082562 | C9: 30879202 | D9: 0 | E9: 30879202 | F9: 0.99345741 | G9: 30879202 | H9: 0.99345741 | I9: 1187661.6 | J9: #DIV/0! | K9: 308792.02 | M9: 11 | N9: 11 - ZACARIAS DAVID | O9: 0.90797546 | P9: 92 | Q9: 56 | R9: 163 | S9: 148 | T9: -9.45
A10: MARTIN (SUPERVISOR) PREVENTA | B10: 2.1077441e+08 | C10: 2.1463436e+08 | D10: 0 | E10: 2.1463436e+08 | F10: 1.0183132 | G10: 2.1463436e+08 | H10: 1.0183132 | I10: 8255167.6 | J10: #DIV/0! | M10: 8 | N10: 8 - RAVAROTTO EMANUEL | O10: 0.83243243 | P10: 64 | Q10: 90 | R10: 185 | S10: 154 | T10: 3.25
A11: 22 - ALMIRON NICOLAS | B11: 84120750 | C11: 64387272 | D11: 0 | E11: 64387272 | F11: 0.76541486 | G11: 64387272 | H11: 0.76541486 | I11: 2476433.5 | J11: #DIV/0! | K11: 0 | M11: 52 | N11: 52 - MARSALL NICOLAS | O11: 0.52884615 | P11: 19 | Q11: 36 | R11: 104 | S11: 55 | T11: 33.4
A12: 49 - ESCOBAR RAÚL | B12: 27439020 | C12: 21503764 | D12: 0 | E12: 21503764 | F12: 0.78369285 | G12: 21503764 | H12: 0.78369285 | I12: 827067.84 | J12: #DIV/0! | K12: 0 | M12: 53 | N12: 53 - SANDOVAL RODRIGO | O12: 0.62727273 | P12: 24 | Q12: 45 | R12: 110 | S12: 69 | T12: 24.5
A13: 15 - GALARZA GERARDO | B13: 111352500 | C13: 81948671 | D13: 0 | E13: 81948671 | F13: 0.73593921 | G13: 81948671 | H13: 0.73593921 | I13: 3151872 | J13: #DIV/0! | K13: 0 | M13: 5 | N13: 5 - SCHELOVER RAUL | O13: 0.96484375 | P13: 144 | Q13: 103 | R13: 256 | S13: 247 | T13: -29.4
A14: 52 - MARSALL NICOLAS | B14: 36823500 | C14: 27773182 | D14: 0 | E14: 27773182 | F14: 0.75422438 | G14: 27773182 | H14: 0.75422438 | I14: 1068199.3 | J14: #DIV/0! | K14: 0 | M14: 4 | N14: 4 - TUR SPRINGER FERNANDO | O14: 0.88571429 | P14: 85 | Q14: 70 | R14: 175 | S14: 155 | T14: -6.25
A15: 53 - SANDOVAL RODRIGO | B15: 36823500 | C15: 40412111 | D15: 0 | E15: 40412111 | F15: 1.0974544 | G15: 40412111 | H15: 1.0974544 | I15: 1554312 | J15: #DIV/0! | K15: 606181.66 | N15: MARTIN (SUPERVISOR) | Q15: 899 | R15: 2191 | S15: 1778
A16: MARTIN (SUPERVISOR) | B16: 296559270 | C16: 2.36025e+08 | D16: 0 | E16: 2.36025e+08 | F16: 0.795878 | G16: 2.36025e+08 | H16: 0.795878 | I16: 9077884.6 | J16: #DIV/0! | M16: 31 | N16: 31 - BARTSCHAT EMILIANO NAHUEL | O16: 0.91082803 | P16: 90 | Q16: 53 | R16: 157 | S16: 143 | T16: -9.55
A17: 2 - OJEDA NORBERTO | B17: 25450000 | C17: 16519194 | D17: 0 | E17: 16519194 | F17: 0.64908425 | G17: 16519194 | H17: 0.64908425 | I17: 635353.63 | J17: #DIV/0! | K17: 0 | M17: 54 | N17: 54 - CAÑETE DIEGO | O17: 0.66494845 | P17: 92 | Q17: 37 | R17: 194 | S17: 129 | T17: 35.9
A18: 3 - VIDAL NAHUEL | B18: 22430000 | C18: 14871119 | D18: 0 | E18: 14871119 | F18: 0.66300128 | G18: 14871119 | H18: 0.66300128 | I18: 571966.1 | J18: #DIV/0! | K18: 0 | M18: 21 | N18: 21 - CATAN MATIAS | O18: 0.81097561 | P18: 88 | Q18: 45 | R18: 164 | S18: 133 | T18: 6.4
A19: 18 - HERRERA PABLO | B19: 22430000 | C19: 17383068 | D19: 0 | E19: 17383068 | F19: 0.77499188 | G19: 17383068 | H19: 0.77499188 | I19: 668579.53 | J19: #DIV/0! | K19: 0 | M19: 23 | N19: 23 - DELGADO JOSÉ | O19: 0.91333333 | P19: 95 | Q19: 42 | R19: 150 | S19: 137 | T19: -9.5
A20: 21 - CATAN MATIAS | B20: 29000000 | C20: 24462625 | D20: 0 | E20: 24462625 | F20: 0.84353878 | G20: 24462625 | H20: 0.84353878 | I20: 940870.18 | J20: #DIV/0! | K20: 0 | M20: 18 | N20: 18 - HERRERA PABLO | O20: 0.86046512 | P20: 83 | Q20: 65 | R20: 172 | S20: 148 | T20: -1.8
A21: 23 - DELGADO JOSÉ | B21: 22000000 | C21: 19224921 | D21: 0 | E21: 19224921 | F21: 0.87386003 | G21: 19224921 | H21: 0.87386003 | I21: 739420.02 | J21: #DIV/0! | K21: 0 | M21: 44 | N21: 44 - MONGE CÉSAR LUIS | O21: 0.88505747 | P21: 64 | Q21: 90 | R21: 174 | S21: 154 | T21: -6.1
A22: 31 - BARTSCHAT EMILIANO NAHUEL | B22: 27500000 | C22: 22580286 | D22: 0 | E22: 22580286 | F22: 0.82110133 | G22: 22580286 | H22: 0.82110133 | I22: 868472.56 | J22: #DIV/0! | K22: 0 | M22: 56 | N22: 56 - JUAN ANDRES SANCHEZ | O22: 0.46268657 | P22: 66 | Q22: 27 | R22: 201 | S22: 93 | T22: 77.85
A23: 44 - MONGE CÉSAR LUIS | B23: 23800000 | C23: 18758064 | D23: 0 | E23: 18758064 | F23: 0.78815396 | G23: 18758064 | H23: 0.78815396 | I23: 721464.01 | J23: #DIV/0! | K23: 0 | M23: 2 | N23: 2 - OJEDA NORBERTO | O23: 0.83783784 | P23: 70 | Q23: 54 | R23: 148 | S23: 124 | T23: 1.8
A24: 54 - CAÑETE DIEGO | B24: 28500000 | C24: 25700325 | D24: 0 | E24: 25700325 | F24: 0.9017658 | G24: 25700325 | H24: 0.9017658 | I24: 988474.05 | J24: #DIV/0! | K24: 0 | M24: 3 | N24: 3 - VIDAL NAHUEL | O24: 0.90967742 | P24: 79 | Q24: 62 | R24: 155 | S24: 141 | T24: -9.25
A25: 56 - JUAN ANDRES SANCHEZ | B25: 46900000 | C25: 26132281 | D25: 0 | E25: 26132281 | F25: 0.55719149 | G25: 26132281 | H25: 0.55719149 | I25: 1005087.7 | J25: #DIV/0! | K25: 0 | N25: CRISTIAN (SUPERVISOR) | Q25: 475 | R25: 1515 | S25: 1202
A26: CRISTIAN (SUPERVISOR) | B26: 248010000 | C26: 1.8563188e+08 | D26: 0 | E26: 1.8563188e+08 | F26: 0.74848548 | G26: 1.8563188e+08 | H26: 0.74848548 | I26: 7139687.8 | J26: #DIV/0! | M26: 32 | N26: 32 - BLANCO FERNANDO | O26: 0.83636364 | P26: 20 | Q26: 26 | R26: 55 | S26: 46 | T26: 0.75
A27: 32 - BLANCO FERNANDO | B27: 72908794 | C27: 59705699 | D27: 0 | E27: 59705699 | F27: 0.81890944 | G27: 59705699 | H27: 0.81890944 | I27: 2296373.1 | J27: #DIV/0! | K27: 0 | M27: 36 | N27: 36 - STELLA MARIS CANO | O27: 0.64705882 | P27: 68 | Q27: 31 | R27: 153 | S27: 99 | T27: 31.05
A28: 36 - STELLA MARIS CANO | B28: 20300095 | C28: 7088486.6 | D28: 0 | E28: 7088486.6 | F28: 0.34918489 | G28: 7088486.6 | H28: 0.34918489 | I28: 272634.1 | J28: #DIV/0! | K28: 0 | M28: 9 | N28: 9 - ESTIGARRIBIA DAVID | O28: 0.7114094 | P28: 80 | Q28: 26 | R28: 149 | S28: 106 | T28: 20.65
A29: 9 - ESTIGARRIBIA DAVID | B29: 21701088 | C29: 11524508 | D29: 0 | E29: 11524508 | F29: 0.53105671 | G29: 11524508 | H29: 0.53105671 | I29: 443250.32 | J29: #DIV/0! | K29: 0 | M29: 40 | N29: 40 - GARCIA BOGARIN SANTIAGO | O29: 0.86666667 | P29: 68 | Q29: 140 | R29: 240 | S29: 208 | T29: -4
A30: 40 - GARCIA BOGARIN SANTIAGO | B30: 33166353 | C30: 32454209 | D30: 0 | E30: 32454209 | F30: 0.97852812 | G30: 32454209 | H30: 0.97852812 | I30: 1248238.8 | J30: #DIV/0! | K30: 0 | M30: 27 | N30: 27 - GOMEZ ADRIÁN | O30: 0.87769784 | P30: 73 | Q30: 49 | R30: 139 | S30: 122 | T30: -3.85
A31: 27 - GOMEZ ADRIÁN | B31: 21701088 | C31: 18178589 | D31: 0 | E31: 18178589 | F31: 0.83768098 | G31: 18178589 | H31: 0.83768098 | I31: 699176.48 | J31: #DIV/0! | K31: 0 | M31: 10 | N31: 10 - SEGOVIA JUAN CRUZ | O31: 0.79558011 | P31: 40 | Q31: 104 | R31: 181 | S31: 144 | T31: 9.85
A32: 10 - SEGOVIA JUAN CRUZ | B32: 21701088 | C32: 22255931 | D32: 0 | E32: 22255931 | F32: 1.0255675 | G32: 22255931 | H32: 1.0255675 | I32: 855997.34 | J32: #DIV/0! | K32: 222559.31 | M32: 28 | N32: 28 - GOMEZ PABLO | O32: 0.87150838 | P32: 67 | Q32: 89 | R32: 179 | S32: 156 | T32: -3.85
A33: 28 - GOMEZ PABLO | B33: 20586012 | C33: 21491454 | D33: 0 | E33: 21491454 | F33: 1.0439834 | G33: 21491454 | H33: 1.0439834 | I33: 826594.39 | J33: #DIV/0! | K33: 268643.18 | M33: 33 | N33: 33 - NICOLAS AZULA | O33: 0.57926829 | P33: 66 | Q33: 29 | R33: 164 | S33: 95 | T33: 44.4
A34: 33 - NICOLAS AZULA | B34: 21701088 | C34: 6604694.9 | D34: 0 | E34: 6604694.9 | F34: 0.30434856 | G34: 6604694.9 | H34: 0.30434856 | I34: 254026.73 | J34: #DIV/0! | K34: 0 | M34: 37 | N34: 37 - PEREZ ESQUIVEL BRUNO NICOLAS | O34: 0.69736842 | P34: 82 | Q34: 24 | R34: 152 | S34: 106 | T34: 23.2
A35: 37 - PEREZ ESQUIVEL BRUNO NICOLAS | B35: 20586012 | C35: 10300686 | D35: 0 | E35: 10300686 | F35: 0.50037307 | G35: 10300686 | H35: 0.50037307 | I35: 396180.23 | J35: #DIV/0! | K35: 0 | M35: 24 | N35: 24 - DELGADO HERNAN GABRIEL | O35: 0.82954545 | P35: 81 | Q35: 65 | R35: 176 | S35: 146 | T35: 3.6
A36: 24 - DELGADO HERNAN GABRIEL | B36: 21729680 | C36: 17015925 | D36: 0 | E36: 17015925 | F36: 0.78307297 | G36: 17015925 | H36: 0.78307297 | I36: 654458.65 | J36: #DIV/0! | K36: 0 | M36: 7 | N36: 7 - VALLEJOS EDUARDO | O36: 0.14414414 | P36: 0 | Q36: 16 | R36: 111 | S36: 16 | T36: 78.35
A37: 7 - VALLEJOS EDUARDO | B37: 1.0293006e+08 | C37: 71043541 | D37: 0 | E37: 71043541 | F37: 0.69021178 | G37: 71043541 | H37: 0.69021178 | I37: 2732443.9 | J37: #DIV/0! | K37: 0 | M37: 57 | N37: 57 - ZARATE NICOLAS | O37: 0.5 | P37: 17 | Q37: 35 | R37: 104 | S37: 52 | T37: 36.4
A38: 57 - ZARATE NICOLAS | B38: 29964085 | C38: 34108717 | D38: 0 | E38: 34108717 | F38: 1.13832 | G38: 34108717 | H38: 1.13832 | I38: 1311873.7 | J38: #DIV/0! | K38: 511630.76 | M38: 1 | N38: 1 - VERA ERNESTO | O38: 0.87903226 | P38: 60 | Q38: 49 | R38: 124 | S38: 109 | T38: -3.6
A39: 1 - VERA ERNESTO | B39: 32594519 | C39: 24484653 | D39: 0 | E39: 24484653 | F39: 0.75118927 | G39: 24484653 | H39: 0.75118927 | I39: 941717.43 | J39: #DIV/0! | K39: 0 | N39: NELSON (SUPERVISOR) | Q39: 683 | R39: 1927 | S39: 1405
A40: NELSON (SUPERVISOR) | B40: 4.4156996e+08 | C40: 3.3625709e+08 | D40: 0 | E40: 3.3625709e+08 | F40: 0.76150355 | G40: 3.3625709e+08 | H40: 0.76150355 | I40: 12932965 | J40: #DIV/0! | N40: LOPEZ ENZO | Q40: 2057 | R40: 5633 | S40: 4385
...

Sheet Historico Febrero
A1: VENDEDOR/ SUPERVISOR | B1: OBJETIVO | C1: FACTURACION ACUMULADA | D1: FACTURACION N-1 | E1: FACTURACION DEL DIA | F1: AVANCE VS OBJETIVO | G1: PROYECCION | H1: CUMPLIMIENTO PROYECTADO | I1: MEDIA REAL | J1: MEDIA NECESARIA | K1: COBRO | N1: VENDEDOR/ SUPERVISOR | O1: COBERTURA TOTAL | P1: DIA ANTERIOR | Q1: INCREMENTO DIARIO | R1: CARTERA TOTAL | S1: CCC | T1: CCC FALTANTE 85%
A2: 20 - FLORES JAVIER | B2: 28561321 | C2: 39721296 | D2: 39088386 | E2: 632909.85 | F2: 1.3907374 | G2: 39721296 | H2: 1.3907374 | I2: 1727012.9 | J2: #DIV/0! | K2: 794425.92 | M2: 22 | N2: 22 - ALMIRON NICOLAS | O2: 0.87142857 | P2: 33 | Q2: 28 | R2: 70 | S2: 61 | T2: -1.5
A3: 19 - GONZALEZ MARCELO | B3: 27414280 | C3: 29249180 | D3: 28088898 | E3: 1160282.6 | F3: 1.0669323 | G3: 29249180 | H3: 1.0669323 | I3: 1271703.5 | J3: #DIV/0! | K3: 365614.75 | M3: 49 | N3: 49 - ESCOBAR RAÚL | O3: 0.45064378 | P3: 1 | Q3: 104 | R3: 233 | S3: 105 | T3: 93.05
A4: 16 - GOMEZ MATÍAS | B4: 25120198 | C4: 23167100 | D4: 21799244 | E4: 1367856.5 | F4: 0.92224991 | G4: 23167100 | H4: 0.92224991 | I4: 1007265.2 | J4: #DIV/0! | K4: 0 | M4: 20 | N4: 20 - FLORES JAVIER | O4: 0.94222222 | P4: 126 | Q4: 86 | R4: 225 | S4: 212 | T4: -20.75
A5: 12 - GUTIERREZ MARCOS DAVID | B5: 25120198 | C5: 31630959 | D5: 30307629 | E5: 1323329.4 | F5: 1.2591843 | G5: 31630959 | H5: 1.2591843 | I5: 1375259.1 | J5: #DIV/0! | K5: 632619.18 | M5: 15 | N5: 15 - GALARZA GERARDO | O5: 0.83076923 | P5: 21 | Q5: 33 | R5: 65 | S5: 54 | T5: 1.25
A6: 11 - ZACARIAS DAVID | B6: 20818794 | C6: 15488446 | D6: 15012989 | E6: 475456.5 | F6: 0.74396461 | G6: 15488446 | H6: 0.74396461 | I6: 673410.69 | J6: #DIV/0! | K6: 0 | M6: 19 | N6: 19 - GONZALEZ MARCELO | O6: 0.89756098 | P6: 100 | Q6: 84 | R6: 205 | S6: 184 | T6: -9.75
A7: 8 - RAVAROTTO EMANUEL | B7: 24546677 | C7: 18088953 | D7: 17362470 | E7: 726482.81 | F7: 0.73692064 | G7: 18088953 | H7: 0.73692064 | I7: 786476.22 | J7: #DIV/0! | K7: 0 | M7: 16 | N7: 16 - GOMEZ MATÍAS | O7: 0.9035533 | P7: 81 | Q7: 97 | R7: 197 | S7: 178 | T7: -10.55
A8: 5 - SCHELOVER RAUL | B8: 31704213 | C8: 25692635 | D8: 25203128 | E8: 489506.21 | F8: 0.8103855 | G8: 25692635 | H8: 0.8103855 | I8: 1117071.1 | J8: #DIV/0! | K8: 0 | M8: 12 | N8: 12 - GUTIERREZ MARCOS DAVID | O8: 0.9 | P8: 89 | Q8: 100 | R8: 210 | S8: 189 | T8: -10.5
A9: 4 - TUR SPRINGER FERNANDO | B9: 31704213 | C9: 32620850 | D9: 30865959 | E9: 1754891.8 | F9: 1.0289122 | G9: 32620850 | H9: 1.0289122 | I9: 1418297.8 | J9: #DIV/0! | K9: 326208.5 | M9: 11 | N9: 11 - ZACARIAS DAVID | O9: 0.84146341 | P9: 92 | Q9: 46 | R9: 164 | S9: 138 | T9: 1.4
A10: MARTIN (SUPERVISOR) PREVENTA | B10: 2.1498989e+08 | C10: 2.1565942e+08 | D10: 2.077287e+08 | E10: 7930715.6 | F10: 1.0031142 | G10: 2.1565942e+08 | H10: 1.0031142 | I10: 9376496.5 | J10: #DIV/0! | M10: 8 | N10: 8 - RAVAROTTO EMANUEL | O10: 0.8655914 | P10: 64 | Q10: 97 | R10: 186 | S10: 161 | T10: -2.9
A11: 22 - ALMIRON NICOLAS | B11: 85803165 | C11: 74801914 | D11: 72706629 | E11: 2095285.3 | F11: 0.87178503 | G11: 74801914 | H11: 0.87178503 | I11: 3252257.1 | J11: #DIV/0! | K11: 0 | M11: 52 | N11: 52 - MARSALL NICOLAS | O11: 0.60576923 | P11: 19 | Q11: 44 | R11: 104 | S11: 63 | T11: 25.4
A12: 49 - ESCOBAR RAÚL | B12: 27987800 | C12: 21624276 | D12: 21624276 | E12: 0 | F12: 0.77263221 | G12: 21624276 | H12: 0.77263221 | I12: 940185.91 | J12: #DIV/0! | K12: 0 | M12: 53 | N12: 53 - SANDOVAL RODRIGO | O12: 0.54867257 | P12: 24 | Q12: 38 | R12: 113 | S12: 62 | T12: 34.05
A13: 15 - GALARZA GERARDO | B13: 113579550 | C13: 1.105629e+08 | D13: 1.0102614e+08 | E13: 9536757.5 | F13: 0.9734402 | G13: 1.105629e+08 | H13: 0.9734402 | I13: 4807082.6 | J13: #DIV/0! | K13: 0 | M13: 5 | N13: 5 - SCHELOVER RAUL | O13: 0.875 | P13: 144 | Q13: 80 | R13: 256 | S13: 224 | T13: -6.4
A14: 52 - MARSALL NICOLAS | B14: 37559970 | C14: 25974210 | D14: 25893547 | E14: 80662.059 | F14: 0.69153968 | G14: 25974210 | H14: 0.69153968 | I14: 1129313.5 | J14: #DIV/0! | K14: 0 | M14: 4 | N14: 4 - TUR SPRINGER FERNANDO | O14: 0.9039548 | P14: 85 | Q14: 75 | R14: 177 | S14: 160 | T14: -9.55
A15: 53 - SANDOVAL RODRIGO | B15: 37559970 | C15: 32322953 | D15: 32261497 | E15: 61455.881 | F15: 0.8605692 | G15: 32322953 | H15: 0.8605692 | I15: 1405345.8 | J15: #DIV/0! | K15: 0 | N15: MARTIN (SUPERVISOR) | Q15: 912 | R15: 2205 | S15: 1791
A16: MARTIN (SUPERVISOR) | B16: 3.0249046e+08 | C16: 2.6528625e+08 | D16: 2.5351209e+08 | E16: 11774161 | F16: 0.87700702 | G16: 2.6528625e+08 | H16: 0.87700702 | I16: 11534185 | J16: #DIV/0! | M16: 31 | N16: 31 - BARTSCHAT EMILIANO NAHUEL | O16: 0.85806452 | P16: 90 | Q16: 43 | R16: 155 | S16: 133 | T16: -1.25
A17: 2 - OJEDA NORBERTO | B17: 25959000 | C17: 15605041 | D17: 15500624 | E17: 104417.64 | F17: 0.60114185 | G17: 15605041 | H17: 0.60114185 | I17: 678480.05 | J17: #DIV/0! | K17: 0 | M17: 54 | N17: 54 - CAÑETE DIEGO | O17: 0.82439024 | P17: 92 | Q17: 77 | R17: 205 | S17: 169 | T17: 5.25
A18: 3 - VIDAL NAHUEL | B18: 22878600 | C18: 17851343 | D18: 17014009 | E18: 837333.71 | F18: 0.78026378 | G18: 17851343 | H18: 0.78026378 | I18: 776145.35 | J18: #DIV/0! | K18: 0 | M18: 21 | N18: 21 - CATAN MATIAS | O18: 0.86419753 | P18: 88 | Q18: 52 | R18: 162 | S18: 140 | T18: -2.3
