Workbook

Sheet COMISIONES
A1: VENDEDOR | B1: SUCURSAL | C1: BULTOS | D1: UNIDAD DE MEDIDA | E1: IMPORTE | F1: COMISIÓN POR IMPORTE FIJO | G1: COMISIÓN POR PORCENTAJE | H1: COMISIÓN TOTAL
A2: 0 - TODOS LOS VENDEDORES | B2: 0 | C2: 13183.924 | D2: 58834.985 | E2: 2.3249327e+08 | F2: 0 | G2: 114436.09 | H2: 114436.08
A3: 1 - VERA ERNESTO | B3: 1 | C3: 167.27163 | D3: 302.86322 | E3: 3814536.4 | F3: 0 | G3: 114436.09 | H3: 114436.08
A4: 2 - OJEDA NORBERTO | B4: 1 | C4: 165.92619 | D4: 211.02518 | E4: 3406960.3 | F4: 0 | G4: 0 | H4: 0
A5: 3 - VIDAL NAHUEL | B5: 1 | C5: 207.20415 | D5: 524.62053 | E5: 4721350.1 | F5: 0 | G5: 0 | H5: 0
A6: 4 - TUR SPRINGER FERNANDO | B6: 1 | C6: 237.33539 | D6: 536.19244 | E6: 5343904.4 | F6: 0 | G6: 0 | H6: 0
A7: 5 - SCHELOVER RAUL | B7: 1 | C7: 262.04554 | D7: 597.11226 | E7: 5443341.4 | F7: 0 | G7: 0 | H7: 0
A8: 7 - VALLEJOS EDUARDO | B8: 1 | C8: 72.077778 | D8: 242.515 | E8: 1280810.5 | F8: 0 | G8: 0 | H8: 0
A9: 8 - PARRA MAXIMILIANO | B9: 1 | C9: 119.92685 | D9: 273.94869 | E9: 2446732.8 | F9: 0 | G9: 0 | H9: 0
A10: 9 - ESTIGARRIBIA DAVID | B10: 1 | C10: 109.23688 | D10: 280.07251 | E10: 2512781.6 | F10: 0 | G10: 0 | H10: 0
A11: 10 - BRITEZ EMMANUEL | B11: 1 | C11: 125.12569 | D11: 289.77952 | E11: 2295395.1 | F11: 0 | G11: 0 | H11: 0
A12: 11 - SANCHEZ RICARDO | B12: 1 | C12: 261.23373 | D12: 563.02 | E12: 4592584.7 | F12: 0 | G12: 0 | H12: 0
A13: 12 - GUTIERREZ MARCOS DAVID | B13: 1 | C13: 508.50794 | D13: 463.96387 | E13: 5665351.9 | F13: 0 | G13: 0 | H13: 0
... A46: 123 - TORRES ROLANDO | B46: 1 | C46: 18.030754 | D46: 60 | E46: 429907.21 | F46: 0 | G46: 0 | H46: 0

Sheet AVANCE
A1: SUPERVISOR | B1: VENDEDOR | C1: OBJETIVO | D1: FACTURACION ACUMULADA | F1: FACTURACION DEL DIA | G1: AVANCE VS OBJETIVO | H1: PROYECCION | I1: CUMPLIMIENTO PROYECTADO | J1: MEDIA REAL | K1: MEDIA NECESARIA | L1: COBRO
A2: MARTIN PREVENTA | B2: 20 - FLORES JAVIER | C2: 33912398 | D2: =IFERROR(+VLOOKUP(B2,COMISIONES!A:E,5,FALSE),"0")*1 -> 7450150.3 | E2: 3465580.1 | F2: =+D2-E2 -> 3984570.1 | G2: =+D2/C2 -> 0.2196881 | H2: =+D2/$N$3*$N$4 -> 62084586 | I2: =+H2/C2 -> 1.8307342 | J2: =+D2/$N$3 -> 2483383.4 | K2: =+(C2-D2)/$N$2 -> 1202829.4 | L2: {=+_xlfn.IFS(I2>114%,H2*0.02,I2>109%,H2*0.015,I2>104%,H2*0.0125,I2>99%,H2*0.01,I2<99%,H2*0)} -> 1241691.7 | M2: DIAS DE TRABAJO RESTANTES | N2: 22
B3: 19 - GONZALEZ MARCELO | C3: 32550454 | D3: =IFERROR(+VLOOKUP(B3,COMISIONES!A:E,5,FALSE),"0")*1 -> 6128669.1 | E3: 4360010.1 | F3: =+D3-E3 -> 1768659 | G3: =+D3/C3 -> 0.18828214 | H3: =+D3/$N$3*$N$4 -> 51072243 | I3: =+H3/C3 -> 1.5690178 | J3: =+D3/$N$3 -> 2042889.7 | K3: =+(C3-D3)/$N$2 -> 1200990.2 | L3: {=+_xlfn.IFS(I3>114%,H3*0.02,I3>109%,H3*0.015,I3>104%,H3*0.0125,I3>99%,H3*0.01,I3<99%,H3*0)} -> 1021444.9 | M3: DIAS TRABAJADOS | N3: =N4-N2 -> 3
B4: 16 - GOMEZ MATÍAS | C4: 29826567 | D4: =IFERROR(+VLOOKUP(B4,COMISIONES!A:E,5,FALSE),"0")*1 -> 4269220.1 | E4: 2579799.6 | F4: =+D4-E4 -> 1689420.5 | G4: =+D4/C4 -> 0.14313481 | H4: =+D4/$N$3*$N$4 -> 35576834 | I4: =+H4/C4 -> 1.1927901 | J4: =+D4/$N$3 -> 1423073.4 | K4: =+(C4-D4)/$N$2 -> 1161697.6 | L4: {=+_xlfn.IFS(I4>114%,H4*0.02,I4>109%,H4*0.015,I4>104%,H4*0.0125,I4>99%,H4*0.01,I4<99%,H4*0)} -> 711536.68 | M4: DIAS DE TRABAJO MES | N4: 25
B5: 12 - GUTIERREZ MARCOS DAVID | C5: 29826567 | D5: =IFERROR(+VLOOKUP(B5,COMISIONES!A:E,5,FALSE),"0")*1 -> 5665351.9 | E5: 3933982.6 | F5: =+D5-E5 -> 1731369.4 | G5: =+D5/C5 -> 0.18994315 | H5: =+D5/$N$3*$N$4 -> 47211266 | I5: =+H5/C5 -> 1.5828596 | J5: =+D5/$N$3 -> 1888450.6 | K5: =+(C5-D5)/$N$2 -> 1098237 | L5: {=+_xlfn.IFS(I5>114%,H5*0.02,I5>109%,H5*0.015,I5>104%,H5*0.0125,I5>99%,H5*0.01,I5<99%,H5*0)} -> 944225.32
B6: 11 - SANCHEZ RICARDO | C6: 24719278 | D6: =IFERROR(+VLOOKUP(B6,COMISIONES!A:E,5,FALSE),"0")*1 -> 4592584.7 | E6: 2492962.1 | F6: =+D6-E6 -> 2099622.6 | G6: =+D6/C6 -> 0.1857896 | H6: =+D6/$N$3*$N$4 -> 38271539 | I6: =+H6/C6 -> 1.5482466 | J6: =+D6/$N$3 -> 1530861.6 | K6: =+(C6-D6)/$N$2 -> 914849.7 | L6: {=+_xlfn.IFS(I6>114%,H6*0.02,I6>109%,H6*0.015,I6>104%,H6*0.0125,I6>99%,H6*0.01,I6<99%,H6*0)} -> 765430.78
B7: 8 - PARRA MAXIMILIANO | C7: 29145595 | D7: =IFERROR(+VLOOKUP(B7,COMISIONES!A:E,5,FALSE),"0")*1 -> 2446732.8 | E7: 1599561.9 | F7: =+D7-E7 -> 847170.91 | G7: =+D7/C7 -> 0.083948631 | H7: =+D7/$N$3*$N$4 -> 20389440 | I7: =+H7/C7 -> 0.69957193 | J7: =+D7/$N$3 -> 815577.6 | K7: =+(C7-D7)/$N$2 -> 1213584.6 | L7: {=+_xlfn.IFS(I7>114%,H7*0.02,I7>109%,H7*0.015,I7>104%,H7*0.0125,I7>99%,H7*0.01,I7<99%,H7*0)} -> 0
B8: 5 - SCHELOVER RAUL | C8: 37644124 | D8: =IFERROR(+VLOOKUP(B8,COMISIONES!A:E,5,FALSE),"0")*1 -> 5443341.4 | E8: 3931733.2 | F8: =+D8-E8 -> 1511608.2 | G8: =+D8/C8 -> 0.14460003 | H8: =+D8/$N$3*$N$4 -> 45361178 | I8: =+H8/C8 -> 1.2050002 | J8: =+D8/$N$3 -> 1814447.1 | K8: =+(C8-D8)/$N$2 -> 1463671.9 | L8: {=+_xlfn.IFS(I8>114%,H8*0.02,I8>109%,H8*0.015,I8>104%,H8*0.0125,I8>99%,H8*0.01,I8<99%,H8*0)} -> 907223.56
B9: 4 - TUR SPRINGER FERNANDO | C9: 37644124 | D9: =IFERROR(+VLOOKUP(B9,COMISIONES!A:E,5,FALSE),"0")*1 -> 5343904.4 | E9: 3168065.4 | F9: =+D9-E9 -> 2175839 | G9: =+D9/C9 -> 0.14195853 | H9: =+D9/$N$3*$N$4 -> 44532536 | I9: =+H9/C9 -> 1.1829877 | J9: =+D9/$N$3 -> 1781301.5 | K9: =+(C9-D9)/$N$2 -> 1468191.8 | L9: {=+_xlfn.IFS(I9>114%,H9*0.02,I9>109%,H9*0.015,I9>104%,H9*0.0125,I9>99%,H9*0.01,I9<99%,H9*0)} -> 890650.73
C10: =SUM(C2:C9) -> 2.5526911e+08 | D10: =+SUM(D2:D9) -> 41339955 | E10: 25531695 | F10: =+D10-E10 -> 15808260 | G10: =+D10/C10 -> 0.16194656 | H10: =+D10/$N$3*$N$4 -> 3.4449962e+08 | I10: =+H10/C10 -> 1.3495547 | J10: =+D10/$N$3 -> 13779985 | K10: =+(C10-D10)/$N$2 -> 9724052.3
A11: MARTIN | B11: 22 - ALMIRON NICOLAS | C11: 1.0187873e+08 | D11: =IFERROR(+VLOOKUP(B11,COMISIONES!A:E,5,FALSE),"0")*1 -> 8820125.1 | E11: 6733266.6 | F11: =+D11-E11 -> 2086858.6 | G11: =+D11/C11 -> 0.086574746 | H11: =+D11/$N$3*$N$4 -> 73501043 | I11: =+H11/C11 -> 0.72145622 | J11: =+D11/$N$3 -> 2940041.7 | K11: =+(C11-D11)/$N$2 -> 4229936.5 | L11: {=+_xlfn.IFS(I11>114%,H11*0.0125,I11>109%,H11*0.01,I11>104%,H11*0.0075,I11>99%,H11*0.005,I11<99%,H11*0)} -> 0
B12: 15 - GALARZA GERARDO | C12: 1.3485913e+08 | D12: =IFERROR(+VLOOKUP(B12,COMISIONES!A:E,5,FALSE),"0")*1 -> 27943403 | E12: 17294265 | F12: =+D12-E12 -> 10649138 | G12: =+D12/C12 -> 0.20720438 | H12: =+D12/$N$3*$N$4 -> 2.3286169e+08 | I12: =+H12/C12 -> 1.7267032 | J12: =+D12/$N$3 -> 9314467.6 | K12: =+(C12-D12)/$N$2 -> 4859805.8 | L12: {=+_xlfn.IFS(I12>114%,H12*0.0125,I12>109%,H12*0.01,I12>104%,H12*0.0075,I12>99%,H12*0.005,I12<99%,H12*0)} -> 2910771.1 | M12: AUMENTO OBJ | N12: 0.02
B13: 52 - RAVAROTTO EMANUEL | C13: 44596980 | D13: =IFERROR(+VLOOKUP(B13,COMISIONES!A:E,5,FALSE),"0")*1 -> 6420674.1 | E13: 5100158.1 | F13: =+D13-E13 -> 1320516 | G13: =+D13/C13 -> 0.14397105 | H13: =+D13/$N$3*$N$4 -> 53505617 | I13: =+H13/C13 -> 1.1997588 | J13: =+D13/$N$3 -> 2140224.7 | K13: =+(C13-D13)/$N$2 -> 1735286.6 | L13: {=+_xlfn.IFS(I13>109%,H13*0.015,I13>104%,H13*0.0125,I13>99%,H13*0.01,I13<99%,H13*0)} -> 802584.26
B14: 53 - SANDOVAL RODRIGO | C14: 44596980 | D14: =IFERROR(+VLOOKUP(B14,COMISIONES!A:E,5,FALSE),"0")*1 -> 8129445.8 | E14: 6857277 | F14: =+D14-E14 -> 1272168.7 | G14: =+D14/C14 -> 0.18228691 | H14: =+D14/$N$3*$N$4 -> 67745382 | I14: =+H14/C14 -> 1.5190576 | J14: =+D14/$N$3 -> 2709815.3 | K14: =+(C14-D14)/$N$2 -> 1657615.2 | L14: {=+_xlfn.IFS(I14>109%,H14*0.015,I14>104%,H14*0.0125,I14>99%,H14*0.01,I14<99%,H14*0)} -> 1016180.7
C15: =SUM(C11:C14) -> 3.2593182e+08 | D15: =+SUM(D11:D14) -> 51313648 | E15: 35984967 | F15: =+D15-E15 -> 15328681 | G15: =+D15/C15 -> 0.15743675 | H15: =+D15/$N$3*$N$4 -> 4.2761373e+08 | I15: =+H15/C15 -> 1.311973 | J15: =+D15/$N$3 -> 17104549 | K15: =+(C15-D15)/$N$2 -> 12482644
A16: CRISTIAN | B16: 2 - OJEDA NORBERTO | C16: 28840000 | D16: =IFERROR(+VLOOKUP(B16,COMISIONES!A:E,5,FALSE),"0")*1 -> 3406960.3 | E16: 2307421.1 | F16: =+D16-E16 -> 1099539.2 | G16: =+D16/C16 -> 0.11813316 | H16: =+D16/$N$3*$N$4 -> 28391336 | I16: =+H16/C16 -> 0.98444299 | J16: =+D16/$N$3 -> 1135653.4 | K16: =+(C16-D16)/$N$2 -> 1156047.3 | L16: {=+_xlfn.IFS(I16>114%,H16*0.02,I16>109%,H16*0.015,I16>104%,H16*0.0125,I16>99%,H16*0.01,I16<99%,H16*0)} -> 0
B17: 3 - VIDAL NAHUEL | C17: 26429800 | D17: =IFERROR(+VLOOKUP(B17,COMISIONES!A:E,5,FALSE),"0")*1 -> 4721350.1 | E17: 3665110.4 | F17: =+D17-E17 -> 1056239.8 | G17: =+D17/C17 -> 0.17863738 | H17: =+D17/$N$3*$N$4 -> 39344584 | I17: =+H17/C17 -> 1.4886448 | J17: =+D17/$N$3 -> 1573783.4 | K17: =+(C17-D17)/$N$2 -> 986747.72 | L17: {=+_xlfn.IFS(I17>114%,H17*0.02,I17>109%,H17*0.015,I17>104%,H17*0.0125,I17>99%,H17*0.01,I17<99%,H17*0)} -> 786891.68
B18: 18 - HERRERA PABLO | C18: 26800600 | D18: =IFERROR(+VLOOKUP(B18,COMISIONES!A:E,5,FALSE),"0")*1 -> 3346205 | E18: 1899369.2 | F18: =+D18-E18 -> 1446835.7 | G18: =+D18/C18 -> 0.1248556 | H18: =+D18/$N$3*$N$4 -> 27885041 | I18: =+H18/C18 -> 1.0404633 | J18: =+D18/$N$3 -> 1115401.7 | K18: =+(C18-D18)/$N$2 -> 1066108.9 | L18: {=+_xlfn.IFS(I18>114%,H18*0.02,I18>109%,H18*0.015,I18>104%,H18*0.0125,I18>99%,H18*0.01,I18<99%,H18*0)} -> 348563.02
B19: 21 - CATAN MATIAS | C19: 37286618 | D19: =IFERROR(+VLOOKUP(B19,COMISIONES!A:E,5,FALSE),"0")*1 -> 6974519.4 | E19: 4746780.9 | F19: =+D19-E19 -> 2227738.5 | G19: =+D19/C19 -> 0.18705154 | H19: =+D19/$N$3*$N$4 -> 58120995 | I19: =+H19/C19 -> 1.5587629 | J19: =+D19/$N$3 -> 2324839.8 | K19: =+(C19-D19)/$N$2 -> 1377822.7 | L19: {=+_xlfn.IFS(I19>114%,H19*0.02,I19>109%,H19*0.015,I19>104%,H19*0.0125,I19>99%,H19*0.01,I19<99%,H19*0)} -> 1162419.9
B20: 23 - DELGADO JOSÉ | C20: 27420660 | D20: =IFERROR(+VLOOKUP(B20,COMISIONES!A:E,5,FALSE),"0")*1 -> 3353505.2 | E20: 2086968 | F20: =+D20-E20 -> 1266537.1 | G20: =+D20/C20 -> 0.12229848 | H20: =+D20/$N$3*$N$4 -> 27945876 | I20: =+H20/C20 -> 1.019154 | J20: =+D20/$N$3 -> 1117835.1 | K20: =+(C20-D20)/$N$2 -> 1093961.6 | L20: {=+_xlfn.IFS(I20>114%,H20*0.02,I20>109%,H20*0.015,I20>104%,H20*0.0125,I20>99%,H20*0.01,I20<99%,H20*0)} -> 279458.76
B21: 31 - RENZO RAMOS | C21: 34257800 | D21: =IFERROR(+VLOOKUP(B21,COMISIONES!A:E,5,FALSE),"0")*1 -> 4809073.5 | E21: 2581541.5 | F21: =+D21-E21 -> 2227532 | G21: =+D21/C21 -> 0.14037894 | H21: =+D21/$N$3*$N$4 -> 40075613 | I21: =+H21/C21 -> 1.1698245 | J21: =+D21/$N$3 -> 1603024.5 | K21: =+(C21-D21)/$N$2 -> 1338578.5 | L21: {=+_xlfn.IFS(I21>114%,H21*0.02,I21>109%,H21*0.015,I21>104%,H21*0.0125,I21>99%,H21*0.01,I21<99%,H21*0)} -> 801512.25
B22: 44 - MONGES CESAR LUIS | C22: 29478600 | D22: =IFERROR(+VLOOKUP(B22,COMISIONES!A:E,5,FALSE),"0")*1 -> 3452485.4 | E22: 2138082.6 | F22: =+D22-E22 -> 1314402.9 | G22: =+D22/C22 -> 0.11711836 | H22: =+D22/$N$3*$N$4 -> 28770712 | I22: =+H22/C22 -> 0.97598637 | J22: =+D22/$N$3 -> 1150828.5 | K22: =+(C22-D22)/$N$2 -> 1183005.2 | L22: {=+_xlfn.IFS(I22>114%,H22*0.02,I22>109%,H22*0.015,I22>104%,H22*0.0125,I22>99%,H22*0.01,I22<99%,H22*0)} -> 0
B23: 54 - BARTSCHAT EMILIANO NAHUEL | C23: 39140000 | D23: =IFERROR(+VLOOKUP(B23,COMISIONES!A:E,5,FALSE),"0")*1 -> 5129094.8 | E23: 3226315.5 | F23: =+D23-E23 -> 1902779.4 | G23: =+D23/C23 -> 0.13104483 | H23: =+D23/$N$3*$N$4 -> 42742457 | I23: =+H23/C23 -> 1.0920403 | J23: =+D23/$N$3 -> 1709698.3 | K23: =+(C23-D23)/$N$2 -> 1545950.2 | L23: {=+_xlfn.IFS(I23>114%,H23*0.02,I23>109%,H23*0.015,I23>104%,H23*0.0125,I23>99%,H23*0.01,I23<99%,H23*0)} -> 641136.85
C24: =SUM(C16:C23) -> 249654078 | D24: =+SUM(D16:D23) -> 35193194 | E24: 22651589 | F24: =+D24-E24 -> 12541605 | G24: =+D24/C24 -> 0.14096783 | H24: =+D24/$N$3*$N$4 -> 2.9327661e+08 | I24: =+H24/C24 -> 1.1747319 | J24: =+D24/$N$3 -> 11731065 | K24: =+(C24-D24)/$N$2 -> 9748222
A25: GONZALO | B25: 32 - CABRAL GONZALO | C25: 89144395 | D25: =IFERROR(+VLOOKUP(B25,COMISIONES!A:E,5,FALSE),"0")*1 -> 6424682 | E25: 3002778.1 | F25: =+D25-E25 -> 3421903.9 | G25: =+D25/C25 -> 0.07207051 | H25: =+D25/$N$3*$N$4 -> 53539016 | I25: =+H25/C25 -> 0.60058758 | J25: =+D25/$N$3 -> 2141560.7 | K25: =+(C25-D25)/$N$2 -> 3759987 | L25: {=+_xlfn.IFS(I25>114%,H25*0.0125,I25>109%,H25*0.01,I25>104%,H25*0.0075,I25>99%,H25*0.005,I25<99%,H25*0)} -> 0
B26: 36 - IBARROLA JORGE | C26: 24731127 | D26: =IFERROR(+VLOOKUP(B26,COMISIONES!A:E,5,FALSE),"0")*1 -> 1484315.7 | E26: 874709.21 | F26: =+D26-E26 -> 609606.51 | G26: =+D26/C26 -> 0.060018118 | H26: =+D26/$N$3*$N$4 -> 12369298 | I26: =+H26/C26 -> 0.50015098 | J26: =+D26/$N$3 -> 494771.91 | K26: =+(C26-D26)/$N$2 -> 1056673.3 | L26: {=+_xlfn.IFS(I26>114%,H26*0.02,I26>109%,H26*0.015,I26>104%,H26*0.0125,I26>99%,H26*0.01,I26<99%,H26*0)} -> 0
B27: 9 - ESTIGARRIBIA DAVID | C27: 27718182 | D27: =IFERROR(+VLOOKUP(B27,COMISIONES!A:E,5,FALSE),"0")*1 -> 2512781.6 | E27: 1980733.4 | F27: =+D27-E27 -> 532048.21 | G27: =+D27/C27 -> 0.090654632 | H27: =+D27/$N$3*$N$4 -> 20939847 | I27: =+H27/C27 -> 0.75545527 | J27: =+D27/$N$3 -> 837593.86 | K27: =+(C27-D27)/$N$2 -> 1145700 | L27: {=+_xlfn.IFS(I27>114%,H27*0.02,I27>109%,H27*0.015,I27>104%,H27*0.0125,I27>99%,H27*0.01,I27<99%,H27*0)} -> 0
B28: 40 - SOLIS EMMANUEL | C28: 40364706 | D28: =IFERROR(+VLOOKUP(B28,COMISIONES!A:E,5,FALSE),"0")*1 -> 3444667.7 | E28: 955339.39 | F28: =+D28-E28 -> 2489328.3 | G28: =+D28/C28 -> 0.085338604 | H28: =+D28/$N$3*$N$4 -> 28705564 | I28: =+H28/C28 -> 0.71115503 | J28: =+D28/$N$3 -> 1148222.6 | K28: =+(C28-D28)/$N$2 -> 1678183.6 | L28: {=+_xlfn.IFS(I28>114%,H28*0.02,I28>109%,H28*0.015,I28>104%,H28*0.0125,I28>99%,H28*0.01,I28<99%,H28*0)} -> 0
B29: 27 - GOMEZ ADRIÁN | C29: 27707000 | D29: =IFERROR(+VLOOKUP(B29,COMISIONES!A:E,5,FALSE),"0")*1 -> 2771512.9 | E29: 1680099.3 | F29: =+D29-E29 -> 1091413.6 | G29: =+D29/C29 -> 0.10002934 | H29: =+D29/$N$3*$N$4 -> 23095940 | I29: =+H29/C29 -> 0.83357781 | J29: =+D29/$N$3 -> 923837.62 | K29: =+(C29-D29)/$N$2 -> 1133431.2 | L29: {=+_xlfn.IFS(I29>114%,H29*0.02,I29>109%,H29*0.015,I29>104%,H29*0.0125,I29>99%,H29*0.01,I29<99%,H29*0)} -> 0
B30: 10 - BRITEZ EMMANUEL | C30: 26604900 | D30: =IFERROR(+VLOOKUP(B30,COMISIONES!A:E,5,FALSE),"0")*1 -> 2295395.1 | E30: 1341768.4 | F30: =+D30-E30 -> 953626.66 | G30: =+D30/C30 -> 0.086277154 | H30: =+D30/$N$3*$N$4 -> 19128292 | I30: =+H30/C30 -> 0.71897629 | J30: =+D30/$N$3 -> 765131.69 | K30: =+(C30-D30)/$N$2 -> 1104977.5 | L30: {=+_xlfn.IFS(I30>114%,H30*0.02,I30>109%,H30*0.015,I30>104%,H30*0.0125,I30>99%,H30*0.01,I30<99%,H30*0)} -> 0
B31: 28 - GOMEZ PABLO | C31: 28533060 | D31: =IFERROR(+VLOOKUP(B31,COMISIONES!A:E,5,FALSE),"0")*1 -> 2694074.2 | E31: 2031918.6 | F31: =+D31-E31 -> 662155.54 | G31: =+D31/C31 -> 0.094419392 | H31: =+D31/$N$3*$N$4 -> 22450618 | I31: =+H31/C31 -> 0.78682827 | J31: =+D31/$N$3 -> 898024.73 | K31: =+(C31-D31)/$N$2 -> 1174499.4 | L31: {=+_xlfn.IFS(I31>114%,H31*0.02,I31>109%,H31*0.015,I31>104%,H31*0.0125,I31>99%,H31*0.01,I31<99%,H31*0)} -> 0
B32: 33 - ESQUIVEL NICOLAS | C32: 24731127 | D32: =IFERROR(+VLOOKUP(B32,COMISIONES!A:E,5,FALSE),"0")*1 -> 1510107.3 | E32: 915628.2 | F32: =+D32-E32 -> 594479.14 | G32: =+D32/C32 -> 0.061060999 | H32: =+D32/$N$3*$N$4 -> 12584228 | I32: =+H32/C32 -> 0.50884166 | J32: =+D32/$N$3 -> 503369.12 | K32: =+(C32-D32)/$N$2 -> 1055500.9 | L32: {=+_xlfn.IFS(I32>114%,H32*0.02,I32>109%,H32*0.015,I32>104%,H32*0.0125,I32>99%,H32*0.01,I32<99%,H32*0)} -> 0
B33: 37 - SALAJ EMILIO | C33: 26553552 | D33: =IFERROR(+VLOOKUP(B33,COMISIONES!A:E,5,FALSE),"0")*1 -> 886833.2 | E33: 582347.37 | F33: =+D33-E33 -> 304485.83 | G33: =+D33/C33 -> 0.033397912 | H33: =+D33/$N$3*$N$4 -> 7390276.7 | I33: =+H33/C33 -> 0.27831593 | J33: =+D33/$N$3 -> 295611.07 | K33: =+(C33-D33)/$N$2 -> 1166669.1 | L33: {=+_xlfn.IFS(I33>114%,H33*0.02,I33>109%,H33*0.015,I33>104%,H33*0.0125,I33>99%,H33*0.01,I33<99%,H33*0)} -> 0
B34: 24 - AZULA NICOLAS | C34: 27174688 | D34: =IFERROR(+VLOOKUP(B34,COMISIONES!A:E,5,FALSE),"0")*1 -> 1487555.9 | E34: 830537.61 | F34: =+D34-E34 -> 657018.34 | G34: =+D34/C34 -> 0.054740498 | H34: =+D34/$N$3*$N$4 -> 12396300 | I34: =+H34/C34 -> 0.45617082 | J34: =+D34/$N$3 -> 495851.98 | K34: =+(C34-D34)/$N$2 -> 1167596.9 | L34: {=+_xlfn.IFS(I34>114%,H34*0.02,I34>109%,H34*0.015,I34>104%,H34*0.0125,I34>99%,H34*0.01,I34<99%,H34*0)} -> 0
B35: 7 - VALLEJOS EDUARDO | C35: 1.2881391e+08 | D35: =IFERROR(+VLOOKUP(B35,COMISIONES!A:E,5,FALSE),"0")*1 -> 1280810.5 | E35: -78051.42 | F35: =+D35-E35 -> 1358861.9 | G35: =+D35/C35 -> 0.0099431077 | H35: =+D35/$N$3*$N$4 -> 10673421 | I35: =+H35/C35 -> 0.082859231 | J35: =+D35/$N$3 -> 426936.84 | K35: =+(C35-D35)/$N$2 -> 5796958.8 | L35: {=+_xlfn.IFS(I35>114%,H35*0.0125,I35>109%,H35*0.01,I35>104%,H35*0.0075,I35>99%,H35*0.005,I35<99%,H35*0)} -> 0
B36: 57 - FEDERRATH MARTIN | C36: 40000000 | D36: =IFERROR(+VLOOKUP(B36,COMISIONES!A:E,5,FALSE),"0")*1 -> 8976329.5 | E36: 2660036.3 | F36: =+D36-E36 -> 6316293.2 | G36: =+D36/C36 -> 0.22440824 | H36: =+D36/$N$3*$N$4 -> 74802746 | I36: =+H36/C36 -> 1.8700687 | J36: =+D36/$N$3 -> 2992109.8 | K36: =+(C36-D36)/$N$2 -> 1410166.8 | L36: {=+_xlfn.IFS(I36>109%,H36*0.015,I36>104%,H36*0.0125,I36>99%,H36*0.01,I36<99%,H36*0)} -> 1122041.2
B37: 1 - VERA ERNESTO | C37: 38388577 | D37: =IFERROR(+VLOOKUP(B37,COMISIONES!A:E,5,FALSE),"0")*1 -> 3814536.4 | E37: 2481853 | F37: =+D37-E37 -> 1332683.4 | G37: =+D37/C37 -> 0.099366443 | H37: =+D37/$N$3*$N$4 -> 31787803 | I37: =+H37/C37 -> 0.82805369 | J37: =+D37/$N$3 -> 1271512.1 | K37: =+(C37-D37)/$N$2 -> 1571547.3 | L37: {=+_xlfn.IFS(I37>114%,H37*0.02,I37>109%,H37*0.015,I37>104%,H37*0.0125,I37>99%,H37*0.01,I37<99%,H37*0)} -> 0
C38: =SUM(C25:C37) -> 5.5046522e+08 | D38: =+SUM(D25:D37) -> 39583602 | E38: 19259697 | F38: =+D38-E38 -> 20323904 | G38: =+D38/C38 -> 0.07190936 | H38: =+D38/$N$3*$N$4 -> 3.2986335e+08 | I38: =+H38/C38 -> 0.59924467 | J38: =+D38/$N$3 -> 13194534 | K38: =+(C38-D38)/$N$2 -> 23221892
A39: MAXI | B39: 58 - BLADIMIR LEZCANO | C39: 45000000 | D39: =IFERROR(+VLOOKUP(B39,COMISIONES!A:E,5,FALSE),"0")*1 -> 5539801 | E39: 0 | F39: =+D39-E39 -> 5539801 | G39: =+D39/C39 -> 0.12310669 | H39: =+D39/$N$3*$N$4 -> 46165008 | I39: =+H39/C39 -> 1.0258891 | J39: =+D39/$N$3 -> 1846600.3 | K39: =+(C39-D39)/$N$2 -> 1793645.4 | L39: {=+_xlfn.IFS(I39>114%,H39*0.02,I39>109%,H39*0.015,I39>104%,H39*0.0125,I39>99%,H39*0.01,I39<99%,H39*0)} -> 461650.08
B40: 59 - LEIVA SILVIO | C40: 30000000 | D40: =IFERROR(+VLOOKUP(B40,COMISIONES!A:E,5,FALSE),"0")*1 -> 3747230 | E40: 0 | F40: =+D40-E40 -> 3747230 | G40: =+D40/C40 -> 0.12490767 | H40: =+D40/$N$3*$N$4 -> 31226917 | I40: =+H40/C40 -> 1.0408972 | J40: =+D40/$N$3 -> 1249076.7 | K40: =+(C40-D40)/$N$2 -> 1193307.7 | L40: {=+_xlfn.IFS(I40>114%,H40*0.02,I40>109%,H40*0.015,I40>104%,H40*0.0125,I40>99%,H40*0.01,I40<99%,H40*0)} -> 390336.46
...

Sheet COBERTURA
A1: SUPERVISOR | C1: VENDEDOR | D1: COBERTURA TOTAL | E1: DIA ANTERIOR | F1: INCREMENTO DIARIO | G1: CARTERA TOTAL | H1: CCC | I1: CCC FALTANTE 85% | P1: Cod vdor | R1: Cobertura x Un de negocio
A2: MARTIN (SUPERVISOR) | B2: 22 | C2: =+AVANCE!B11 -> 22 - ALMIRON NICOLAS | D2: =H2/G2 -> 0.24050633 | E2: 33 | F2: =+H2-E2 -> -14 | G2: =VLOOKUP(B2,'Base Cobertura'!$A:$C,3,FALSE) -> 79 | H2: =VLOOKUP(B2,'Base Cobertura'!$A:$C,2,FALSE) -> 19 | I2: =(+G2*$M$2)-H2 -> 48.15 | J2: bien | K2: bien | L2: OBJETIVO | M2: 0.85 | P2: 25 | Q2: =VLOOKUP(P2,$B:$C,2,FALSE) -> 25 - KALATAKI GUSTAVO | R2: =VLOOKUP(P2,$B:$C,2,FALSE) -> 25 - KALATAKI GUSTAVO | S2: CCC | T2: CARTERA TOTAL | U2: % ALCANZADO
B3: 20 | C3: =+AVANCE!B2 -> 20 - FLORES JAVIER | D3: =H3/G3 -> 0.27826087 | E3: 126 | F3: =+H3-E3 -> -62 | G3: =VLOOKUP(B3,'Base Cobertura'!$A:$C,3,FALSE) -> 230 | H3: =VLOOKUP(B3,'Base Cobertura'!$A:$C,2,FALSE) -> 64 | I3: =(+G3*$M$2)-H3 -> 131.5 | J3: mal | K3: chaca | P3: {=+_xlfn._xlws.FILTER('Base Cobertura'!E:I,'Base Cobertura'!E:E=COBERTURA!P2)} -> 25 | Q3: 25 | R3: 135 - ALMACEN | S3: 0 | T3: 174 | U3: =+S3/T3 -> 0
B4: 15 | C4: =+AVANCE!B12 -> 15 - GALARZA GERARDO | D4: =H4/G4 -> 0.12307692 | E4: 21 | F4: =+H4-E4 -> -13 | G4: =VLOOKUP(B4,'Base Cobertura'!$A:$C,3,FALSE) -> 65 | H4: =VLOOKUP(B4,'Base Cobertura'!$A:$C,2,FALSE) -> 8 | I4: =(+G4*$M$2)-H4 -> 47.25 | J4: re bien | K4: muy bien | P4: 25 | Q4: 0 | R4: 135 - Articulos Sin Asociar Agrupacion | S4: 0 | T4: 174 | U4: =+S4/T4 -> 0
B5: 19 | C5: =+AVANCE!B3 -> 19 - GONZALEZ MARCELO | D5: =H5/G5 -> 0.26315789 | E5: 100 | F5: =+H5-E5 -> -45 | G5: =VLOOKUP(B5,'Base Cobertura'!$A:$C,3,FALSE) -> 209 | H5: =VLOOKUP(B5,'Base Cobertura'!$A:$C,2,FALSE) -> 55 | I5: =(+G5*$M$2)-H5 -> 122.65 | K5: muy bien | P5: 25 | Q5: 0 | R5: 135 - BEBIDAS | S5: 0 | T5: 174 | U5: =+S5/T5 -> 0
B6: 16 | C6: =+AVANCE!B4 -> 16 - GOMEZ MATÍAS | D6: =H6/G6 -> 0.17910448 | E6: 81 | F6: =+H6-E6 -> -45 | G6: =VLOOKUP(B6,'Base Cobertura'!$A:$C,3,FALSE) -> 201 | H6: =VLOOKUP(B6,'Base Cobertura'!$A:$C,2,FALSE) -> 36 | I6: =(+G6*$M$2)-H6 -> 134.85 | J6: apretarlo | K6: apretarlo | P6: 25 | Q6: 0 | R6: 135 - CHOCOLATE | S6: 0 | T6: 174 | U6: =+S6/T6 -> 0
B7: 12 | C7: =+AVANCE!B5 -> 12 - GUTIERREZ MARCOS DAVID | D7: =H7/G7 -> 0.21596244 | E7: 89 | F7: =+H7-E7 -> -43 | G7: =VLOOKUP(B7,'Base Cobertura'!$A:$C,3,FALSE) -> 213 | H7: =VLOOKUP(B7,'Base Cobertura'!$A:$C,2,FALSE) -> 46 | I7: =(+G7*$M$2)-H7 -> 135.05 | J7: apretarlo | K7: apretarlo | P7: 25 | Q7: 0 | R7: 135 - GALLETITAS | S7: 0 | T7: 174 | U7: =+S7/T7 -> 0
B8: 11 | C8: =+AVANCE!B6 -> 11 - SANCHEZ RICARDO | D8: =H8/G8 -> 0.25 | E8: 92 | F8: =+H8-E8 -> -50 | G8: =VLOOKUP(B8,'Base Cobertura'!$A:$C,3,FALSE) -> 168 | H8: =VLOOKUP(B8,'Base Cobertura'!$A:$C,2,FALSE) -> 42 | I8: =(+G8*$M$2)-H8 -> 100.8 | J8: bien | K8: apretarlo | P8: 25 | Q8: 0 | R8: 135 - GOLOSINAS | S8: 0 | T8: 174 | U8: =+S8/T8 -> 0
B9: 8 | C9: =+AVANCE!B7 -> 8 - PARRA MAXIMILIANO | D9: =H9/G9 -> 0.21674877 | E9: 64 | F9: =+H9-E9 -> -20 | G9: =VLOOKUP(B9,'Base Cobertura'!$A:$C,3,FALSE) -> 203 | H9: =VLOOKUP(B9,'Base Cobertura'!$A:$C,2,FALSE) -> 44 | I9: =(+G9*$M$2)-H9 -> 128.55 | J9: bien | K9: apretarlo con ema | P9: 25 | Q9: 0 | R9: 135 - MASCOTAS | S9: 0 | T9: 174 | U9: =+S9/T9 -> 0
B10: 52 | C10: =+AVANCE!B13 -> 52 - RAVAROTTO EMANUEL | D10: =H10/G10 -> 0.11214953 | E10: 19 | F10: =+H10-E10 -> -7 | G10: =VLOOKUP(B10,'Base Cobertura'!$A:$C,3,FALSE) -> 107 | H10: =VLOOKUP(B10,'Base Cobertura'!$A:$C,2,FALSE) -> 12 | I10: =(+G10*$M$2)-H10 -> 78.95 | J10: apretarlo | K10: apretarlo | P10: 25 | Q10: 0 | R10: 135 - NO PERECEDEROS | S10: 0 | T10: 174 | U10: =+S10/T10 -> 0
B11: 53 | C11: =+AVANCE!B14 -> 53 - SANDOVAL RODRIGO | D11: =H11/G11 -> 0.1047619 | E11: 24 | F11: =+H11-E11 -> -13 | G11: =VLOOKUP(B11,'Base Cobertura'!$A:$C,3,FALSE) -> 105 | H11: =VLOOKUP(B11,'Base Cobertura'!$A:$C,2,FALSE) -> 11 | I11: =(+G11*$M$2)-H11 -> 78.25 | J11: verlo | P11: 25 | Q11: 0 | R11: 135 - PILAS | S11: 0 | T11: 174 | U11: =+S11/T11 -> 0
B12: 5 | C12: =+AVANCE!B8 -> 5 - SCHELOVER RAUL | D12: =H12/G12 -> 0.30075188 | E12: 144 | F12: =+H12-E12 -> -64 | G12: =VLOOKUP(B12,'Base Cobertura'!$A:$C,3,FALSE) -> 266 | H12: =VLOOKUP(B12,'Base Cobertura'!$A:$C,2,FALSE) -> 80 | I12: =(+G12*$M$2)-H12 -> 146.1 | J12: verlo
B13: 4 | C13: =+AVANCE!B9 -> 4 - TUR SPRINGER FERNANDO | D13: =H13/G13 -> 0.2295082 | E13: 85 | F13: =+H13-E13 -> -43 | G13: =VLOOKUP(B13,'Base Cobertura'!$A:$C,3,FALSE) -> 183 | H13: =VLOOKUP(B13,'Base Cobertura'!$A:$C,2,FALSE) -> 42 | I13: =(+G13*$M$2)-H13 -> 113.55 | J13: re bien | K13: muy bien
F14: =+SUM(F1:F13) -> -419 | G14: =+SUM(G1:G13) -> 2029 | H14: =+SUM(H1:H13) -> 459 | J14: bien | K14: muy bien
A15: CRISTIAN (SUPERVISOR) | B15: 31 | C15: =+AVANCE!B21 -> 31 - RENZO RAMOS | D15: =H15/G15 -> 0.23121387 | E15: 90 | F15: =+H15-E15 -> -50 | G15: =VLOOKUP(B15,'Base Cobertura'!$A:$C,3,FALSE) -> 173 | H15: =VLOOKUP(B15,'Base Cobertura'!$A:$C,2,FALSE) -> 40 | I15: =(+G15*$M$2)-H15 -> 107.05 | J15: bien | K15: bien
B16: 54 | C16: =+AVANCE!B23 -> 54 - BARTSCHAT EMILIANO NAHUEL | D16: =H16/G16 -> 0.21463415 | E16: 92 | F16: =+H16-E16 -> -48 | G16: =VLOOKUP(B16,'Base Cobertura'!$A:$C,3,FALSE) -> 205 | H16: =VLOOKUP(B16,'Base Cobertura'!$A:$C,2,FALSE) -> 44 | I16: =(+G16*$M$2)-H16 -> 130.25 | J16: bien | K16: chaca
B17: 21 | C17: =+AVANCE!B19 -> 21 - CATAN MATIAS | D17: =H17/G17 -> 0.34337349 | E17: 88 | F17: =+H17-E17 -> -31 | G17: =VLOOKUP(B17,'Base Cobertura'!$A:$C,3,FALSE) -> 166 | H17: =VLOOKUP(B17,'Base Cobertura'!$A:$C,2,FALSE) -> 57 | I17: =(+G17*$M$2)-H17 -> 84.1 | J17: apretarlo | K17: bien
B18: 23 | C18: =+AVANCE!B20 -> 23 - DELGADO JOSÉ | D18: =H18/G18 -> 0.37341772 | E18: 95 | F18: =+H18-E18 -> -36 | G18: =VLOOKUP(B18,'Base Cobertura'!$A:$C,3,FALSE) -> 158 | H18: =VLOOKUP(B18,'Base Cobertura'!$A:$C,2,FALSE) -> 59 | I18: =(+G18*$M$2)-H18 -> 75.3 | J18: apretarlo | K18: muy bien
B19: 18 | C19: =+AVANCE!B18 -> 18 - HERRERA PABLO | D19: =H19/G19 -> 0.28571429 | E19: 83 | F19: =+H19-E19 -> -31 | G19: =VLOOKUP(B19,'Base Cobertura'!$A:$C,3,FALSE) -> 182 | H19: =VLOOKUP(B19,'Base Cobertura'!$A:$C,2,FALSE) -> 52 | I19: =(+G19*$M$2)-H19 -> 102.7 | J19: bien | K19: bien
B20: 44 | C20: =+AVANCE!B22 -> 44 - MONGES CESAR LUIS | D20: =H20/G20 -> 0.21264368 | E20: 64 | F20: =+H20-E20 -> -27 | G20: =VLOOKUP(B20,'Base Cobertura'!$A:$C,3,FALSE) -> 174 | H20: =VLOOKUP(B20,'Base Cobertura'!$A:$C,2,FALSE) -> 37 | I20: =(+G20*$M$2)-H20 -> 110.9 | J20: apretarlo | K20: muy bien
B21: 2 | C21: =+AVANCE!B16 -> 2 - OJEDA NORBERTO | D21: =H21/G21 -> 0.23387097 | E21: 70 | F21: =+H21-E21 -> -41 | G21: =VLOOKUP(B21,'Base Cobertura'!$A:$C,3,FALSE) -> 124 | H21: =VLOOKUP(B21,'Base Cobertura'!$A:$C,2,FALSE) -> 29 | I21: =(+G21*$M$2)-H21 -> 76.4 | J21: apretarlo | K21: apretar
B22: 3 | C22: =+AVANCE!B17 -> 3 - VIDAL NAHUEL | D22: =H22/G22 -> 0.33526012 | E22: 79 | F22: =+H22-E22 -> -21 | G22: =VLOOKUP(B22,'Base Cobertura'!$A:$C,3,FALSE) -> 173 | H22: =VLOOKUP(B22,'Base Cobertura'!$A:$C,2,FALSE) -> 58 | I22: =(+G22*$M$2)-H22 -> 89.05 | J22: abrazo | K22: muy bien
F23: =+SUM(F15:F22) -> -285 | G23: =+SUM(G15:G22) -> 1355 | H23: =+SUM(H15:H22) -> 376
A24: GONZALO (SUPERVISOR) | B24: 32 | C24: =+AVANCE!B25 -> 32 - CABRAL GONZALO | D24: =H24/G24 -> 0.10344828 | E24: 20 | F24: =+H24-E24 -> -14 | G24: =VLOOKUP(B24,'Base Cobertura'!$A:$C,3,FALSE) -> 58 | H24: =VLOOKUP(B24,'Base Cobertura'!$A:$C,2,FALSE) -> 6 | I24: =(+G24*$M$2)-H24 -> 43.3 | J24: bien | K24: apretar
B25: 36 | C25: =+AVANCE!B26 -> 36 - IBARROLA JORGE | D25: =H25/G25 -> 0.16149068 | E25: 68 | F25: =+H25-E25 -> -42 | G25: =VLOOKUP(B25,'Base Cobertura'!$A:$C,3,FALSE) -> 161 | H25: =VLOOKUP(B25,'Base Cobertura'!$A:$C,2,FALSE) -> 26 | I25: =(+G25*$M$2)-H25 -> 110.85 | J25: apretarlo | K25: apretar
B26: 9 | C26: =+AVANCE!B27 -> 9 - ESTIGARRIBIA DAVID | D26: =H26/G26 -> 0.25503356 | E26: 80 | F26: =+H26-E26 -> -42 | G26: =VLOOKUP(B26,'Base Cobertura'!$A:$C,3,FALSE) -> 149 | H26: =VLOOKUP(B26,'Base Cobertura'!$A:$C,2,FALSE) -> 38 | I26: =(+G26*$M$2)-H26 -> 88.65 | J26: apretarlo | K26: bien
B27: 40 | C27: =+AVANCE!B28 -> 40 - SOLIS EMMANUEL | D27: =H27/G27 -> 0.10572687 | E27: 68 | F27: =+H27-E27 -> -44 | G27: =VLOOKUP(B27,'Base Cobertura'!$A:$C,3,FALSE) -> 227 | H27: =VLOOKUP(B27,'Base Cobertura'!$A:$C,2,FALSE) -> 24 | I27: =(+G27*$M$2)-H27 -> 168.95 | J27: apretarlo | K27: apretar
B28: 27 | C28: =+AVANCE!B29 -> 27 - GOMEZ ADRIÁN | D28: =H28/G28 -> 0.30534351 | E28: 73 | F28: =+H28-E28 -> -33 | G28: =VLOOKUP(B28,'Base Cobertura'!$A:$C,3,FALSE) -> 131 | H28: =VLOOKUP(B28,'Base Cobertura'!$A:$C,2,FALSE) -> 40 | I28: =(+G28*$M$2)-H28 -> 71.35 | J28: bien | K28: apretar
B29: 10 | C29: =+AVANCE!B30 -> 10 - BRITEZ EMMANUEL | D29: =H29/G29 -> 0.18787879 | E29: 40 | F29: =+H29-E29 -> -9 | G29: =VLOOKUP(B29,'Base Cobertura'!$A:$C,3,FALSE) -> 165 | H29: =VLOOKUP(B29,'Base Cobertura'!$A:$C,2,FALSE) -> 31 | I29: =(+G29*$M$2)-H29 -> 109.25 | J29: apretarlo | K29: apretar
B30: 28 | C30: =+AVANCE!B31 -> 28 - GOMEZ PABLO | D30: =H30/G30 -> 0.29299363 | E30: 67 | F30: =+H30-E30 -> -21 | G30: =VLOOKUP(B30,'Base Cobertura'!$A:$C,3,FALSE) -> 157 | H30: =VLOOKUP(B30,'Base Cobertura'!$A:$C,2,FALSE) -> 46 | I30: =(+G30*$M$2)-H30 -> 87.45 | J30: apretarlo | K30: apretar
B31: 33 | C31: =+AVANCE!B32 -> 33 - ESQUIVEL NICOLAS | D31: =H31/G31 -> 0.15204678 | E31: 66 | F31: =+H31-E31 -> -40 | G31: =VLOOKUP(B31,'Base Cobertura'!$A:$C,3,FALSE) -> 171 | H31: =VLOOKUP(B31,'Base Cobertura'!$A:$C,2,FALSE) -> 26 | I31: =(+G31*$M$2)-H31 -> 119.35 | J31: apretarlo | K31: apretar
B32: 37 | C32: =+AVANCE!B33 -> 37 - SALAJ EMILIO | D32: =H32/G32 -> 0.14864865 | E32: 82 | F32: =+H32-E32 -> -60 | G32: =VLOOKUP(B32,'Base Cobertura'!$A:$C,3,FALSE) -> 148 | H32: =VLOOKUP(B32,'Base Cobertura'!$A:$C,2,FALSE) -> 22 | I32: =(+G32*$M$2)-H32 -> 103.8 | J32: bien | K32: apretar
B33: 24 | C33: =+AVANCE!B34 -> 24 - AZULA NICOLAS | D33: =H33/G33 -> 0.12716763 | E33: 81 | F33: =+H33-E33 -> -59 | G33: =VLOOKUP(B33,'Base Cobertura'!$A:$C,3,FALSE) -> 173 | H33: =VLOOKUP(B33,'Base Cobertura'!$A:$C,2,FALSE) -> 22 | I33: =(+G33*$M$2)-H33 -> 125.05 | J33: apretarlo | K33: apretar
B34: 7 | C34: =+AVANCE!B35 -> 7 - VALLEJOS EDUARDO | D34: =H34/G34 -> 0.0086206897 | E34: 0 | F34: =+H34-E34 -> 1 | G34: =VLOOKUP(B34,'Base Cobertura'!$A:$C,3,FALSE) -> 116 | H34: =VLOOKUP(B34,'Base Cobertura'!$A:$C,2,FALSE) -> 1 | I34: =(+G34*$M$2)-H34 -> 97.6 | J34: apretarlo
B35: 57 | C35: =+AVANCE!B36 -> 57 - FEDERRATH MARTIN | D35: =H35/G35 -> 0.12149533 | E35: 17 | F35: =+H35-E35 -> -4 | G35: =VLOOKUP(B35,'Base Cobertura'!$A:$C,3,FALSE) -> 107 | H35: =VLOOKUP(B35,'Base Cobertura'!$A:$C,2,FALSE) -> 13 | I35: =(+G35*$M$2)-H35 -> 77.95 | J35: verlo
B36: 1 | C36: =+AVANCE!B37 -> 1 - VERA ERNESTO | D36: =H36/G36 -> 0.29565217 | E36: 60 | F36: =+H36-E36 -> -26 | G36: =VLOOKUP(B36,'Base Cobertura'!$A:$C,3,FALSE) -> 115 | H36: =VLOOKUP(B36,'Base Cobertura'!$A:$C,2,FALSE) -> 34 | I36: =(+G36*$M$2)-H36 -> 63.75 | J36: bien | K36: bien
F37: =+SUM(F24:F36) -> -393 | G37: =+SUM(G24:G36) -> 1878 | H37: =+SUM(H24:H36) -> 329
A38: MAXI (SUPERVISOR) | B38: 58 | C38: =+AVANCE!B39 -> 58 - BLADIMIR LEZCANO | D38: =H38/G38 -> 0 | E38: 60 | F38: =+H38-E38 -> -60 | G38: =VLOOKUP(B38,'Base Cobertura'!$A:$C,3,FALSE) -> 83 | H38: =VLOOKUP(B38,'Base Cobertura'!$A:$C,2,FALSE) -> 0 | I38: =(+G38*$M$2)-H38 -> 70.55
B39: 59 | C39: =+AVANCE!B40 -> 59 - LEIVA SILVIO | D39: =H39/G39 -> 0 | E39: 60 | F39: =+H39-E39 -> -60 | G39: =VLOOKUP(B39,'Base Cobertura'!$A:$C,3,FALSE) -> 128 | H39: =VLOOKUP(B39,'Base Cobertura'!$A:$C,2,FALSE) -> 0 | I39: =(+G39*$M$2)-H39 -> 108.8
B40: 49 | C40: =+AVANCE!B41 -> 49 - ESCOBAR RAÚL | D40: =H40/G40 -> 0 | E40: 60 | F40: =+H40-E40 -> -60 | G40: =VLOOKUP(B40,'Base Cobertura'!$A:$C,3,FALSE) -> 247 | H40: =VLOOKUP(B40,'Base Cobertura'!$A:$C,2,FALSE) -> 0 | I40: =(+G40*$M$2)-H40 -> 209.95
...

Sheet Cantidad Sku
B1: Cantidad skus
A2: Supervisor Cristian | E2: Vendedores Mayoristas | G2: Cantidad skus
A3: Cod vdor | C3: Cantidad skus | E3: 15 | F3: GALARZA GERARDO | G3: =SUMIFS('Base SKU'!$AM:$AM,'Base SKU'!$E:$E,E3,'Base SKU'!$AM:$AM,1) -> 72
A4: 2 | B4: OJEDA NORBERTO | C4: =SUMIFS('Base SKU'!$AM:$AM,'Base SKU'!$E:$E,A4,'Base SKU'!$AM:$AM,1) -> 135 | E4: 7 | F4: VALLEJOS EDUARDO | G4: 128
A5: 3 | B5: VIDAL NAHUEL | C5: =SUMIFS('Base SKU'!$AM:$AM,'Base SKU'!$E:$E,A5,'Base SKU'!$AM:$AM,1) -> 203
A6: 18 | B6: HERRERA PABLO | C6: =SUMIFS('Base SKU'!$AM:$AM,'Base SKU'!$E:$E,A6,'Base SKU'!$AM:$AM,1) -> 178
A7: 21 | B7: CATAN MATIAS | C7: =SUMIFS('Base SKU'!$AM:$AM,'Base SKU'!$E:$E,A7,'Base SKU'!$AM:$AM,1) -> 202
A8: 23 | B8: DELGADO JOSÉ | C8: =SUMIFS('Base SKU'!$AM:$AM,'Base SKU'!$E:$E,A8,'Base SKU'!$AM:$AM,1) -> 171 | E8: Vendedores Supermercados | G8: Cantidad skus
A9: 31 | B9: RENZO RAMOS | C9: =SUMIFS('Base SKU'!$AM:$AM,'Base SKU'!$E:$E,A9,'Base SKU'!$AM:$AM,1) -> 201 | E9: 22 | F9: ALMIRON NICOLAS | G9: =SUMIFS('Base SKU'!$AM:$AM,'Base SKU'!$E:$E,E9,'Base SKU'!$AM:$AM,1) -> 207
A10: 44 | B10: MONGES CESAR LUIS | C10: =SUMIFS('Base SKU'!$AM:$AM,'Base SKU'!$E:$E,A10,'Base SKU'!$AM:$AM,1) -> 149 | E10: 32 | F10: CABRAL GONZALO | G10: =SUMIFS('Base SKU'!$AM:$AM,'Base SKU'!$E:$E,E10,'Base SKU'!$AM:$AM,1) -> 100
A11: 54 | B11: BARTSCHAT EMILIANO NAHUEL | C11: =SUMIFS('Base SKU'!$AM:$AM,'Base SKU'!$E:$E,A11,'Base SKU'!$AM:$AM,1) -> 191
A12: Totales | E12: Supervisior Maxi | G12: Cantidad skus
A13: Supervisor Martin | C13: Cantidad skus | E13: 58 | F13: BLADIMIR LEZCANO | G13: =SUMIFS('Base SKU'!$AM:$AM,'Base SKU'!$E:$E,E13,'Base SKU'!$AM:$AM,1) -> 125
A14: 4 | B14: TUR SPRINGER FERNANDO | C14: =SUMIFS('Base SKU'!$AM:$AM,'Base SKU'!$E:$E,A14,'Base SKU'!$AM:$AM,1) -> 174 | E14: 59 | F14: LEIVA SILVIO | G14: =SUMIFS('Base SKU'!$AM:$AM,'Base SKU'!$E:$E,E14,'Base SKU'!$AM:$AM,1) -> 107
A15: 5 | B15: SCHELOVER RAUL | C15: =SUMIFS('Base SKU'!$AM:$AM,'Base SKU'!$E:$E,A15,'Base SKU'!$AM:$AM,1) -> 207 | E15: 60 | F15: SILVA ADRIAN | G15: =SUMIFS('Base SKU'!$AM:$AM,'Base SKU'!$E:$E,E15,'Base SKU'!$AM:$AM,1) -> 74
A16: 8 | B16: PARRA MAXIMILIANO | C16: =SUMIFS('Base SKU'!$AM:$AM,'Base SKU'!$E:$E,A16,'Base SKU'!$AM:$AM,1) -> 133 | E16: 56 | F16: JUAN ANDRES SANCHEZ | G16: =SUMIFS('Base SKU'!$AM:$AM,'Base SKU'!$E:$E,E16,'Base SKU'!$AM:$AM,1) -> 149
A17: 11 | B17: SANCHEZ RICARDO | C17: =SUMIFS('Base SKU'!$AM:$AM,'Base SKU'!$E:$E,A17,'Base SKU'!$AM:$AM,1) -> 153 | E17: 26 | F17: PUJOL ERNESTO | G17: =SUMIFS('Base SKU'!$AM:$AM,'Base SKU'!$E:$E,E17,'Base SKU'!$AM:$AM,1) -> 166
A18: 12 | B18: GUTIERREZ MARCOS DAVID | C18: =SUMIFS('Base SKU'!$AM:$AM,'Base SKU'!$E:$E,A18,'Base SKU'!$AM:$AM,1) -> 157 | E18: 25 | F18: KALATAKI GUSTAVO | G18: =SUMIFS('Base SKU'!$AM:$AM,'Base SKU'!$E:$E,E18,'Base SKU'!$AM:$AM,1) -> 182
A19: 16 | B19: GOMEZ MATÍAS | C19: =SUMIFS('Base SKU'!$AM:$AM,'Base SKU'!$E:$E,A19,'Base SKU'!$AM:$AM,1) -> 130 | E19: 43 | F19: COLHER DIEGO | G19: =SUMIFS('Base SKU'!$AM:$AM,'Base SKU'!$E:$E,E19,'Base SKU'!$AM:$AM,1) -> 0
A20: 19 | B20: GONZALEZ MARCELO | C20: =SUMIFS('Base SKU'!$AM:$AM,'Base SKU'!$E:$E,A20,'Base SKU'!$AM:$AM,1) -> 195 | E20: 49 | F20: ESCOBAR RAÚL | G20: =SUMIFS('Base SKU'!$AM:$AM,'Base SKU'!$E:$E,E20,'Base SKU'!$AM:$AM,1) -> 13
A21: 20 | B21: FLORES JAVIER | C21: =SUMIFS('Base SKU'!$AM:$AM,'Base SKU'!$E:$E,A21,'Base SKU'!$AM:$AM,1) -> 186
A22: Totales | E22: Vendedores PETS | G22: Cantidad skus
A23: Supervision Corrientes | C23: Cantidad skus | E23: 52 | F23: RAVAROTTO EMANUEL | G23: =SUMIFS('Base SKU'!$AM:$AM,'Base SKU'!$E:$E,E23,'Base SKU'!$AM:$AM,1) -> 61
A24: 1 | B24: VERA ERNESTO | C24: =SUMIFS('Base SKU'!$AM:$AM,'Base SKU'!$E:$E,A24,'Base SKU'!$AM:$AM,1) -> 165 | E24: 53 | F24: SANDOVAL RODRIGO | G24: =SUMIFS('Base SKU'!$AM:$AM,'Base SKU'!$E:$E,E24,'Base SKU'!$AM:$AM,1) -> 66
A25: 9 | B25: ESTIGARRIBIA DAVID | C25: =SUMIFS('Base SKU'!$AM:$AM,'Base SKU'!$E:$E,A25,'Base SKU'!$AM:$AM,1) -> 133 | E25: 57 | F25: FEDERRATH MARTIN | G25: =SUMIFS('Base SKU'!$AM:$AM,'Base SKU'!$E:$E,E25,'Base SKU'!$AM:$AM,1) -> 56
A26: 10 | B26: BRITEZ EMMANUEL | C26: =SUMIFS('Base SKU'!$AM:$AM,'Base SKU'!$E:$E,A26,'Base SKU'!$AM:$AM,1) -> 127
A27: 24 | B27: SOLIS EMMANUEL | C27: =SUMIFS('Base SKU'!$AM:$AM,'Base SKU'!$E:$E,A27,'Base SKU'!$AM:$AM,1) -> 90
A28: 27 | B28: GOMEZ ADRIÁN | C28: =SUMIFS('Base SKU'!$AM:$AM,'Base SKU'!$E:$E,A28,'Base SKU'!$AM:$AM,1) -> 153
A29: 28 | B29: GOMEZ PABLO | C29: =SUMIFS('Base SKU'!$AM:$AM,'Base SKU'!$E:$E,A29,'Base SKU'!$AM:$AM,1) -> 145
A30: 33 | B30: NICOLAS AZULA | C30: =SUMIFS('Base SKU'!$AM:$AM,'Base SKU'!$E:$E,A30,'Base SKU'!$AM:$AM,1) -> 109
A31: 36 | B31: COSARINSKI DIEGO | C31: =SUMIFS('Base SKU'!$AM:$AM,'Base SKU'!$E:$E,A31,'Base SKU'!$AM:$AM,1) -> 88
A32: 37 | B32: SALAJ EMILIO | C32: =SUMIFS('Base SKU'!$AM:$AM,'Base SKU'!$E:$E,A32,'Base SKU'!$AM:$AM,1) -> 69
A33: 40 | B33: IBARROLA JORGE | C33: =SUMIFS('Base SKU'!$AM:$AM,'Base SKU'!$E:$E,A33,'Base SKU'!$AM:$AM,1) -> 152
A34: Totales

Sheet Base SKU
A1: Periodos | B1: Cod. Período | C1: Descripción Período | D1: Vendedor según comprobante | E1: Código | F1: Descripción | G1: Artículos | H1: Código | I1: Descripción | J1: Marca | K1: Descripción | L1: Detalle | M1: Calibre | N1: Descripción | O1: Detalle | P1: División | Q1: Descripción | R1: Detalle | S1: Producto Estadístico | T1: Descripción | U1: Detalle | V1: Sabor | W1: Descripción | X1: Detalle | Y1: Unidad de Negocio | Z1: Descripción | AA1: Detalle | AB1: P.P.P. Neto | AC1: P.P.P. Final | AD1: Cantidades CON Cargo | AE1: Cantidades SIN Cargo | AF1: Cantidades Totales | AG1: Pesos Totales | AH1: Importes Netos | AI1: Importes Finales | AJ1: Cantidad de Facturas | AK1: Bultos Promedio | AL1: Cantidades en Combos
A2: (001) 01 SEP 2026 - 03 SEP 2026 | B2: 1 | C2: 01 SEP 2026 - 03 SEP 2026 | D2: Suc: 001 (000001) VERA ERNESTO | E2: 1 | F2: VERA ERNESTO | G2: (000001) PILA E 91AA X 4U ENERGIZER ALCALINA | H2: 1 | I2: PILA E 91AA X 4U ENERGIZER ALCALINA | J2: 1019 | K2: ENERGIZER | L2: 1019 - ENERGIZER | P2: 1020 | Q2: PILA | R2: 1020 - PILA | Y2: 1402 | Z2: PILAS | AA2: 1402 - PILAS | AB2: 246389.6 | AC2: 301827.26 | AD2: 0.1 | AE2: 0 | AF2: 0.1 | AG2: 0 | AH2: 24638.96 | AI2: 30182.73 | AJ2: 1 | AK2: 0.1 | AL2: 0 | AM2: 1 | AN2: =VLOOKUP(H2,'Base Art'!$A:$AJ,36,FALSE) -> ENERGIZER ARGENTINA S.A.
A3: (001) 01 SEP 2026 - 03 SEP 2026 | B3: 1 | C3: 01 SEP 2026 - 03 SEP 2026 | D3: Suc: 001 (000001) VERA ERNESTO | E3: 1 | F3: VERA ERNESTO | G3: (000005) BATERIA 9V X 1U -522BP ENERGIZER ALCALIN | H3: 5 | I3: BATERIA 9V X 1U -522BP ENERGIZER ALCALIN | J3: 1019 | K3: ENERGIZER | L3: 1019 - ENERGIZER | P3: 1020 | Q3: PILA | R3: 1020 - PILA | Y3: 1402 | Z3: PILAS | AA3: 1402 - PILAS | AB3: 177045.47 | AC3: 216880.7 | AD3: 0.0833 | AE3: 0 | AF3: 0.0833 | AG3: 0 | AH3: 14753.79 | AI3: 18073.39 | AJ3: 1 | AK3: 0.08 | AL3: 0 | AM3: 1 | AN3: =VLOOKUP(H3,'Base Art'!$A:$AJ,36,FALSE) -> ENERGIZER ARGENTINA S.A.
A4: (001) 01 SEP 2026 - 03 SEP 2026 | B4: 1 | C4: 01 SEP 2026 - 03 SEP 2026 | D4: Suc: 001 (000001) VERA ERNESTO | E4: 1 | F4: VERA ERNESTO | G4: (000027) PEDIGREE ADTO RAZ PEQ ETAPA2 X1,5KG | H4: 27 | I4: PEDIGREE ADTO RAZ PEQ ETAPA2 X1,5KG | J4: 1194 | K4: PEDIGREE MARCA | L4: 1194 - PEDIGREE MARCA | P4: 1098 | Q4: PAQUETERIA WHISKAS Y PEDIG | R4: 1098 - PAQUETERIA WHISKAS Y PEDIG | Y4: 1375 | Z4: MASCOTAS | AA4: 1375 - MASCOTAS | AB4: 37205.401 | AC4: 45576.619 | AD4: 0.2222 | AE4: 0 | AF4: 0.2222 | AG4: 0 | AH4: 8267.87 | AI4: 10128.14 | AJ4: 0 | AK4: 0 | AL4: 0 | AM4: 1 | AN4: =VLOOKUP(H4,'Base Art'!$A:$AJ,36,FALSE) -> MASTERFOODS ARGENTINA LTD.
A5: (001) 01 SEP 2026 - 03 SEP 2026 | B5: 1 | C5: 01 SEP 2026 - 03 SEP 2026 | D5: Suc: 001 (000001) VERA ERNESTO | E5: 1 | F5: VERA ERNESTO | G5: (000156) LA GOTITA X 2 ML CHICA | H5: 156 | I5: LA GOTITA X 2 ML CHICA | J5: 1437 | K5: LA GOTITA | L5: 1437 - LA GOTITA | Y5: 1376 | Z5: NO PERECEDEROS | AA5: 1376 - NO PERECEDEROS | AB5: 352614.34 | AC5: 431952.58 | AD5: 0.175 | AE5: 0 | AF5: 0.175 | AG5: 0 | AH5: 61707.51 | AI5: 75591.7 | AJ5: 3 | AK5: 0.06 | AL5: 0 | AM5: 1 | AN5: =VLOOKUP(H5,'Base Art'!$A:$AJ,36,FALSE) -> JORGE LUIS SUAREZ
A6: (001) 01 SEP 2026 - 03 SEP 2026 | B6: 1 | C6: 01 SEP 2026 - 03 SEP 2026 | D6: Suc: 001 (000001) VERA ERNESTO | E6: 1 | F6: VERA ERNESTO | G6: (000158) LA GOTITA GEL X 3 GR CHICO | H6: 158 | I6: LA GOTITA GEL X 3 GR CHICO | J6: 1437 | K6: LA GOTITA | L6: 1437 - LA GOTITA | Y6: 1376 | Z6: NO PERECEDEROS | AA6: 1376 - NO PERECEDEROS | AB6: 421734.78 | AC6: 516625.09 | AD6: 0.125 | AE6: 0 | AF6: 0.125 | AG6: 0 | AH6: 52716.85 | AI6: 64578.14 | AJ6: 0 | AK6: 0 | AL6: 0 | AM6: 1 | AN6: =VLOOKUP(H6,'Base Art'!$A:$AJ,36,FALSE) -> JORGE LUIS SUAREZ
A7: (001) 01 SEP 2026 - 03 SEP 2026 | B7: 1 | C7: 01 SEP 2026 - 03 SEP 2026 | D7: Suc: 001 (000001) VERA ERNESTO | E7: 1 | F7: VERA ERNESTO | G7: (000164) POXIPOL 10' X 14 ML. TPTE. CHICO | H7: 164 | I7: POXIPOL 10' X 14 ML. TPTE. CHICO | J7: 1439 | K7: POXIPOL | L7: 1439 - POXIPOL | Y7: 1376 | Z7: NO PERECEDEROS | AA7: 1376 - NO PERECEDEROS | AB7: 1097448.9 | AC7: 1344374.9 | AD7: 0.025 | AE7: 0 | AF7: 0.025 | AG7: 0 | AH7: 27436.22 | AI7: 33609.37 | AJ7: 0 | AK7: 0 | AL7: 0 | AM7: 1 | AN7: =VLOOKUP(H7,'Base Art'!$A:$AJ,36,FALSE) -> JORGE LUIS SUAREZ
A8: (001) 01 SEP 2026 - 03 SEP 2026 | B8: 1 | C8: 01 SEP 2026 - 03 SEP 2026 | D8: Suc: 001 (000001) VERA ERNESTO | E8: 1 | F8: VERA ERNESTO | G8: (000273) ALKA CARAMELOS STRONG X 800 GR | H8: 273 | I8: ALKA CARAMELOS STRONG X 800 GR | J8: 1413 | K8: ALKA | L8: 1413 - ALKA | Y8: 1374 | Z8: GOLOSINAS | AA8: 1374 - GOLOSINAS | AB8: 80232.279 | AC8: 99086.869 | AD8: 0.3 | AE8: 0 | AF8: 0.3 | AG8: 0 | AH8: 24069.68 | AI8: 29726.06 | AJ8: 0 | AK8: 0 | AL8: 0 | AM8: 1 | AN8: =VLOOKUP(H8,'Base Art'!$A:$AJ,36,FALSE) -> ARCOR S.A.I.C.
A9: (001) 01 SEP 2026 - 03 SEP 2026 | B9: 1 | C9: 01 SEP 2026 - 03 SEP 2026 | D9: Suc: 001 (000001) VERA ERNESTO | E9: 1 | F9: VERA ERNESTO | G9: (000400) PILA 377 / 376 X 5U ESP RELOJERIA PLATA | H9: 400 | I9: PILA 377 / 376 X 5U ESP RELOJERIA PLATA | J9: 1019 | K9: ENERGIZER | L9: 1019 - ENERGIZER | P9: 1020 | Q9: PILA | R9: 1020 - PILA | Y9: 1402 | Z9: PILAS | AA9: 1402 - PILAS | AB9: 141264 | AC9: 175167.36 | AD9: 0.2 | AE9: 0 | AF9: 0.2 | AG9: 0 | AH9: 28252.8 | AI9: 35033.47 | AJ9: 1 | AK9: 0.2 | AL9: 0 | AM9: 1 | AN9: =VLOOKUP(H9,'Base Art'!$A:$AJ,36,FALSE) -> ENERGIZER ARGENTINA S.A.
A10: (001) 01 SEP 2026 - 03 SEP 2026 | B10: 1 | C10: 01 SEP 2026 - 03 SEP 2026 | D10: Suc: 001 (000001) VERA ERNESTO | E10: 1 | F10: VERA ERNESTO | G10: (000461) MATE LISTO TARAGUI X 35 GR | H10: 461 | I10: MATE LISTO TARAGUI X 35 GR | J10: 1006 | K10: TARAGUI | L10: 1006 - TARAGUI | P10: 1004 | Q10: INFUSIONES | R10: 1004 - INFUSIONES | Y10: 1369 | Z10: ALMACEN | AA10: 1369 - ALMACEN | AB10: 19339.909 | AC10: 24271.588 | AD10: 0.3333 | AE10: 0 | AF10: 0.3333 | AG10: 0 | AH10: 6446.64 | AI10: 8090.53 | AJ10: 0 | AK10: 0 | AL10: 0 | AM10: 1 | AN10: =VLOOKUP(H10,'Base Art'!$A:$AJ,36,FALSE) -> EST. LAS MARIAS S.A.C.I.F.A.
A11: (001) 01 SEP 2026 - 03 SEP 2026 | B11: 1 | C11: 01 SEP 2026 - 03 SEP 2026 | D11: Suc: 001 (000001) VERA ERNESTO | E11: 1 | F11: VERA ERNESTO | G11: (000462) BOTELLA TERMICA MATE LISTO | H11: 462 | I11: BOTELLA TERMICA MATE LISTO | J11: 1006 | K11: TARAGUI | L11: 1006 - TARAGUI | Y11: 1369 | Z11: ALMACEN | AA11: 1369 - ALMACEN | AB11: 15679.431 | AC11: 19677.688 | AD11: 0.3333 | AE11: 0 | AF11: 0.3333 | AG11: 0 | AH11: 5226.48 | AI11: 6559.23 | AJ11: 0 | AK11: 0 | AL11: 0 | AM11: 1 | AN11: =VLOOKUP(H11,'Base Art'!$A:$AJ,36,FALSE) -> EST. LAS MARIAS S.A.C.I.F.A.
A12: (001) 01 SEP 2026 - 03 SEP 2026 | B12: 1 | C12: 01 SEP 2026 - 03 SEP 2026 | D12: Suc: 001 (000001) VERA ERNESTO | E12: 1 | F12: VERA ERNESTO | G12: (000542) PILA ECR-2032 X 5U ESP CALCULADORA | H12: 542 | I12: PILA ECR-2032 X 5U ESP CALCULADORA | J12: 1019 | K12: ENERGIZER | L12: 1019 - ENERGIZER | P12: 1020 | Q12: PILA | R12: 1020 - PILA | Y12: 1402 | Z12: PILAS | AA12: 1402 - PILAS | AB12: 125705.25 | AC12: 153988.93 | AD12: 0.15 | AE12: 0 | AF12: 0.15 | AG12: 0 | AH12: 18855.79 | AI12: 23098.34 | AJ12: 1 | AK12: 0.15 | AL12: 0 | AM12: 1 | AN12: =VLOOKUP(H12,'Base Art'!$A:$AJ,36,FALSE) -> ENERGIZER ARGENTINA S.A.
A13: (001) 01 SEP 2026 - 03 SEP 2026 | B13: 1 | C13: 01 SEP 2026 - 03 SEP 2026 | D13: Suc: 001 (000001) VERA ERNESTO | E13: 1 | F13: VERA ERNESTO | G13: (000559) UNI-POX X 25 ML. CHICO | H13: 559 | I13: UNI-POX X 25 ML. CHICO | J13: 1442 | K13: UNI-POX | L13: 1442 - UNI-POX | P13: 1090 | Q13: PEGAMENTOS | R13: 1090 - PEGAMENTOS | Y13: 1376 | Z13: NO PERECEDEROS | AA13: 1376 - NO PERECEDEROS | AB13: 220169.87 | AC13: 269708.09 | AD13: 0.075 | AE13: 0 | AF13: 0.075 | AG13: 0 | AH13: 16512.74 | AI13: 20228.11 | AJ13: 0 | AK13: 0 | AL13: 0 | AM13: 1 | AN13: =VLOOKUP(H13,'Base Art'!$A:$AJ,36,FALSE) -> JORGE LUIS SUAREZ
A14: (001) 01 SEP 2026 - 03 SEP 2026 | B14: 1 | C14: 01 SEP 2026 - 03 SEP 2026 | D14: Suc: 001 (000001) VERA ERNESTO | E14: 1 | F14: VERA ERNESTO | G14: (000568) BUBBALOO 60'S UVA | H14: 568 | I14: BUBBALOO 60'S UVA | Y14: 1374 | Z14: GOLOSINAS | AA14: 1374 - GOLOSINAS | AB14: 144342.45 | AC14: 176819.49 | AD14: 0.0313 | AE14: 0 | AF14: 0.0313 | AG14: 0 | AH14: 4510.7 | AI14: 5525.61 | AJ14: 0 | AK14: 0 | AL14: 0 | AM14: 1 | AN14: =VLOOKUP(H14,'Base Art'!$A:$AJ,36,FALSE) -> MONDELEZ ARGENTINA S.A.
A15: (001) 01 SEP 2026 - 03 SEP 2026 | B15: 1 | C15: 01 SEP 2026 - 03 SEP 2026 | D15: Suc: 001 (000001) VERA ERNESTO | E15: 1 | F15: VERA ERNESTO | G15: (000639) BATERIA A23 -12V X 5U -ENERGIZER ALCALINA | H15: 639 | I15: BATERIA A23 -12V X 5U -ENERGIZER ALCALINA | J15: 1019 | K15: ENERGIZER | L15: 1019 - ENERGIZER | P15: 1020 | Q15: PILA | R15: 1020 - PILA | Y15: 1402 | Z15: PILAS | AA15: 1402 - PILAS | AB15: 158898.3 | AC15: 194650.42 | AD15: 0.15 | AE15: 0 | AF15: 0.15 | AG15: 0 | AH15: 23834.75 | AI15: 29197.56 | AJ15: 0 | AK15: 0 | AL15: 0 | AM15: 1 | AN15: =VLOOKUP(H15,'Base Art'!$A:$AJ,36,FALSE) -> ENERGIZER ARGENTINA S.A.
A16: (001) 01 SEP 2026 - 03 SEP 2026 | B16: 1 | C16: 01 SEP 2026 - 03 SEP 2026 | D16: Suc: 001 (000001) VERA ERNESTO | E16: 1 | F16: VERA ERNESTO | G16: (000653) CARAM MAST SURT MISKY X800 GR | H16: 653 | I16: CARAM MAST SURT MISKY X800 GR | J16: 1414 | K16: MISKY | L16: 1414 - MISKY | P16: 1072 | Q16: MISKY CARAM | R16: 1072 - MISKY CARAM | Y16: 1374 | Z16: GOLOSINAS | AA16: 1374 - GOLOSINAS | AB16: 50907.528 | AC16: 63125.328 | AD16: 0.1 | AE16: 0 | AF16: 0.1 | AG16: 0 | AH16: 5090.75 | AI16: 6312.53 | AJ16: 0 | AK16: 0 | AL16: 0 | AM16: 1 | AN16: =VLOOKUP(H16,'Base Art'!$A:$AJ,36,FALSE) -> ARCOR S.A.I.C.
A17: (001) 01 SEP 2026 - 03 SEP 2026 | B17: 1 | C17: 01 SEP 2026 - 03 SEP 2026 | D17: Suc: 001 (000001) VERA ERNESTO | E17: 1 | F17: VERA ERNESTO | G17: (000710) PILA ECR-2025 X 5U ESP CALCULADORA | H17: 710 | I17: PILA ECR-2025 X 5U ESP CALCULADORA | J17: 1019 | K17: ENERGIZER | L17: 1019 - ENERGIZER | P17: 1020 | Q17: PILA | R17: 1020 - PILA | Y17: 1402 | Z17: PILAS | AA17: 1402 - PILAS | AB17: 118162.93 | AC17: 144749.61 | AD17: 0.05 | AE17: 0 | AF17: 0.05 | AG17: 0 | AH17: 5908.15 | AI17: 7237.48 | AJ17: 1 | AK17: 0.05 | AL17: 0 | AM17: 1 | AN17: =VLOOKUP(H17,'Base Art'!$A:$AJ,36,FALSE) -> ENERGIZER ARGENTINA S.A.
A18: (001) 01 SEP 2026 - 03 SEP 2026 | B18: 1 | C18: 01 SEP 2026 - 03 SEP 2026 | D18: Suc: 001 (000001) VERA ERNESTO | E18: 1 | F18: VERA ERNESTO | G18: (000731) POLVORITAS VAINILLA X 81 GR | H18: 731 | I18: POLVORITAS VAINILLA X 81 GR | J18: 1422 | K18: POLVORITAS | L18: 1422 - POLVORITAS | P18: 1067 | Q18: POLVORITAS 80G Y 147G | R18: 1067 - POLVORITAS 80G Y 147G | Y18: 1373 | Z18: GALLETITAS | AA18: 1373 - GALLETITAS | AB18: 17387.677 | AC18: 21499.839 | AD18: 0.45 | AE18: 0.025 | AF18: 0.475 | AG18: 0 | AH18: 8259.15 | AI18: 10212.42 | AJ18: 0 | AK18: 0 | AL18: 0 | AM18: 1 | AN18: =VLOOKUP(H18,'Base Art'!$A:$AJ,36,FALSE) -> ARCOR S.A.I.C.
A19: (001) 01 SEP 2026 - 03 SEP 2026 | B19: 1 | C19: 01 SEP 2026 - 03 SEP 2026 | D19: Suc: 001 (000001) VERA ERNESTO | E19: 1 | F19: VERA ERNESTO | G19: (000877) PETACA SAN VICENTE ANIS X 200CC | H19: 877 | I19: PETACA SAN VICENTE ANIS X 200CC | P19: 1102 | Q19: PETACAS | R19: 1102 - PETACAS | Y19: 1370 | Z19: BEBIDAS | AA19: 1370 - BEBIDAS | AB19: 12653.26 | AC19: 15500.241 | AD19: 0.3333 | AE19: 0 | AF19: 0.3333 | AG19: 0 | AH19: 4217.75 | AI19: 5166.75 | AJ19: 1 | AK19: 0.33 | AL19: 0 | AM19: 1 | AN19: =VLOOKUP(H19,'Base Art'!$A:$AJ,36,FALSE) -> LICORES ARGENTINOS SA
A20: (001) 01 SEP 2026 - 03 SEP 2026 | B20: 1 | C20: 01 SEP 2026 - 03 SEP 2026 | D20: Suc: 001 (000001) VERA ERNESTO | E20: 1 | F20: VERA ERNESTO | G20: (001116) MAURI FAUNA SURTIDA X 150 GS | H20: 1116 | I20: MAURI FAUNA SURTIDA X 150 GS | Y20: 1373 | Z20: GALLETITAS | AA20: 1373 - GALLETITAS | AB20: 16858.42 | AC20: 20651.566 | AD20: 0.1071 | AE20: 0 | AF20: 0.1071 | AG20: 0 | AH20: 1806.26 | AI20: 2212.67 | AJ20: 0 | AK20: 0 | AL20: 0 | AM20: 1 | AN20: =VLOOKUP(H20,'Base Art'!$A:$AJ,36,FALSE) -> MAURI S.A.
A21: (001) 01 SEP 2026 - 03 SEP 2026 | B21: 1 | C21: 01 SEP 2026 - 03 SEP 2026 | D21: Suc: 001 (000001) VERA ERNESTO | E21: 1 | F21: VERA ERNESTO | G21: (001118) MAURI VAINILLAS X 80 GS | H21: 1118 | I21: MAURI VAINILLAS X 80 GS | P21: 1335 | Q21: VAINILLAS MAURI | R21: 1335 - VAINILLAS MAURI | Y21: 1373 | Z21: GALLETITAS | AA21: 1373 - GALLETITAS | AB21: 15866.81 | AC21: 19619.142 | AD21: 1.3056 | AE21: 0 | AF21: 1.3056 | AG21: 0 | AH21: 20715 | AI21: 25613.88 | AJ21: 0 | AK21: 0 | AL21: 0 | AM21: 1 | AN21: =VLOOKUP(H21,'Base Art'!$A:$AJ,36,FALSE) -> MAURI S.A.
A22: (001) 01 SEP 2026 - 03 SEP 2026 | B22: 1 | C22: 01 SEP 2026 - 03 SEP 2026 | D22: Suc: 001 (000001) VERA ERNESTO | E22: 1 | F22: VERA ERNESTO | G22: (001119) MAURI VAINILLAS X 160 GS | H22: 1119 | I22: MAURI VAINILLAS X 160 GS | P22: 1335 | Q22: VAINILLAS MAURI | R22: 1335 - VAINILLAS MAURI | Y22: 1373 | Z22: GALLETITAS | AA22: 1373 - GALLETITAS | AB22: 29045.447 | AC22: 35899.058 | AD22: 0.5938 | AE22: 0 | AF22: 0.5938 | AG22: 0 | AH22: 17245.73 | AI22: 21315.07 | AJ22: 0 | AK22: 0 | AL22: 0 | AM22: 1 | AN22: =VLOOKUP(H22,'Base Art'!$A:$AJ,36,FALSE) -> MAURI S.A.
A23: (001) 01 SEP 2026 - 03 SEP 2026 | B23: 1 | C23: 01 SEP 2026 - 03 SEP 2026 | D23: Suc: 001 (000001) VERA ERNESTO | E23: 1 | F23: VERA ERNESTO | G23: (001341) CHOCOLATIN JACK BLANCO X20U X14G | H23: 1341 | I23: CHOCOLATIN JACK BLANCO X20U X14G | Y23: 1372 | Z23: CHOCOLATE | AA23: 1372 - CHOCOLATE | AB23: 413186.45 | AC23: 518548.98 | AD23: 0.1667 | AE23: 0 | AF23: 0.1667 | AG23: 0 | AH23: 68864.41 | AI23: 86424.83 | AJ23: 0 | AK23: 0 | AL23: 0 | AM23: 1 | AN23: =VLOOKUP(H23,'Base Art'!$A:$AJ,36,FALSE) -> LA DELICIA FELIPE FORT S.A.
A24: (001) 01 SEP 2026 - 03 SEP 2026 | B24: 1 | C24: 01 SEP 2026 - 03 SEP 2026 | D24: Suc: 001 (000001) VERA ERNESTO | E24: 1 | F24: VERA ERNESTO | G24: (001345) PARAGUITAS FELFORT X 40U. X 13G | H24: 1345 | I24: PARAGUITAS FELFORT X 40U. X 13G | Y24: 1372 | Z24: CHOCOLATE | AA24: 1372 - CHOCOLATE | AB24: 261523.6 | AC24: 320366.41 | AD24: 0.1667 | AE24: 0 | AF24: 0.1667 | AG24: 0 | AH24: 43587.27 | AI24: 53394.4 | AJ24: 2 | AK24: 0.08 | AL24: 0 | AM24: 1 | AN24: =VLOOKUP(H24,'Base Art'!$A:$AJ,36,FALSE) -> LA DELICIA FELIPE FORT S.A.
A25: (001) 01 SEP 2026 - 03 SEP 2026 | B25: 1 | C25: 01 SEP 2026 - 03 SEP 2026 | D25: Suc: 001 (000001) VERA ERNESTO | E25: 1 | F25: VERA ERNESTO | G25: (001352) DOS CORAZONES X20U X26G CHOCO C/POESIA | H25: 1352 | I25: DOS CORAZONES X20U X26G CHOCO C/POESIA | Y25: 1372 | Z25: CHOCOLATE | AA25: 1372 - CHOCOLATE | AB25: 220487.41 | AC25: 271402.97 | AD25: 0.8333 | AE25: 0 | AF25: 0.8333 | AG25: 0 | AH25: 183739.51 | AI25: 226169.14 | AJ25: 2 | AK25: 0.42 | AL25: 0 | AM25: 1 | AN25: =VLOOKUP(H25,'Base Art'!$A:$AJ,36,FALSE) -> LA DELICIA FELIPE FORT S.A.
A26: (001) 01 SEP 2026 - 03 SEP 2026 | B26: 1 | C26: 01 SEP 2026 - 03 SEP 2026 | D26: Suc: 001 (000001) VERA ERNESTO | E26: 1 | F26: VERA ERNESTO | G26: (001353) MENTITAS BOMBON MENTA AL CHOC X30U. X16G | H26: 1353 | I26: MENTITAS BOMBON MENTA AL CHOC X30U. X16G | Y26: 1372 | Z26: CHOCOLATE | AA26: 1372 - CHOCOLATE | AB26: 150700.36 | AC26: 189128.94 | AD26: 0.0833 | AE26: 0 | AF26: 0.0833 | AG26: 0 | AH26: 12558.36 | AI26: 15760.75 | AJ26: 0 | AK26: 0 | AL26: 0 | AM26: 1 | AN26: =VLOOKUP(H26,'Base Art'!$A:$AJ,36,FALSE) -> LA DELICIA FELIPE FORT S.A.
A27: (001) 01 SEP 2026 - 03 SEP 2026 | B27: 1 | C27: 01 SEP 2026 - 03 SEP 2026 | D27: Suc: 001 (000001) VERA ERNESTO | E27: 1 | F27: VERA ERNESTO | G27: (001354) BOCADITOS MARROC X60U X14G | H27: 1354 | I27: BOCADITOS MARROC X60U X14G | Y27: 1372 | Z27: CHOCOLATE | AA27: 1372 - CHOCOLATE | AB27: 251102.66 | AC27: 310041.05 | AD27: 0.375 | AE27: 0 | AF27: 0.375 | AG27: 0 | AH27: 94163.5 | AI27: 116265.39 | AJ27: 0 | AK27: 0 | AL27: 0 | AM27: 1 | AN27: =VLOOKUP(H27,'Base Art'!$A:$AJ,36,FALSE) -> LA DELICIA FELIPE FORT S.A.
A28: (001) 01 SEP 2026 - 03 SEP 2026 | B28: 1 | C28: 01 SEP 2026 - 03 SEP 2026 | D28: Suc: 001 (000001) VERA ERNESTO | E28: 1 | F28: VERA ERNESTO | G28: (001410) BAZOOKA TUTI FRUTTI X80U | H28: 1410 | I28: BAZOOKA TUTI FRUTTI X80U | J28: 1427 | K28: BAZOOKA | L28: 1427 - BAZOOKA | Y28: 1374 | Z28: GOLOSINAS | AA28: 1374 - GOLOSINAS | AB28: 86362.65 | AC28: 105794.27 | AD28: 0.0556 | AE28: 0 | AF28: 0.0556 | AG28: 0 | AH28: 4797.93 | AI28: 5877.46 | AJ28: 0 | AK28: 0 | AL28: 0 | AM28: 1 | AN28: =VLOOKUP(H28,'Base Art'!$A:$AJ,36,FALSE) -> GEORGALOS HNOS. S.A.I.C.A.
A29: (001) 01 SEP 2026 - 03 SEP 2026 | B29: 1 | C29: 01 SEP 2026 - 03 SEP 2026 | D29: Suc: 001 (000001) VERA ERNESTO | E29: 1 | F29: VERA ERNESTO | G29: (001419) PALITOS DE LA SELVA X 660GR | H29: 1419 | I29: PALITOS DE LA SELVA X 660GR | J29: 1429 | K29: PAL DE LA SELVA | L29: 1429 - PAL DE LA SELVA | Y29: 1374 | Z29: GOLOSINAS | AA29: 1374 - GOLOSINAS | AB29: 86500.213 | AC29: 105962.76 | AD29: 0.25 | AE29: 0 | AF29: 0.25 | AG29: 0 | AH29: 21625.05 | AI29: 26490.69 | AJ29: 0 | AK29: 0 | AL29: 0 | AM29: 1 | AN29: =VLOOKUP(H29,'Base Art'!$A:$AJ,36,FALSE) -> GEORGALOS HNOS. S.A.I.C.A.
A30: (001) 01 SEP 2026 - 03 SEP 2026 | B30: 1 | C30: 01 SEP 2026 - 03 SEP 2026 | D30: Suc: 001 (000001) VERA ERNESTO | E30: 1 | F30: VERA ERNESTO | G30: (001594) POLVORITAS FRUTILLA X 81 GR | H30: 1594 | I30: POLVORITAS FRUTILLA X 81 GR | J30: 1422 | K30: POLVORITAS | L30: 1422 - POLVORITAS | P30: 1067 | Q30: POLVORITAS 80G Y 147G | R30: 1067 - POLVORITAS 80G Y 147G | Y30: 1373 | Z30: GALLETITAS | AA30: 1373 - GALLETITAS | AB30: 18089.197 | AC30: 22593.408 | AD30: 0.5 | AE30: 0 | AF30: 0.5 | AG30: 0 | AH30: 9044.6 | AI30: 11296.7 | AJ30: 0 | AK30: 0 | AL30: 0 | AM30: 1 | AN30: =VLOOKUP(H30,'Base Art'!$A:$AJ,36,FALSE) -> ARCOR S.A.I.C.
A31: (001) 01 SEP 2026 - 03 SEP 2026 | B31: 1 | C31: 01 SEP 2026 - 03 SEP 2026 | D31: Suc: 001 (000001) VERA ERNESTO | E31: 1 | F31: VERA ERNESTO | G31: (001641) 9 DE ORO AGRIDULCE X 200 GR | H31: 1641 | I31: 9 DE ORO AGRIDULCE X 200 GR | J31: 1064 | K31: 9 DE ORO | L31: 1064 - 9 DE ORO | P31: 1066 | Q31: BIZCOCHOS 9 DE ORO | R31: 1066 - BIZCOCHOS 9 DE ORO | Y31: 1373 | Z31: GALLETITAS | AA31: 1373 - GALLETITAS | AB31: 16571.043 | AC31: 20389.587 | AD31: 0.9 | AE31: 0.05 | AF31: 0.95 | AG31: 0 | AH31: 15742.49 | AI31: 19370.11 | AJ31: 1 | AK31: 0.95 | AL31: 0 | AM31: 1 | AN31: =VLOOKUP(H31,'Base Art'!$A:$AJ,36,FALSE) -> MOLINO CAÑUELAS S.A.C.I.F.I.A.
A32: (001) 01 SEP 2026 - 03 SEP 2026 | B32: 1 | C32: 01 SEP 2026 - 03 SEP 2026 | D32: Suc: 001 (000001) VERA ERNESTO | E32: 1 | F32: VERA ERNESTO | G32: (001642) 9 DE ORO SCONCITOS X 200 GR | H32: 1642 | I32: 9 DE ORO SCONCITOS X 200 GR | J32: 1064 | K32: 9 DE ORO | L32: 1064 - 9 DE ORO | P32: 1066 | Q32: BIZCOCHOS 9 DE ORO | R32: 1066 - BIZCOCHOS 9 DE ORO | Y32: 1373 | Z32: GALLETITAS | AA32: 1373 - GALLETITAS | AB32: 19432.18 | AC32: 24095.9 | AD32: 0.3 | AE32: 0 | AF32: 0.3 | AG32: 0 | AH32: 5829.65 | AI32: 7228.77 | AJ32: 0 | AK32: 0 | AL32: 0 | AM32: 1 | AN32: =VLOOKUP(H32,'Base Art'!$A:$AJ,36,FALSE) -> MOLINO CAÑUELAS S.A.C.I.F.I.A.
A33: (001) 01 SEP 2026 - 03 SEP 2026 | B33: 1 | C33: 01 SEP 2026 - 03 SEP 2026 | D33: Suc: 001 (000001) VERA ERNESTO | E33: 1 | F33: VERA ERNESTO | G33: (001643) PASEO CRACKERS X 300GR | H33: 1643 | I33: PASEO CRACKERS X 300GR | J33: 1065 | K33: PASEO | L33: 1065 - PASEO | Y33: 1373 | Z33: GALLETITAS | AA33: 1373 - GALLETITAS | AB33: 14410.413 | AC33: 17652.755 | AD33: 1 | AE33: 0 | AF33: 1 | AG33: 0 | AH33: 14410.41 | AI33: 17652.75 | AJ33: 2 | AK33: 0.5 | AL33: 0 | AM33: 1 | AN33: =VLOOKUP(H33,'Base Art'!$A:$AJ,36,FALSE) -> MOLINO CAÑUELAS S.A.C.I.F.I.A.
A34: (001) 01 SEP 2026 - 03 SEP 2026 | B34: 1 | C34: 01 SEP 2026 - 03 SEP 2026 | D34: Suc: 001 (000001) VERA ERNESTO | E34: 1 | F34: VERA ERNESTO | G34: (001646) 9 DE ORO CLASICO X 200 GR | H34: 1646 | I34: 9 DE ORO CLASICO X 200 GR | J34: 1064 | K34: 9 DE ORO | L34: 1064 - 9 DE ORO | P34: 1066 | Q34: BIZCOCHOS 9 DE ORO | R34: 1066 - BIZCOCHOS 9 DE ORO | Y34: 1373 | Z34: GALLETITAS | AA34: 1373 - GALLETITAS | AB34: 21142.085 | AC34: 25947.944 | AD34: 1.7083 | AE34: 0.0417 | AF34: 1.75 | AG34: 0 | AH34: 36998.65 | AI34: 45408.9 | AJ34: 0 | AK34: 0 | AL34: 0 | AM34: 1 | AN34: =VLOOKUP(H34,'Base Art'!$A:$AJ,36,FALSE) -> MOLINO CAÑUELAS S.A.C.I.F.I.A.
A35: (001) 01 SEP 2026 - 03 SEP 2026 | B35: 1 | C35: 01 SEP 2026 - 03 SEP 2026 | D35: Suc: 001 (000001) VERA ERNESTO | E35: 1 | F35: VERA ERNESTO | G35: (001648) POLVORITAS CHOCOLATE X 81 GR | H35: 1648 | I35: POLVORITAS CHOCOLATE X 81 GR | J35: 1422 | K35: POLVORITAS | L35: 1422 - POLVORITAS | P35: 1067 | Q35: POLVORITAS 80G Y 147G | R35: 1067 - POLVORITAS 80G Y 147G | Y35: 1373 | Z35: GALLETITAS | AA35: 1373 - GALLETITAS | AB35: 18315.879 | AC35: 22540.32 | AD35: 0.525 | AE35: 0 | AF35: 0.525 | AG35: 0 | AH35: 9615.84 | AI35: 11833.67 | AJ35: 0 | AK35: 0 | AL35: 0 | AM35: 1 | AN35: =VLOOKUP(H35,'Base Art'!$A:$AJ,36,FALSE) -> ARCOR S.A.I.C.
A36: (001) 01 SEP 2026 - 03 SEP 2026 | B36: 1 | C36: 01 SEP 2026 - 03 SEP 2026 | D36: Suc: 001 (000001) VERA ERNESTO | E36: 1 | F36: VERA ERNESTO | G36: (001696) PAÑUELITO CANDELA 1RA CALIDAD 10X6U. | H36: 1696 | I36: PAÑUELITO CANDELA 1RA CALIDAD 10X6U. | J36: 1460 | K36: CANDELA | L36: 1460 - CANDELA | Y36: 1369 | Z36: ALMACEN | AA36: 1369 - ALMACEN | AB36: 62035.826 | AC36: 75993.887 | AD36: 0.4792 | AE36: 0 | AF36: 0.4792 | AG36: 0 | AH36: 29725.5 | AI36: 36413.74 | AJ36: 3 | AK36: 0.16 | AL36: 0 | AM36: 1 | AN36: =VLOOKUP(H36,'Base Art'!$A:$AJ,36,FALSE) -> IMPORTADORA SUDAMERICANA S.R.L.
A37: (001) 01 SEP 2026 - 03 SEP 2026 | B37: 1 | C37: 01 SEP 2026 - 03 SEP 2026 | D37: Suc: 001 (000001) VERA ERNESTO | E37: 1 | F37: VERA ERNESTO | G37: (001699) SALSA PIZZA NOEL DOY PACK X340 | H37: 1699 | I37: SALSA PIZZA NOEL DOY PACK X340 | J37: 1419 | K37: NOEL | L37: 1419 - NOEL | P37: 1255 | Q37: SALSAS NOEL | R37: 1255 - SALSAS NOEL | Y37: 1369 | Z37: ALMACEN | AA37: 1369 - ALMACEN | AB37: 21759.32 | AC37: 26655.162 | AD37: 0.1667 | AE37: 0 | AF37: 0.1667 | AG37: 0 | AH37: 3626.55 | AI37: 4442.53 | AJ37: 1 | AK37: 0.17 | AL37: 0 | AM37: 1 | AN37: =VLOOKUP(H37,'Base Art'!$A:$AJ,36,FALSE) -> ARCOR S.A.I.C.
A38: (001) 01 SEP 2026 - 03 SEP 2026 | B38: 1 | C38: 01 SEP 2026 - 03 SEP 2026 | D38: Suc: 001 (000001) VERA ERNESTO | E38: 1 | F38: VERA ERNESTO | G38: (001808) CHUPETIN PICO DULCE POTE X48U | H38: 1808 | I38: CHUPETIN PICO DULCE POTE X48U | J38: 1470 | K38: PICO DULCE | L38: 1470 - PICO DULCE | Y38: 1374 | Z38: GOLOSINAS | AA38: 1374 - GOLOSINAS | AB38: 101800.88 | AC38: 125715.23 | AD38: 0.5 | AE38: 0 | AF38: 0.5 | AG38: 0 | AH38: 50900.44 | AI38: 62857.62 | AJ38: 1 | AK38: 0.5 | AL38: 0 | AM38: 1 | AN38: =VLOOKUP(H38,'Base Art'!$A:$AJ,36,FALSE) -> LHERITIER ARGENTINA S.A.
A39: (001) 01 SEP 2026 - 03 SEP 2026 | B39: 1 | C39: 01 SEP 2026 - 03 SEP 2026 | D39: Suc: 001 (000001) VERA ERNESTO | E39: 1 | F39: VERA ERNESTO | G39: (001870) TIC TAC X12U MENTA | H39: 1870 | I39: TIC TAC X12U MENTA | J39: 1351 | K39: TICTACS | L39: 1351 - TICTACS | P39: 1141 | Q39: TIC TAC | R39: 1141 - TIC TAC | Y39: 1372 | Z39: CHOCOLATE | AA39: 1372 - CHOCOLATE | AB39: 264368.62 | AC39: 323851.56 | AD39: 0.0833 | AE39: 0 | AF39: 0.0833 | AG39: 0 | AH39: 22030.72 | AI39: 26987.63 | AJ39: 1 | AK39: 0.08 | AL39: 0 | AM39: 1 | AN39: =VLOOKUP(H39,'Base Art'!$A:$AJ,36,FALSE) -> FERRERO ARGENTINA S.A.
A40: (001) 01 SEP 2026 - 03 SEP 2026 | B40: 1 | C40: 01 SEP 2026 - 03 SEP 2026 | D40: Suc: 001 (000001) VERA ERNESTO | E40: 1 | F40: VERA ERNESTO | G40: (001919) CARAM SUGUS CONFITADO X 50 GR. | H40: 1919 | I40: CARAM SUGUS CONFITADO X 50 GR. | J40: 1421 | K40: SUGUS | L40: 1421 - SUGUS | Y40: 1374 | Z40: GOLOSINAS | AA40: 1374 - GOLOSINAS | AB40: 26417.69 | AC40: 32484.996 | AD40: 2.1333 | AE40: 0 | AF40: 2.1333 | AG40: 0 | AH40: 56357.74 | AI40: 69301.32 | AJ40: 0 | AK40: 0 | AL40: 0 | AM40: 1 | AN40: =VLOOKUP(H40,'Base Art'!$A:$AJ,36,FALSE) -> ARCOR S.A.I.C.
...

Sheet Base Art
A1: CAMPOS OBLIGATORIOS Y FIJOS | D1: ATRIBUTOS COMPAÑÍA | F1: GENERAL | X1: GENERAL -> Datos Impositivo de Ventas | AI1: ABASTECIMIENTO -> Proveedor | AK1: INVENTARIO -> General | AP1: INVENTARIO -> Ordenes de Pedido | AR1: INVENTARIO -> Frescura | AT1: INVENTARIO -> Datos de Almacenamiento | AW1: INVENTARIO -> Activos Fijos | BB1: LOGISTICA -> Presentación | BL1: LOGISTICA -> Retornables
