Workbook

Sheet COMISIONES
A1: VENDEDOR | B1: SUCURSAL | C1: BULTOS | D1: UNIDAD DE MEDIDA | E1: IMPORTE | F1: COMISIÓN POR IMPORTE FIJO | G1: COMISIÓN POR PORCENTAJE | H1: COMISIÓN TOTAL
A2: 0 - TODOS LOS VENDEDORES | B2: 0 | C2: 43028.542 | D2: 178246.04 | E2: 7.8320893e+08 | F2: 0 | G2: 367848.94 | H2: 367849.12
A3: 1 - VERA ERNESTO | B3: 1 | C3: 529.69897 | D3: 729.15178 | E3: 12277521 | F3: 0 | G3: 367848.94 | H3: 367849.12
A4: 2 - OJEDA NORBERTO | B4: 1 | C4: 375.65635 | D4: 565.65179 | E4: 8521460.7 | F4: 0 | G4: 0 | H4: 0
A5: 3 - VIDAL NAHUEL | B5: 1 | C5: 455.41595 | D5: 1241.8252 | E5: 11101682 | F5: 0 | G5: 0 | H5: 0
A6: 4 - TUR SPRINGER FERNANDO | B6: 1 | C6: 817.93097 | D6: 1939.6469 | E6: 18279632 | F6: 0 | G6: 0 | H6: 0
A7: 5 - SCHELOVER RAUL | B7: 1 | C7: 685.03956 | D7: 2188.9208 | E7: 16717419 | F7: 0 | G7: 0 | H7: 0
A8: 7 - VALLEJOS EDUARDO | B8: 1 | C8: 2974.9167 | D8: 7148.15 | E8: 43665769 | F8: 0 | G8: 0 | H8: 0
A9: 8 - PARRA MAXIMILIANO | B9: 1 | C9: 332.23387 | D9: 830.09792 | E9: 7226935.7 | F9: 0 | G9: 0 | H9: 0
A10: 9 - ESTIGARRIBIA DAVID | B10: 1 | C10: 444.38883 | D10: 989.73358 | E10: 10304349 | F10: 0 | G10: 0 | H10: 0
A11: 10 - BRITEZ EMMANUEL | B11: 1 | C11: 779.24405 | D11: 544.79176 | E11: 9575852.5 | F11: 0 | G11: 0 | H11: 0
A12: 11 - SANCHEZ RICARDO | B12: 1 | C12: 461.45004 | D12: 1213.2725 | E12: 8753017.9 | F12: 0 | G12: 0 | H12: 0
A13: 12 - GUTIERREZ MARCOS DAVID | B13: 1 | C13: 433.27903 | D13: 1298.5373 | E13: 11014326 | F13: 0 | G13: 0 | H13: 0
... A47: 123 - TORRES ROLANDO | B47: 1 | C47: 970.9627 | D47: 3224.08 | E47: 29771261 | F47: 0 | G47: 0 | H47: 0

Sheet AVANCE
A1: SUPERVISOR | B1: VENDEDOR | C1: OBJETIVO | D1: FACTURACION ACUMULADA | E1: FACTURACION N-1 | F1: FACTURACION DEL DIA | G1: AVANCE VS OBJETIVO | H1: PROYECCION | I1: CUMPLIMIENTO PROYECTADO | J1: MEDIA REAL | K1: MEDIA NECESARIA | L1: COBRO
A2: MARTIN PREVENTA | B2: 20 - FLORES JAVIER | C2: 32924658 | D2: =IFERROR(+VLOOKUP(B2,COMISIONES!A:E,5,FALSE),"0")*1 -> 21945371 | E2: 18065782 | F2: =+D2-E2 -> 3879589.4 | G2: =+D2/C2 -> 0.666533 | H2: =+D2/$N$3*$N$4 -> 49875844 | I2: =+H2/C2 -> 1.5148477 | J2: =+D2/$N$3 -> 1995033.8 | K2: =+(C2-D2)/$N$2 -> 784234.77 | L2: {=+_xlfn.IFS(I2>114%,H2*0.02,I2>109%,H2*0.015,I2>104%,H2*0.0125,I2>99%,H2*0.01,I2<99%,H2*0)} -> 997516.88 | M2: DIAS DE TRABAJO RESTANTES | N2: 14
B3: 19 - GONZALEZ MARCELO | C3: 31602383 | D3: =IFERROR(+VLOOKUP(B3,COMISIONES!A:E,5,FALSE),"0")*1 -> 16657556 | E3: 15843215 | F3: =+D3-E3 -> 814341.31 | G3: =+D3/C3 -> 0.52709811 | H3: =+D3/$N$3*$N$4 -> 37858082 | I3: =+H3/C3 -> 1.1979502 | J3: =+D3/$N$3 -> 1514323.3 | K3: =+(C3-D3)/$N$2 -> 1067487.6 | L3: {=+_xlfn.IFS(I3>114%,H3*0.02,I3>109%,H3*0.015,I3>104%,H3*0.0125,I3>99%,H3*0.01,I3<99%,H3*0)} -> 757161.64 | M3: DIAS TRABAJADOS | N3: =N4-N2 -> 11
B4: 16 - GOMEZ MATÍAS | C4: 28957832 | D4: =IFERROR(+VLOOKUP(B4,COMISIONES!A:E,5,FALSE),"0")*1 -> 10239918 | E4: 9389996.3 | F4: =+D4-E4 -> 849921.69 | G4: =+D4/C4 -> 0.3536148 | H4: =+D4/$N$3*$N$4 -> 23272541 | I4: =+H4/C4 -> 0.80367001 | J4: =+D4/$N$3 -> 930901.64 | K4: =+(C4-D4)/$N$2 -> 1336993.8 | L4: {=+_xlfn.IFS(I4>114%,H4*0.02,I4>109%,H4*0.015,I4>104%,H4*0.0125,I4>99%,H4*0.01,I4<99%,H4*0)} -> 0 | M4: DIAS DE TRABAJO MES | N4: 25
B5: 12 - GUTIERREZ MARCOS DAVID | C5: 28957832 | D5: =IFERROR(+VLOOKUP(B5,COMISIONES!A:E,5,FALSE),"0")*1 -> 11014326 | E5: 10020831 | F5: =+D5-E5 -> 993495.04 | G5: =+D5/C5 -> 0.38035742 | H5: =+D5/$N$3*$N$4 -> 25032559 | I5: =+H5/C5 -> 0.86444867 | J5: =+D5/$N$3 -> 1001302.4 | K5: =+(C5-D5)/$N$2 -> 1281679 | L5: {=+_xlfn.IFS(I5>114%,H5*0.02,I5>109%,H5*0.015,I5>104%,H5*0.0125,I5>99%,H5*0.01,I5<99%,H5*0)} -> 0
B6: 11 - SANCHEZ RICARDO | C6: 23999299 | D6: =IFERROR(+VLOOKUP(B6,COMISIONES!A:E,5,FALSE),"0")*1 -> 8753017.9 | E6: 7401243.4 | F6: =+D6-E6 -> 1351774.5 | G6: =+D6/C6 -> 0.36471973 | H6: =+D6/$N$3*$N$4 -> 19893222 | I6: =+H6/C6 -> 0.82890848 | J6: =+D6/$N$3 -> 795728.9 | K6: =+(C6-D6)/$N$2 -> 1089020.1 | L6: {=+_xlfn.IFS(I6>114%,H6*0.02,I6>109%,H6*0.015,I6>104%,H6*0.0125,I6>99%,H6*0.01,I6<99%,H6*0)} -> 0
B7: 8 - PARRA MAXIMILIANO | C7: 28296694 | D7: =IFERROR(+VLOOKUP(B7,COMISIONES!A:E,5,FALSE),"0")*1 -> 7226935.7 | E7: 6570132.1 | F7: =+D7-E7 -> 656803.56 | G7: =+D7/C7 -> 0.25539859 | H7: =+D7/$N$3*$N$4 -> 16424854 | I7: =+H7/C7 -> 0.58045133 | J7: =+D7/$N$3 -> 656994.15 | K7: =+(C7-D7)/$N$2 -> 1504982.8 | L7: {=+_xlfn.IFS(I7>114%,H7*0.02,I7>109%,H7*0.015,I7>104%,H7*0.0125,I7>99%,H7*0.01,I7<99%,H7*0)} -> 0
B8: 5 - SCHELOVER RAUL | C8: 36547693 | D8: =IFERROR(+VLOOKUP(B8,COMISIONES!A:E,5,FALSE),"0")*1 -> 16717419 | E8: 14803849 | F8: =+D8-E8 -> 1913570.2 | G8: =+D8/C8 -> 0.45741379 | H8: =+D8/$N$3*$N$4 -> 37994134 | I8: =+H8/C8 -> 1.0395768 | J8: =+D8/$N$3 -> 1519765.3 | K8: =+(C8-D8)/$N$2 -> 1416448.1 | L8: {=+_xlfn.IFS(I8>114%,H8*0.02,I8>109%,H8*0.015,I8>104%,H8*0.0125,I8>99%,H8*0.01,I8<99%,H8*0)} -> 379941.34
B9: 4 - TUR SPRINGER FERNANDO | C9: 36547693 | D9: =IFERROR(+VLOOKUP(B9,COMISIONES!A:E,5,FALSE),"0")*1 -> 18279632 | E9: 14593020 | F9: =+D9-E9 -> 3686612.4 | G9: =+D9/C9 -> 0.50015831 | H9: =+D9/$N$3*$N$4 -> 41544619 | I9: =+H9/C9 -> 1.1367234 | J9: =+D9/$N$3 -> 1661784.8 | K9: =+(C9-D9)/$N$2 -> 1304861.5 | L9: {=+_xlfn.IFS(I9>114%,H9*0.02,I9>109%,H9*0.015,I9>104%,H9*0.0125,I9>99%,H9*0.01,I9<99%,H9*0)} -> 623169.28
C10: 247834083 | D10: =+SUM(D2:D9) -> 1.1083418e+08 | E10: 96688068 | F10: =+D10-E10 -> 14146108 | G10: =+D10/C10 -> 0.44721119 | H10: =+D10/$N$3*$N$4 -> 2.5189585e+08 | I10: =+H10/C10 -> 1.0163891 | J10: =+D10/$N$3 -> 10075834 | K10: =+(C10-D10)/$N$2 -> 9785707.6
A11: MARTIN | B11: 22 - ALMIRON NICOLAS | C11: 98911387 | D11: =IFERROR(+VLOOKUP(B11,COMISIONES!A:E,5,FALSE),"0")*1 -> 46666403 | E11: 45118874 | F11: =+D11-E11 -> 1547528.6 | G11: =+D11/C11 -> 0.4718001 | H11: =+D11/$N$3*$N$4 -> 1.0606001e+08 | I11: =+H11/C11 -> 1.072273 | J11: =+D11/$N$3 -> 4242400.3 | K11: =+(C11-D11)/$N$2 -> 3731784.6 | L11: {=+_xlfn.IFS(I11>114%,H11*0.0125,I11>109%,H11*0.01,I11>104%,H11*0.0075,I11>99%,H11*0.005,I11<99%,H11*0)} -> 795450.05
B12: 15 - GALARZA GERARDO | C12: 1.3093119e+08 | D12: =IFERROR(+VLOOKUP(B12,COMISIONES!A:E,5,FALSE),"0")*1 -> 35081545 | E12: 34273740 | F12: =+D12-E12 -> 807805.21 | G12: =+D12/C12 -> 0.26793878 | H12: =+D12/$N$3*$N$4 -> 79730784 | I12: =+H12/C12 -> 0.60895178 | J12: =+D12/$N$3 -> 3189231.4 | K12: =+(C12-D12)/$N$2 -> 6846403.5 | L12: {=+_xlfn.IFS(I12>114%,H12*0.0125,I12>109%,H12*0.01,I12>104%,H12*0.0075,I12>99%,H12*0.005,I12<99%,H12*0)} -> 0 | M12: AUMENTO OBJ | N12: 0.02
B13: 52 - RAVAROTTO EMANUEL | C13: 43298039 | D13: =IFERROR(+VLOOKUP(B13,COMISIONES!A:E,5,FALSE),"0")*1 -> 26974253 | E13: 26665321 | F13: =+D13-E13 -> 308932.38 | G13: =+D13/C13 -> 0.62299018 | H13: =+D13/$N$3*$N$4 -> 61305120 | I13: =+H13/C13 -> 1.4158868 | J13: =+D13/$N$3 -> 2452204.8 | K13: =+(C13-D13)/$N$2 -> 1165984.7 | L13: {=+_xlfn.IFS(I13>109%,H13*0.015,I13>104%,H13*0.0125,I13>99%,H13*0.01,I13<99%,H13*0)} -> 919576.8
B14: 53 - SANDOVAL RODRIGO | C14: 43298039 | D14: =IFERROR(+VLOOKUP(B14,COMISIONES!A:E,5,FALSE),"0")*1 -> 17446723 | E14: 16353652 | F14: =+D14-E14 -> 1093071 | G14: =+D14/C14 -> 0.40294488 | H14: =+D14/$N$3*$N$4 -> 39651643 | I14: =+H14/C14 -> 0.91578382 | J14: =+D14/$N$3 -> 1586065.7 | K14: =+(C14-D14)/$N$2 -> 1846522.5 | L14: {=+_xlfn.IFS(I14>109%,H14*0.015,I14>104%,H14*0.0125,I14>99%,H14*0.01,I14<99%,H14*0)} -> 0
C15: 348702179 | D15: =+SUM(D11:D14) -> 1.2616892e+08 | E15: 1.2241159e+08 | F15: =+D15-E15 -> 3757337.2 | G15: =+D15/C15 -> 0.36182431 | H15: =+D15/$N$3*$N$4 -> 2.8674755e+08 | I15: =+H15/C15 -> 0.82232797 | J15: =+D15/$N$3 -> 11469902 | K15: =+(C15-D15)/$N$2 -> 15895233
A16: CRISTIAN | B16: 2 - OJEDA NORBERTO | C16: 28000000 | D16: =IFERROR(+VLOOKUP(B16,COMISIONES!A:E,5,FALSE),"0")*1 -> 8521460.7 | E16: 6918641.5 | F16: =+D16-E16 -> 1602819.2 | G16: =+D16/C16 -> 0.30433788 | H16: =+D16/$N$3*$N$4 -> 19366956 | I16: =+H16/C16 -> 0.69167701 | J16: =+D16/$N$3 -> 774678.25 | K16: =+(C16-D16)/$N$2 -> 1391324.2 | L16: {=+_xlfn.IFS(I16>114%,H16*0.02,I16>109%,H16*0.015,I16>104%,H16*0.0125,I16>99%,H16*0.01,I16<99%,H16*0)} -> 0
B17: 3 - VIDAL NAHUEL | C17: 25660000 | D17: =IFERROR(+VLOOKUP(B17,COMISIONES!A:E,5,FALSE),"0")*1 -> 11101682 | E17: 10207094 | F17: =+D17-E17 -> 894588.32 | G17: =+D17/C17 -> 0.43264545 | H17: =+D17/$N$3*$N$4 -> 25231096 | I17: =+H17/C17 -> 0.98328512 | J17: =+D17/$N$3 -> 1009243.9 | K17: =+(C17-D17)/$N$2 -> 1039879.8 | L17: {=+_xlfn.IFS(I17>114%,H17*0.02,I17>109%,H17*0.015,I17>104%,H17*0.0125,I17>99%,H17*0.01,I17<99%,H17*0)} -> 0
B18: 18 - HERRERA PABLO | C18: 26020000 | D18: =IFERROR(+VLOOKUP(B18,COMISIONES!A:E,5,FALSE),"0")*1 -> 8842180.9 | E18: 8144323 | F18: =+D18-E18 -> 697857.94 | G18: =+D18/C18 -> 0.33982248 | H18: =+D18/$N$3*$N$4 -> 20095866 | I18: =+H18/C18 -> 0.77232382 | J18: =+D18/$N$3 -> 803834.63 | K18: =+(C18-D18)/$N$2 -> 1226987.1 | L18: {=+_xlfn.IFS(I18>114%,H18*0.02,I18>109%,H18*0.015,I18>104%,H18*0.0125,I18>99%,H18*0.01,I18<99%,H18*0)} -> 0
B19: 21 - CATAN MATIAS | C19: 36200600 | D19: =IFERROR(+VLOOKUP(B19,COMISIONES!A:E,5,FALSE),"0")*1 -> 15741099 | E19: 14465212 | F19: =+D19-E19 -> 1275886.5 | G19: =+D19/C19 -> 0.43482978 | H19: =+D19/$N$3*$N$4 -> 35775225 | I19: =+H19/C19 -> 0.9882495 | J19: =+D19/$N$3 -> 1431009 | K19: =+(C19-D19)/$N$2 -> 1461392.9 | L19: {=+_xlfn.IFS(I19>114%,H19*0.02,I19>109%,H19*0.015,I19>104%,H19*0.0125,I19>99%,H19*0.01,I19<99%,H19*0)} -> 0
B20: 23 - DELGADO JOSÉ | C20: 26622000 | D20: =IFERROR(+VLOOKUP(B20,COMISIONES!A:E,5,FALSE),"0")*1 -> 10823907 | E20: 9004740 | F20: =+D20-E20 -> 1819166.6 | G20: =+D20/C20 -> 0.40657752 | H20: =+D20/$N$3*$N$4 -> 24599788 | I20: =+H20/C20 -> 0.92403981 | J20: =+D20/$N$3 -> 983991.51 | K20: =+(C20-D20)/$N$2 -> 1128435.2 | L20: {=+_xlfn.IFS(I20>114%,H20*0.02,I20>109%,H20*0.015,I20>104%,H20*0.0125,I20>99%,H20*0.01,I20<99%,H20*0)} -> 0
B21: 31 - RENZO RAMOS | C21: 33260000 | D21: =IFERROR(+VLOOKUP(B21,COMISIONES!A:E,5,FALSE),"0")*1 -> 11111999 | E21: 9414166.3 | F21: =+D21-E21 -> 1697832.2 | G21: =+D21/C21 -> 0.33409497 | H21: =+D21/$N$3*$N$4 -> 25254542 | I21: =+H21/C21 -> 0.75930674 | J21: =+D21/$N$3 -> 1010181.7 | K21: =+(C21-D21)/$N$2 -> 1582000.1 | L21: {=+_xlfn.IFS(I21>114%,H21*0.02,I21>109%,H21*0.015,I21>104%,H21*0.0125,I21>99%,H21*0.01,I21<99%,H21*0)} -> 0
B22: 44 - MONGES CESAR LUIS | C22: 28620000 | D22: =IFERROR(+VLOOKUP(B22,COMISIONES!A:E,5,FALSE),"0")*1 -> 13174081 | E22: 11650345 | F22: =+D22-E22 -> 1523736.5 | G22: =+D22/C22 -> 0.46031031 | H22: =+D22/$N$3*$N$4 -> 29941094 | I22: =+H22/C22 -> 1.0461598 | J22: =+D22/$N$3 -> 1197643.7 | K22: =+(C22-D22)/$N$2 -> 1103279.9 | L22: {=+_xlfn.IFS(I22>114%,H22*0.02,I22>109%,H22*0.015,I22>104%,H22*0.0125,I22>99%,H22*0.01,I22<99%,H22*0)} -> 374263.67
B23: 54 - BARTSCHAT EMILIANO NAHUEL | C23: 38000000 | D23: =IFERROR(+VLOOKUP(B23,COMISIONES!A:E,5,FALSE),"0")*1 -> 16497964 | E23: 14285777 | F23: =+D23-E23 -> 2212187.2 | G23: =+D23/C23 -> 0.43415696 | H23: =+D23/$N$3*$N$4 -> 37495374 | I23: =+H23/C23 -> 0.98672036 | J23: =+D23/$N$3 -> 1499814.9 | K23: =+(C23-D23)/$N$2 -> 1535859.7 | L23: {=+_xlfn.IFS(I23>114%,H23*0.02,I23>109%,H23*0.015,I23>104%,H23*0.0125,I23>99%,H23*0.01,I23<99%,H23*0)} -> 0
C24: 242382600 | D24: =+SUM(D16:D23) -> 95814374 | E24: 84090299 | F24: =+D24-E24 -> 11724074 | G24: =+D24/C24 -> 0.39530219 | H24: =+D24/$N$3*$N$4 -> 2.1775994e+08 | I24: =+H24/C24 -> 0.89841408 | J24: =+D24/$N$3 -> 8710397.6 | K24: =+(C24-D24)/$N$2 -> 10469159
A25: GONZALO | B25: 32 - CABRAL GONZALO | C25: 86547956 | D25: =IFERROR(+VLOOKUP(B25,COMISIONES!A:E,5,FALSE),"0")*1 -> 23810922 | E25: 20686972 | F25: =+D25-E25 -> 3123950.4 | G25: =+D25/C25 -> 0.27511825 | H25: =+D25/$N$3*$N$4 -> 54115732 | I25: =+H25/C25 -> 0.62526875 | J25: =+D25/$N$3 -> 2164629.3 | K25: =+(C25-D25)/$N$2 -> 4481216.7 | L25: {=+_xlfn.IFS(I25>114%,H25*0.0125,I25>109%,H25*0.01,I25>104%,H25*0.0075,I25>99%,H25*0.005,I25<99%,H25*0)} -> 0
B26: 36 - COSARINSKI DIEGO | C26: 24010803 | D26: =IFERROR(+VLOOKUP(B26,COMISIONES!A:E,5,FALSE),"0")*1 -> 6506939.6 | E26: 6022668.8 | F26: =+D26-E26 -> 484270.89 | G26: =+D26/C26 -> 0.2710005 | H26: =+D26/$N$3*$N$4 -> 14788499 | I26: =+H26/C26 -> 0.61591022 | J26: =+D26/$N$3 -> 591539.97 | K26: =+(C26-D26)/$N$2 -> 1250276 | L26: {=+_xlfn.IFS(I26>114%,H26*0.02,I26>109%,H26*0.015,I26>104%,H26*0.0125,I26>99%,H26*0.01,I26<99%,H26*0)} -> 0
B27: 9 - ESTIGARRIBIA DAVID | C27: 26910856 | D27: =IFERROR(+VLOOKUP(B27,COMISIONES!A:E,5,FALSE),"0")*1 -> 10304349 | E27: 9596353.8 | F27: =+D27-E27 -> 707995.06 | G27: =+D27/C27 -> 0.38290676 | H27: =+D27/$N$3*$N$4 -> 23418975 | I27: =+H27/C27 -> 0.87024264 | J27: =+D27/$N$3 -> 936758.99 | K27: =+(C27-D27)/$N$2 -> 1186179.1 | L27: {=+_xlfn.IFS(I27>114%,H27*0.02,I27>109%,H27*0.015,I27>104%,H27*0.0125,I27>99%,H27*0.01,I27<99%,H27*0)} -> 0
B28: 40 - IBARROLA JORGE | C28: 39189035 | D28: =IFERROR(+VLOOKUP(B28,COMISIONES!A:E,5,FALSE),"0")*1 -> 11375384 | E28: 9565104.6 | F28: =+D28-E28 -> 1810279.2 | G28: =+D28/C28 -> 0.29026956 | H28: =+D28/$N$3*$N$4 -> 25853145 | I28: =+H28/C28 -> 0.65970354 | J28: =+D28/$N$3 -> 1034125.8 | K28: =+(C28-D28)/$N$2 -> 1986689.4 | L28: {=+_xlfn.IFS(I28>114%,H28*0.02,I28>109%,H28*0.015,I28>104%,H28*0.0125,I28>99%,H28*0.01,I28<99%,H28*0)} -> 0
B29: 27 - GOMEZ ADRIÁN | C29: 26900000 | D29: =IFERROR(+VLOOKUP(B29,COMISIONES!A:E,5,FALSE),"0")*1 -> 13272296 | E29: 12406650 | F29: =+D29-E29 -> 865645.29 | G29: =+D29/C29 -> 0.49339389 | H29: =+D29/$N$3*$N$4 -> 30164308 | I29: =+H29/C29 -> 1.1213497 | J29: =+D29/$N$3 -> 1206572.3 | K29: =+(C29-D29)/$N$2 -> 973407.45 | L29: {=+_xlfn.IFS(I29>114%,H29*0.02,I29>109%,H29*0.015,I29>104%,H29*0.0125,I29>99%,H29*0.01,I29<99%,H29*0)} -> 452464.62
B30: 10 - BRITEZ EMMANUEL | C30: 25830000 | D30: =IFERROR(+VLOOKUP(B30,COMISIONES!A:E,5,FALSE),"0")*1 -> 9575852.5 | E30: 8755339.3 | F30: =+D30-E30 -> 820513.15 | G30: =+D30/C30 -> 0.370726 | H30: =+D30/$N$3*$N$4 -> 21763301 | I30: =+H30/C30 -> 0.84255908 | J30: =+D30/$N$3 -> 870532.04 | K30: =+(C30-D30)/$N$2 -> 1161010.5 | L30: {=+_xlfn.IFS(I30>114%,H30*0.02,I30>109%,H30*0.015,I30>104%,H30*0.0125,I30>99%,H30*0.01,I30<99%,H30*0)} -> 0
B31: 28 - GOMEZ PABLO | C31: 27702000 | D31: =IFERROR(+VLOOKUP(B31,COMISIONES!A:E,5,FALSE),"0")*1 -> 5823813.3 | E31: 5385739.6 | F31: =+D31-E31 -> 438073.69 | G31: =+D31/C31 -> 0.21023079 | H31: =+D31/$N$3*$N$4 -> 13235939 | I31: =+H31/C31 -> 0.47779725 | J31: =+D31/$N$3 -> 529437.57 | K31: =+(C31-D31)/$N$2 -> 1562727.6 | L31: {=+_xlfn.IFS(I31>114%,H31*0.02,I31>109%,H31*0.015,I31>104%,H31*0.0125,I31>99%,H31*0.01,I31<99%,H31*0)} -> 0
B32: 33 - NICOLAS AZULA | C32: 24010803 | D32: =IFERROR(+VLOOKUP(B32,COMISIONES!A:E,5,FALSE),"0")*1 -> 6485264.5 | E32: 5740624.9 | F32: =+D32-E32 -> 744639.68 | G32: =+D32/C32 -> 0.27009777 | H32: =+D32/$N$3*$N$4 -> 14739238 | I32: =+H32/C32 -> 0.61385858 | J32: =+D32/$N$3 -> 589569.5 | K32: =+(C32-D32)/$N$2 -> 1251824.2 | L32: {=+_xlfn.IFS(I32>114%,H32*0.02,I32>109%,H32*0.015,I32>104%,H32*0.0125,I32>99%,H32*0.01,I32<99%,H32*0)} -> 0
B33: 37 - SALAJ EMILIO | C33: 25780148 | D33: =IFERROR(+VLOOKUP(B33,COMISIONES!A:E,5,FALSE),"0")*1 -> 5352544.9 | E33: 5033432.8 | F33: =+D33-E33 -> 319112.09 | G33: =+D33/C33 -> 0.20762274 | H33: =+D33/$N$3*$N$4 -> 12164875 | I33: =+H33/C33 -> 0.47186986 | J33: =+D33/$N$3 -> 486594.99 | K33: =+(C33-D33)/$N$2 -> 1459114.5 | L33: {=+_xlfn.IFS(I33>114%,H33*0.02,I33>109%,H33*0.015,I33>104%,H33*0.0125,I33>99%,H33*0.01,I33<99%,H33*0)} -> 0
B34: 24 - SOLIS EMMANUEL | C34: 26383192 | D34: =IFERROR(+VLOOKUP(B34,COMISIONES!A:E,5,FALSE),"0")*1 -> 7258430.1 | E34: 6519905.4 | F34: =+D34-E34 -> 738524.69 | G34: =+D34/C34 -> 0.27511569 | H34: =+D34/$N$3*$N$4 -> 16496432 | I34: =+H34/C34 -> 0.62526293 | J34: =+D34/$N$3 -> 659857.28 | K34: =+(C34-D34)/$N$2 -> 1366054.4 | L34: {=+_xlfn.IFS(I34>114%,H34*0.02,I34>109%,H34*0.015,I34>104%,H34*0.0125,I34>99%,H34*0.01,I34<99%,H34*0)} -> 0
B35: 7 - VALLEJOS EDUARDO | C35: 1.2506204e+08 | D35: =IFERROR(+VLOOKUP(B35,COMISIONES!A:E,5,FALSE),"0")*1 -> 43665769 | E35: 42908997 | F35: =+D35-E35 -> 756771.98 | G35: =+D35/C35 -> 0.34915285 | H35: =+D35/$N$3*$N$4 -> 99240384 | I35: =+H35/C35 -> 0.7935292 | J35: =+D35/$N$3 -> 3969615.3 | K35: =+(C35-D35)/$N$2 -> 5814019.6 | L35: {=+_xlfn.IFS(I35>114%,H35*0.0125,I35>109%,H35*0.01,I35>104%,H35*0.0075,I35>99%,H35*0.005,I35<99%,H35*0)} -> 0
B36: 57 - FEDERRATH MARTIN | C36: 36592500 | D36: =IFERROR(+VLOOKUP(B36,COMISIONES!A:E,5,FALSE),"0")*1 -> 21993713 | E36: 19786949 | F36: =+D36-E36 -> 2206764.3 | G36: =+D36/C36 -> 0.60104428 | H36: =+D36/$N$3*$N$4 -> 49985711 | I36: =+H36/C36 -> 1.3660097 | J36: =+D36/$N$3 -> 1999428.4 | K36: =+(C36-D36)/$N$2 -> 1042770.5 | L36: {=+_xlfn.IFS(I36>109%,H36*0.015,I36>104%,H36*0.0125,I36>99%,H36*0.01,I36<99%,H36*0)} -> 749785.67
B37: 1 - VERA ERNESTO | C37: 37270463 | D37: =IFERROR(+VLOOKUP(B37,COMISIONES!A:E,5,FALSE),"0")*1 -> 12277521 | E37: 10992914 | F37: =+D37-E37 -> 1284607.4 | G37: =+D37/C37 -> 0.32941692 | H37: =+D37/$N$3*$N$4 -> 27903458 | I37: =+H37/C37 -> 0.74867483 | J37: =+D37/$N$3 -> 1116138.3 | K37: =+(C37-D37)/$N$2 -> 1785210.1 | L37: {=+_xlfn.IFS(I37>114%,H37*0.02,I37>109%,H37*0.015,I37>104%,H37*0.0125,I37>99%,H37*0.01,I37<99%,H37*0)} -> 0
C38: 532189801 | D38: =+SUM(D25:D37) -> 1.777028e+08 | E38: 1.6340165e+08 | F38: =+D38-E38 -> 14301148 | G38: =+D38/C38 -> 0.33390869 | H38: =+D38/$N$3*$N$4 -> 4.0387e+08 | I38: =+H38/C38 -> 0.75888338 | J38: =+D38/$N$3 -> 16154800 | K38: =+(C38-D38)/$N$2 -> 25320500
A39: MAXI | B39: 58 - BLADIMIR LEZCANO | C39: 35000000 | D39: =IFERROR(+VLOOKUP(B39,COMISIONES!A:E,5,FALSE),"0")*1 -> 5729568.7 | E39: 5729568.7 | F39: =+D39-E39 -> 0 | G39: =+D39/C39 -> 0.16370196 | H39: =+D39/$N$3*$N$4 -> 13021747 | I39: =+H39/C39 -> 0.37204992 | J39: =+D39/$N$3 -> 520869.89 | K39: =+(C39-D39)/$N$2 -> 2090745.1 | L39: {=+_xlfn.IFS(I39>114%,H39*0.02,I39>109%,H39*0.015,I39>104%,H39*0.0125,I39>99%,H39*0.01,I39<99%,H39*0)} -> 0
B40: 59 - LEIVA SILVIO | C40: 30000000 | D40: =IFERROR(+VLOOKUP(B40,COMISIONES!A:E,5,FALSE),"0")*1 -> 3842660.3 | E40: 3842660.3 | F40: =+D40-E40 -> 0 | G40: =+D40/C40 -> 0.12808868 | H40: =+D40/$N$3*$N$4 -> 8733318.9 | I40: =+H40/C40 -> 0.29111063 | J40: =+D40/$N$3 -> 349332.76 | K40: =+(C40-D40)/$N$2 -> 1868381.4 | L40: {=+_xlfn.IFS(I40>114%,H40*0.02,I40>109%,H40*0.015,I40>104%,H40*0.0125,I40>99%,H40*0.01,I40<99%,H40*0)} -> 0
...

Sheet COBERTURA
A1: SUPERVISOR | C1: VENDEDOR | D1: COBERTURA TOTAL | E1: DIA ANTERIOR | F1: INCREMENTO DIARIO | G1: CARTERA TOTAL | H1: CCC | I1: CCC FALTANTE 85% | P1: Cod vdor | R1: Cobertura x Un de negocio
A2: MARTIN (SUPERVISOR) | B2: 22 | C2: =+AVANCE!B11 -> 22 - ALMIRON NICOLAS | D2: =H2/G2 -> 0.65822785 | E2: 33 | F2: =+H2-E2 -> 19 | G2: =VLOOKUP(B2,'Base Cobertura'!$A:$C,3,FALSE) -> 79 | H2: =VLOOKUP(B2,'Base Cobertura'!$A:$C,2,FALSE) -> 52 | I2: =(+G2*$M$2)-H2 -> 15.15 | J2: bien | K2: bien | L2: OBJETIVO | M2: 0.85 | P2: 25 | Q2: =VLOOKUP(P2,$B:$C,2,FALSE) -> 25 - KALATAKI GUSTAVO | R2: =VLOOKUP(P2,$B:$C,2,FALSE) -> 25 - KALATAKI GUSTAVO | S2: CCC | T2: CARTERA TOTAL | U2: % ALCANZADO
B3: 20 | C3: =+AVANCE!B2 -> 20 - FLORES JAVIER | D3: =H3/G3 -> 0.78947368 | E3: 126 | F3: =+H3-E3 -> 54 | G3: =VLOOKUP(B3,'Base Cobertura'!$A:$C,3,FALSE) -> 228 | H3: =VLOOKUP(B3,'Base Cobertura'!$A:$C,2,FALSE) -> 180 | I3: =(+G3*$M$2)-H3 -> 13.8 | J3: mal | K3: chaca | P3: {=+_xlfn._xlws.FILTER('Base Cobertura'!E:I,'Base Cobertura'!E:E=COBERTURA!P2)} -> 25 | Q3: 25 | R3: 138 - ALMACEN | S3: 24 | T3: 174 | U3: =+S3/T3 -> 0.13793103
B4: 15 | C4: =+AVANCE!B12 -> 15 - GALARZA GERARDO | D4: =H4/G4 -> 0.58461538 | E4: 21 | F4: =+H4-E4 -> 17 | G4: =VLOOKUP(B4,'Base Cobertura'!$A:$C,3,FALSE) -> 65 | H4: =VLOOKUP(B4,'Base Cobertura'!$A:$C,2,FALSE) -> 38 | I4: =(+G4*$M$2)-H4 -> 17.25 | J4: re bien | K4: muy bien | P4: 25 | Q4: 0 | R4: 138 - Articulos Sin Asociar Agrupacion | S4: 8 | T4: 174 | U4: =+S4/T4 -> 0.045977011
B5: 19 | C5: =+AVANCE!B3 -> 19 - GONZALEZ MARCELO | D5: =H5/G5 -> 0.73684211 | E5: 100 | F5: =+H5-E5 -> 54 | G5: =VLOOKUP(B5,'Base Cobertura'!$A:$C,3,FALSE) -> 209 | H5: =VLOOKUP(B5,'Base Cobertura'!$A:$C,2,FALSE) -> 154 | I5: =(+G5*$M$2)-H5 -> 23.65 | K5: muy bien | P5: 25 | Q5: 0 | R5: 138 - BEBIDAS | S5: 28 | T5: 174 | U5: =+S5/T5 -> 0.16091954
B6: 16 | C6: =+AVANCE!B4 -> 16 - GOMEZ MATÍAS | D6: =H6/G6 -> 0.545 | E6: 81 | F6: =+H6-E6 -> 28 | G6: =VLOOKUP(B6,'Base Cobertura'!$A:$C,3,FALSE) -> 200 | H6: =VLOOKUP(B6,'Base Cobertura'!$A:$C,2,FALSE) -> 109 | I6: =(+G6*$M$2)-H6 -> 61 | J6: apretarlo | K6: apretarlo | P6: 25 | Q6: 0 | R6: 138 - CHOCOLATE | S6: 19 | T6: 174 | U6: =+S6/T6 -> 0.1091954
B7: 12 | C7: =+AVANCE!B5 -> 12 - GUTIERREZ MARCOS DAVID | D7: =H7/G7 -> 0.6713615 | E7: 89 | F7: =+H7-E7 -> 54 | G7: =VLOOKUP(B7,'Base Cobertura'!$A:$C,3,FALSE) -> 213 | H7: =VLOOKUP(B7,'Base Cobertura'!$A:$C,2,FALSE) -> 143 | I7: =(+G7*$M$2)-H7 -> 38.05 | J7: apretarlo | K7: apretarlo | P7: 25 | Q7: 0 | R7: 138 - GALLETITAS | S7: 35 | T7: 174 | U7: =+S7/T7 -> 0.20114943
B8: 11 | C8: =+AVANCE!B6 -> 11 - SANCHEZ RICARDO | D8: =H8/G8 -> 0.64534884 | E8: 92 | F8: =+H8-E8 -> 19 | G8: =VLOOKUP(B8,'Base Cobertura'!$A:$C,3,FALSE) -> 172 | H8: =VLOOKUP(B8,'Base Cobertura'!$A:$C,2,FALSE) -> 111 | I8: =(+G8*$M$2)-H8 -> 35.2 | J8: bien | K8: apretarlo | P8: 25 | Q8: 0 | R8: 138 - GOLOSINAS | S8: 25 | T8: 174 | U8: =+S8/T8 -> 0.14367816
B9: 8 | C9: =+AVANCE!B7 -> 8 - PARRA MAXIMILIANO | D9: =H9/G9 -> 0.60696517 | E9: 64 | F9: =+H9-E9 -> 58 | G9: =VLOOKUP(B9,'Base Cobertura'!$A:$C,3,FALSE) -> 201 | H9: =VLOOKUP(B9,'Base Cobertura'!$A:$C,2,FALSE) -> 122 | I9: =(+G9*$M$2)-H9 -> 48.85 | J9: bien | K9: apretarlo con ema | P9: 25 | Q9: 0 | R9: 138 - MASCOTAS | S9: 25 | T9: 174 | U9: =+S9/T9 -> 0.14367816
B10: 52 | C10: =+AVANCE!B13 -> 52 - RAVAROTTO EMANUEL | D10: =H10/G10 -> 0.32380952 | E10: 19 | F10: =+H10-E10 -> 15 | G10: =VLOOKUP(B10,'Base Cobertura'!$A:$C,3,FALSE) -> 105 | H10: =VLOOKUP(B10,'Base Cobertura'!$A:$C,2,FALSE) -> 34 | I10: =(+G10*$M$2)-H10 -> 55.25 | J10: apretarlo | K10: apretarlo | P10: 25 | Q10: 0 | R10: 138 - NO PERECEDEROS | S10: 17 | T10: 174 | U10: =+S10/T10 -> 0.097701149
B11: 53 | C11: =+AVANCE!B14 -> 53 - SANDOVAL RODRIGO | D11: =H11/G11 -> 0.28571429 | E11: 24 | F11: =+H11-E11 -> 6 | G11: =VLOOKUP(B11,'Base Cobertura'!$A:$C,3,FALSE) -> 105 | H11: =VLOOKUP(B11,'Base Cobertura'!$A:$C,2,FALSE) -> 30 | I11: =(+G11*$M$2)-H11 -> 59.25 | J11: verlo | P11: 25 | Q11: 0 | R11: 138 - PILAS | S11: 9 | T11: 174 | U11: =+S11/T11 -> 0.051724138
B12: 5 | C12: =+AVANCE!B8 -> 5 - SCHELOVER RAUL | D12: =H12/G12 -> 0.68560606 | E12: 144 | F12: =+H12-E12 -> 37 | G12: =VLOOKUP(B12,'Base Cobertura'!$A:$C,3,FALSE) -> 264 | H12: =VLOOKUP(B12,'Base Cobertura'!$A:$C,2,FALSE) -> 181 | I12: =(+G12*$M$2)-H12 -> 43.4 | J12: verlo
B13: 4 | C13: =+AVANCE!B9 -> 4 - TUR SPRINGER FERNANDO | D13: =H13/G13 -> 0.57692308 | E13: 85 | F13: =+H13-E13 -> 20 | G13: =VLOOKUP(B13,'Base Cobertura'!$A:$C,3,FALSE) -> 182 | H13: =VLOOKUP(B13,'Base Cobertura'!$A:$C,2,FALSE) -> 105 | I13: =(+G13*$M$2)-H13 -> 49.7 | J13: re bien | K13: muy bien
F14: =+SUM(F1:F13) -> 381 | G14: =+SUM(G1:G13) -> 2023 | H14: =+SUM(H1:H13) -> 1259 | J14: bien | K14: muy bien
A15: CRISTIAN (SUPERVISOR) | B15: 31 | C15: =+AVANCE!B21 -> 31 - RENZO RAMOS | D15: =H15/G15 -> 0.65680473 | E15: 90 | F15: =+H15-E15 -> 21 | G15: =VLOOKUP(B15,'Base Cobertura'!$A:$C,3,FALSE) -> 169 | H15: =VLOOKUP(B15,'Base Cobertura'!$A:$C,2,FALSE) -> 111 | I15: =(+G15*$M$2)-H15 -> 32.65 | J15: bien | K15: bien
B16: 54 | C16: =+AVANCE!B23 -> 54 - BARTSCHAT EMILIANO NAHUEL | D16: =H16/G16 -> 0.59313725 | E16: 92 | F16: =+H16-E16 -> 29 | G16: =VLOOKUP(B16,'Base Cobertura'!$A:$C,3,FALSE) -> 204 | H16: =VLOOKUP(B16,'Base Cobertura'!$A:$C,2,FALSE) -> 121 | I16: =(+G16*$M$2)-H16 -> 52.4 | J16: bien | K16: chaca
B17: 21 | C17: =+AVANCE!B19 -> 21 - CATAN MATIAS | D17: =H17/G17 -> 0.71686747 | E17: 88 | F17: =+H17-E17 -> 31 | G17: =VLOOKUP(B17,'Base Cobertura'!$A:$C,3,FALSE) -> 166 | H17: =VLOOKUP(B17,'Base Cobertura'!$A:$C,2,FALSE) -> 119 | I17: =(+G17*$M$2)-H17 -> 22.1 | J17: apretarlo | K17: bien
B18: 23 | C18: =+AVANCE!B20 -> 23 - DELGADO JOSÉ | D18: =H18/G18 -> 0.70700637 | E18: 95 | F18: =+H18-E18 -> 16 | G18: =VLOOKUP(B18,'Base Cobertura'!$A:$C,3,FALSE) -> 157 | H18: =VLOOKUP(B18,'Base Cobertura'!$A:$C,2,FALSE) -> 111 | I18: =(+G18*$M$2)-H18 -> 22.45 | J18: apretarlo | K18: muy bien
B19: 18 | C19: =+AVANCE!B18 -> 18 - HERRERA PABLO | D19: =H19/G19 -> 0.65745856 | E19: 83 | F19: =+H19-E19 -> 36 | G19: =VLOOKUP(B19,'Base Cobertura'!$A:$C,3,FALSE) -> 181 | H19: =VLOOKUP(B19,'Base Cobertura'!$A:$C,2,FALSE) -> 119 | I19: =(+G19*$M$2)-H19 -> 34.85 | J19: bien | K19: bien
B20: 44 | C20: =+AVANCE!B22 -> 44 - MONGES CESAR LUIS | D20: =H20/G20 -> 0.66081871 | E20: 64 | F20: =+H20-E20 -> 49 | G20: =VLOOKUP(B20,'Base Cobertura'!$A:$C,3,FALSE) -> 171 | H20: =VLOOKUP(B20,'Base Cobertura'!$A:$C,2,FALSE) -> 113 | I20: =(+G20*$M$2)-H20 -> 32.35 | J20: apretarlo | K20: muy bien
B21: 2 | C21: =+AVANCE!B16 -> 2 - OJEDA NORBERTO | D21: =H21/G21 -> 0.65 | E21: 70 | F21: =+H21-E21 -> 8 | G21: =VLOOKUP(B21,'Base Cobertura'!$A:$C,3,FALSE) -> 120 | H21: =VLOOKUP(B21,'Base Cobertura'!$A:$C,2,FALSE) -> 78 | I21: =(+G21*$M$2)-H21 -> 24 | J21: apretarlo | K21: apretar
B22: 3 | C22: =+AVANCE!B17 -> 3 - VIDAL NAHUEL | D22: =H22/G22 -> 0.69186047 | E22: 79 | F22: =+H22-E22 -> 40 | G22: =VLOOKUP(B22,'Base Cobertura'!$A:$C,3,FALSE) -> 172 | H22: =VLOOKUP(B22,'Base Cobertura'!$A:$C,2,FALSE) -> 119 | I22: =(+G22*$M$2)-H22 -> 27.2 | J22: abrazo | K22: muy bien
F23: =+SUM(F15:F22) -> 230 | G23: =+SUM(G15:G22) -> 1340 | H23: =+SUM(H15:H22) -> 891
A24: GONZALO (SUPERVISOR) | B24: 32 | C24: =+AVANCE!B25 -> 32 - CABRAL GONZALO | D24: =H24/G24 -> 0.46551724 | E24: 20 | F24: =+H24-E24 -> 7 | G24: =VLOOKUP(B24,'Base Cobertura'!$A:$C,3,FALSE) -> 58 | H24: =VLOOKUP(B24,'Base Cobertura'!$A:$C,2,FALSE) -> 27 | I24: =(+G24*$M$2)-H24 -> 22.3 | J24: bien | K24: apretar
B25: 36 | C25: =+AVANCE!B26 -> 36 - COSARINSKI DIEGO | D25: =H25/G25 -> 0.625 | E25: 68 | F25: =+H25-E25 -> 32 | G25: =VLOOKUP(B25,'Base Cobertura'!$A:$C,3,FALSE) -> 160 | H25: =VLOOKUP(B25,'Base Cobertura'!$A:$C,2,FALSE) -> 100 | I25: =(+G25*$M$2)-H25 -> 36 | J25: apretarlo | K25: apretar
B26: 9 | C26: =+AVANCE!B27 -> 9 - ESTIGARRIBIA DAVID | D26: =H26/G26 -> 0.71974522 | E26: 80 | F26: =+H26-E26 -> 33 | G26: =VLOOKUP(B26,'Base Cobertura'!$A:$C,3,FALSE) -> 157 | H26: =VLOOKUP(B26,'Base Cobertura'!$A:$C,2,FALSE) -> 113 | I26: =(+G26*$M$2)-H26 -> 20.45 | J26: apretarlo | K26: bien
B27: 40 | C27: =+AVANCE!B28 -> 40 - IBARROLA JORGE | D27: =H27/G27 -> 0.44444444 | E27: 68 | F27: =+H27-E27 -> 32 | G27: =VLOOKUP(B27,'Base Cobertura'!$A:$C,3,FALSE) -> 225 | H27: =VLOOKUP(B27,'Base Cobertura'!$A:$C,2,FALSE) -> 100 | I27: =(+G27*$M$2)-H27 -> 91.25 | J27: apretarlo | K27: apretar
B28: 27 | C28: =+AVANCE!B29 -> 27 - GOMEZ ADRIÁN | D28: =H28/G28 -> 0.75572519 | E28: 73 | F28: =+H28-E28 -> 26 | G28: =VLOOKUP(B28,'Base Cobertura'!$A:$C,3,FALSE) -> 131 | H28: =VLOOKUP(B28,'Base Cobertura'!$A:$C,2,FALSE) -> 99 | I28: =(+G28*$M$2)-H28 -> 12.35 | J28: bien | K28: apretar
B29: 10 | C29: =+AVANCE!B30 -> 10 - BRITEZ EMMANUEL | D29: =H29/G29 -> 0.48663102 | E29: 40 | F29: =+H29-E29 -> 51 | G29: =VLOOKUP(B29,'Base Cobertura'!$A:$C,3,FALSE) -> 187 | H29: =VLOOKUP(B29,'Base Cobertura'!$A:$C,2,FALSE) -> 91 | I29: =(+G29*$M$2)-H29 -> 67.95 | J29: apretarlo | K29: apretar
B30: 28 | C30: =+AVANCE!B31 -> 28 - GOMEZ PABLO | D30: =H30/G30 -> 0.55882353 | E30: 67 | F30: =+H30-E30 -> 28 | G30: =VLOOKUP(B30,'Base Cobertura'!$A:$C,3,FALSE) -> 170 | H30: =VLOOKUP(B30,'Base Cobertura'!$A:$C,2,FALSE) -> 95 | I30: =(+G30*$M$2)-H30 -> 49.5 | J30: apretarlo | K30: apretar
B31: 33 | C31: =+AVANCE!B32 -> 33 - NICOLAS AZULA | D31: =H31/G31 -> 0.63905325 | E31: 66 | F31: =+H31-E31 -> 42 | G31: =VLOOKUP(B31,'Base Cobertura'!$A:$C,3,FALSE) -> 169 | H31: =VLOOKUP(B31,'Base Cobertura'!$A:$C,2,FALSE) -> 108 | I31: =(+G31*$M$2)-H31 -> 35.65 | J31: apretarlo | K31: apretar
B32: 37 | C32: =+AVANCE!B33 -> 37 - SALAJ EMILIO | D32: =H32/G32 -> 0.42176871 | E32: 82 | F32: =+H32-E32 -> -20 | G32: =VLOOKUP(B32,'Base Cobertura'!$A:$C,3,FALSE) -> 147 | H32: =VLOOKUP(B32,'Base Cobertura'!$A:$C,2,FALSE) -> 62 | I32: =(+G32*$M$2)-H32 -> 62.95 | J32: bien | K32: apretar
B33: 24 | C33: =+AVANCE!B34 -> 24 - SOLIS EMMANUEL | D33: =H33/G33 -> 0.47849462 | E33: 81 | F33: =+H33-E33 -> 8 | G33: =VLOOKUP(B33,'Base Cobertura'!$A:$C,3,FALSE) -> 186 | H33: =VLOOKUP(B33,'Base Cobertura'!$A:$C,2,FALSE) -> 89 | I33: =(+G33*$M$2)-H33 -> 69.1 | J33: apretarlo | K33: apretar
B34: 7 | C34: =+AVANCE!B35 -> 7 - VALLEJOS EDUARDO | D34: =H34/G34 -> 0.050847458 | E34: 0 | F34: =+H34-E34 -> 6 | G34: =VLOOKUP(B34,'Base Cobertura'!$A:$C,3,FALSE) -> 118 | H34: =VLOOKUP(B34,'Base Cobertura'!$A:$C,2,FALSE) -> 6 | I34: =(+G34*$M$2)-H34 -> 94.3 | J34: apretarlo
B35: 57 | C35: =+AVANCE!B36 -> 57 - FEDERRATH MARTIN | D35: =H35/G35 -> 0.47747748 | E35: 17 | F35: =+H35-E35 -> 36 | G35: =VLOOKUP(B35,'Base Cobertura'!$A:$C,3,FALSE) -> 111 | H35: =VLOOKUP(B35,'Base Cobertura'!$A:$C,2,FALSE) -> 53 | I35: =(+G35*$M$2)-H35 -> 41.35 | J35: verlo
B36: 1 | C36: =+AVANCE!B37 -> 1 - VERA ERNESTO | D36: =H36/G36 -> 0.6779661 | E36: 60 | F36: =+H36-E36 -> 20 | G36: =VLOOKUP(B36,'Base Cobertura'!$A:$C,3,FALSE) -> 118 | H36: =VLOOKUP(B36,'Base Cobertura'!$A:$C,2,FALSE) -> 80 | I36: =(+G36*$M$2)-H36 -> 20.3 | J36: bien | K36: bien
F37: =+SUM(F24:F36) -> 301 | G37: =+SUM(G24:G36) -> 1937 | H37: =+SUM(H24:H36) -> 1023
A38: MAXI (SUPERVISOR) | B38: 58 | C38: =+AVANCE!B39 -> 58 - BLADIMIR LEZCANO | D38: =H38/G38 -> 0.21686747 | E38: 60 | F38: =+H38-E38 -> -42 | G38: =VLOOKUP(B38,'Base Cobertura'!$A:$C,3,FALSE) -> 83 | H38: =VLOOKUP(B38,'Base Cobertura'!$A:$C,2,FALSE) -> 18 | I38: =(+G38*$M$2)-H38 -> 52.55
B39: 59 | C39: =+AVANCE!B40 -> 59 - LEIVA SILVIO | D39: =H39/G39 -> 0.19685039 | E39: 60 | F39: =+H39-E39 -> -35 | G39: =VLOOKUP(B39,'Base Cobertura'!$A:$C,3,FALSE) -> 127 | H39: =VLOOKUP(B39,'Base Cobertura'!$A:$C,2,FALSE) -> 25 | I39: =(+G39*$M$2)-H39 -> 82.95
B40: 49 | C40: =+AVANCE!B41 -> 49 - ESCOBAR RAÚL | D40: =H40/G40 -> 0.31428571 | E40: 60 | F40: =+H40-E40 -> 17 | G40: =VLOOKUP(B40,'Base Cobertura'!$A:$C,3,FALSE) -> 245 | H40: =VLOOKUP(B40,'Base Cobertura'!$A:$C,2,FALSE) -> 77 | I40: =(+G40*$M$2)-H40 -> 131.25
...

Sheet Venta C
B1: VENDEDOR/ SUPERVISOR | C1: Venta NETA ARTICULOS C
A2: 20 | B2: 20 - FLORES JAVIER | C2: =IFERROR(VLOOKUP(A2,'Base venta C'!$E:$P,12,FALSE),"0")*1 -> 343887.46
A3: 19 | B3: 19 - GONZALEZ MARCELO | C3: =IFERROR(VLOOKUP(A3,'Base venta C'!$E:$P,12,FALSE),"0")*1 -> 365262.82
A4: 16 | B4: 16 - GOMEZ MATÍAS | C4: =IFERROR(VLOOKUP(A4,'Base venta C'!$E:$P,12,FALSE),"0")*1 -> 271002.4
A5: 12 | B5: 12 - GUTIERREZ MARCOS DAVID | C5: =IFERROR(VLOOKUP(A5,'Base venta C'!$E:$P,12,FALSE),"0")*1 -> 284624.48
A6: 11 | B6: 11 - ZACARIAS DAVID | C6: =IFERROR(VLOOKUP(A6,'Base venta C'!$E:$P,12,FALSE),"0")*1 -> 166886.05
A7: 8 | B7: 8 - RAVAROTTO EMANUEL | C7: =IFERROR(VLOOKUP(A7,'Base venta C'!$E:$P,12,FALSE),"0")*1 -> 284846.64
A8: 5 | B8: 5 - SCHELOVER RAUL | C8: =IFERROR(VLOOKUP(A8,'Base venta C'!$E:$P,12,FALSE),"0")*1 -> 322216.7
A9: 4 | B9: 4 - TUR SPRINGER FERNANDO | C9: =IFERROR(VLOOKUP(A9,'Base venta C'!$E:$P,12,FALSE),"0")*1 -> 875228.78
B10: MARTIN (SUPERVISOR) PREVENTA
A11: 22 | B11: 22 - ALMIRON NICOLAS | C11: =IFERROR(VLOOKUP(A11,'Base venta C'!$E:$P,12,FALSE),"0")*1 -> 270784.37
A12: 49 | B12: 49 - ESCOBAR RAÚL | C12: =IFERROR(VLOOKUP(A12,'Base venta C'!$E:$P,12,FALSE),"0")*1 -> 76349.44
A13: 15 | B13: 15 - GALARZA GERARDO | C13: =IFERROR(VLOOKUP(A13,'Base venta C'!$E:$P,12,FALSE),"0")*1 -> 1329007.3
A14: 52 | B14: 52 - MARSALL NICOLAS | C14: =IFERROR(VLOOKUP(A14,'Base venta C'!$E:$P,12,FALSE),"0")*1 -> 155315.73
A15: 53 | B15: 53 - SANDOVAL RODRIGO | C15: =IFERROR(VLOOKUP(A15,'Base venta C'!$E:$P,12,FALSE),"0")*1 -> 833691.44
B16: MARTIN (SUPERVISOR)
A17: 2 | B17: 2 - OJEDA NORBERTO | C17: =IFERROR(VLOOKUP(A17,'Base venta C'!$E:$P,12,FALSE),"0")*1 -> 355809.05
A18: 3 | B18: 3 - VIDAL NAHUEL | C18: =IFERROR(VLOOKUP(A18,'Base venta C'!$E:$P,12,FALSE),"0")*1 -> 461503.95
A19: 18 | B19: 18 - HERRERA PABLO | C19: =IFERROR(VLOOKUP(A19,'Base venta C'!$E:$P,12,FALSE),"0")*1 -> 465462.81
A20: 21 | B20: 21 - CATAN MATIAS | C20: =IFERROR(VLOOKUP(A20,'Base venta C'!$E:$P,12,FALSE),"0")*1 -> 300786.17
A21: 23 | B21: 23 - DELGADO JOSÉ | C21: =IFERROR(VLOOKUP(A21,'Base venta C'!$E:$P,12,FALSE),"0")*1 -> 517438.51
A22: 31 | B22: 31 - BARTSCHAT EMILIANO NAHUEL | C22: =IFERROR(VLOOKUP(A22,'Base venta C'!$E:$P,12,FALSE),"0")*1 -> 346898.23
A23: 44 | B23: 44 - MONGE CÉSAR LUIS | C23: =IFERROR(VLOOKUP(A23,'Base venta C'!$E:$P,12,FALSE),"0")*1 -> 475747.4
A24: 54 | B24: 54 - CAÑETE DIEGO | C24: =IFERROR(VLOOKUP(A24,'Base venta C'!$E:$P,12,FALSE),"0")*1 -> 394891.73
A25: 56 | B25: 56 - JUAN ANDRES SANCHEZ | C25: =IFERROR(VLOOKUP(A25,'Base venta C'!$E:$P,12,FALSE),"0")*1 -> 254599.35
B26: CRISTIAN (SUPERVISOR)
A27: 32 | B27: 32 - BLANCO FERNANDO | C27: =IFERROR(VLOOKUP(A27,'Base venta C'!$E:$P,12,FALSE),"0")*1 -> 357064.39
A28: 36 | B28: 36 - STELLA MARIS CANO | C28: =IFERROR(VLOOKUP(A28,'Base venta C'!$E:$P,12,FALSE),"0")*1 -> 228911.14
A29: 9 | B29: 9 - ESTIGARRIBIA DAVID | C29: =IFERROR(VLOOKUP(A29,'Base venta C'!$E:$P,12,FALSE),"0")*1 -> 449396.93
A30: 40 | B30: 40 - GARCIA BOGARIN SANTIAGO | C30: =IFERROR(VLOOKUP(A30,'Base venta C'!$E:$P,12,FALSE),"0")*1 -> 259074.86
A31: 27 | B31: 27 - GOMEZ ADRIÁN | C31: =IFERROR(VLOOKUP(A31,'Base venta C'!$E:$P,12,FALSE),"0")*1 -> 315929.47
A32: 10 | B32: 10 - SEGOVIA JUAN CRUZ | C32: =IFERROR(VLOOKUP(A32,'Base venta C'!$E:$P,12,FALSE),"0")*1 -> 385757.33
A33: 28 | B33: 28 - GOMEZ PABLO | C33: =IFERROR(VLOOKUP(A33,'Base venta C'!$E:$P,12,FALSE),"0")*1 -> 216785.26
A34: 33 | B34: 33 - NICOLAS AZULA | C34: =IFERROR(VLOOKUP(A34,'Base venta C'!$E:$P,12,FALSE),"0")*1 -> 218111.24
A35: 37 | B35: 37 - PEREZ ESQUIVEL BRUNO NICOLAS | C35: =IFERROR(VLOOKUP(A35,'Base venta C'!$E:$P,12,FALSE),"0")*1 -> 160532.76
A36: 24 | B36: 24 - DELGADO HERNAN GABRIEL | C36: =IFERROR(VLOOKUP(A36,'Base venta C'!$E:$P,12,FALSE),"0")*1 -> 294217.66
A37: 7 | B37: 7 - VALLEJOS EDUARDO | C37: =IFERROR(VLOOKUP(A37,'Base venta C'!$E:$P,12,FALSE),"0")*1 -> 264122.85
A38: 57 | B38: 57 - ZARATE NICOLAS | C38: =IFERROR(VLOOKUP(A38,'Base venta C'!$E:$P,12,FALSE),"0")*1 -> 62179.29
A39: 1 | B39: 1 - VERA ERNESTO | C39: =IFERROR(VLOOKUP(A39,'Base venta C'!$E:$P,12,FALSE),"0")*1 -> 1671221.4
B40: GONZALO (SUPERVISOR)
...

Sheet Base Cobertura
A1: COBERTURAMESENCURSO | F1: COBERTURAUNIDADDENEGOCIO
A2: Nro Vendedor | B2: CCC x Bultos | C2: Cartera Clientes | F2: Nro Vendedor | G2: Agrupacion | H2: CCC x Bultos | I2: Cartera Clientes
B3: 5 | C3: 3623 | G3: 138 - ALMACEN | H3: 3 | I3: 3623
A4: 1 | B4: 80 | C4: 118 | G4: 138 - Articulos Sin Asociar Agrupacion | H4: 1 | I4: 3623
A5: 10 | B5: 91 | C5: 187 | G5: 138 - BEBIDAS | H5: 2 | I5: 3623
A6: 100 | B6: 35 | C6: 2033 | G6: 138 - CHOCOLATE | H6: 2 | I6: 3623
A7: 11 | B7: 111 | C7: 172 | G7: 138 - GALLETITAS | H7: 4 | I7: 3623
A8: 12 | B8: 143 | C8: 213 | G8: 138 - GOLOSINAS | H8: 4 | I8: 3623
A9: 123 | B9: 32 | C9: 490 | G9: 138 - MASCOTAS | H9: 3 | I9: 3623
A10: 15 | B10: 38 | C10: 65 | G10: 138 - NO PERECEDEROS | I10: 3623
A11: 16 | B11: 109 | C11: 200 | G11: 138 - PILAS | I11: 3623
A12: 18 | B12: 119 | C12: 181 | E12: =+F12 -> 1 | F12: 1 | G12: 138 - ALMACEN | H12: 37 | I12: 118
A13: 19 | B13: 154 | C13: 209 | E13: =+$E$12 -> 1 | G13: 138 - Articulos Sin Asociar Agrupacion | H13: 27 | I13: 118
A14: 2 | B14: 78 | C14: 120 | E14: =+$E$12 -> 1 | G14: 138 - BEBIDAS | H14: 40 | I14: 118
A15: 20 | B15: 180 | C15: 228 | E15: =+$E$12 -> 1 | G15: 138 - CHOCOLATE | H15: 28 | I15: 118
A16: 21 | B16: 119 | C16: 166 | E16: =+$E$12 -> 1 | G16: 138 - GALLETITAS | H16: 55 | I16: 118
A17: 22 | B17: 52 | C17: 79 | E17: =+$E$12 -> 1 | G17: 138 - GOLOSINAS | H17: 49 | I17: 118
A18: 23 | B18: 111 | C18: 157 | E18: =+$E$12 -> 1 | G18: 138 - MASCOTAS | H18: 24 | I18: 118
A19: 24 | B19: 89 | C19: 186 | E19: =+$E$12 -> 1 | G19: 138 - NO PERECEDEROS | H19: 28 | I19: 118
A20: 25 | B20: 50 | C20: 174 | E20: =+$E$12 -> 1 | G20: 138 - PILAS | H20: 26 | I20: 118
A21: 26 | B21: 65 | C21: 173 | E21: =+$F$21 -> 10 | F21: 10 | G21: 138 - ALMACEN | H21: 19 | I21: 187
A22: 27 | B22: 99 | C22: 131 | E22: =+$F$21 -> 10 | G22: 138 - Articulos Sin Asociar Agrupacion | H22: 6 | I22: 187
A23: 28 | B23: 95 | C23: 170 | E23: =+$F$21 -> 10 | G23: 138 - BEBIDAS | H23: 36 | I23: 187
A24: 3 | B24: 119 | C24: 172 | E24: =+$F$21 -> 10 | G24: 138 - CHOCOLATE | H24: 25 | I24: 187
A25: 30 | B25: 16 | C25: 122 | E25: =+$F$21 -> 10 | G25: 138 - GALLETITAS | H25: 45 | I25: 187
A26: 31 | B26: 111 | C26: 169 | E26: =+$F$21 -> 10 | G26: 138 - GOLOSINAS | H26: 35 | I26: 187
A27: 32 | B27: 27 | C27: 58 | E27: =+$F$21 -> 10 | G27: 138 - MASCOTAS | H27: 11 | I27: 187
A28: 33 | B28: 108 | C28: 169 | E28: =+$F$21 -> 10 | G28: 138 - NO PERECEDEROS | H28: 11 | I28: 187
A29: 36 | B29: 100 | C29: 160 | E29: =+$F$21 -> 10 | G29: 138 - PILAS | H29: 13 | I29: 187
A30: 37 | B30: 62 | C30: 147 | E30: =+$F$30 -> 100 | F30: 100 | G30: 138 - ALMACEN | H30: 19 | I30: 2033
A31: 4 | B31: 105 | C31: 182 | E31: =+$F$30 -> 100 | G31: 138 - Articulos Sin Asociar Agrupacion | H31: 14 | I31: 2033
A32: 40 | B32: 100 | C32: 225 | E32: =+$F$30 -> 100 | G32: 138 - BEBIDAS | H32: 15 | I32: 2033
A33: 42 | B33: 7 | C33: 52 | E33: =+$F$30 -> 100 | G33: 138 - CHOCOLATE | H33: 7 | I33: 2033
A34: 43 | B34: 11 | C34: 93 | E34: =+$F$30 -> 100 | G34: 138 - GALLETITAS | H34: 23 | I34: 2033
A35: 44 | B35: 113 | C35: 171 | E35: =+$F$30 -> 100 | G35: 138 - GOLOSINAS | H35: 16 | I35: 2033
A36: 49 | B36: 77 | C36: 245 | E36: =+$F$30 -> 100 | G36: 138 - MASCOTAS | H36: 14 | I36: 2033
A37: 5 | B37: 181 | C37: 264 | E37: =+$F$30 -> 100 | G37: 138 - NO PERECEDEROS | H37: 3 | I37: 2033
A38: 52 | B38: 34 | C38: 105 | E38: =+$F$30 -> 100 | G38: 138 - PILAS | H38: 4 | I38: 2033
A39: 53 | B39: 30 | C39: 105 | E39: =+$F$39 -> 11 | F39: 11 | G39: 138 - ALMACEN | H39: 34 | I39: 172
A40: 54 | B40: 121 | C40: 204 | E40: =+$F$39 -> 11 | G40: 138 - Articulos Sin Asociar Agrupacion | H40: 23 | I40: 172
...

Sheet Base venta C
A1: Periodos | B1: Cod. Período | C1: Descripción Período | D1: Vendedor según comprobante | E1: Código | F1: Descripción | G1: Rotacion a-b-c | H1: Código | I1: Descripción | J1: P.P.P. Neto | K1: P.P.P. Final | L1: Cantidades CON Cargo | M1: Cantidades SIN Cargo | N1: Cantidades Totales | O1: Pesos Totales | P1: Importes Netos | Q1: Importes Finales | R1: Cantidad de Facturas | S1: Bultos Promedio | T1: Cantidades en Combos
A2: (001) MAR 2026 | B2: 1 | C2: 46082 | D2: Suc: 001 (000001) VERA ERNESTO | E2: 1 | F2: VERA ERNESTO | G2: (1382) ROTACION C INCENTIVO | H2: 1382 | I2: ROTACION C INCENTIVO | J2: 98746.145 | K2: 122432.8 | L2: 14.2607 | M2: 2.6637 | N2: 16.9244 | O2: 0 | P2: 1671221.4 | Q2: 2072104.4 | R2: 128 | S2: 0.13 | T2: 0
A3: (001) MAR 2026 | B3: 1 | C3: 46082 | D3: Suc: 001 (000002) OJEDA NORBERTO | E3: 2 | F3: OJEDA NORBERTO | G3: (1382) ROTACION C INCENTIVO | H3: 1382 | I3: ROTACION C INCENTIVO | J3: 11815.421 | K3: 14554.453 | L3: 25.5498 | M3: 4.5642 | N3: 30.114 | O3: 0 | P3: 355809.05 | Q3: 438292.15 | R3: 73 | S3: 0.41 | T3: 0
A4: (001) MAR 2026 | B4: 1 | C4: 46082 | D4: Suc: 001 (000003) VIDAL NAHUEL | E4: 3 | F4: VIDAL NAHUEL | G4: (1382) ROTACION C INCENTIVO | H4: 1382 | I4: ROTACION C INCENTIVO | J4: 12029.634 | K4: 14825.838 | L4: 27.3731 | M4: 10.9908 | N4: 38.3639 | O4: 0 | P4: 461503.95 | Q4: 568777.28 | R4: 79 | S4: 0.49 | T4: 0
A5: (001) MAR 2026 | B5: 1 | C5: 46082 | D5: Suc: 001 (000004) TUR SPRINGER FERNANDO | E5: 4 | F5: TUR SPRINGER FERNANDO | G5: (1382) ROTACION C INCENTIVO | H5: 1382 | I5: ROTACION C INCENTIVO | J5: 17624.902 | K5: 21774.702 | L5: 44.3529 | M5: 5.3058 | N5: 49.6586 | O5: 0 | P5: 875228.78 | Q5: 1081302.2 | R5: 100 | S5: 0.5 | T5: 0
A6: (001) MAR 2026 | B6: 1 | C6: 46082 | D6: Suc: 001 (000005) SCHELOVER RAUL | E6: 5 | F6: SCHELOVER RAUL | G6: (1382) ROTACION C INCENTIVO | H6: 1382 | I6: ROTACION C INCENTIVO | J6: 26707.909 | K6: 32656.222 | L6: 7.0172 | M6: 5.0472 | N6: 12.0645 | O6: 0 | P6: 322216.7 | Q6: 393979.93 | R6: 70 | S6: 0.17 | T6: 0
A7: (001) MAR 2026 | B7: 1 | C7: 46082 | D7: Suc: 001 (000007) VALLEJOS EDUARDO | E7: 7 | F7: VALLEJOS EDUARDO | G7: (1382) ROTACION C INCENTIVO | H7: 1382 | I7: ROTACION C INCENTIVO | J7: 6772.381 | K7: 8382.717 | L7: 39 | M7: 0 | N7: 39 | O7: 0 | P7: 264122.85 | Q7: 326925.97 | R7: 1 | S7: 39 | T7: 0
A8: (001) MAR 2026 | B8: 1 | C8: 46082 | D8: Suc: 001 (000008) RAVAROTTO EMANUEL | E8: 8 | F8: RAVAROTTO EMANUEL | G8: (1382) ROTACION C INCENTIVO | H8: 1382 | I8: ROTACION C INCENTIVO | J8: 18047.967 | K8: 22290.443 | L8: 8.0508 | M8: 7.7319 | N8: 15.7828 | O8: 0 | P8: 284846.64 | Q8: 351804.59 | R8: 61 | S8: 0.26 | T8: 0
A9: (001) MAR 2026 | B9: 1 | C9: 46082 | D9: Suc: 001 (000009) ESTIGARRIBIA DAVID | E9: 9 | F9: ESTIGARRIBIA DAVID | G9: (1382) ROTACION C INCENTIVO | H9: 1382 | I9: ROTACION C INCENTIVO | J9: 9288.078 | K9: 11426.613 | L9: 40.549 | M9: 7.8353 | N9: 48.3843 | O9: 0 | P9: 449396.93 | Q9: 552868.39 | R9: 85 | S9: 0.57 | T9: 0
A10: (001) MAR 2026 | B10: 1 | C10: 46082 | D10: Suc: 001 (000010) SEGOVIA JUAN CRUZ | E10: 10 | F10: SEGOVIA JUAN CRUZ | G10: (1382) ROTACION C INCENTIVO | H10: 1382 | I10: ROTACION C INCENTIVO | J10: 19423.102 | K10: 23755.08 | L10: 16.26 | M10: 3.6008 | N10: 19.8607 | O10: 0 | P10: 385757.33 | Q10: 471793.64 | R10: 61 | S10: 0.33 | T10: 0
A11: (001) MAR 2026 | B11: 1 | C11: 46082 | D11: Suc: 001 (000011) ZACARIAS DAVID | E11: 11 | F11: ZACARIAS DAVID | G11: (1382) ROTACION C INCENTIVO | H11: 1382 | I11: ROTACION C INCENTIVO | J11: 19880.77 | K11: 24580.662 | L11: 6.225 | M11: 2.1693 | N11: 8.3943 | O11: 0 | P11: 166886.05 | Q11: 206338.57 | R11: 53 | S11: 0.16 | T11: 0
A12: (001) MAR 2026 | B12: 1 | C12: 46082 | D12: Suc: 001 (000012) GUTIERREZ MARCOS DAVID | E12: 12 | F12: GUTIERREZ MARCOS DAVID | G12: (1382) ROTACION C INCENTIVO | H12: 1382 | I12: ROTACION C INCENTIVO | J12: 21003.651 | K12: 25910.202 | L12: 6.2833 | M12: 7.2679 | N12: 13.5512 | O12: 0 | P12: 284624.48 | Q12: 351114.08 | R12: 65 | S12: 0.21 | T12: 0
A13: (001) MAR 2026 | B13: 1 | C13: 46082 | D13: Suc: 001 (000015) GALARZA GERARDO | E13: 15 | F13: GALARZA GERARDO | G13: (1382) ROTACION C INCENTIVO | H13: 1382 | I13: ROTACION C INCENTIVO | J13: 39203.754 | K13: 49427.271 | L13: 33.6667 | M13: 0.2333 | N13: 33.9 | O13: 0 | P13: 1329007.3 | Q13: 1675584.5 | R13: 10 | S13: 3.39 | T13: 0
... A45: (001) MAR 2026 | B45: 1 | C45: 46082 | D45: Suc: 001 (000123) TORRES ROLANDO | E45: 123 | F45: TORRES ROLANDO | G45: (1382) ROTACION C INCENTIVO | H45: 1382 | I45: ROTACION C INCENTIVO | J45: 52587.592 | K45: 64949.011 | L45: 26.325 | M45: 0.1667 | N45: 26.4917 | O45: 0 | P45: 1393132.9 | Q45: 1720607.6 | R45: 13 | S45: 2.04 | T45: 0

Sheet Promedio Horas
A1: Cod | B1: Vendedor | D1: Promedio Mensual
A2: V2 | B2: =+AVANCE!B16 -> 2 - OJEDA NORBERTO | D2: 0.17689545
A3: V3 | B3: =+AVANCE!B17 -> 3 - VIDAL NAHUEL | D3: 0.26885841
A4: V18 | B4: =+AVANCE!B18 -> 18 - HERRERA PABLO | D4: 0.25382793
A5: V21 | B5: =+AVANCE!B19 -> 21 - CATAN MATIAS | D5: 0.26086767
A6: V23 | B6: =+AVANCE!B20 -> 23 - DELGADO JOSÉ | D6: 0.23091397
A7: V31 | B7: =+AVANCE!B21 -> 31 - RENZO RAMOS | D7: 0.26410108
A8: V44 | B8: =+AVANCE!B22 -> 44 - MONGES CESAR LUIS | D8: 0.24712809
A9: V54 | B9: =+AVANCE!B23 -> 54 - BARTSCHAT EMILIANO NAHUEL | D9: 0.23885918
A10: V56 | B10: =+AVANCE!B42 -> 56 - JUAN ANDRES SANCHEZ | D10: 0.12771605
A11: V4 | B11: =+AVANCE!B9 -> 4 - TUR SPRINGER FERNANDO | D11: 0.25248958
A12: V5 | B12: =+AVANCE!B8 -> 5 - SCHELOVER RAUL | D12: 0.29602238
A13: V8 | B13: =+AVANCE!B7 -> 8 - PARRA MAXIMILIANO | D13: 0.2442284
A14: V11 | B14: =+AVANCE!B6 -> 11 - SANCHEZ RICARDO | D14: 0.28296644
A15: V12 | B15: =+AVANCE!B5 -> 12 - GUTIERREZ MARCOS DAVID | D15: 0.24145216
A16: V16 | B16: =+AVANCE!B4 -> 16 - GOMEZ MATÍAS | D16: 0.20970872
A17: V19 | B17: =+AVANCE!B3 -> 19 - GONZALEZ MARCELO | D17: 0.25107562
A18: V20 | B18: =+AVANCE!B2 -> 20 - FLORES JAVIER | D18: 0.28378897
A19: V49 | B19: =+AVANCE!B41 -> 49 - ESCOBAR RAÚL | D19: 0.26686188
A20: V1 | B20: =+AVANCE!B37 -> 1 - VERA ERNESTO | D20: 0.29647724
A21: V9 | B21: =+AVANCE!B27 -> 9 - ESTIGARRIBIA DAVID | D21: 0.24353897
A22: V10 | B22: =+AVANCE!B30 -> 10 - BRITEZ EMMANUEL | D22: 0.23924383
A23: V24 | B23: =+AVANCE!B34 -> 24 - SOLIS EMMANUEL | D23: 0.22634491
A24: V27 | B24: =+AVANCE!B29 -> 27 - GOMEZ ADRIÁN | D24: 0.24776196
A25: V28 | B25: =+AVANCE!B31 -> 28 - GOMEZ PABLO | D25: 0.21435494
A26: V33 | B26: =+AVANCE!B32 -> 33 - NICOLAS AZULA | D26: 0.27032793
A27: V36 | B27: =+AVANCE!B26 -> 36 - COSARINSKI DIEGO | D27: 0.23621142
A28: V37 | B28: =+AVANCE!B33 -> 37 - SALAJ EMILIO | D28: 0.2581902
A29: V40 | B29: =+AVANCE!B28 -> 40 - IBARROLA JORGE | D29: 0.22793248
A30: V52 | B30: =+AVANCE!B13 -> 52 - RAVAROTTO EMANUEL | D30: 0.2342064
A31: V53 | B31: =+AVANCE!B14 -> 53 - SANDOVAL RODRIGO | D31: 0.22565972
A32: V15 | B32: =+AVANCE!B12 -> 15 - GALARZA GERARDO | D32: 0.22561921
A33: V22 | B33: =+AVANCE!B11 -> 22 - ALMIRON NICOLAS | D33: 0.21710224
A34: V7 | B34: =+AVANCE!B35 -> 7 - VALLEJOS EDUARDO | D34: 0.10785648
A35: V32 | B35: =+AVANCE!B25 -> 32 - CABRAL GONZALO | D35: 0.13182137
A36: V57 | B36: =+AVANCE!B36 -> 57 - FEDERRATH MARTIN | D36: 0.17538117

Sheet Venta x Proveedor
A1: Periodos | B1: Código | C1: Descripción | D1: Descripción | E1: Cantidades Totales | F1: Importes Netos
A2: (001) ENE 2026 | B2: 0 | C2: SIN VENDEDOR ASIGNADO | E2: 1919 | F2: 46919362
A3: (001) ENE 2026 | B3: 0 | C3: SIN VENDEDOR ASIGNADO | D3: MASTERFOODS | E3: 1 | F3: 24822.42
A4: (001) ENE 2026 | B4: 1 | C4: VERA ERNESTO | E4: 6 | F4: 37793.64
A5: (001) ENE 2026 | B5: 1 | C5: VERA ERNESTO | D5: ENERGIZER | E5: 40.4806 | F5: 4250769.8
A6: (001) ENE 2026 | B6: 1 | C6: VERA ERNESTO | D6: EST. LAS MARIAS | E6: 133.1917 | F6: 2923447.7
A7: (001) ENE 2026 | B7: 1 | C7: VERA ERNESTO | D7: SUAREZ JORGE LUIS | E7: 5.2417 | F7: 936039.17
A8: (001) ENE 2026 | B8: 1 | C8: VERA ERNESTO | D8: RPB | E8: 628.8333 | F8: 4848055.8
A9: (001) ENE 2026 | B9: 1 | C9: VERA ERNESTO | D9: MAURI | E9: 16.4673 | F9: 262109.93
A10: (001) ENE 2026 | B10: 1 | C10: VERA ERNESTO | D10: DON SATUR | E10: 52.7333 | F10: 895459.08
A11: (001) ENE 2026 | B11: 1 | C11: VERA ERNESTO | D11: LICORES ARG | E11: 2 | F11: 18671.26
A12: (001) ENE 2026 | B12: 1 | C12: VERA ERNESTO | D12: FERRERO | E12: 23.3563 | F12: 2726517.5
A13: (001) ENE 2026 | B13: 1 | C13: VERA ERNESTO | D13: LHERITIER | E13: 6.0417 | F13: 336492.23
A14: (001) ENE 2026 | B14: 1 | C14: VERA ERNESTO | D14: IMP SUDAMERICANA | E14: 0.8467 | F14: 147334.43
A15: (001) ENE 2026 | B15: 1 | C15: VERA ERNESTO | D15: FELFORT | E15: 3.625 | F15: 829501.06
A16: (001) ENE 2026 | B16: 1 | C16: VERA ERNESTO | D16: ARCOR | E16: 58.2127 | F16: 1272173.3
... A30: (001) ENE 2026 | B30: 1 | C30: VERA ERNESTO | D30: LORCA | E30: 0.3333 | F30: 10402
A31: (001) ENE 2026 | B31: 2 | C31: OJEDA NORBERTO | E31: 7.925 | F31: 187180.78
A32: (001) ENE 2026 | B32: 2 | C32: OJEDA NORBERTO | D32: ENERGIZER | E32: 18.9958 | F32: 2552286.2
A33: (001) ENE 2026 | B33: 2 | C33: OJEDA NORBERTO | D33: EST. LAS MARIAS | E33: 66.1111 | F33: 1191432.2
A34: (001) ENE 2026 | B34: 2 | C34: OJEDA NORBERTO | D34: SUAREZ JORGE LUIS | E34: 4.8833 | F34: 1068622.6
A35: (001) ENE 2026 | B35: 2 | C35: OJEDA NORBERTO | D35: RPB | E35: 428.1806 | F35: 3164375.6
A36: (001) ENE 2026 | B36: 2 | C36: OJEDA NORBERTO | D36: MAURI | E36: 10.8333 | F36: 165082.67
A37: (001) ENE 2026 | B37: 2 | C37: OJEDA NORBERTO | D37: DON SATUR | E37: 89.1833 | F37: 1497743.4
A38: (001) ENE 2026 | B38: 2 | C38: OJEDA NORBERTO | D38: LICORES ARG | E38: 0.1667 | F38: 3489.24
A39: (001) ENE 2026 | B39: 2 | C39: OJEDA NORBERTO | D39: FERRERO | E39: 13.852 | F39: 1711067.3
A40: (001) ENE 2026 | B40: 2 | C40: OJEDA NORBERTO | D40: LHERITIER | E40: 1.7708 | F40: 139442.54
A41: (001) ENE 2026 | B41: 2 | C41: OJEDA NORBERTO | D41: IMP SUDAMERICANA | E41: 1.7333 | F41: 226935.37
A42: (001) ENE 2026 | B42: 2 | C42: OJEDA NORBERTO | D42: FELFORT | E42: 0.9167 | F42: 224000.22
A43: (001) ENE 2026 | B43: 2 | C43: OJEDA NORBERTO | D43: ARCOR | E43: 17.3294 | F43: 427306.59
... A57: (001) ENE 2026 | B57: 2 | C57: OJEDA NORBERTO | D57: CRESCINI | E57: 1.5 | F57: 16851.24
A58: (001) ENE 2026 | B58: 3 | C58: VIDAL NAHUEL | E58: 13.4167 | F58: 258607.75
A59: (001) ENE 2026 | B59: 3 | C59: VIDAL NAHUEL | D59: ENERGIZER | E59: 14.05 | F59: 1730161.2
A60: (001) ENE 2026 | B60: 3 | C60: VIDAL NAHUEL | D60: EST. LAS MARIAS | E60: 49.0778 | F60: 703611.83
A61: (001) ENE 2026 | B61: 3 | C61: VIDAL NAHUEL | D61: SUAREZ JORGE LUIS | E61: 1.8375 | F61: 485440.34
A62: (001) ENE 2026 | B62: 3 | C62: VIDAL NAHUEL | D62: RPB | E62: 411.2361 | F62: 3460577.8
A63: (001) ENE 2026 | B63: 3 | C63: VIDAL NAHUEL | D63: MAURI | E63: 23.6964 | F63: 384701.96
A64: (001) ENE 2026 | B64: 3 | C64: VIDAL NAHUEL | D64: DON SATUR | E64: 41.15 | F64: 672930.04
A65: (001) ENE 2026 | B65: 3 | C65: VIDAL NAHUEL | D65: LICORES ARG | E65: 14.1667 | F65: 147061.86
A66: (001) ENE 2026 | B66: 3 | C66: VIDAL NAHUEL | D66: FERRERO | E66: 3.375 | F66: 477425.5
...

Sheet Historico Enero
A1: VENDEDOR/ SUPERVISOR | B1: OBJETIVO | C1: FACTURACION ACUMULADA | D1: FACTURACION N-1 | E1: FACTURACION DEL DIA | F1: AVANCE VS OBJETIVO | G1: PROYECCION | H1: CUMPLIMIENTO PROYECTADO | I1: MEDIA REAL | J1: MEDIA NECESARIA | K1: COBRO | N1: VENDEDOR/ SUPERVISOR | O1: COBERTURA TOTAL | P1: DIA ANTERIOR | Q1: INCREMENTO DIARIO | R1: CARTERA TOTAL | S1: CCC | T1: CCC FALTANTE 85%
A2: 20 - FLORES JAVIER | B2: 28001295 | C2: 32969064 | D2: 0 | E2: 32969064 | F2: 1.1774121 | G2: 32969064 | H2: 1.1774121 | I2: 1268040.9 | J2: #DIV/0! | K2: 659381.28 | M2: 22 | N2: 22 - ALMIRON NICOLAS | O2: 0.79411765 | P2: 33 | Q2: 21 | R2: 68 | S2: 54 | T2: 3.8
A3: 19 - GONZALEZ MARCELO | B3: 26876745 | C3: 29130365 | D3: 0 | E3: 29130365 | F3: 1.0838502 | G3: 29130365 | H3: 1.0838502 | I3: 1120398.6 | J3: #DIV/0! | K3: 364129.56 | M3: 49 | N3: 49 - ESCOBAR RAÚL | O3: 0.45493562 | P3: 1 | Q3: 105 | R3: 233 | S3: 106 | T3: 92.05
A4: 16 - GOMEZ MATÍAS | B4: 24627645 | C4: 20258834 | D4: 0 | E4: 20258834 | F4: 0.82260539 | G4: 20258834 | H4: 0.82260539 | I4: 779185.91 | J4: #DIV/0! | K4: 0 | M4: 20 | N4: 20 - FLORES JAVIER | O4: 0.91891892 | P4: 126 | Q4: 78 | R4: 222 | S4: 204 | T4: -15.3
A5: 12 - GUTIERREZ MARCOS DAVID | B5: 24627645 | C5: 26537938 | D5: 0 | E5: 26537938 | F5: 1.077567 | G5: 26537938 | H5: 1.077567 | I5: 1020689.9 | J5: #DIV/0! | K5: 331724.23 | M5: 15 | N5: 15 - GALARZA GERARDO | O5: 0.78461538 | P5: 21 | Q5: 30 | R5: 65 | S5: 51 | T5: 4.25
A6: 11 - ZACARIAS DAVID | B6: 20410582 | C6: 17576103 | D6: 0 | E6: 17576103 | F6: 0.86112695 | G6: 17576103 | H6: 0.86112695 | I6: 676003.95 | J6: #DIV/0! | K6: 0 | M6: 19 | N6: 19 - GONZALEZ MARCELO | O6: 0.85784314 | P6: 100 | Q6: 75 | R6: 204 | S6: 175 | T6: -1.6
A7: 8 - RAVAROTTO EMANUEL | B7: 24065370 | C7: 24383409 | D7: 0 | E7: 24383409 | F7: 1.0132156 | G7: 24383409 | H7: 1.0132156 | I7: 937823.42 | J7: #DIV/0! | K7: 243834.09 | M7: 16 | N7: 16 - GOMEZ MATÍAS | O7: 0.87309645 | P7: 81 | Q7: 91 | R7: 197 | S7: 172 | T7: -4.55
A8: 5 - SCHELOVER RAUL | B8: 31082562 | C8: 32899445 | D8: 0 | E8: 32899445 | F8: 1.0584534 | G8: 32899445 | H8: 1.0584534 | I8: 1265363.3 | J8: #DIV/0! | K8: 411243.06 | M8: 12 | N8: 12 - GUTIERREZ MARCOS DAVID | O8: 0.89952153 | P8: 89 | Q8: 99 | R8: 209 | S8: 188 | T8: -10.35
A9: 4 - TUR SPRINGER FERNANDO | B9: 31082562 | C9: 30879202 | D9: 0 | E9: 30879202 | F9: 0.99345741 | G9: 30879202 | H9: 0.99345741 | I9: 1187661.6 | J9: #DIV/0! | K9: 308792.02 | M9: 11 | N9: 11 - ZACARIAS DAVID | O9: 0.90797546 | P9: 92 | Q9: 56 | R9: 163 | S9: 148 | T9: -9.45
A10: MARTIN (SUPERVISOR) PREVENTA | B10: 2.1077441e+08 | C10: 2.1463436e+08 | D10: 0 | E10: 2.1463436e+08 | F10: 1.0183132 | G10: 2.1463436e+08 | H10: 1.0183132 | I10: 8255167.6 | J10: #DIV/0! | M10: 8 | N10: 8 - RAVAROTTO EMANUEL | O10: 0.83243243 | P10: 64 | Q10: 90 | R10: 185 | S10: 154 | T10: 3.25
A11: 22 - ALMIRON NICOLAS | B11: 84120750 | C11: 64387272 | D11: 0 | E11: 64387272 | F11: 0.76541486 | G11: 64387272 | H11: 0.76541486 | I11: 2476433.5 | J11: #DIV/0! | K11: 0 | M11: 52 | N11: 52 - MARSALL NICOLAS | O11: 0.52884615 | P11: 19 | Q11: 36 | R11: 104 | S11: 55 | T11: 33.4
A12: 49 - ESCOBAR RAÚL | B12: 27439020 | C12: 21503764 | D12: 0 | E12: 21503764 | F12: 0.78369285 | G12: 21503764 | H12: 0.78369285 | I12: 827067.84 | J12: #DIV/0! | K12: 0 | M12: 53 | N12: 53 - SANDOVAL RODRIGO | O12: 0.62727273 | P12: 24 | Q12: 45 | R12: 110 | S12: 69 | T12: 24.5
A13: 15 - GALARZA GERARDO | B13: 111352500 | C13: 81948671 | D13: 0 | E13: 81948671 | F13: 0.73593921 | G13: 81948671 | H13: 0.73593921 | I13: 3151872 | J13: #DIV/0! | K13: 0 | M13: 5 | N13: 5 - SCHELOVER RAUL | O13: 0.96484375 | P13: 144 | Q13: 103 | R13: 256 | S13: 247 | T13: -29.4
A14: 52 - MARSALL NICOLAS | B14: 36823500 | C14: 27773182 | D14: 0 | E14: 27773182 | F14: 0.75422438 | G14: 27773182 | H14: 0.75422438 | I14: 1068199.3 | J14: #DIV/0! | K14: 0 | M14: 4 | N14: 4 - TUR SPRINGER FERNANDO | O14: 0.88571429 | P14: 85 | Q14: 70 | R14: 175 | S14: 155 | T14: -6.25
A15: 53 - SANDOVAL RODRIGO | B15: 36823500 | C15: 40412111 | D15: 0 | E15: 40412111 | F15: 1.0974544 | G15: 40412111 | H15: 1.0974544 | I15: 1554312 | J15: #DIV/0! | K15: 606181.66 | N15: MARTIN (SUPERVISOR) | Q15: 899 | R15: 2191 | S15: 1778
A16: MARTIN (SUPERVISOR) | B16: 296559270 | C16: 2.36025e+08 | D16: 0 | E16: 2.36025e+08 | F16: 0.795878 | G16: 2.36025e+08 | H16: 0.795878 | I16: 9077884.6 | J16: #DIV/0! | M16: 31 | N16: 31 - BARTSCHAT EMILIANO NAHUEL | O16: 0.91082803 | P16: 90 | Q16: 53 | R16: 157 | S16: 143 | T16: -9.55
A17: 2 - OJEDA NORBERTO | B17: 25450000 | C17: 16519194 | D17: 0 | E17: 16519194 | F17: 0.64908425 | G17: 16519194 | H17: 0.64908425 | I17: 635353.63 | J17: #DIV/0! | K17: 0 | M17: 54 | N17: 54 - CAÑETE DIEGO | O17: 0.66494845 | P17: 92 | Q17: 37 | R17: 194 | S17: 129 | T17: 35.9
A18: 3 - VIDAL NAHUEL | B18: 22430000 | C18: 14871119 | D18: 0 | E18: 14871119 | F18: 0.66300128 | G18: 14871119 | H18: 0.66300128 | I18: 571966.1 | J18: #DIV/0! | K18: 0 | M18: 21 | N18: 21 - CATAN MATIAS | O18: 0.81097561 | P18: 88 | Q18: 45 | R18: 164 | S18: 133 | T18: 6.4
A19: 18 - HERRERA PABLO | B19: 22430000 | C19: 17383068 | D19: 0 | E19: 17383068 | F19: 0.77499188 | G19: 17383068 | H19: 0.77499188 | I19: 668579.53 | J19: #DIV/0! | K19: 0 | M19: 23 | N19: 23 - DELGADO JOSÉ | O19: 0.91333333 | P19: 95 | Q19: 42 | R19: 150 | S19: 137 | T19: -9.5
A20: 21 - CATAN MATIAS | B20: 29000000 | C20: 24462625 | D20: 0 | E20: 24462625 | F20: 0.84353878 | G20: 24462625 | H20: 0.84353878 | I20: 940870.18 | J20: #DIV/0! | K20: 0 | M20: 18 | N20: 18 - HERRERA PABLO | O20: 0.86046512 | P20: 83 | Q20: 65 | R20: 172 | S20: 148 | T20: -1.8
A21: 23 - DELGADO JOSÉ | B21: 22000000 | C21: 19224921 | D21: 0 | E21: 19224921 | F21: 0.87386003 | G21: 19224921 | H21: 0.87386003 | I21: 739420.02 | J21: #DIV/0! | K21: 0 | M21: 44 | N21: 44 - MONGE CÉSAR LUIS | O21: 0.88505747 | P21: 64 | Q21: 90 | R21: 174 | S21: 154 | T21: -6.1
A22: 31 - BARTSCHAT EMILIANO NAHUEL | B22: 27500000 | C22: 22580286 | D22: 0 | E22: 22580286 | F22: 0.82110133 | G22: 22580286 | H22: 0.82110133 | I22: 868472.56 | J22: #DIV/0! | K22: 0 | M22: 56 | N22: 56 - JUAN ANDRES SANCHEZ | O22: 0.46268657 | P22: 66 | Q22: 27 | R22: 201 | S22: 93 | T22: 77.85
A23: 44 - MONGE CÉSAR LUIS | B23: 23800000 | C23: 18758064 | D23: 0 | E23: 18758064 | F23: 0.78815396 | G23: 18758064 | H23: 0.78815396 | I23: 721464.01 | J23: #DIV/0! | K23: 0 | M23: 2 | N23: 2 - OJEDA NORBERTO | O23: 0.83783784 | P23: 70 | Q23: 54 | R23: 148 | S23: 124 | T23: 1.8
A24: 54 - CAÑETE DIEGO | B24: 28500000 | C24: 25700325 | D24: 0 | E24: 25700325 | F24: 0.9017658 | G24: 25700325 | H24: 0.9017658 | I24: 988474.05 | J24: #DIV/0! | K24: 0 | M24: 3 | N24: 3 - VIDAL NAHUEL | O24: 0.90967742 | P24: 79 | Q24: 62 | R24: 155 | S24: 141 | T24: -9.25
A25: 56 - JUAN ANDRES SANCHEZ | B25: 46900000 | C25: 26132281 | D25: 0 | E25: 26132281 | F25: 0.55719149 | G25: 26132281 | H25: 0.55719149 | I25: 1005087.7 | J25: #DIV/0! | K25: 0 | N25: CRISTIAN (SUPERVISOR) | Q25: 475 | R25: 1515 | S25: 1202
A26: CRISTIAN (SUPERVISOR) | B26: 248010000 | C26: 1.8563188e+08 | D26: 0 | E26: 1.8563188e+08 | F26: 0.74848548 | G26: 1.8563188e+08 | H26: 0.74848548 | I26: 7139687.8 | J26: #DIV/0! | M26: 32 | N26: 32 - BLANCO FERNANDO | O26: 0.83636364 | P26: 20 | Q26: 26 | R26: 55 | S26: 46 | T26: 0.75
A27: 32 - BLANCO FERNANDO | B27: 72908794 | C27: 59705699 | D27: 0 | E27: 59705699 | F27: 0.81890944 | G27: 59705699 | H27: 0.81890944 | I27: 2296373.1 | J27: #DIV/0! | K27: 0 | M27: 36 | N27: 36 - STELLA MARIS CANO | O27: 0.64705882 | P27: 68 | Q27: 31 | R27: 153 | S27: 99 | T27: 31.05
A28: 36 - STELLA MARIS CANO | B28: 20300095 | C28: 7088486.6 | D28: 0 | E28: 7088486.6 | F28: 0.34918489 | G28: 7088486.6 | H28: 0.34918489 | I28: 272634.1 | J28: #DIV/0! | K28: 0 | M28: 9 | N28: 9 - ESTIGARRIBIA DAVID | O28: 0.7114094 | P28: 80 | Q28: 26 | R28: 149 | S28: 106 | T28: 20.65
A29: 9 - ESTIGARRIBIA DAVID | B29: 21701088 | C29: 11524508 | D29: 0 | E29: 11524508 | F29: 0.53105671 | G29: 11524508 | H29: 0.53105671 | I29: 443250.32 | J29: #DIV/0! | K29: 0 | M29: 40 | N29: 40 - GARCIA BOGARIN SANTIAGO | O29: 0.86666667 | P29: 68 | Q29: 140 | R29: 240 | S29: 208 | T29: -4
A30: 40 - GARCIA BOGARIN SANTIAGO | B30: 33166353 | C30: 32454209 | D30: 0 | E30: 32454209 | F30: 0.97852812 | G30: 32454209 | H30: 0.97852812 | I30: 1248238.8 | J30: #DIV/0! | K30: 0 | M30: 27 | N30: 27 - GOMEZ ADRIÁN | O30: 0.87769784 | P30: 73 | Q30: 49 | R30: 139 | S30: 122 | T30: -3.85
A31: 27 - GOMEZ ADRIÁN | B31: 21701088 | C31: 18178589 | D31: 0 | E31: 18178589 | F31: 0.83768098 | G31: 18178589 | H31: 0.83768098 | I31: 699176.48 | J31: #DIV/0! | K31: 0 | M31: 10 | N31: 10 - SEGOVIA JUAN CRUZ | O31: 0.79558011 | P31: 40 | Q31: 104 | R31: 181 | S31: 144 | T31: 9.85
A32: 10 - SEGOVIA JUAN CRUZ | B32: 21701088 | C32: 22255931 | D32: 0 | E32: 22255931 | F32: 1.0255675 | G32: 22255931 | H32: 1.0255675 | I32: 855997.34 | J32: #DIV/0! | K32: 222559.31 | M32: 28 | N32: 28 - GOMEZ PABLO | O32: 0.87150838 | P32: 67 | Q32: 89 | R32: 179 | S32: 156 | T32: -3.85
A33: 28 - GOMEZ PABLO | B33: 20586012 | C33: 21491454 | D33: 0 | E33: 21491454 | F33: 1.0439834 | G33: 21491454 | H33: 1.0439834 | I33: 826594.39 | J33: #DIV/0! | K33: 268643.18 | M33: 33 | N33: 33 - NICOLAS AZULA | O33: 0.57926829 | P33: 66 | Q33: 29 | R33: 164 | S33: 95 | T33: 44.4
A34: 33 - NICOLAS AZULA | B34: 21701088 | C34: 6604694.9 | D34: 0 | E34: 6604694.9 | F34: 0.30434856 | G34: 6604694.9 | H34: 0.30434856 | I34: 254026.73 | J34: #DIV/0! | K34: 0 | M34: 37 | N34: 37 - PEREZ ESQUIVEL BRUNO NICOLAS | O34: 0.69736842 | P34: 82 | Q34: 24 | R34: 152 | S34: 106 | T34: 23.2
A35: 37 - PEREZ ESQUIVEL BRUNO NICOLAS | B35: 20586012 | C35: 10300686 | D35: 0 | E35: 10300686 | F35: 0.50037307 | G35: 10300686 | H35: 0.50037307 | I35: 396180.23 | J35: #DIV/0! | K35: 0 | M35: 24 | N35: 24 - DELGADO HERNAN GABRIEL | O35: 0.82954545 | P35: 81 | Q35: 65 | R35: 176 | S35: 146 | T35: 3.6
A36: 24 - DELGADO HERNAN GABRIEL | B36: 21729680 | C36: 17015925 | D36: 0 | E36: 17015925 | F36: 0.78307297 | G36: 17015925 | H36: 0.78307297 | I36: 654458.65 | J36: #DIV/0! | K36: 0 | M36: 7 | N36: 7 - VALLEJOS EDUARDO | O36: 0.14414414 | P36: 0 | Q36: 16 | R36: 111 | S36: 16 | T36: 78.35
A37: 7 - VALLEJOS EDUARDO | B37: 1.0293006e+08 | C37: 71043541 | D37: 0 | E37: 71043541 | F37: 0.69021178 | G37: 71043541 | H37: 0.69021178 | I37: 2732443.9 | J37: #DIV/0! | K37: 0 | M37: 57 | N37: 57 - ZARATE NICOLAS | O37: 0.5 | P37: 17 | Q37: 35 | R37: 104 | S37: 52 | T37: 36.4
