Workbook

Sheet COMISIONES
A1: VENDEDOR | B1: SUCURSAL | C1: BULTOS | D1: UNIDAD DE MEDIDA | E1: IMPORTE | F1: COMISIÓN POR IMPORTE FIJO | G1: COMISIÓN POR PORCENTAJE | H1: COMISIÓN TOTAL
A2: 0 - TODOS LOS VENDEDORES | B2: 0 | C2: 54574.052 | D2: 224435.59 | E2: 1.0289274e+09 | F2: 0 | G2: 507412.79 | H2: 507413.02
A3: 1 - VERA ERNESTO | B3: 1 | C3: 704.0581 | D3: 932.73412 | E3: 16929650 | F3: 0 | G3: 507412.79 | H3: 507413.02
A4: 2 - OJEDA NORBERTO | B4: 1 | C4: 482.22445 | D4: 936.58011 | E4: 11770812 | F4: 0 | G4: 0 | H4: 0
A5: 3 - VIDAL NAHUEL | B5: 1 | C5: 627.07157 | D5: 1780.0921 | E5: 15346417 | F5: 0 | G5: 0 | H5: 0
A6: 4 - TUR SPRINGER FERNANDO | B6: 1 | C6: 1097.0714 | D6: 2295.7363 | E6: 23827606 | F6: 0 | G6: 0 | H6: 0
A7: 5 - SCHELOVER RAUL | B7: 1 | C7: 981.78474 | D7: 2943.9223 | E7: 23105351 | F7: 0 | G7: 0 | H7: 0
A8: 7 - VALLEJOS EDUARDO | B8: 1 | C8: 3264.0583 | D8: 8309.155 | E8: 48362192 | F8: 0 | G8: 0 | H8: 0
A9: 8 - PARRA MAXIMILIANO | B9: 1 | C9: 433.49066 | D9: 1150.8363 | E9: 9731445 | F9: 0 | G9: 0 | H9: 0
A10: 9 - ESTIGARRIBIA DAVID | B10: 1 | C10: 597.21337 | D10: 1355.8538 | E10: 13643333 | F10: 0 | G10: 0 | H10: 0
A11: 10 - BRITEZ EMMANUEL | B11: 1 | C11: 945.16389 | D11: 1014.7551 | E11: 12863939 | F11: 0 | G11: 0 | H11: 0
A12: 11 - SANCHEZ RICARDO | B12: 1 | C12: 710.88337 | D12: 1479.45 | E12: 13292647 | F12: 0 | G12: 0 | H12: 0
A13: 12 - GUTIERREZ MARCOS DAVID | B13: 1 | C13: 672.70006 | D13: 1845.5377 | E13: 15491414 | F13: 0 | G13: 0 | H13: 0
... A47: 123 - TORRES ROLANDO | B47: 1 | C47: 970.99603 | D47: 3224.08 | E47: 29772171 | F47: 0 | G47: 0 | H47: 0

Sheet AVANCE
A1: SUPERVISOR | B1: VENDEDOR | C1: OBJETIVO | D1: FACTURACION ACUMULADA | E1: FACTURACION N-1 | F1: FACTURACION DEL DIA | G1: AVANCE VS OBJETIVO | H1: PROYECCION | I1: CUMPLIMIENTO PROYECTADO | J1: MEDIA REAL | K1: MEDIA NECESARIA | L1: COBRO
A2: MARTIN PREVENTA | B2: 20 - FLORES JAVIER | C2: 32924658 | D2: =IFERROR(+VLOOKUP(B2,COMISIONES!A:E,5,FALSE),"0")*1 -> 28322793 | E2: 26743816 | F2: =+D2-E2 -> 1578977.7 | G2: =+D2/C2 -> 0.86023045 | H2: =+D2/$N$3*$N$4 -> 47204656 | I2: =+H2/C2 -> 1.4337174 | J2: =+D2/$N$3 -> 1888186.2 | K2: =+(C2-D2)/$N$2 -> 460186.47 | L2: {=+_xlfn.IFS(I2>114%,H2*0.02,I2>109%,H2*0.015,I2>104%,H2*0.0125,I2>99%,H2*0.01,I2<99%,H2*0)} -> 944093.12 | M2: DIAS DE TRABAJO RESTANTES | N2: 10
B3: 19 - GONZALEZ MARCELO | C3: 31602383 | D3: =IFERROR(+VLOOKUP(B3,COMISIONES!A:E,5,FALSE),"0")*1 -> 22706451 | E3: 20734022 | F3: =+D3-E3 -> 1972428.4 | G3: =+D3/C3 -> 0.7185044 | H3: =+D3/$N$3*$N$4 -> 37844085 | I3: =+H3/C3 -> 1.1975073 | J3: =+D3/$N$3 -> 1513763.4 | K3: =+(C3-D3)/$N$2 -> 889593.18 | L3: {=+_xlfn.IFS(I3>114%,H3*0.02,I3>109%,H3*0.015,I3>104%,H3*0.0125,I3>99%,H3*0.01,I3<99%,H3*0)} -> 756881.7 | M3: DIAS TRABAJADOS | N3: =N4-N2 -> 15
B4: 16 - GOMEZ MATÍAS | C4: 28957832 | D4: =IFERROR(+VLOOKUP(B4,COMISIONES!A:E,5,FALSE),"0")*1 -> 14365603 | E4: 14016960 | F4: =+D4-E4 -> 348642.76 | G4: =+D4/C4 -> 0.49608696 | H4: =+D4/$N$3*$N$4 -> 23942671 | I4: =+H4/C4 -> 0.8268116 | J4: =+D4/$N$3 -> 957706.85 | K4: =+(C4-D4)/$N$2 -> 1459222.9 | L4: {=+_xlfn.IFS(I4>114%,H4*0.02,I4>109%,H4*0.015,I4>104%,H4*0.0125,I4>99%,H4*0.01,I4<99%,H4*0)} -> 0 | M4: DIAS DE TRABAJO MES | N4: 25
B5: 12 - GUTIERREZ MARCOS DAVID | C5: 28957832 | D5: =IFERROR(+VLOOKUP(B5,COMISIONES!A:E,5,FALSE),"0")*1 -> 15491414 | E5: 14531981 | F5: =+D5-E5 -> 959432.73 | G5: =+D5/C5 -> 0.53496455 | H5: =+D5/$N$3*$N$4 -> 25819023 | I5: =+H5/C5 -> 0.89160759 | J5: =+D5/$N$3 -> 1032760.9 | K5: =+(C5-D5)/$N$2 -> 1346641.8 | L5: {=+_xlfn.IFS(I5>114%,H5*0.02,I5>109%,H5*0.015,I5>104%,H5*0.0125,I5>99%,H5*0.01,I5<99%,H5*0)} -> 0
B6: 11 - SANCHEZ RICARDO | C6: 23999299 | D6: =IFERROR(+VLOOKUP(B6,COMISIONES!A:E,5,FALSE),"0")*1 -> 13292647 | E6: 12129118 | F6: =+D6-E6 -> 1163528.9 | G6: =+D6/C6 -> 0.55387646 | H6: =+D6/$N$3*$N$4 -> 22154411 | I6: =+H6/C6 -> 0.92312743 | J6: =+D6/$N$3 -> 886176.44 | K6: =+(C6-D6)/$N$2 -> 1070665.2 | L6: {=+_xlfn.IFS(I6>114%,H6*0.02,I6>109%,H6*0.015,I6>104%,H6*0.0125,I6>99%,H6*0.01,I6<99%,H6*0)} -> 0
B7: 8 - PARRA MAXIMILIANO | C7: 28296694 | D7: =IFERROR(+VLOOKUP(B7,COMISIONES!A:E,5,FALSE),"0")*1 -> 9731445 | E7: 8991012.2 | F7: =+D7-E7 -> 740432.82 | G7: =+D7/C7 -> 0.34390749 | H7: =+D7/$N$3*$N$4 -> 16219075 | I7: =+H7/C7 -> 0.57317915 | J7: =+D7/$N$3 -> 648763 | K7: =+(C7-D7)/$N$2 -> 1856524.9 | L7: {=+_xlfn.IFS(I7>114%,H7*0.02,I7>109%,H7*0.015,I7>104%,H7*0.0125,I7>99%,H7*0.01,I7<99%,H7*0)} -> 0
B8: 5 - SCHELOVER RAUL | C8: 36547693 | D8: =IFERROR(+VLOOKUP(B8,COMISIONES!A:E,5,FALSE),"0")*1 -> 23105351 | E8: 20622326 | F8: =+D8-E8 -> 2483024.7 | G8: =+D8/C8 -> 0.63219724 | H8: =+D8/$N$3*$N$4 -> 38508918 | I8: =+H8/C8 -> 1.0536621 | J8: =+D8/$N$3 -> 1540356.7 | K8: =+(C8-D8)/$N$2 -> 1344234.2 | L8: {=+_xlfn.IFS(I8>114%,H8*0.02,I8>109%,H8*0.015,I8>104%,H8*0.0125,I8>99%,H8*0.01,I8<99%,H8*0)} -> 481361.47
B9: 4 - TUR SPRINGER FERNANDO | C9: 36547693 | D9: =IFERROR(+VLOOKUP(B9,COMISIONES!A:E,5,FALSE),"0")*1 -> 23827606 | E9: 22061974 | F9: =+D9-E9 -> 1765631.8 | G9: =+D9/C9 -> 0.65195923 | H9: =+D9/$N$3*$N$4 -> 39712676 | I9: =+H9/C9 -> 1.0865987 | J9: =+D9/$N$3 -> 1588507.1 | K9: =+(C9-D9)/$N$2 -> 1272008.7 | L9: {=+_xlfn.IFS(I9>114%,H9*0.02,I9>109%,H9*0.015,I9>104%,H9*0.0125,I9>99%,H9*0.01,I9<99%,H9*0)} -> 496408.45
C10: 247834083 | D10: =+SUM(D2:D9) -> 1.5084331e+08 | E10: 1.3983121e+08 | F10: =+D10-E10 -> 11012100 | G10: =+D10/C10 -> 0.60864635 | H10: =+D10/$N$3*$N$4 -> 2.5140551e+08 | I10: =+H10/C10 -> 1.0144106 | J10: =+D10/$N$3 -> 10056221 | K10: =+(C10-D10)/$N$2 -> 9699077.4
A11: MARTIN | B11: 22 - ALMIRON NICOLAS | C11: 98911387 | D11: =IFERROR(+VLOOKUP(B11,COMISIONES!A:E,5,FALSE),"0")*1 -> 64346819 | E11: 59234561 | F11: =+D11-E11 -> 5112258.8 | G11: =+D11/C11 -> 0.65055016 | H11: =+D11/$N$3*$N$4 -> 1.072447e+08 | I11: =+H11/C11 -> 1.0842503 | J11: =+D11/$N$3 -> 4289788 | K11: =+(C11-D11)/$N$2 -> 3456456.8 | L11: {=+_xlfn.IFS(I11>114%,H11*0.0125,I11>109%,H11*0.01,I11>104%,H11*0.0075,I11>99%,H11*0.005,I11<99%,H11*0)} -> 804335.24
B12: 15 - GALARZA GERARDO | C12: 1.3093119e+08 | D12: =IFERROR(+VLOOKUP(B12,COMISIONES!A:E,5,FALSE),"0")*1 -> 68490623 | E12: 47060597 | F12: =+D12-E12 -> 21430026 | G12: =+D12/C12 -> 0.52310393 | H12: =+D12/$N$3*$N$4 -> 1.1415104e+08 | I12: =+H12/C12 -> 0.87183989 | J12: =+D12/$N$3 -> 4566041.5 | K12: =+(C12-D12)/$N$2 -> 6244057.1 | L12: {=+_xlfn.IFS(I12>114%,H12*0.0125,I12>109%,H12*0.01,I12>104%,H12*0.0075,I12>99%,H12*0.005,I12<99%,H12*0)} -> 0 | M12: AUMENTO OBJ | N12: 0.02
B13: 52 - RAVAROTTO EMANUEL | C13: 43298039 | D13: =IFERROR(+VLOOKUP(B13,COMISIONES!A:E,5,FALSE),"0")*1 -> 32574968 | E13: 31854806 | F13: =+D13-E13 -> 720161.8 | G13: =+D13/C13 -> 0.75234282 | H13: =+D13/$N$3*$N$4 -> 54291614 | I13: =+H13/C13 -> 1.2539047 | J13: =+D13/$N$3 -> 2171664.5 | K13: =+(C13-D13)/$N$2 -> 1072307 | L13: {=+_xlfn.IFS(I13>109%,H13*0.015,I13>104%,H13*0.0125,I13>99%,H13*0.01,I13<99%,H13*0)} -> 814374.21
B14: 53 - SANDOVAL RODRIGO | C14: 43298039 | D14: =IFERROR(+VLOOKUP(B14,COMISIONES!A:E,5,FALSE),"0")*1 -> 23026728 | E14: 22420218 | F14: =+D14-E14 -> 606510.87 | G14: =+D14/C14 -> 0.5318192 | H14: =+D14/$N$3*$N$4 -> 38377881 | I14: =+H14/C14 -> 0.88636534 | J14: =+D14/$N$3 -> 1535115.2 | K14: =+(C14-D14)/$N$2 -> 2027131 | L14: {=+_xlfn.IFS(I14>109%,H14*0.015,I14>104%,H14*0.0125,I14>99%,H14*0.01,I14<99%,H14*0)} -> 0
C15: 348702179 | D15: =+SUM(D11:D14) -> 1.8843914e+08 | E15: 1.6057018e+08 | F15: =+D15-E15 -> 27868957 | G15: =+D15/C15 -> 0.54040138 | H15: =+D15/$N$3*$N$4 -> 3.1406523e+08 | I15: =+H15/C15 -> 0.90066897 | J15: =+D15/$N$3 -> 12562609 | K15: =+(C15-D15)/$N$2 -> 16026304
A16: CRISTIAN | B16: 2 - OJEDA NORBERTO | C16: 28000000 | D16: =IFERROR(+VLOOKUP(B16,COMISIONES!A:E,5,FALSE),"0")*1 -> 11770812 | E16: 11093442 | F16: =+D16-E16 -> 677369.74 | G16: =+D16/C16 -> 0.42038615 | H16: =+D16/$N$3*$N$4 -> 19618020 | I16: =+H16/C16 -> 0.70064358 | J16: =+D16/$N$3 -> 784720.81 | K16: =+(C16-D16)/$N$2 -> 1622918.8 | L16: {=+_xlfn.IFS(I16>114%,H16*0.02,I16>109%,H16*0.015,I16>104%,H16*0.0125,I16>99%,H16*0.01,I16<99%,H16*0)} -> 0
B17: 3 - VIDAL NAHUEL | C17: 25660000 | D17: =IFERROR(+VLOOKUP(B17,COMISIONES!A:E,5,FALSE),"0")*1 -> 15346417 | E17: 13782062 | F17: =+D17-E17 -> 1564354.7 | G17: =+D17/C17 -> 0.5980677 | H17: =+D17/$N$3*$N$4 -> 25577362 | I17: =+H17/C17 -> 0.9967795 | J17: =+D17/$N$3 -> 1023094.5 | K17: =+(C17-D17)/$N$2 -> 1031358.3 | L17: {=+_xlfn.IFS(I17>114%,H17*0.02,I17>109%,H17*0.015,I17>104%,H17*0.0125,I17>99%,H17*0.01,I17<99%,H17*0)} -> 255773.62
B18: 18 - HERRERA PABLO | C18: 26020000 | D18: =IFERROR(+VLOOKUP(B18,COMISIONES!A:E,5,FALSE),"0")*1 -> 11907565 | E18: 10146098 | F18: =+D18-E18 -> 1761466.1 | G18: =+D18/C18 -> 0.45763123 | H18: =+D18/$N$3*$N$4 -> 19845941 | I18: =+H18/C18 -> 0.76271871 | J18: =+D18/$N$3 -> 793837.64 | K18: =+(C18-D18)/$N$2 -> 1411243.5 | L18: {=+_xlfn.IFS(I18>114%,H18*0.02,I18>109%,H18*0.015,I18>104%,H18*0.0125,I18>99%,H18*0.01,I18<99%,H18*0)} -> 0
B19: 21 - CATAN MATIAS | C19: 36200600 | D19: =IFERROR(+VLOOKUP(B19,COMISIONES!A:E,5,FALSE),"0")*1 -> 23569603 | E19: 21883676 | F19: =+D19-E19 -> 1685926.9 | G19: =+D19/C19 -> 0.65108322 | H19: =+D19/$N$3*$N$4 -> 39282672 | I19: =+H19/C19 -> 1.0851387 | J19: =+D19/$N$3 -> 1571306.9 | K19: =+(C19-D19)/$N$2 -> 1263099.7 | L19: {=+_xlfn.IFS(I19>114%,H19*0.02,I19>109%,H19*0.015,I19>104%,H19*0.0125,I19>99%,H19*0.01,I19<99%,H19*0)} -> 491033.4
B20: 23 - DELGADO JOSÉ | C20: 26622000 | D20: =IFERROR(+VLOOKUP(B20,COMISIONES!A:E,5,FALSE),"0")*1 -> 14248827 | E20: 13568788 | F20: =+D20-E20 -> 680038.97 | G20: =+D20/C20 -> 0.53522752 | H20: =+D20/$N$3*$N$4 -> 23748045 | I20: =+H20/C20 -> 0.89204587 | J20: =+D20/$N$3 -> 949921.8 | K20: =+(C20-D20)/$N$2 -> 1237317.3 | L20: {=+_xlfn.IFS(I20>114%,H20*0.02,I20>109%,H20*0.015,I20>104%,H20*0.0125,I20>99%,H20*0.01,I20<99%,H20*0)} -> 0
B21: 31 - RENZO RAMOS | C21: 33260000 | D21: =IFERROR(+VLOOKUP(B21,COMISIONES!A:E,5,FALSE),"0")*1 -> 15433479 | E21: 14802944 | F21: =+D21-E21 -> 630534.68 | G21: =+D21/C21 -> 0.46402522 | H21: =+D21/$N$3*$N$4 -> 25722465 | I21: =+H21/C21 -> 0.77337537 | J21: =+D21/$N$3 -> 1028898.6 | K21: =+(C21-D21)/$N$2 -> 1782652.1 | L21: {=+_xlfn.IFS(I21>114%,H21*0.02,I21>109%,H21*0.015,I21>104%,H21*0.0125,I21>99%,H21*0.01,I21<99%,H21*0)} -> 0
B22: 44 - MONGES CESAR LUIS | C22: 28620000 | D22: =IFERROR(+VLOOKUP(B22,COMISIONES!A:E,5,FALSE),"0")*1 -> 16682119 | E22: 15736299 | F22: =+D22-E22 -> 945820.33 | G22: =+D22/C22 -> 0.58288327 | H22: =+D22/$N$3*$N$4 -> 27803532 | I22: =+H22/C22 -> 0.97147211 | J22: =+D22/$N$3 -> 1112141.3 | K22: =+(C22-D22)/$N$2 -> 1193788.1 | L22: {=+_xlfn.IFS(I22>114%,H22*0.02,I22>109%,H22*0.015,I22>104%,H22*0.0125,I22>99%,H22*0.01,I22<99%,H22*0)} -> 0
B23: 54 - BARTSCHAT EMILIANO NAHUEL | C23: 38000000 | D23: =IFERROR(+VLOOKUP(B23,COMISIONES!A:E,5,FALSE),"0")*1 -> 26057029 | E23: 25426377 | F23: =+D23-E23 -> 630651.83 | G23: =+D23/C23 -> 0.68571129 | H23: =+D23/$N$3*$N$4 -> 43428382 | I23: =+H23/C23 -> 1.1428521 | J23: =+D23/$N$3 -> 1737135.3 | K23: =+(C23-D23)/$N$2 -> 1194297.1 | L23: {=+_xlfn.IFS(I23>114%,H23*0.02,I23>109%,H23*0.015,I23>104%,H23*0.0125,I23>99%,H23*0.01,I23<99%,H23*0)} -> 868567.63
C24: 242382600 | D24: =+SUM(D16:D23) -> 1.3501585e+08 | E24: 1.2643969e+08 | F24: =+D24-E24 -> 8576163.3 | G24: =+D24/C24 -> 0.55703607 | H24: =+D24/$N$3*$N$4 -> 2.2502642e+08 | I24: =+H24/C24 -> 0.92839345 | J24: =+D24/$N$3 -> 9001056.7 | K24: =+(C24-D24)/$N$2 -> 10736675
A25: GONZALO | B25: 32 - CABRAL GONZALO | C25: 86547956 | D25: =IFERROR(+VLOOKUP(B25,COMISIONES!A:E,5,FALSE),"0")*1 -> 33204549 | E25: 30074670 | F25: =+D25-E25 -> 3129879.3 | G25: =+D25/C25 -> 0.38365492 | H25: =+D25/$N$3*$N$4 -> 55340916 | I25: =+H25/C25 -> 0.63942487 | J25: =+D25/$N$3 -> 2213636.6 | K25: =+(C25-D25)/$N$2 -> 5334340.7 | L25: {=+_xlfn.IFS(I25>114%,H25*0.0125,I25>109%,H25*0.01,I25>104%,H25*0.0075,I25>99%,H25*0.005,I25<99%,H25*0)} -> 0
B26: 36 - COSARINSKI DIEGO | C26: 24010803 | D26: =IFERROR(+VLOOKUP(B26,COMISIONES!A:E,5,FALSE),"0")*1 -> 8521275.8 | E26: 8468506 | F26: =+D26-E26 -> 52769.751 | G26: =+D26/C26 -> 0.3548934 | H26: =+D26/$N$3*$N$4 -> 14202126 | I26: =+H26/C26 -> 0.59148901 | J26: =+D26/$N$3 -> 568085.05 | K26: =+(C26-D26)/$N$2 -> 1548952.8 | L26: {=+_xlfn.IFS(I26>114%,H26*0.02,I26>109%,H26*0.015,I26>104%,H26*0.0125,I26>99%,H26*0.01,I26<99%,H26*0)} -> 0
B27: 9 - ESTIGARRIBIA DAVID | C27: 26910856 | D27: =IFERROR(+VLOOKUP(B27,COMISIONES!A:E,5,FALSE),"0")*1 -> 13643333 | E27: 12565199 | F27: =+D27-E27 -> 1078134.1 | G27: =+D27/C27 -> 0.50698249 | H27: =+D27/$N$3*$N$4 -> 22738888 | I27: =+H27/C27 -> 0.84497082 | J27: =+D27/$N$3 -> 909555.54 | K27: =+(C27-D27)/$N$2 -> 1326752.3 | L27: {=+_xlfn.IFS(I27>114%,H27*0.02,I27>109%,H27*0.015,I27>104%,H27*0.0125,I27>99%,H27*0.01,I27<99%,H27*0)} -> 0
B28: 40 - IBARROLA JORGE | C28: 39189035 | D28: =IFERROR(+VLOOKUP(B28,COMISIONES!A:E,5,FALSE),"0")*1 -> 13977900 | E28: 13597035 | F28: =+D28-E28 -> 380865.83 | G28: =+D28/C28 -> 0.35667886 | H28: =+D28/$N$3*$N$4 -> 23296501 | I28: =+H28/C28 -> 0.59446477 | J28: =+D28/$N$3 -> 931860.03 | K28: =+(C28-D28)/$N$2 -> 2521113.5 | L28: {=+_xlfn.IFS(I28>114%,H28*0.02,I28>109%,H28*0.015,I28>104%,H28*0.0125,I28>99%,H28*0.01,I28<99%,H28*0)} -> 0
B29: 27 - GOMEZ ADRIÁN | C29: 26900000 | D29: =IFERROR(+VLOOKUP(B29,COMISIONES!A:E,5,FALSE),"0")*1 -> 17611618 | E29: 16339982 | F29: =+D29-E29 -> 1271635.9 | G29: =+D29/C29 -> 0.65470698 | H29: =+D29/$N$3*$N$4 -> 29352696 | I29: =+H29/C29 -> 1.0911783 | J29: =+D29/$N$3 -> 1174107.9 | K29: =+(C29-D29)/$N$2 -> 928838.22 | L29: {=+_xlfn.IFS(I29>114%,H29*0.02,I29>109%,H29*0.015,I29>104%,H29*0.0125,I29>99%,H29*0.01,I29<99%,H29*0)} -> 440290.45
B30: 10 - BRITEZ EMMANUEL | C30: 25830000 | D30: =IFERROR(+VLOOKUP(B30,COMISIONES!A:E,5,FALSE),"0")*1 -> 12863939 | E30: 12120550 | F30: =+D30-E30 -> 743389.57 | G30: =+D30/C30 -> 0.4980232 | H30: =+D30/$N$3*$N$4 -> 21439899 | I30: =+H30/C30 -> 0.83003867 | J30: =+D30/$N$3 -> 857595.96 | K30: =+(C30-D30)/$N$2 -> 1296606.1 | L30: {=+_xlfn.IFS(I30>114%,H30*0.02,I30>109%,H30*0.015,I30>104%,H30*0.0125,I30>99%,H30*0.01,I30<99%,H30*0)} -> 0
B31: 28 - GOMEZ PABLO | C31: 27702000 | D31: =IFERROR(+VLOOKUP(B31,COMISIONES!A:E,5,FALSE),"0")*1 -> 8994450.6 | E31: 7979618.5 | F31: =+D31-E31 -> 1014832.1 | G31: =+D31/C31 -> 0.32468596 | H31: =+D31/$N$3*$N$4 -> 14990751 | I31: =+H31/C31 -> 0.54114327 | J31: =+D31/$N$3 -> 599630.04 | K31: =+(C31-D31)/$N$2 -> 1870754.9 | L31: {=+_xlfn.IFS(I31>114%,H31*0.02,I31>109%,H31*0.015,I31>104%,H31*0.0125,I31>99%,H31*0.01,I31<99%,H31*0)} -> 0
B32: 33 - NICOLAS AZULA | C32: 24010803 | D32: =IFERROR(+VLOOKUP(B32,COMISIONES!A:E,5,FALSE),"0")*1 -> 8686686.9 | E32: 8052823.5 | F32: =+D32-E32 -> 633863.41 | G32: =+D32/C32 -> 0.36178244 | H32: =+D32/$N$3*$N$4 -> 14477812 | I32: =+H32/C32 -> 0.60297073 | J32: =+D32/$N$3 -> 579112.46 | K32: =+(C32-D32)/$N$2 -> 1532411.6 | L32: {=+_xlfn.IFS(I32>114%,H32*0.02,I32>109%,H32*0.015,I32>104%,H32*0.0125,I32>99%,H32*0.01,I32<99%,H32*0)} -> 0
B33: 37 - SALAJ EMILIO | C33: 25780148 | D33: =IFERROR(+VLOOKUP(B33,COMISIONES!A:E,5,FALSE),"0")*1 -> 6206206.6 | E33: 6144659.6 | F33: =+D33-E33 -> 61547.014 | G33: =+D33/C33 -> 0.24073588 | H33: =+D33/$N$3*$N$4 -> 10343678 | I33: =+H33/C33 -> 0.40122647 | J33: =+D33/$N$3 -> 413747.11 | K33: =+(C33-D33)/$N$2 -> 1957394.1 | L33: {=+_xlfn.IFS(I33>114%,H33*0.02,I33>109%,H33*0.015,I33>104%,H33*0.0125,I33>99%,H33*0.01,I33<99%,H33*0)} -> 0
B34: 24 - SOLIS EMMANUEL | C34: 26383192 | D34: =IFERROR(+VLOOKUP(B34,COMISIONES!A:E,5,FALSE),"0")*1 -> 9267183.7 | E34: 8594211.5 | F34: =+D34-E34 -> 672972.16 | G34: =+D34/C34 -> 0.35125332 | H34: =+D34/$N$3*$N$4 -> 15445306 | I34: =+H34/C34 -> 0.58542219 | J34: =+D34/$N$3 -> 617812.24 | K34: =+(C34-D34)/$N$2 -> 1711600.8 | L34: {=+_xlfn.IFS(I34>114%,H34*0.02,I34>109%,H34*0.015,I34>104%,H34*0.0125,I34>99%,H34*0.01,I34<99%,H34*0)} -> 0
B35: 7 - VALLEJOS EDUARDO | C35: 1.2506204e+08 | D35: =IFERROR(+VLOOKUP(B35,COMISIONES!A:E,5,FALSE),"0")*1 -> 48362192 | E35: 48362192 | F35: =+D35-E35 -> 0 | G35: =+D35/C35 -> 0.38670559 | H35: =+D35/$N$3*$N$4 -> 80603653 | I35: =+H35/C35 -> 0.64450932 | J35: =+D35/$N$3 -> 3224146.1 | K35: =+(C35-D35)/$N$2 -> 7669985.2 | L35: {=+_xlfn.IFS(I35>114%,H35*0.0125,I35>109%,H35*0.01,I35>104%,H35*0.0075,I35>99%,H35*0.005,I35<99%,H35*0)} -> 0
B36: 57 - FEDERRATH MARTIN | C36: 36592500 | D36: =IFERROR(+VLOOKUP(B36,COMISIONES!A:E,5,FALSE),"0")*1 -> 25668656 | E36: 25450183 | F36: =+D36-E36 -> 218473.18 | G36: =+D36/C36 -> 0.70147315 | H36: =+D36/$N$3*$N$4 -> 42781094 | I36: =+H36/C36 -> 1.1691219 | J36: =+D36/$N$3 -> 1711243.7 | K36: =+(C36-D36)/$N$2 -> 1092384.4 | L36: {=+_xlfn.IFS(I36>109%,H36*0.015,I36>104%,H36*0.0125,I36>99%,H36*0.01,I36<99%,H36*0)} -> 641716.4
B37: 1 - VERA ERNESTO | C37: 37270463 | D37: =IFERROR(+VLOOKUP(B37,COMISIONES!A:E,5,FALSE),"0")*1 -> 16929650 | E37: 15657547 | F37: =+D37-E37 -> 1272102.2 | G37: =+D37/C37 -> 0.4542377 | H37: =+D37/$N$3*$N$4 -> 28216083 | I37: =+H37/C37 -> 0.75706283 | J37: =+D37/$N$3 -> 1128643.3 | K37: =+(C37-D37)/$N$2 -> 2034081.4 | L37: {=+_xlfn.IFS(I37>114%,H37*0.02,I37>109%,H37*0.015,I37>104%,H37*0.0125,I37>99%,H37*0.01,I37<99%,H37*0)} -> 0
C38: 532189801 | D38: =+SUM(D25:D37) -> 2.2393764e+08 | E38: 2.1340718e+08 | F38: =+D38-E38 -> 10530464 | G38: =+D38/C38 -> 0.42078529 | H38: =+D38/$N$3*$N$4 -> 3.732294e+08 | I38: =+H38/C38 -> 0.70130882 | J38: =+D38/$N$3 -> 14929176 | K38: =+(C38-D38)/$N$2 -> 30825216
A39: MAXI | B39: 58 - BLADIMIR LEZCANO | C39: 35000000 | D39: =IFERROR(+VLOOKUP(B39,COMISIONES!A:E,5,FALSE),"0")*1 -> 11291407 | E39: 11323950 | F39: =+D39-E39 -> -32543.146 | G39: =+D39/C39 -> 0.32261163 | H39: =+D39/$N$3*$N$4 -> 18819012 | I39: =+H39/C39 -> 0.53768606 | J39: =+D39/$N$3 -> 752760.48 | K39: =+(C39-D39)/$N$2 -> 2370859.3 | L39: {=+_xlfn.IFS(I39>114%,H39*0.02,I39>109%,H39*0.015,I39>104%,H39*0.0125,I39>99%,H39*0.01,I39<99%,H39*0)} -> 0
B40: 59 - LEIVA SILVIO | C40: 30000000 | D40: =IFERROR(+VLOOKUP(B40,COMISIONES!A:E,5,FALSE),"0")*1 -> 6966504.5 | E40: 7044991.8 | F40: =+D40-E40 -> -78487.321 | G40: =+D40/C40 -> 0.23221682 | H40: =+D40/$N$3*$N$4 -> 11610841 | I40: =+H40/C40 -> 0.38702803 | J40: =+D40/$N$3 -> 464433.63 | K40: =+(C40-D40)/$N$2 -> 2303349.5 | L40: {=+_xlfn.IFS(I40>114%,H40*0.02,I40>109%,H40*0.015,I40>104%,H40*0.0125,I40>99%,H40*0.01,I40<99%,H40*0)} -> 0
...

Sheet COBERTURA
A1: SUPERVISOR | C1: VENDEDOR | D1: COBERTURA TOTAL | E1: DIA ANTERIOR | F1: INCREMENTO DIARIO | G1: CARTERA TOTAL | H1: CCC | I1: CCC FALTANTE 85% | P1: Cod vdor | R1: Cobertura x Un de negocio
A2: MARTIN (SUPERVISOR) | B2: 22 | C2: =+AVANCE!B11 -> 22 - ALMIRON NICOLAS | D2: =H2/G2 -> 0.73417722 | E2: 33 | F2: =+H2-E2 -> 25 | G2: =VLOOKUP(B2,'Base Cobertura'!$A:$C,3,FALSE) -> 79 | H2: =VLOOKUP(B2,'Base Cobertura'!$A:$C,2,FALSE) -> 58 | I2: =(+G2*$M$2)-H2 -> 9.15 | J2: bien | K2: bien | L2: OBJETIVO | M2: 0.85 | P2: 25 | Q2: =VLOOKUP(P2,$B:$C,2,FALSE) -> 25 - KALATAKI GUSTAVO | R2: =VLOOKUP(P2,$B:$C,2,FALSE) -> 25 - KALATAKI GUSTAVO | S2: CCC | T2: CARTERA TOTAL | U2: % ALCANZADO
B3: 20 | C3: =+AVANCE!B2 -> 20 - FLORES JAVIER | D3: =H3/G3 -> 0.8558952 | E3: 126 | F3: =+H3-E3 -> 70 | G3: =VLOOKUP(B3,'Base Cobertura'!$A:$C,3,FALSE) -> 229 | H3: =VLOOKUP(B3,'Base Cobertura'!$A:$C,2,FALSE) -> 196 | I3: =(+G3*$M$2)-H3 -> -1.35 | J3: mal | K3: chaca | P3: {=+_xlfn._xlws.FILTER('Base Cobertura'!E:I,'Base Cobertura'!E:E=COBERTURA!P2)} -> 25 | Q3: 25 | R3: 135 - ALMACEN | S3: 32 | T3: 174 | U3: =+S3/T3 -> 0.18390805
B4: 15 | C4: =+AVANCE!B12 -> 15 - GALARZA GERARDO | D4: =H4/G4 -> 0.64615385 | E4: 21 | F4: =+H4-E4 -> 21 | G4: =VLOOKUP(B4,'Base Cobertura'!$A:$C,3,FALSE) -> 65 | H4: =VLOOKUP(B4,'Base Cobertura'!$A:$C,2,FALSE) -> 42 | I4: =(+G4*$M$2)-H4 -> 13.25 | J4: re bien | K4: muy bien | P4: 25 | Q4: 0 | R4: 135 - Articulos Sin Asociar Agrupacion | S4: 15 | T4: 174 | U4: =+S4/T4 -> 0.086206897
B5: 19 | C5: =+AVANCE!B3 -> 19 - GONZALEZ MARCELO | D5: =H5/G5 -> 0.84210526 | E5: 100 | F5: =+H5-E5 -> 76 | G5: =VLOOKUP(B5,'Base Cobertura'!$A:$C,3,FALSE) -> 209 | H5: =VLOOKUP(B5,'Base Cobertura'!$A:$C,2,FALSE) -> 176 | I5: =(+G5*$M$2)-H5 -> 1.65 | K5: muy bien | P5: 25 | Q5: 0 | R5: 135 - BEBIDAS | S5: 35 | T5: 174 | U5: =+S5/T5 -> 0.20114943
B6: 16 | C6: =+AVANCE!B4 -> 16 - GOMEZ MATÍAS | D6: =H6/G6 -> 0.635 | E6: 81 | F6: =+H6-E6 -> 46 | G6: =VLOOKUP(B6,'Base Cobertura'!$A:$C,3,FALSE) -> 200 | H6: =VLOOKUP(B6,'Base Cobertura'!$A:$C,2,FALSE) -> 127 | I6: =(+G6*$M$2)-H6 -> 43 | J6: apretarlo | K6: apretarlo | P6: 25 | Q6: 0 | R6: 135 - CHOCOLATE | S6: 33 | T6: 174 | U6: =+S6/T6 -> 0.18965517
B7: 12 | C7: =+AVANCE!B5 -> 12 - GUTIERREZ MARCOS DAVID | D7: =H7/G7 -> 0.80751174 | E7: 89 | F7: =+H7-E7 -> 83 | G7: =VLOOKUP(B7,'Base Cobertura'!$A:$C,3,FALSE) -> 213 | H7: =VLOOKUP(B7,'Base Cobertura'!$A:$C,2,FALSE) -> 172 | I7: =(+G7*$M$2)-H7 -> 9.05 | J7: apretarlo | K7: apretarlo | P7: 25 | Q7: 0 | R7: 135 - GALLETITAS | S7: 45 | T7: 174 | U7: =+S7/T7 -> 0.25862069
B8: 11 | C8: =+AVANCE!B6 -> 11 - SANCHEZ RICARDO | D8: =H8/G8 -> 0.71428571 | E8: 92 | F8: =+H8-E8 -> 28 | G8: =VLOOKUP(B8,'Base Cobertura'!$A:$C,3,FALSE) -> 168 | H8: =VLOOKUP(B8,'Base Cobertura'!$A:$C,2,FALSE) -> 120 | I8: =(+G8*$M$2)-H8 -> 22.8 | J8: bien | K8: apretarlo | P8: 25 | Q8: 0 | R8: 135 - GOLOSINAS | S8: 42 | T8: 174 | U8: =+S8/T8 -> 0.24137931
B9: 8 | C9: =+AVANCE!B7 -> 8 - PARRA MAXIMILIANO | D9: =H9/G9 -> 0.69651741 | E9: 64 | F9: =+H9-E9 -> 76 | G9: =VLOOKUP(B9,'Base Cobertura'!$A:$C,3,FALSE) -> 201 | H9: =VLOOKUP(B9,'Base Cobertura'!$A:$C,2,FALSE) -> 140 | I9: =(+G9*$M$2)-H9 -> 30.85 | J9: bien | K9: apretarlo con ema | P9: 25 | Q9: 0 | R9: 135 - MASCOTAS | S9: 40 | T9: 174 | U9: =+S9/T9 -> 0.22988506
B10: 52 | C10: =+AVANCE!B13 -> 52 - RAVAROTTO EMANUEL | D10: =H10/G10 -> 0.45283019 | E10: 19 | F10: =+H10-E10 -> 29 | G10: =VLOOKUP(B10,'Base Cobertura'!$A:$C,3,FALSE) -> 106 | H10: =VLOOKUP(B10,'Base Cobertura'!$A:$C,2,FALSE) -> 48 | I10: =(+G10*$M$2)-H10 -> 42.1 | J10: apretarlo | K10: apretarlo | P10: 25 | Q10: 0 | R10: 135 - NO PERECEDEROS | S10: 24 | T10: 174 | U10: =+S10/T10 -> 0.13793103
B11: 53 | C11: =+AVANCE!B14 -> 53 - SANDOVAL RODRIGO | D11: =H11/G11 -> 0.4 | E11: 24 | F11: =+H11-E11 -> 18 | G11: =VLOOKUP(B11,'Base Cobertura'!$A:$C,3,FALSE) -> 105 | H11: =VLOOKUP(B11,'Base Cobertura'!$A:$C,2,FALSE) -> 42 | I11: =(+G11*$M$2)-H11 -> 47.25 | J11: verlo | P11: 25 | Q11: 0 | R11: 135 - PILAS | S11: 16 | T11: 174 | U11: =+S11/T11 -> 0.091954023
B12: 5 | C12: =+AVANCE!B8 -> 5 - SCHELOVER RAUL | D12: =H12/G12 -> 0.75378788 | E12: 144 | F12: =+H12-E12 -> 55 | G12: =VLOOKUP(B12,'Base Cobertura'!$A:$C,3,FALSE) -> 264 | H12: =VLOOKUP(B12,'Base Cobertura'!$A:$C,2,FALSE) -> 199 | I12: =(+G12*$M$2)-H12 -> 25.4 | J12: verlo
B13: 4 | C13: =+AVANCE!B9 -> 4 - TUR SPRINGER FERNANDO | D13: =H13/G13 -> 0.68131868 | E13: 85 | F13: =+H13-E13 -> 39 | G13: =VLOOKUP(B13,'Base Cobertura'!$A:$C,3,FALSE) -> 182 | H13: =VLOOKUP(B13,'Base Cobertura'!$A:$C,2,FALSE) -> 124 | I13: =(+G13*$M$2)-H13 -> 30.7 | J13: re bien | K13: muy bien
F14: =+SUM(F1:F13) -> 566 | G14: =+SUM(G1:G13) -> 2021 | H14: =+SUM(H1:H13) -> 1444 | J14: bien | K14: muy bien
A15: CRISTIAN (SUPERVISOR) | B15: 31 | C15: =+AVANCE!B21 -> 31 - RENZO RAMOS | D15: =H15/G15 -> 0.70588235 | E15: 90 | F15: =+H15-E15 -> 30 | G15: =VLOOKUP(B15,'Base Cobertura'!$A:$C,3,FALSE) -> 170 | H15: =VLOOKUP(B15,'Base Cobertura'!$A:$C,2,FALSE) -> 120 | I15: =(+G15*$M$2)-H15 -> 24.5 | J15: bien | K15: bien
B16: 54 | C16: =+AVANCE!B23 -> 54 - BARTSCHAT EMILIANO NAHUEL | D16: =H16/G16 -> 0.67317073 | E16: 92 | F16: =+H16-E16 -> 46 | G16: =VLOOKUP(B16,'Base Cobertura'!$A:$C,3,FALSE) -> 205 | H16: =VLOOKUP(B16,'Base Cobertura'!$A:$C,2,FALSE) -> 138 | I16: =(+G16*$M$2)-H16 -> 36.25 | J16: bien | K16: chaca
B17: 21 | C17: =+AVANCE!B19 -> 21 - CATAN MATIAS | D17: =H17/G17 -> 0.78313253 | E17: 88 | F17: =+H17-E17 -> 42 | G17: =VLOOKUP(B17,'Base Cobertura'!$A:$C,3,FALSE) -> 166 | H17: =VLOOKUP(B17,'Base Cobertura'!$A:$C,2,FALSE) -> 130 | I17: =(+G17*$M$2)-H17 -> 11.1 | J17: apretarlo | K17: bien
B18: 23 | C18: =+AVANCE!B20 -> 23 - DELGADO JOSÉ | D18: =H18/G18 -> 0.75316456 | E18: 95 | F18: =+H18-E18 -> 24 | G18: =VLOOKUP(B18,'Base Cobertura'!$A:$C,3,FALSE) -> 158 | H18: =VLOOKUP(B18,'Base Cobertura'!$A:$C,2,FALSE) -> 119 | I18: =(+G18*$M$2)-H18 -> 15.3 | J18: apretarlo | K18: muy bien
B19: 18 | C19: =+AVANCE!B18 -> 18 - HERRERA PABLO | D19: =H19/G19 -> 0.70879121 | E19: 83 | F19: =+H19-E19 -> 46 | G19: =VLOOKUP(B19,'Base Cobertura'!$A:$C,3,FALSE) -> 182 | H19: =VLOOKUP(B19,'Base Cobertura'!$A:$C,2,FALSE) -> 129 | I19: =(+G19*$M$2)-H19 -> 25.7 | J19: bien | K19: bien
B20: 44 | C20: =+AVANCE!B22 -> 44 - MONGES CESAR LUIS | D20: =H20/G20 -> 0.73255814 | E20: 64 | F20: =+H20-E20 -> 62 | G20: =VLOOKUP(B20,'Base Cobertura'!$A:$C,3,FALSE) -> 172 | H20: =VLOOKUP(B20,'Base Cobertura'!$A:$C,2,FALSE) -> 126 | I20: =(+G20*$M$2)-H20 -> 20.2 | J20: apretarlo | K20: muy bien
B21: 2 | C21: =+AVANCE!B16 -> 2 - OJEDA NORBERTO | D21: =H21/G21 -> 0.70491803 | E21: 70 | F21: =+H21-E21 -> 16 | G21: =VLOOKUP(B21,'Base Cobertura'!$A:$C,3,FALSE) -> 122 | H21: =VLOOKUP(B21,'Base Cobertura'!$A:$C,2,FALSE) -> 86 | I21: =(+G21*$M$2)-H21 -> 17.7 | J21: apretarlo | K21: apretar
B22: 3 | C22: =+AVANCE!B17 -> 3 - VIDAL NAHUEL | D22: =H22/G22 -> 0.76162791 | E22: 79 | F22: =+H22-E22 -> 52 | G22: =VLOOKUP(B22,'Base Cobertura'!$A:$C,3,FALSE) -> 172 | H22: =VLOOKUP(B22,'Base Cobertura'!$A:$C,2,FALSE) -> 131 | I22: =(+G22*$M$2)-H22 -> 15.2 | J22: abrazo | K22: muy bien
F23: =+SUM(F15:F22) -> 318 | G23: =+SUM(G15:G22) -> 1347 | H23: =+SUM(H15:H22) -> 979
A24: GONZALO (SUPERVISOR) | B24: 32 | C24: =+AVANCE!B25 -> 32 - CABRAL GONZALO | D24: =H24/G24 -> 0.63793103 | E24: 20 | F24: =+H24-E24 -> 17 | G24: =VLOOKUP(B24,'Base Cobertura'!$A:$C,3,FALSE) -> 58 | H24: =VLOOKUP(B24,'Base Cobertura'!$A:$C,2,FALSE) -> 37 | I24: =(+G24*$M$2)-H24 -> 12.3 | J24: bien | K24: apretar
B25: 36 | C25: =+AVANCE!B26 -> 36 - COSARINSKI DIEGO | D25: =H25/G25 -> 0.6625 | E25: 68 | F25: =+H25-E25 -> 38 | G25: =VLOOKUP(B25,'Base Cobertura'!$A:$C,3,FALSE) -> 160 | H25: =VLOOKUP(B25,'Base Cobertura'!$A:$C,2,FALSE) -> 106 | I25: =(+G25*$M$2)-H25 -> 30 | J25: apretarlo | K25: apretar
B26: 9 | C26: =+AVANCE!B27 -> 9 - ESTIGARRIBIA DAVID | D26: =H26/G26 -> 0.83892617 | E26: 80 | F26: =+H26-E26 -> 45 | G26: =VLOOKUP(B26,'Base Cobertura'!$A:$C,3,FALSE) -> 149 | H26: =VLOOKUP(B26,'Base Cobertura'!$A:$C,2,FALSE) -> 125 | I26: =(+G26*$M$2)-H26 -> 1.65 | J26: apretarlo | K26: bien
B27: 40 | C27: =+AVANCE!B28 -> 40 - IBARROLA JORGE | D27: =H27/G27 -> 0.51769912 | E27: 68 | F27: =+H27-E27 -> 49 | G27: =VLOOKUP(B27,'Base Cobertura'!$A:$C,3,FALSE) -> 226 | H27: =VLOOKUP(B27,'Base Cobertura'!$A:$C,2,FALSE) -> 117 | I27: =(+G27*$M$2)-H27 -> 75.1 | J27: apretarlo | K27: apretar
B28: 27 | C28: =+AVANCE!B29 -> 27 - GOMEZ ADRIÁN | D28: =H28/G28 -> 0.87022901 | E28: 73 | F28: =+H28-E28 -> 41 | G28: =VLOOKUP(B28,'Base Cobertura'!$A:$C,3,FALSE) -> 131 | H28: =VLOOKUP(B28,'Base Cobertura'!$A:$C,2,FALSE) -> 114 | I28: =(+G28*$M$2)-H28 -> -2.65 | J28: bien | K28: apretar
B29: 10 | C29: =+AVANCE!B30 -> 10 - BRITEZ EMMANUEL | D29: =H29/G29 -> 0.68862275 | E29: 40 | F29: =+H29-E29 -> 75 | G29: =VLOOKUP(B29,'Base Cobertura'!$A:$C,3,FALSE) -> 167 | H29: =VLOOKUP(B29,'Base Cobertura'!$A:$C,2,FALSE) -> 115 | I29: =(+G29*$M$2)-H29 -> 26.95 | J29: apretarlo | K29: apretar
B30: 28 | C30: =+AVANCE!B31 -> 28 - GOMEZ PABLO | D30: =H30/G30 -> 0.65294118 | E30: 67 | F30: =+H30-E30 -> 44 | G30: =VLOOKUP(B30,'Base Cobertura'!$A:$C,3,FALSE) -> 170 | H30: =VLOOKUP(B30,'Base Cobertura'!$A:$C,2,FALSE) -> 111 | I30: =(+G30*$M$2)-H30 -> 33.5 | J30: apretarlo | K30: apretar
B31: 33 | C31: =+AVANCE!B32 -> 33 - NICOLAS AZULA | D31: =H31/G31 -> 0.72941176 | E31: 66 | F31: =+H31-E31 -> 58 | G31: =VLOOKUP(B31,'Base Cobertura'!$A:$C,3,FALSE) -> 170 | H31: =VLOOKUP(B31,'Base Cobertura'!$A:$C,2,FALSE) -> 124 | I31: =(+G31*$M$2)-H31 -> 20.5 | J31: apretarlo | K31: apretar
B32: 37 | C32: =+AVANCE!B33 -> 37 - SALAJ EMILIO | D32: =H32/G32 -> 0.48979592 | E32: 82 | F32: =+H32-E32 -> -10 | G32: =VLOOKUP(B32,'Base Cobertura'!$A:$C,3,FALSE) -> 147 | H32: =VLOOKUP(B32,'Base Cobertura'!$A:$C,2,FALSE) -> 72 | I32: =(+G32*$M$2)-H32 -> 52.95 | J32: bien | K32: apretar
B33: 24 | C33: =+AVANCE!B34 -> 24 - SOLIS EMMANUEL | D33: =H33/G33 -> 0.58235294 | E33: 81 | F33: =+H33-E33 -> 18 | G33: =VLOOKUP(B33,'Base Cobertura'!$A:$C,3,FALSE) -> 170 | H33: =VLOOKUP(B33,'Base Cobertura'!$A:$C,2,FALSE) -> 99 | I33: =(+G33*$M$2)-H33 -> 45.5 | J33: apretarlo | K33: apretar
B34: 7 | C34: =+AVANCE!B35 -> 7 - VALLEJOS EDUARDO | D34: =H34/G34 -> 0.094017094 | E34: 0 | F34: =+H34-E34 -> 11 | G34: =VLOOKUP(B34,'Base Cobertura'!$A:$C,3,FALSE) -> 117 | H34: =VLOOKUP(B34,'Base Cobertura'!$A:$C,2,FALSE) -> 11 | I34: =(+G34*$M$2)-H34 -> 88.45 | J34: apretarlo
B35: 57 | C35: =+AVANCE!B36 -> 57 - FEDERRATH MARTIN | D35: =H35/G35 -> 0.62264151 | E35: 17 | F35: =+H35-E35 -> 49 | G35: =VLOOKUP(B35,'Base Cobertura'!$A:$C,3,FALSE) -> 106 | H35: =VLOOKUP(B35,'Base Cobertura'!$A:$C,2,FALSE) -> 66 | I35: =(+G35*$M$2)-H35 -> 24.1 | J35: verlo
B36: 1 | C36: =+AVANCE!B37 -> 1 - VERA ERNESTO | D36: =H36/G36 -> 0.83478261 | E36: 60 | F36: =+H36-E36 -> 36 | G36: =VLOOKUP(B36,'Base Cobertura'!$A:$C,3,FALSE) -> 115 | H36: =VLOOKUP(B36,'Base Cobertura'!$A:$C,2,FALSE) -> 96 | I36: =(+G36*$M$2)-H36 -> 1.75 | J36: bien | K36: bien
F37: =+SUM(F24:F36) -> 471 | G37: =+SUM(G24:G36) -> 1886 | H37: =+SUM(H24:H36) -> 1193
A38: MAXI (SUPERVISOR) | B38: 58 | C38: =+AVANCE!B39 -> 58 - BLADIMIR LEZCANO | D38: =H38/G38 -> 0.3253012 | E38: 60 | F38: =+H38-E38 -> -33 | G38: =VLOOKUP(B38,'Base Cobertura'!$A:$C,3,FALSE) -> 83 | H38: =VLOOKUP(B38,'Base Cobertura'!$A:$C,2,FALSE) -> 27 | I38: =(+G38*$M$2)-H38 -> 43.55
B39: 59 | C39: =+AVANCE!B40 -> 59 - LEIVA SILVIO | D39: =H39/G39 -> 0.33070866 | E39: 60 | F39: =+H39-E39 -> -18 | G39: =VLOOKUP(B39,'Base Cobertura'!$A:$C,3,FALSE) -> 127 | H39: =VLOOKUP(B39,'Base Cobertura'!$A:$C,2,FALSE) -> 42 | I39: =(+G39*$M$2)-H39 -> 65.95
B40: 49 | C40: =+AVANCE!B41 -> 49 - ESCOBAR RAÚL | D40: =H40/G40 -> 0.38617886 | E40: 60 | F40: =+H40-E40 -> 35 | G40: =VLOOKUP(B40,'Base Cobertura'!$A:$C,3,FALSE) -> 246 | H40: =VLOOKUP(B40,'Base Cobertura'!$A:$C,2,FALSE) -> 95 | I40: =(+G40*$M$2)-H40 -> 114.1
...

Sheet Cantidad Sku
B1: Cantidad skus
A2: Supervisor Cristian | E2: Vendedores Mayoristas | G2: Cantidad skus
A3: Cod vdor | C3: Cantidad skus | E3: 15 | F3: GALARZA GERARDO | G3: =SUMIFS('Base SKU'!$AM:$AM,'Base SKU'!$E:$E,E3,'Base SKU'!$AM:$AM,1) -> 307
A4: 2 | B4: OJEDA NORBERTO | C4: =SUMIFS('Base SKU'!$AM:$AM,'Base SKU'!$E:$E,A4,'Base SKU'!$AM:$AM,1) -> 264 | E4: 7 | F4: VALLEJOS EDUARDO | G4: 128
A5: 3 | B5: VIDAL NAHUEL | C5: =SUMIFS('Base SKU'!$AM:$AM,'Base SKU'!$E:$E,A5,'Base SKU'!$AM:$AM,1) -> 325
A6: 18 | B6: HERRERA PABLO | C6: =SUMIFS('Base SKU'!$AM:$AM,'Base SKU'!$E:$E,A6,'Base SKU'!$AM:$AM,1) -> 302
A7: 21 | B7: CATAN MATIAS | C7: =SUMIFS('Base SKU'!$AM:$AM,'Base SKU'!$E:$E,A7,'Base SKU'!$AM:$AM,1) -> 312
A8: 23 | B8: DELGADO JOSÉ | C8: =SUMIFS('Base SKU'!$AM:$AM,'Base SKU'!$E:$E,A8,'Base SKU'!$AM:$AM,1) -> 322 | E8: Vendedores Supermercados | G8: Cantidad skus
A9: 31 | B9: RENZO RAMOS | C9: =SUMIFS('Base SKU'!$AM:$AM,'Base SKU'!$E:$E,A9,'Base SKU'!$AM:$AM,1) -> 300 | E9: 22 | F9: ALMIRON NICOLAS | G9: =SUMIFS('Base SKU'!$AM:$AM,'Base SKU'!$E:$E,E9,'Base SKU'!$AM:$AM,1) -> 394
A10: 44 | B10: MONGES CESAR LUIS | C10: =SUMIFS('Base SKU'!$AM:$AM,'Base SKU'!$E:$E,A10,'Base SKU'!$AM:$AM,1) -> 305 | E10: 32 | F10: CABRAL GONZALO | G10: =SUMIFS('Base SKU'!$AM:$AM,'Base SKU'!$E:$E,E10,'Base SKU'!$AM:$AM,1) -> 234
A11: 54 | B11: BARTSCHAT EMILIANO NAHUEL | C11: =SUMIFS('Base SKU'!$AM:$AM,'Base SKU'!$E:$E,A11,'Base SKU'!$AM:$AM,1) -> 361
A12: Totales | E12: Supervisior Maxi | G12: Cantidad skus
A13: Supervisor Martin | C13: Cantidad skus | E13: 58 | F13: BLADIMIR LEZCANO | G13: =SUMIFS('Base SKU'!$AM:$AM,'Base SKU'!$E:$E,E13,'Base SKU'!$AM:$AM,1) -> 212
A14: 4 | B14: TUR SPRINGER FERNANDO | C14: =SUMIFS('Base SKU'!$AM:$AM,'Base SKU'!$E:$E,A14,'Base SKU'!$AM:$AM,1) -> 313 | E14: 59 | F14: LEIVA SILVIO | G14: =SUMIFS('Base SKU'!$AM:$AM,'Base SKU'!$E:$E,E14,'Base SKU'!$AM:$AM,1) -> 160
A15: 5 | B15: SCHELOVER RAUL | C15: =SUMIFS('Base SKU'!$AM:$AM,'Base SKU'!$E:$E,A15,'Base SKU'!$AM:$AM,1) -> 357 | E15: 60 | F15: SILVA ADRIAN | G15: =SUMIFS('Base SKU'!$AM:$AM,'Base SKU'!$E:$E,E15,'Base SKU'!$AM:$AM,1) -> 256
A16: 8 | B16: PARRA MAXIMILIANO | C16: =SUMIFS('Base SKU'!$AM:$AM,'Base SKU'!$E:$E,A16,'Base SKU'!$AM:$AM,1) -> 232 | E16: 56 | F16: JUAN ANDRES SANCHEZ | G16: =SUMIFS('Base SKU'!$AM:$AM,'Base SKU'!$E:$E,E16,'Base SKU'!$AM:$AM,1) -> 234
A17: 11 | B17: SANCHEZ RICARDO | C17: =SUMIFS('Base SKU'!$AM:$AM,'Base SKU'!$E:$E,A17,'Base SKU'!$AM:$AM,1) -> 257 | E17: 26 | F17: PUJOL ERNESTO | G17: =SUMIFS('Base SKU'!$AM:$AM,'Base SKU'!$E:$E,E17,'Base SKU'!$AM:$AM,1) -> 286
A18: 12 | B18: GUTIERREZ MARCOS DAVID | C18: =SUMIFS('Base SKU'!$AM:$AM,'Base SKU'!$E:$E,A18,'Base SKU'!$AM:$AM,1) -> 324 | E18: 25 | F18: KALATAKI GUSTAVO | G18: =SUMIFS('Base SKU'!$AM:$AM,'Base SKU'!$E:$E,E18,'Base SKU'!$AM:$AM,1) -> 336
A19: 16 | B19: GOMEZ MATÍAS | C19: =SUMIFS('Base SKU'!$AM:$AM,'Base SKU'!$E:$E,A19,'Base SKU'!$AM:$AM,1) -> 248 | E19: 43 | F19: COLHER DIEGO | G19: =SUMIFS('Base SKU'!$AM:$AM,'Base SKU'!$E:$E,E19,'Base SKU'!$AM:$AM,1) -> 68
A20: 19 | B20: GONZALEZ MARCELO | C20: =SUMIFS('Base SKU'!$AM:$AM,'Base SKU'!$E:$E,A20,'Base SKU'!$AM:$AM,1) -> 312 | E20: 49 | F20: ESCOBAR RAÚL | G20: =SUMIFS('Base SKU'!$AM:$AM,'Base SKU'!$E:$E,E20,'Base SKU'!$AM:$AM,1) -> 244
A21: 20 | B21: FLORES JAVIER | C21: =SUMIFS('Base SKU'!$AM:$AM,'Base SKU'!$E:$E,A21,'Base SKU'!$AM:$AM,1) -> 332
A22: Totales | E22: Vendedores PETS | G22: Cantidad skus
A23: Supervision Corrientes | C23: Cantidad skus | E23: 52 | F23: RAVAROTTO EMANUEL | G23: =SUMIFS('Base SKU'!$AM:$AM,'Base SKU'!$E:$E,E23,'Base SKU'!$AM:$AM,1) -> 155
A24: 1 | B24: VERA ERNESTO | C24: =SUMIFS('Base SKU'!$AM:$AM,'Base SKU'!$E:$E,A24,'Base SKU'!$AM:$AM,1) -> 304 | E24: 53 | F24: SANDOVAL RODRIGO | G24: =SUMIFS('Base SKU'!$AM:$AM,'Base SKU'!$E:$E,E24,'Base SKU'!$AM:$AM,1) -> 102
A25: 9 | B25: ESTIGARRIBIA DAVID | C25: =SUMIFS('Base SKU'!$AM:$AM,'Base SKU'!$E:$E,A25,'Base SKU'!$AM:$AM,1) -> 306
A26: 10 | B26: BRITEZ EMMANUEL | C26: =SUMIFS('Base SKU'!$AM:$AM,'Base SKU'!$E:$E,A26,'Base SKU'!$AM:$AM,1) -> 205
A27: 24 | B27: SOLIS EMMANUEL | C27: =SUMIFS('Base SKU'!$AM:$AM,'Base SKU'!$E:$E,A27,'Base SKU'!$AM:$AM,1) -> 264
A28: 27 | B28: GOMEZ ADRIÁN | C28: =SUMIFS('Base SKU'!$AM:$AM,'Base SKU'!$E:$E,A28,'Base SKU'!$AM:$AM,1) -> 268
A29: 28 | B29: GOMEZ PABLO | C29: =SUMIFS('Base SKU'!$AM:$AM,'Base SKU'!$E:$E,A29,'Base SKU'!$AM:$AM,1) -> 240
A30: 33 | B30: NICOLAS AZULA | C30: =SUMIFS('Base SKU'!$AM:$AM,'Base SKU'!$E:$E,A30,'Base SKU'!$AM:$AM,1) -> 264
A31: 36 | B31: COSARINSKI DIEGO | C31: =SUMIFS('Base SKU'!$AM:$AM,'Base SKU'!$E:$E,A31,'Base SKU'!$AM:$AM,1) -> 220
A32: 37 | B32: SALAJ EMILIO | C32: =SUMIFS('Base SKU'!$AM:$AM,'Base SKU'!$E:$E,A32,'Base SKU'!$AM:$AM,1) -> 143
A33: 40 | B33: IBARROLA JORGE | C33: =SUMIFS('Base SKU'!$AM:$AM,'Base SKU'!$E:$E,A33,'Base SKU'!$AM:$AM,1) -> 280
A34: Totales

Sheet Base SKU
A1: Periodos | B1: Cod. Período | C1: Descripción Período | D1: Vendedor según comprobante | E1: Código | F1: Descripción | G1: Artículos | H1: Código | I1: Descripción | J1: Marca | K1: Descripción | L1: Detalle | M1: Calibre | N1: Descripción | O1: Detalle | P1: División | Q1: Descripción | R1: Detalle | S1: Producto Estadístico | T1: Descripción | U1: Detalle | V1: Sabor | W1: Descripción | X1: Detalle | Y1: Unidad de Negocio | Z1: Descripción | AA1: Detalle | AB1: P.P.P. Neto | AC1: P.P.P. Final | AD1: Cantidades CON Cargo | AE1: Cantidades SIN Cargo | AF1: Cantidades Totales | AG1: Pesos Totales | AH1: Importes Netos | AI1: Importes Finales | AJ1: Cantidad de Facturas | AK1: Bultos Promedio | AL1: Cantidades en Combos
A2: (001) 01 AGO 2026 - 19 AGO 2026 | B2: 1 | C2: 01 AGO 2026 - 19 AGO 2026 | D2: Suc: 001 (000001) VERA ERNESTO | E2: 1 | F2: VERA ERNESTO | G2: (000001) PILA E 91AA X 4U ENERGIZER ALCALINA | H2: 1 | I2: PILA E 91AA X 4U ENERGIZER ALCALINA | J2: 1019 | K2: ENERGIZER | L2: 1019 - ENERGIZER | P2: 1020 | Q2: PILA | R2: 1020 - PILA | Y2: 1402 | Z2: PILAS | AA2: 1402 - PILAS | AB2: 165651.8 | AC2: 202923.45 | AD2: 0.6 | AE2: 0.125 | AF2: 0.725 | AG2: 0 | AH2: 120097.56 | AI2: 147119.5 | AJ2: 3 | AK2: 0.24 | AL2: 0 | AM2: 1
A3: (001) 01 AGO 2026 - 19 AGO 2026 | B3: 1 | C3: 01 AGO 2026 - 19 AGO 2026 | D3: Suc: 001 (000001) VERA ERNESTO | E3: 1 | F3: VERA ERNESTO | G3: (000002) PILA E 92 AAA X 2U ENERGIZER ALCALINA | H3: 2 | I3: PILA E 92 AAA X 2U ENERGIZER ALCALINA | J3: 1019 | K3: ENERGIZER | L3: 1019 - ENERGIZER | P3: 1020 | Q3: PILA | R3: 1020 - PILA | Y3: 1402 | Z3: PILAS | AA3: 1402 - PILAS | AB3: 127957.84 | AC3: 158454.46 | AD3: 0.5625 | AE3: 0.0833 | AF3: 0.6458 | AG3: 0 | AH3: 82639.44 | AI3: 102335.17 | AJ3: 0 | AK3: 0 | AL3: 0 | AM3: 1
A4: (001) 01 AGO 2026 - 19 AGO 2026 | B4: 1 | C4: 01 AGO 2026 - 19 AGO 2026 | D4: Suc: 001 (000001) VERA ERNESTO | E4: 1 | F4: VERA ERNESTO | G4: (000003) PILA E 93 C X 2U ENERGIZER ALCALINA | H4: 3 | I4: PILA E 93 C X 2U ENERGIZER ALCALINA | J4: 1019 | K4: ENERGIZER | L4: 1019 - ENERGIZER | P4: 1020 | Q4: PILA | R4: 1020 - PILA | Y4: 1402 | Z4: PILAS | AA4: 1402 - PILAS | AB4: 97700.4 | AC4: 119682.99 | AD4: 0.0833 | AE4: 0 | AF4: 0.0833 | AG4: 0 | AH4: 8141.7 | AI4: 9973.58 | AJ4: 0 | AK4: 0 | AL4: 0 | AM4: 1
A5: (001) 01 AGO 2026 - 19 AGO 2026 | B5: 1 | C5: 01 AGO 2026 - 19 AGO 2026 | D5: Suc: 001 (000001) VERA ERNESTO | E5: 1 | F5: VERA ERNESTO | G5: (000004) PILA E 95 D X 2U ENERGIZER ALCALINA | H5: 4 | I5: PILA E 95 D X 2U ENERGIZER ALCALINA | J5: 1019 | K5: ENERGIZER | L5: 1019 - ENERGIZER | P5: 1020 | Q5: PILA | R5: 1020 - PILA | Y5: 1402 | Z5: PILAS | AA5: 1402 - PILAS | AB5: 81783.473 | AC5: 101147.96 | AD5: 2.3333 | AE5: 0.0833 | AF5: 2.4167 | AG5: 0 | AH5: 197643.39 | AI5: 244440.91 | AJ5: 1 | AK5: 2.42 | AL5: 0 | AM5: 1
A6: (001) 01 AGO 2026 - 19 AGO 2026 | B6: 1 | C6: 01 AGO 2026 - 19 AGO 2026 | D6: Suc: 001 (000001) VERA ERNESTO | E6: 1 | F6: VERA ERNESTO | G6: (000005) BATERIA 9V X 1U -522BP ENERGIZER ALCALIN | H6: 5 | I6: BATERIA 9V X 1U -522BP ENERGIZER ALCALIN | J6: 1019 | K6: ENERGIZER | L6: 1019 - ENERGIZER | P6: 1020 | Q6: PILA | R6: 1020 - PILA | Y6: 1402 | Z6: PILAS | AA6: 1402 - PILAS | AB6: 228298.75 | AC6: 281378.21 | AD6: 0.5 | AE6: 0 | AF6: 0.5 | AG6: 0 | AH6: 114149.38 | AI6: 140689.11 | AJ6: 1 | AK6: 0.5 | AL6: 0 | AM6: 1
A7: (001) 01 AGO 2026 - 19 AGO 2026 | B7: 1 | C7: 01 AGO 2026 - 19 AGO 2026 | D7: Suc: 001 (000001) VERA ERNESTO | E7: 1 | F7: VERA ERNESTO | G7: (000027) PEDIGREE ADTO RAZ PEQ ETAPA2 X1,5KG | H7: 27 | I7: PEDIGREE ADTO RAZ PEQ ETAPA2 X1,5KG | J7: 1194 | K7: PEDIGREE MARCA | L7: 1194 - PEDIGREE MARCA | P7: 1098 | Q7: PAQUETERIA WHISKAS Y PEDIG | R7: 1098 - PAQUETERIA WHISKAS Y PEDIG | Y7: 1375 | Z7: MASCOTAS | AA7: 1375 - MASCOTAS | AB7: 37716.23 | AC7: 46202.383 | AD7: 2.5556 | AE7: 0 | AF7: 2.5556 | AG7: 0 | AH7: 96385.92 | AI7: 118072.76 | AJ7: 0 | AK7: 0 | AL7: 0 | AM7: 1
A8: (001) 01 AGO 2026 - 19 AGO 2026 | B8: 1 | C8: 01 AGO 2026 - 19 AGO 2026 | D8: Suc: 001 (000001) VERA ERNESTO | E8: 1 | F8: VERA ERNESTO | G8: (000156) LA GOTITA X 2 ML CHICA | H8: 156 | I8: LA GOTITA X 2 ML CHICA | J8: 1437 | K8: LA GOTITA | L8: 1437 - LA GOTITA | Y8: 1376 | Z8: NO PERECEDEROS | AA8: 1376 - NO PERECEDEROS | AB8: 359272.67 | AC8: 440837.28 | AD8: 0.5125 | AE8: 0 | AF8: 0.5125 | AG8: 0 | AH8: 184127.24 | AI8: 225929.11 | AJ8: 11 | AK8: 0.05 | AL8: 0 | AM8: 1
A9: (001) 01 AGO 2026 - 19 AGO 2026 | B9: 1 | C9: 01 AGO 2026 - 19 AGO 2026 | D9: Suc: 001 (000001) VERA ERNESTO | E9: 1 | F9: VERA ERNESTO | G9: (000158) LA GOTITA GEL X 3 GR CHICO | H9: 158 | I9: LA GOTITA GEL X 3 GR CHICO | J9: 1437 | K9: LA GOTITA | L9: 1437 - LA GOTITA | Y9: 1376 | Z9: NO PERECEDEROS | AA9: 1376 - NO PERECEDEROS | AB9: 424177.69 | AC9: 522282.64 | AD9: 0.1125 | AE9: 0 | AF9: 0.1125 | AG9: 0 | AH9: 47719.99 | AI9: 58756.8 | AJ9: 0 | AK9: 0 | AL9: 0 | AM9: 1
A10: (001) 01 AGO 2026 - 19 AGO 2026 | B10: 1 | C10: 01 AGO 2026 - 19 AGO 2026 | D10: Suc: 001 (000001) VERA ERNESTO | E10: 1 | F10: VERA ERNESTO | G10: (000159) POXI-RAN X 25 ML CHICO (23GR) | H10: 159 | I10: POXI-RAN X 25 ML CHICO (23GR) | J10: 1438 | K10: POXI-RAN | L10: 1438 - POXI-RAN | Y10: 1376 | Z10: NO PERECEDEROS | AA10: 1376 - NO PERECEDEROS | AB10: 410198.23 | AC10: 502381 | AD10: 0.15 | AE10: 0 | AF10: 0.15 | AG10: 0 | AH10: 61529.73 | AI10: 75357.15 | AJ10: 1 | AK10: 0.15 | AL10: 0 | AM10: 1
A11: (001) 01 AGO 2026 - 19 AGO 2026 | B11: 1 | C11: 01 AGO 2026 - 19 AGO 2026 | D11: Suc: 001 (000001) VERA ERNESTO | E11: 1 | F11: VERA ERNESTO | G11: (000164) POXIPOL 10' X 14 ML. TPTE. CHICO | H11: 164 | I11: POXIPOL 10' X 14 ML. TPTE. CHICO | J11: 1439 | K11: POXIPOL | L11: 1439 - POXIPOL | Y11: 1376 | Z11: NO PERECEDEROS | AA11: 1376 - NO PERECEDEROS | AB11: 1097448.9 | AC11: 1360836.6 | AD11: 0.025 | AE11: 0 | AF11: 0.025 | AG11: 0 | AH11: 27436.22 | AI11: 34020.92 | AJ11: 0 | AK11: 0 | AL11: 0 | AM11: 1
A12: (001) 01 AGO 2026 - 19 AGO 2026 | B12: 1 | C12: 01 AGO 2026 - 19 AGO 2026 | D12: Suc: 001 (000001) VERA ERNESTO | E12: 1 | F12: VERA ERNESTO | G12: (000273) ALKA CARAMELOS STRONG X 800 GR | H12: 273 | I12: ALKA CARAMELOS STRONG X 800 GR | J12: 1413 | K12: ALKA | L12: 1413 - ALKA | Y12: 1374 | Z12: GOLOSINAS | AA12: 1374 - GOLOSINAS | AB12: 75725.947 | AC12: 94267.543 | AD12: 0.6 | AE12: 0 | AF12: 0.6 | AG12: 0 | AH12: 45435.57 | AI12: 56560.53 | AJ12: 0 | AK12: 0 | AL12: 0 | AM12: 1
A13: (001) 01 AGO 2026 - 19 AGO 2026 | B13: 1 | C13: 01 AGO 2026 - 19 AGO 2026 | D13: Suc: 001 (000001) VERA ERNESTO | E13: 1 | F13: VERA ERNESTO | G13: (000274) ALKA CARAMELOS MENTA X 800 GR | H13: 274 | I13: ALKA CARAMELOS MENTA X 800 GR | J13: 1413 | K13: ALKA | L13: 1413 - ALKA | P13: 1069 | Q13: CARAM Y CHUP ARCOR | R13: 1069 - CARAM Y CHUP ARCOR | Y13: 1374 | Z13: GOLOSINAS | AA13: 1374 - GOLOSINAS | AB13: 76852.53 | AC13: 94144.354 | AD13: 0.2 | AE13: 0 | AF13: 0.2 | AG13: 0 | AH13: 15370.51 | AI13: 18828.87 | AJ13: 0 | AK13: 0 | AL13: 0 | AM13: 1
A14: (001) 01 AGO 2026 - 19 AGO 2026 | B14: 1 | C14: 01 AGO 2026 - 19 AGO 2026 | D14: Suc: 001 (000001) VERA ERNESTO | E14: 1 | F14: VERA ERNESTO | G14: (000344) PILA E 91 AA X 2U ENERGIZER ALCALINA | H14: 344 | I14: PILA E 91 AA X 2U ENERGIZER ALCALINA | J14: 1019 | K14: ENERGIZER | L14: 1019 - ENERGIZER | P14: 1020 | Q14: PILA | R14: 1020 - PILA | Y14: 1402 | Z14: PILAS | AA14: 1402 - PILAS | AB14: 131839.85 | AC14: 162653.58 | AD14: 0.4375 | AE14: 0.0417 | AF14: 0.4792 | AG14: 0 | AH14: 63173.26 | AI14: 77938.17 | AJ14: 2 | AK14: 0.24 | AL14: 0 | AM14: 1
A15: (001) 01 AGO 2026 - 19 AGO 2026 | B15: 1 | C15: 01 AGO 2026 - 19 AGO 2026 | D15: Suc: 001 (000001) VERA ERNESTO | E15: 1 | F15: VERA ERNESTO | G15: (000346) PILA E 92 AAA X 4U ENERGIZER ALCALINA | H15: 346 | I15: PILA E 92 AAA X 4U ENERGIZER ALCALINA | J15: 1019 | K15: ENERGIZER | L15: 1019 - ENERGIZER | P15: 1020 | Q15: PILA | R15: 1020 - PILA | Y15: 1402 | Z15: PILAS | AA15: 1402 - PILAS | AB15: 161771.62 | AC15: 198170.23 | AD15: 0.325 | AE15: 0.125 | AF15: 0.45 | AG15: 0 | AH15: 72797.23 | AI15: 89176.6 | AJ15: 1 | AK15: 0.45 | AL15: 0 | AM15: 1
A16: (001) 01 AGO 2026 - 19 AGO 2026 | B16: 1 | C16: 01 AGO 2026 - 19 AGO 2026 | D16: Suc: 001 (000001) VERA ERNESTO | E16: 1 | F16: VERA ERNESTO | G16: (000362) BANANINA X30U. X 15G | H16: 362 | I16: BANANINA X30U. X 15G | Y16: 1372 | Z16: CHOCOLATE | AA16: 1372 - CHOCOLATE | AB16: 97888.625 | AC16: 120878.15 | AD16: 0.25 | AE16: 0.0833 | AF16: 0.3333 | AG16: 0 | AH16: 32629.54 | AI16: 40292.72 | AJ16: 0 | AK16: 0 | AL16: 0 | AM16: 1
A17: (001) 01 AGO 2026 - 19 AGO 2026 | B17: 1 | C17: 01 AGO 2026 - 19 AGO 2026 | D17: Suc: 001 (000001) VERA ERNESTO | E17: 1 | F17: VERA ERNESTO | G17: (000461) MATE LISTO TARAGUI X 35 GR | H17: 461 | I17: MATE LISTO TARAGUI X 35 GR | J17: 1006 | K17: TARAGUI | L17: 1006 - TARAGUI | P17: 1004 | Q17: INFUSIONES | R17: 1004 - INFUSIONES | Y17: 1369 | Z17: ALMACEN | AA17: 1369 - ALMACEN | AB17: 19339.909 | AC17: 23807.43 | AD17: 0.8333 | AE17: 0 | AF17: 0.8333 | AG17: 0 | AH17: 16116.59 | AI17: 19839.53 | AJ17: 0 | AK17: 0 | AL17: 0 | AM17: 1
A18: (001) 01 AGO 2026 - 19 AGO 2026 | B18: 1 | C18: 01 AGO 2026 - 19 AGO 2026 | D18: Suc: 001 (000001) VERA ERNESTO | E18: 1 | F18: VERA ERNESTO | G18: (000462) BOTELLA TERMICA MATE LISTO | H18: 462 | I18: BOTELLA TERMICA MATE LISTO | J18: 1006 | K18: TARAGUI | L18: 1006 - TARAGUI | Y18: 1369 | Z18: ALMACEN | AA18: 1369 - ALMACEN | AB18: 10907.43 | AC18: 13475.222 | AD18: 1 | AE18: 0.5 | AF18: 1.5 | AG18: 0 | AH18: 16361.15 | AI18: 20212.83 | AJ18: 0 | AK18: 0 | AL18: 0 | AM18: 1
A19: (001) 01 AGO 2026 - 19 AGO 2026 | B19: 1 | C19: 01 AGO 2026 - 19 AGO 2026 | D19: Suc: 001 (000001) VERA ERNESTO | E19: 1 | F19: VERA ERNESTO | G19: (000542) PILA ECR-2032 X 5U ESP CALCULADORA | H19: 542 | I19: PILA ECR-2032 X 5U ESP CALCULADORA | J19: 1019 | K19: ENERGIZER | L19: 1019 - ENERGIZER | P19: 1020 | Q19: PILA | R19: 1020 - PILA | Y19: 1402 | Z19: PILAS | AA19: 1402 - PILAS | AB19: 105941.96 | AC19: 129980.58 | AD19: 0.8 | AE19: 0.05 | AF19: 0.85 | AG19: 0 | AH19: 90050.67 | AI19: 110483.49 | AJ19: 5 | AK19: 0.17 | AL19: 0 | AM19: 1
A20: (001) 01 AGO 2026 - 19 AGO 2026 | B20: 1 | C20: 01 AGO 2026 - 19 AGO 2026 | D20: Suc: 001 (000001) VERA ERNESTO | E20: 1 | F20: VERA ERNESTO | G20: (000549) CARAM MASTICABLE DONGA X 218 U | H20: 549 | I20: CARAM MASTICABLE DONGA X 218 U | P20: 1151 | Q20: CARAMELOS LHERITIER | R20: 1151 - CARAMELOS LHERITIER | Y20: 1374 | Z20: GOLOSINAS | AA20: 1374 - GOLOSINAS | AB20: 42064.5 | AC20: 51529.013 | AD20: 0.1 | AE20: 0 | AF20: 0.1 | AG20: 0 | AH20: 4206.45 | AI20: 5152.9 | AJ20: 1 | AK20: 0.1 | AL20: 0 | AM20: 1
A21: (001) 01 AGO 2026 - 19 AGO 2026 | B21: 1 | C21: 01 AGO 2026 - 19 AGO 2026 | D21: Suc: 001 (000001) VERA ERNESTO | E21: 1 | F21: VERA ERNESTO | G21: (000559) UNI-POX X 25 ML. CHICO | H21: 559 | I21: UNI-POX X 25 ML. CHICO | J21: 1442 | K21: UNI-POX | L21: 1442 - UNI-POX | Y21: 1376 | Z21: NO PERECEDEROS | AA21: 1376 - NO PERECEDEROS | AB21: 201319.71 | AC21: 248194.4 | AD21: 0.1 | AE21: 0 | AF21: 0.1 | AG21: 0 | AH21: 20131.97 | AI21: 24819.44 | AJ21: 0 | AK21: 0 | AL21: 0 | AM21: 1
A22: (001) 01 AGO 2026 - 19 AGO 2026 | B22: 1 | C22: 01 AGO 2026 - 19 AGO 2026 | D22: Suc: 001 (000001) VERA ERNESTO | E22: 1 | F22: VERA ERNESTO | G22: (000565) BUBBALOO 60'S TUTTI FRUTTI | H22: 565 | I22: BUBBALOO 60'S TUTTI FRUTTI | Y22: 1374 | Z22: GOLOSINAS | AA22: 1374 - GOLOSINAS | AB22: 144342.45 | AC22: 176819.49 | AD22: 0.0625 | AE22: 0 | AF22: 0.0625 | AG22: 0 | AH22: 9021.4 | AI22: 11051.22 | AJ22: 0 | AK22: 0 | AL22: 0 | AM22: 1
A23: (001) 01 AGO 2026 - 19 AGO 2026 | B23: 1 | C23: 01 AGO 2026 - 19 AGO 2026 | D23: Suc: 001 (000001) VERA ERNESTO | E23: 1 | F23: VERA ERNESTO | G23: (000566) BUBBALOO 60'S FRUTILLA | H23: 566 | I23: BUBBALOO 60'S FRUTILLA | Y23: 1374 | Z23: GOLOSINAS | AA23: 1374 - GOLOSINAS | AB23: 144342.45 | AC23: 176819.49 | AD23: 0.0313 | AE23: 0 | AF23: 0.0313 | AG23: 0 | AH23: 4510.7 | AI23: 5525.61 | AJ23: 0 | AK23: 0 | AL23: 0 | AM23: 1
A24: (001) 01 AGO 2026 - 19 AGO 2026 | B24: 1 | C24: 01 AGO 2026 - 19 AGO 2026 | D24: Suc: 001 (000001) VERA ERNESTO | E24: 1 | F24: VERA ERNESTO | G24: (000567) BUBBALOO 60'S MENTA | H24: 567 | I24: BUBBALOO 60'S MENTA | Y24: 1374 | Z24: GOLOSINAS | AA24: 1374 - GOLOSINAS | AB24: 144342.45 | AC24: 176819.49 | AD24: 0.0938 | AE24: 0 | AF24: 0.0938 | AG24: 0 | AH24: 13532.1 | AI24: 16576.83 | AJ24: 0 | AK24: 0 | AL24: 0 | AM24: 1
A25: (001) 01 AGO 2026 - 19 AGO 2026 | B25: 1 | C25: 01 AGO 2026 - 19 AGO 2026 | D25: Suc: 001 (000001) VERA ERNESTO | E25: 1 | F25: VERA ERNESTO | G25: (000639) BATERIA A23 -12V X 5U -ENERGIZER ALCALINA | H25: 639 | I25: BATERIA A23 -12V X 5U -ENERGIZER ALCALINA | J25: 1019 | K25: ENERGIZER | L25: 1019 - ENERGIZER | P25: 1020 | Q25: PILA | R25: 1020 - PILA | Y25: 1402 | Z25: PILAS | AA25: 1402 - PILAS | AB25: 144453 | AC25: 176954.92 | AD25: 0.35 | AE25: 0 | AF25: 0.35 | AG25: 0 | AH25: 50558.55 | AI25: 61934.22 | AJ25: 0 | AK25: 0 | AL25: 0 | AM25: 1
A26: (001) 01 AGO 2026 - 19 AGO 2026 | B26: 1 | C26: 01 AGO 2026 - 19 AGO 2026 | D26: Suc: 001 (000001) VERA ERNESTO | E26: 1 | F26: VERA ERNESTO | G26: (000653) CARAM MAST SURT MISKY X800 GR | H26: 653 | I26: CARAM MAST SURT MISKY X800 GR | J26: 1414 | K26: MISKY | L26: 1414 - MISKY | P26: 1072 | Q26: MISKY CARAM | R26: 1072 - MISKY CARAM | Y26: 1374 | Z26: GOLOSINAS | AA26: 1374 - GOLOSINAS | AB26: 49291.416 | AC26: 60624.406 | AD26: 0.3 | AE26: 0 | AF26: 0.3 | AG26: 0 | AH26: 14787.42 | AI26: 18187.32 | AJ26: 1 | AK26: 0.3 | AL26: 0 | AM26: 1
A27: (001) 01 AGO 2026 - 19 AGO 2026 | B27: 1 | C27: 01 AGO 2026 - 19 AGO 2026 | D27: Suc: 001 (000001) VERA ERNESTO | E27: 1 | F27: VERA ERNESTO | G27: (000692) ACEITE LUBRICANTE WD-40 X 155 G | H27: 692 | I27: ACEITE LUBRICANTE WD-40 X 155 G | J27: 1169 | K27: WD40 | L27: 1169 - WD40 | Y27: 1376 | Z27: NO PERECEDEROS | AA27: 1376 - NO PERECEDEROS | AB27: 61592.641 | AC27: 76374.874 | AD27: 2 | AE27: 0 | AF27: 2 | AG27: 0 | AH27: 123185.28 | AI27: 152749.75 | AJ27: 0 | AK27: 0 | AL27: 0 | AM27: 1
A28: (001) 01 AGO 2026 - 19 AGO 2026 | B28: 1 | C28: 01 AGO 2026 - 19 AGO 2026 | D28: Suc: 001 (000001) VERA ERNESTO | E28: 1 | F28: VERA ERNESTO | G28: (000711) PILA ECR-2016 X 5U ESP CALCULADORA | H28: 711 | I28: PILA ECR-2016 X 5U ESP CALCULADORA | J28: 1019 | K28: ENERGIZER | L28: 1019 - ENERGIZER | P28: 1020 | Q28: PILA | R28: 1020 - PILA | Y28: 1402 | Z28: PILAS | AA28: 1402 - PILAS | AB28: 114277.5 | AC28: 141132.72 | AD28: 0.15 | AE28: 0 | AF28: 0.15 | AG28: 0 | AH28: 17141.63 | AI28: 21169.91 | AJ28: 1 | AK28: 0.15 | AL28: 0 | AM28: 1
A29: (001) 01 AGO 2026 - 19 AGO 2026 | B29: 1 | C29: 01 AGO 2026 - 19 AGO 2026 | D29: Suc: 001 (000001) VERA ERNESTO | E29: 1 | F29: VERA ERNESTO | G29: (000731) POLVORITAS VAINILLA X 81 GR | H29: 731 | I29: POLVORITAS VAINILLA X 81 GR | J29: 1422 | K29: POLVORITAS | L29: 1422 - POLVORITAS | P29: 1067 | Q29: POLVORITAS 80G Y 147G | R29: 1067 - POLVORITAS 80G Y 147G | Y29: 1373 | Z29: GALLETITAS | AA29: 1373 - GALLETITAS | AB29: 16025.989 | AC29: 19783.921 | AD29: 2.825 | AE29: 0.225 | AF29: 3.05 | AG29: 0 | AH29: 48879.27 | AI29: 60340.96 | AJ29: 0 | AK29: 0 | AL29: 0 | AM29: 1
A30: (001) 01 AGO 2026 - 19 AGO 2026 | B30: 1 | C30: 01 AGO 2026 - 19 AGO 2026 | D30: Suc: 001 (000001) VERA ERNESTO | E30: 1 | F30: VERA ERNESTO | G30: (000742) PRESERV PRIME CON ESPERMICIDA X 3U | H30: 742 | I30: PRESERV PRIME CON ESPERMICIDA X 3U | J30: 1150 | K30: PRIME | L30: 1150 - PRIME | Y30: 1376 | Z30: NO PERECEDEROS | AA30: 1376 - NO PERECEDEROS | AB30: 59908.8 | AC30: 73388.28 | AD30: 0.375 | AE30: 0 | AF30: 0.375 | AG30: 0 | AH30: 22465.8 | AI30: 27520.61 | AJ30: 0 | AK30: 0 | AL30: 0 | AM30: 1
A31: (001) 01 AGO 2026 - 19 AGO 2026 | B31: 1 | C31: 01 AGO 2026 - 19 AGO 2026 | D31: Suc: 001 (000001) VERA ERNESTO | E31: 1 | F31: VERA ERNESTO | G31: (000744) PRESERV PRIME SUPER FINOS X 3U. | H31: 744 | I31: PRESERV PRIME SUPER FINOS X 3U. | J31: 1150 | K31: PRIME | L31: 1150 - PRIME | Y31: 1376 | Z31: NO PERECEDEROS | AA31: 1376 - NO PERECEDEROS | AB31: 52919.44 | AC31: 65415.417 | AD31: 2 | AE31: 0.25 | AF31: 2.25 | AG31: 0 | AH31: 119068.74 | AI31: 147184.69 | AJ31: 0 | AK31: 0 | AL31: 0 | AM31: 1
A32: (001) 01 AGO 2026 - 19 AGO 2026 | B32: 1 | C32: 01 AGO 2026 - 19 AGO 2026 | D32: Suc: 001 (000001) VERA ERNESTO | E32: 1 | F32: VERA ERNESTO | G32: (000746) PRESERV PRIME TEXTURADOS X 3U. | H32: 746 | I32: PRESERV PRIME TEXTURADOS X 3U. | J32: 1150 | K32: PRIME | L32: 1150 - PRIME | Y32: 1376 | Z32: NO PERECEDEROS | AA32: 1376 - NO PERECEDEROS | AB32: 45930.08 | AC32: 56843.466 | AD32: 0.875 | AE32: 0.25 | AF32: 1.125 | AG32: 0 | AH32: 51671.34 | AI32: 63948.9 | AJ32: 0 | AK32: 0 | AL32: 0 | AM32: 1
A33: (001) 01 AGO 2026 - 19 AGO 2026 | B33: 1 | C33: 01 AGO 2026 - 19 AGO 2026 | D33: Suc: 001 (000001) VERA ERNESTO | E33: 1 | F33: VERA ERNESTO | G33: (000799) BATERIA ENERGIZER 12V X 1U -A27 | H33: 799 | I33: BATERIA ENERGIZER 12V X 1U -A27 | J33: 1019 | K33: ENERGIZER | L33: 1019 - ENERGIZER | P33: 1020 | Q33: PILA | R33: 1020 - PILA | Y33: 1402 | Z33: PILAS | AA33: 1402 - PILAS | AB33: 29429.724 | AC33: 36051.413 | AD33: 1.75 | AE33: 0 | AF33: 1.75 | AG33: 0 | AH33: 51502.02 | AI33: 63089.97 | AJ33: 0 | AK33: 0 | AL33: 0 | AM33: 1
A34: (001) 01 AGO 2026 - 19 AGO 2026 | B34: 1 | C34: 01 AGO 2026 - 19 AGO 2026 | D34: Suc: 001 (000001) VERA ERNESTO | E34: 1 | F34: VERA ERNESTO | G34: (000819) PILA 1215 AA X 4U EVEREADY EXTRA DURAC | H34: 819 | I34: PILA 1215 AA X 4U EVEREADY EXTRA DURAC | J34: 1018 | K34: EVEREADY | L34: 1018 - EVEREADY | P34: 1020 | Q34: PILA | R34: 1020 - PILA | Y34: 1402 | Z34: PILAS | AA34: 1402 - PILAS | AB34: 98618.688 | AC34: 120807.89 | AD34: 0.2083 | AE34: 0 | AF34: 0.2083 | AG34: 0 | AH34: 20545.56 | AI34: 25168.31 | AJ34: 0 | AK34: 0 | AL34: 0 | AM34: 1
A35: (001) 01 AGO 2026 - 19 AGO 2026 | B35: 1 | C35: 01 AGO 2026 - 19 AGO 2026 | D35: Suc: 001 (000001) VERA ERNESTO | E35: 1 | F35: VERA ERNESTO | G35: (000822) PILA 1212 AAA X 2U EVEREADY EXTRA DURAC | H35: 822 | I35: PILA 1212 AAA X 2U EVEREADY EXTRA DURAC | J35: 1018 | K35: EVEREADY | L35: 1018 - EVEREADY | P35: 1020 | Q35: PILA | R35: 1020 - PILA | Y35: 1402 | Z35: PILAS | AA35: 1402 - PILAS | AB35: 73964.016 | AC35: 90605.921 | AD35: 1 | AE35: 0 | AF35: 1 | AG35: 0 | AH35: 73964.02 | AI35: 90605.92 | AJ35: 0 | AK35: 0 | AL35: 0 | AM35: 1
A36: (001) 01 AGO 2026 - 19 AGO 2026 | B36: 1 | C36: 01 AGO 2026 - 19 AGO 2026 | D36: Suc: 001 (000001) VERA ERNESTO | E36: 1 | F36: VERA ERNESTO | G36: (000824) BATERIA EVEREADY EXTRA DURAC 9V -1222 | H36: 824 | I36: BATERIA EVEREADY EXTRA DURAC 9V -1222 | J36: 1018 | K36: EVEREADY | L36: 1018 - EVEREADY | P36: 1020 | Q36: PILA | R36: 1020 - PILA | Y36: 1402 | Z36: PILAS | AA36: 1402 - PILAS | AB36: 72889.92 | AC36: 89290.152 | AD36: 0.125 | AE36: 0 | AF36: 0.125 | AG36: 0 | AH36: 9111.24 | AI36: 11161.27 | AJ36: 1 | AK36: 0.13 | AL36: 0 | AM36: 1
A37: (001) 01 AGO 2026 - 19 AGO 2026 | B37: 1 | C37: 01 AGO 2026 - 19 AGO 2026 | D37: Suc: 001 (000001) VERA ERNESTO | E37: 1 | F37: VERA ERNESTO | G37: (000826) ACEITE LUBRICANTE WD-40 X 311 G | H37: 826 | I37: ACEITE LUBRICANTE WD-40 X 311 G | J37: 1169 | K37: WD40 | L37: 1169 - WD40 | Y37: 1376 | Z37: NO PERECEDEROS | AA37: 1376 - NO PERECEDEROS | AB37: 95857.212 | AC37: 118862.94 | AD37: 1 | AE37: 0 | AF37: 1 | AG37: 0 | AH37: 95857.21 | AI37: 118862.94 | AJ37: 0 | AK37: 0 | AL37: 0 | AM37: 1
A38: (001) 01 AGO 2026 - 19 AGO 2026 | B38: 1 | C38: 01 AGO 2026 - 19 AGO 2026 | D38: Suc: 001 (000001) VERA ERNESTO | E38: 1 | F38: VERA ERNESTO | G38: (000862) PETACA NEW STYLE X 200 CC CAFE AL COÑAC | H38: 862 | I38: PETACA NEW STYLE X 200 CC CAFE AL COÑAC | P38: 1102 | Q38: PETACAS | R38: 1102 - PETACAS | Y38: 1370 | Z38: BEBIDAS | AA38: 1370 - BEBIDAS | AB38: 10533.468 | AC38: 13061.501 | AD38: 2 | AE38: 0 | AF38: 2 | AG38: 0 | AH38: 21066.94 | AI38: 26123 | AJ38: 1 | AK38: 2 | AL38: 0 | AM38: 1
A39: (001) 01 AGO 2026 - 19 AGO 2026 | B39: 1 | C39: 01 AGO 2026 - 19 AGO 2026 | D39: Suc: 001 (000001) VERA ERNESTO | E39: 1 | F39: VERA ERNESTO | G39: (000868) PRESERV PRIME X 3U. TACHA | H39: 868 | I39: PRESERV PRIME X 3U. TACHA | J39: 1150 | K39: PRIME | L39: 1150 - PRIME | Y39: 1376 | Z39: NO PERECEDEROS | AA39: 1376 - NO PERECEDEROS | AB39: 43498.998 | AC39: 53731.682 | AD39: 0.7083 | AE39: 0.25 | AF39: 0.9583 | AG39: 0 | AH39: 41686.54 | AI39: 51492.86 | AJ39: 0 | AK39: 0 | AL39: 0 | AM39: 1
A40: (001) 01 AGO 2026 - 19 AGO 2026 | B40: 1 | C40: 01 AGO 2026 - 19 AGO 2026 | D40: Suc: 001 (000001) VERA ERNESTO | E40: 1 | F40: VERA ERNESTO | G40: (000877) PETACA SAN VICENTE ANIS X 200CC | H40: 877 | I40: PETACA SAN VICENTE ANIS X 200CC | P40: 1102 | Q40: PETACAS | R40: 1102 - PETACAS | Y40: 1370 | Z40: BEBIDAS | AA40: 1370 - BEBIDAS | AB40: 12653.26 | AC40: 15500.241 | AD40: 0.3333 | AE40: 0 | AF40: 0.3333 | AG40: 0 | AH40: 4217.75 | AI40: 5166.75 | AJ40: 0 | AK40: 0 | AL40: 0 | AM40: 1
...

Sheet Promedio Horas
A1: Cod | B1: Vendedor | D1: Promedio Mensual
A2: V2 | B2: =+AVANCE!B16 -> 2 - OJEDA NORBERTO | D2: 0.19079398
A3: V3 | B3: =+AVANCE!B17 -> 3 - VIDAL NAHUEL | D3: 0.28310571
A4: V18 | B4: =+AVANCE!B18 -> 18 - HERRERA PABLO | D4: 0.26613194
A5: V21 | B5: =+AVANCE!B19 -> 21 - CATAN MATIAS | D5: 0.26454167
A6: V23 | B6: =+AVANCE!B20 -> 23 - DELGADO JOSÉ | D6: 0.25136651
A7: V31 | B7: =+AVANCE!B21 -> 31 - RENZO RAMOS | D7: 0.26971219
A8: V44 | B8: =+AVANCE!B22 -> 44 - MONGES CESAR LUIS | D8: 0.25700077
A9: V54 | B9: =+AVANCE!B23 -> 54 - BARTSCHAT EMILIANO NAHUEL | D9: 0.24046914
A10: V56 | B10: =+AVANCE!B42 -> 56 - JUAN ANDRES SANCHEZ | D10: 0.1005517
A11: V4 | B11: =+AVANCE!B9 -> 4 - TUR SPRINGER FERNANDO | D11: 0.25588503
A12: V5 | B12: =+AVANCE!B8 -> 5 - SCHELOVER RAUL | D12: 0.2990108
A13: V8 | B13: =+AVANCE!B7 -> 8 - PARRA MAXIMILIANO | D13: 0.26771065
A14: V11 | B14: =+AVANCE!B6 -> 11 - SANCHEZ RICARDO | D14: 0.29193287
A15: V12 | B15: =+AVANCE!B5 -> 12 - GUTIERREZ MARCOS DAVID | D15: 0.24288426
A16: V16 | B16: =+AVANCE!B4 -> 16 - GOMEZ MATÍAS | D16: 0.2233269
A17: V19 | B17: =+AVANCE!B3 -> 19 - GONZALEZ MARCELO | D17: 0.2550216
A18: V20 | B18: =+AVANCE!B2 -> 20 - FLORES JAVIER | D18: 0.2709946
A19: V49 | B19: =+AVANCE!B41 -> 49 - ESCOBAR RAÚL | D19: 0.25970988
A20: V1 | B20: =+AVANCE!B37 -> 1 - VERA ERNESTO | D20: 0.2933017
A21: V9 | B21: =+AVANCE!B27 -> 9 - ESTIGARRIBIA DAVID | D21: 0.24611111
A22: V10 | B22: =+AVANCE!B30 -> 10 - BRITEZ EMMANUEL | D22: 0.26748534
A23: V24 | B23: =+AVANCE!B34 -> 24 - SOLIS EMMANUEL | D23: 0.2472554
A24: V27 | B24: =+AVANCE!B29 -> 27 - GOMEZ ADRIÁN | D24: 0.25832485
A25: V28 | B25: =+AVANCE!B31 -> 28 - GOMEZ PABLO | D25: 0.22076157
A26: V33 | B26: =+AVANCE!B32 -> 33 - NICOLAS AZULA | D26: 0.26807639
A27: V36 | B27: =+AVANCE!B26 -> 36 - COSARINSKI DIEGO | D27: 0.24040278
A28: V37 | B28: =+AVANCE!B33 -> 37 - SALAJ EMILIO | D28: 0.26019213
A29: V40 | B29: =+AVANCE!B28 -> 40 - IBARROLA JORGE | D29: 0.23019792
A30: V52 | B30: =+AVANCE!B13 -> 52 - RAVAROTTO EMANUEL | D30: 0.23220679
A31: V53 | B31: =+AVANCE!B14 -> 53 - SANDOVAL RODRIGO | D31: 0.15221258
A32: V15 | B32: =+AVANCE!B12 -> 15 - GALARZA GERARDO | D32: 0.2249267
A33: V22 | B33: =+AVANCE!B11 -> 22 - ALMIRON NICOLAS | D33: 0.20851312
A34: V7 | B34: =+AVANCE!B35 -> 7 - VALLEJOS EDUARDO | D34: 0.13290895
A35: V32 | B35: =+AVANCE!B25 -> 32 - CABRAL GONZALO | D35: 0.14253472
A36: V57 | B36: =+AVANCE!B36 -> 57 - FEDERRATH MARTIN | D36: 0.18373148

Sheet Venta C
B1: VENDEDOR/ SUPERVISOR | C1: Venta NETA ARTICULOS C
A2: 20 | B2: 20 - FLORES JAVIER | C2: =IFERROR(VLOOKUP(A2,'Base venta C'!$E:$P,12,FALSE),"0")*1 -> 343887.46
A3: 19 | B3: 19 - GONZALEZ MARCELO | C3: =IFERROR(VLOOKUP(A3,'Base venta C'!$E:$P,12,FALSE),"0")*1 -> 365262.82
A4: 16 | B4: 16 - GOMEZ MATÍAS | C4: =IFERROR(VLOOKUP(A4,'Base venta C'!$E:$P,12,FALSE),"0")*1 -> 271002.4
A5: 12 | B5: 12 - GUTIERREZ MARCOS DAVID | C5: =IFERROR(VLOOKUP(A5,'Base venta C'!$E:$P,12,FALSE),"0")*1 -> 284624.48
A6: 11 | B6: 11 - ZACARIAS DAVID | C6: =IFERROR(VLOOKUP(A6,'Base venta C'!$E:$P,12,FALSE),"0")*1 -> 166886.05
A7: 8 | B7: 8 - RAVAROTTO EMANUEL | C7: =IFERROR(VLOOKUP(A7,'Base venta C'!$E:$P,12,FALSE),"0")*1 -> 284846.64
A8: 5 | B8: 5 - SCHELOVER RAUL | C8: =IFERROR(VLOOKUP(A8,'Base venta C'!$E:$P,12,FALSE),"0")*1 -> 322216.7
A9: 4 | B9: 4 - TUR SPRINGER FERNANDO | C9: =IFERROR(VLOOKUP(A9,'Base venta C'!$E:$P,12,FALSE),"0")*1 -> 875228.78
B10: MARTIN (SUPERVISOR) PREVENTA
A11: 22 | B11: 22 - ALMIRON NICOLAS | C11: =IFERROR(VLOOKUP(A11,'Base venta C'!$E:$P,12,FALSE),"0")*1 -> 270784.37
A12: 49 | B12: 49 - ESCOBAR RAÚL | C12: =IFERROR(VLOOKUP(A12,'Base venta C'!$E:$P,12,FALSE),"0")*1 -> 76349.44
