Workbook

Sheet COMISIONES
A1: VENDEDOR | B1: SUCURSAL | C1: BULTOS | D1: UNIDAD DE MEDIDA | E1: IMPORTE | F1: COMISIÓN POR IMPORTE FIJO | G1: COMISIÓN POR PORCENTAJE | H1: COMISIÓN TOTAL
A2: 0 - TODOS LOS VENDEDORES | B2: 0 | C2: 2833.8918 | D2: 17845.083 | E2: 64466960 | F2: 0 | G2: 72294.261 | H2: 72294.23
A3: 1 - VERA ERNESTO | B3: 1 | C3: 69.37829 | D3: 127.82572 | E3: 2409808.7 | F3: 0 | G3: 72294.261 | H3: 72294.23
A4: 2 - OJEDA NORBERTO | B4: 1 | C4: 10.483333 | D4: 57.01 | E4: 910195.67 | F4: 0 | G4: 0 | H4: 0
A5: 3 - VIDAL NAHUEL | B5: 1 | C5: 27.204464 | D5: 28.2525 | E5: 501148.96 | F5: 0 | G5: 0 | H5: 0
A6: 4 - TUR SPRINGER FERNANDO | B6: 1 | C6: 150.14464 | D6: 414.10025 | E6: 2772298.6 | F6: 0 | G6: 0 | H6: 0
A7: 5 - SCHELOVER RAUL | B7: 1 | C7: 60.156131 | D7: 287.2725 | E7: 1318036.7 | F7: 0 | G7: 0 | H7: 0
A8: 7 - VALLEJOS EDUARDO | B8: 1 | C8: -0.066666667 | D8: -1.476 | E8: -41520.786 | F8: 0 | G8: 0 | H8: 0
A9: 8 - RAVAROTTO EMANUEL | B9: 1 | C9: 27.220536 | D9: 123.7475 | E9: 488198.71 | F9: 0 | G9: 0 | H9: 0
A10: 9 - ESTIGARRIBIA DAVID | B10: 1 | C10: 11.962698 | D10: 24.005833 | E10: 560866.84 | F10: 0 | G10: 0 | H10: 0
A11: 10 - BRITEZ EMMANUEL | B11: 1 | C11: 14.28254 | D11: 69.213929 | E11: 235546.28 | F11: 0 | G11: 0 | H11: 0
A12: 11 - SANCHEZ RICARDO | B12: 1 | C12: 24.419048 | D12: 85.116667 | E12: 673949.31 | F12: 0 | G12: 0 | H12: 0
A13: 12 - GUTIERREZ MARCOS DAVID | B13: 1 | C13: 143.69901 | D13: 557.1525 | E13: 2694955.2 | F13: 0 | G13: 0 | H13: 0
... A38: 100 - MOSTRADOR | B38: 1 | C38: 16.25 | D38: 38 | E38: 316968.01 | F38: 0 | G38: 0 | H38: 0

Sheet AVANCE
A1: SUPERVISOR | B1: VENDEDOR | C1: OBJETIVO | D1: FACTURACION ACUMULADA | E1: FACTURACION N-1 | F1: FACTURACION DEL DIA | G1: AVANCE VS OBJETIVO | H1: PROYECCION | I1: CUMPLIMIENTO PROYECTADO | J1: MEDIA REAL | K1: MEDIA NECESARIA | L1: COBRO
A2: MARTIN PREVENTA | B2: 20 - FLORES JAVIER | C2: 32279077 | D2: =IFERROR(+VLOOKUP(B2,COMISIONES!A:E,5,FALSE),"0")*1 -> 1379496.3 | F2: =+D2-E2 -> 1379496.3 | G2: =+D2/C2 -> 0.042736546 | H2: =+D2/$N$3*$N$4 -> 33107910 | I2: =+H2/C2 -> 1.0256771 | J2: =+D2/$N$3 -> 1379496.3 | K2: =+(C2-D2)/$N$2 -> 1343460 | L2: {=+_xlfn.IFS(I2>114%,H2*0.02,I2>109%,H2*0.015,I2>104%,H2*0.0125,I2>99%,H2*0.01,I2<99%,H2*0)} -> 331079.1 | M2: DIAS DE TRABAJO RESTANTES | N2: 23
B3: 19 - GONZALEZ MARCELO | C3: 30982728 | D3: =IFERROR(+VLOOKUP(B3,COMISIONES!A:E,5,FALSE),"0")*1 -> 1210391.5 | F3: =+D3-E3 -> 1210391.5 | G3: =+D3/C3 -> 0.039066654 | H3: =+D3/$N$3*$N$4 -> 29049396 | I3: =+H3/C3 -> 0.93759969 | J3: =+D3/$N$3 -> 1210391.5 | K3: =+(C3-D3)/$N$2 -> 1294449.4 | L3: {=+_xlfn.IFS(I3>114%,H3*0.02,I3>109%,H3*0.015,I3>104%,H3*0.0125,I3>99%,H3*0.01,I3<99%,H3*0)} -> 0 | M3: DIAS TRABAJADOS | N3: =N4-N2 -> 1
B4: 16 - GOMEZ MATÍAS | C4: 28390031 | D4: =IFERROR(+VLOOKUP(B4,COMISIONES!A:E,5,FALSE),"0")*1 -> 1183899.2 | F4: =+D4-E4 -> 1183899.2 | G4: =+D4/C4 -> 0.041701229 | H4: =+D4/$N$3*$N$4 -> 28413581 | I4: =+H4/C4 -> 1.0008295 | J4: =+D4/$N$3 -> 1183899.2 | K4: =+(C4-D4)/$N$2 -> 1182875.3 | L4: {=+_xlfn.IFS(I4>114%,H4*0.02,I4>109%,H4*0.015,I4>104%,H4*0.0125,I4>99%,H4*0.01,I4<99%,H4*0)} -> 284135.81 | M4: DIAS DE TRABAJO MES | N4: 24
B5: 12 - GUTIERREZ MARCOS DAVID | C5: 28390031 | D5: =IFERROR(+VLOOKUP(B5,COMISIONES!A:E,5,FALSE),"0")*1 -> 2694955.2 | F5: =+D5-E5 -> 2694955.2 | G5: =+D5/C5 -> 0.094926109 | H5: =+D5/$N$3*$N$4 -> 64678925 | I5: =+H5/C5 -> 2.2782266 | J5: =+D5/$N$3 -> 2694955.2 | K5: =+(C5-D5)/$N$2 -> 1117177.2 | L5: {=+_xlfn.IFS(I5>114%,H5*0.02,I5>109%,H5*0.015,I5>104%,H5*0.0125,I5>99%,H5*0.01,I5<99%,H5*0)} -> 1293578.5
B6: 11 - SANCHEZ RICARDO | C6: 23528725 | D6: =IFERROR(+VLOOKUP(B6,COMISIONES!A:E,5,FALSE),"0")*1 -> 673949.31 | F6: =+D6-E6 -> 673949.31 | G6: =+D6/C6 -> 0.028643682 | H6: =+D6/$N$3*$N$4 -> 16174784 | I6: =+H6/C6 -> 0.68744838 | J6: =+D6/$N$3 -> 673949.31 | K6: =+(C6-D6)/$N$2 -> 993685.88 | L6: {=+_xlfn.IFS(I6>114%,H6*0.02,I6>109%,H6*0.015,I6>104%,H6*0.0125,I6>99%,H6*0.01,I6<99%,H6*0)} -> 0
B7: 8 - RAVAROTTO EMANUEL | C7: 27741857 | D7: =IFERROR(+VLOOKUP(B7,COMISIONES!A:E,5,FALSE),"0")*1 -> 488198.71 | F7: =+D7-E7 -> 488198.71 | G7: =+D7/C7 -> 0.01759791 | H7: =+D7/$N$3*$N$4 -> 11716769 | I7: =+H7/C7 -> 0.42234985 | J7: =+D7/$N$3 -> 488198.71 | K7: =+(C7-D7)/$N$2 -> 1184941.7 | L7: {=+_xlfn.IFS(I7>114%,H7*0.02,I7>109%,H7*0.015,I7>104%,H7*0.0125,I7>99%,H7*0.01,I7<99%,H7*0)} -> 0
B8: 5 - SCHELOVER RAUL | C8: 35831071 | D8: =IFERROR(+VLOOKUP(B8,COMISIONES!A:E,5,FALSE),"0")*1 -> 1318036.7 | F8: =+D8-E8 -> 1318036.7 | G8: =+D8/C8 -> 0.036784741 | H8: =+D8/$N$3*$N$4 -> 31632880 | I8: =+H8/C8 -> 0.88283378 | J8: =+D8/$N$3 -> 1318036.7 | K8: =+(C8-D8)/$N$2 -> 1500566.7 | L8: {=+_xlfn.IFS(I8>114%,H8*0.02,I8>109%,H8*0.015,I8>104%,H8*0.0125,I8>99%,H8*0.01,I8<99%,H8*0)} -> 0
B9: 4 - TUR SPRINGER FERNANDO | C9: 35831071 | D9: =IFERROR(+VLOOKUP(B9,COMISIONES!A:E,5,FALSE),"0")*1 -> 2772298.6 | F9: =+D9-E9 -> 2772298.6 | G9: =+D9/C9 -> 0.077371357 | H9: =+D9/$N$3*$N$4 -> 66535167 | I9: =+H9/C9 -> 1.8569126 | J9: =+D9/$N$3 -> 2772298.6 | K9: =+(C9-D9)/$N$2 -> 1437337.9 | L9: {=+_xlfn.IFS(I9>114%,H9*0.02,I9>109%,H9*0.015,I9>104%,H9*0.0125,I9>99%,H9*0.01,I9<99%,H9*0)} -> 1330703.3
C10: 2.4297459e+08 | D10: =+SUM(D2:D9) -> 11721225 | F10: =+SUM(F2:F9) -> 11721225 | G10: =+D10/C10 -> 0.04824054 | H10: =+D10/$N$3*$N$4 -> 2.8130941e+08 | I10: =+H10/C10 -> 1.157773 | J10: =+D10/$N$3 -> 11721225 | K10: =+(C10-D10)/$N$2 -> 10054494
A11: MARTIN | B11: 22 - ALMIRON NICOLAS | C11: 96971948 | D11: =IFERROR(+VLOOKUP(B11,COMISIONES!A:E,5,FALSE),"0")*1 -> 1279296.2 | F11: =+D11-E11 -> 1279296.2 | G11: =+D11/C11 -> 0.013192436 | H11: =+D11/$N$3*$N$4 -> 30703109 | I11: =+H11/C11 -> 0.31661846 | J11: =+D11/$N$3 -> 1279296.2 | K11: =+(C11-D11)/$N$2 -> 4160550.1 | L11: {=+_xlfn.IFS(I11>114%,H11*0.0125,I11>109%,H11*0.01,I11>104%,H11*0.0075,I11>99%,H11*0.005,I11<99%,H11*0)} -> 0
B12: 49 - ESCOBAR RAÚL | C12: 31630902 | D12: =IFERROR(+VLOOKUP(B12,COMISIONES!A:E,5,FALSE),"0")*1 -> 7398672 | F12: =+D12-E12 -> 7398672 | G12: =+D12/C12 -> 0.23390645 | H12: =+D12/$N$3*$N$4 -> 1.7756813e+08 | I12: =+H12/C12 -> 5.6137547 | J12: =+D12/$N$3 -> 7398672 | K12: =+(C12-D12)/$N$2 -> 1053575.2 | L12: {=+_xlfn.IFS(I12>114%,H12*0.02,I12>109%,H12*0.015,I12>104%,H12*0.0125,I12>99%,H12*0.01,I12<99%,H12*0)} -> 3551362.5
B13: 15 - GALARZA GERARDO | C13: 1.2836392e+08 | D13: =IFERROR(+VLOOKUP(B13,COMISIONES!A:E,5,FALSE),"0")*1 -> 22103798 | F13: =+D13-E13 -> 22103798 | G13: =+D13/C13 -> 0.17219635 | H13: =+D13/$N$3*$N$4 -> 5.3049116e+08 | I13: =+H13/C13 -> 4.1327125 | J13: =+D13/$N$3 -> 22103798 | K13: =+(C13-D13)/$N$2 -> 4620005.1 | L13: {=+_xlfn.IFS(I13>114%,H13*0.0125,I13>109%,H13*0.01,I13>104%,H13*0.0075,I13>99%,H13*0.005,I13<99%,H13*0)} -> 6631139.5 | M13: AUMENTO OBJ | N13: 0.02
B14: 52 - MARSALL NICOLAS | C14: 42449057 | D14: =IFERROR(+VLOOKUP(B14,COMISIONES!A:E,5,FALSE),"0")*1 -> 483655.59 | F14: =+D14-E14 -> 483655.59 | G14: =+D14/C14 -> 0.011393789 | H14: =+D14/$N$3*$N$4 -> 11607734 | I14: =+H14/C14 -> 0.27345093 | J14: =+D14/$N$3 -> 483655.59 | K14: =+(C14-D14)/$N$2 -> 1824582.7 | L14: {=+_xlfn.IFS(I14>109%,H14*0.015,I14>104%,H14*0.0125,I14>99%,H14*0.01,I14<99%,H14*0)} -> 0
B15: 53 - SANDOVAL RODRIGO | C15: 42449057 | D15: =IFERROR(+VLOOKUP(B15,COMISIONES!A:E,5,FALSE),"0")*1 -> -6760.581 | F15: =+D15-E15 -> -6760.581 | G15: =+D15/C15 -> -0.0001592634 | H15: =+D15/$N$3*$N$4 -> -162253.94 | I15: =+H15/C15 -> -0.0038223215 | J15: =+D15/$N$3 -> -6760.581 | K15: =+(C15-D15)/$N$2 -> 1845905.1 | L15: {=+_xlfn.IFS(I15>109%,H15*0.015,I15>104%,H15*0.0125,I15>99%,H15*0.01,I15<99%,H15*0)} -> 0
C16: 3.4186488e+08 | D16: =+SUM(D11:D15) -> 31258662 | F16: =+D16-E16 -> 31258662 | G16: =+D16/C16 -> 0.09143572 | H16: =+D16/$N$3*$N$4 -> 7.5020788e+08 | I16: =+H16/C16 -> 2.1944573 | J16: =+D16/$N$3 -> 31258662 | K16: =+(C16-D16)/$N$2 -> 13504618
A17: CRISTIAN | B17: 2 - OJEDA NORBERTO | C17: 29338018 | D17: =IFERROR(+VLOOKUP(B17,COMISIONES!A:E,5,FALSE),"0")*1 -> 910195.67 | F17: =+D17-E17 -> 910195.67 | G17: =+D17/C17 -> 0.031024443 | H17: =+D17/$N$3*$N$4 -> 21844696 | I17: =+H17/C17 -> 0.74458663 | J17: =+D17/$N$3 -> 910195.67 | K17: =+(C17-D17)/$N$2 -> 1235992.3 | L17: {=+_xlfn.IFS(I17>114%,H17*0.02,I17>109%,H17*0.015,I17>104%,H17*0.0125,I17>99%,H17*0.01,I17<99%,H17*0)} -> 0
B18: 3 - VIDAL NAHUEL | C18: 24959506 | D18: =IFERROR(+VLOOKUP(B18,COMISIONES!A:E,5,FALSE),"0")*1 -> 501148.96 | F18: =+D18-E18 -> 501148.96 | G18: =+D18/C18 -> 0.020078481 | H18: =+D18/$N$3*$N$4 -> 12027575 | I18: =+H18/C18 -> 0.48188353 | J18: =+D18/$N$3 -> 501148.96 | K18: =+(C18-D18)/$N$2 -> 1063406.8 | L18: {=+_xlfn.IFS(I18>114%,H18*0.02,I18>109%,H18*0.015,I18>104%,H18*0.0125,I18>99%,H18*0.01,I18<99%,H18*0)} -> 0
B19: 18 - HERRERA PABLO | C19: 25856650 | D19: =IFERROR(+VLOOKUP(B19,COMISIONES!A:E,5,FALSE),"0")*1 -> 1123309.4 | F19: =+D19-E19 -> 1123309.4 | G19: =+D19/C19 -> 0.043443734 | H19: =+D19/$N$3*$N$4 -> 26959426 | I19: =+H19/C19 -> 1.0426496 | J19: =+D19/$N$3 -> 1123309.4 | K19: =+(C19-D19)/$N$2 -> 1075362.6 | L19: {=+_xlfn.IFS(I19>114%,H19*0.02,I19>109%,H19*0.015,I19>104%,H19*0.0125,I19>99%,H19*0.01,I19<99%,H19*0)} -> 336992.83
B20: 21 - CATAN MATIAS | C20: 33548130 | D20: =IFERROR(+VLOOKUP(B20,COMISIONES!A:E,5,FALSE),"0")*1 -> 1545484.3 | F20: =+D20-E20 -> 1545484.3 | G20: =+D20/C20 -> 0.046067675 | H20: =+D20/$N$3*$N$4 -> 37091624 | I20: =+H20/C20 -> 1.1056242 | J20: =+D20/$N$3 -> 1545484.3 | K20: =+(C20-D20)/$N$2 -> 1391419.4 | L20: {=+_xlfn.IFS(I20>114%,H20*0.02,I20>109%,H20*0.015,I20>104%,H20*0.0125,I20>99%,H20*0.01,I20<99%,H20*0)} -> 556374.36
B21: 23 - DELGADO JOSÉ | C21: 25458510 | D21: =IFERROR(+VLOOKUP(B21,COMISIONES!A:E,5,FALSE),"0")*1 -> 1299165.9 | F21: =+D21-E21 -> 1299165.9 | G21: =+D21/C21 -> 0.051030713 | H21: =+D21/$N$3*$N$4 -> 31179982 | I21: =+H21/C21 -> 1.2247371 | J21: =+D21/$N$3 -> 1299165.9 | K21: =+(C21-D21)/$N$2 -> 1050406.3 | L21: {=+_xlfn.IFS(I21>114%,H21*0.02,I21>109%,H21*0.015,I21>104%,H21*0.0125,I21>99%,H21*0.01,I21<99%,H21*0)} -> 623599.64
B22: 31 - BARTSCHAT EMILIANO NAHUEL | C22: 31742890 | D22: =IFERROR(+VLOOKUP(B22,COMISIONES!A:E,5,FALSE),"0")*1 -> 1904211.6 | F22: =+D22-E22 -> 1904211.6 | G22: =+D22/C22 -> 0.059988601 | H22: =+D22/$N$3*$N$4 -> 45701078 | I22: =+H22/C22 -> 1.4397264 | J22: =+D22/$N$3 -> 1904211.6 | K22: =+(C22-D22)/$N$2 -> 1297333.9 | L22: {=+_xlfn.IFS(I22>114%,H22*0.02,I22>109%,H22*0.015,I22>104%,H22*0.0125,I22>99%,H22*0.01,I22<99%,H22*0)} -> 914021.56
B23: 44 - MONGES CESAR LUIS | C23: 27435946 | D23: =IFERROR(+VLOOKUP(B23,COMISIONES!A:E,5,FALSE),"0")*1 -> 831624.25 | F23: =+D23-E23 -> 831624.25 | G23: =+D23/C23 -> 0.030311484 | H23: =+D23/$N$3*$N$4 -> 19958982 | I23: =+H23/C23 -> 0.72747562 | J23: =+D23/$N$3 -> 831624.25 | K23: =+(C23-D23)/$N$2 -> 1156709.7 | L23: {=+_xlfn.IFS(I23>114%,H23*0.02,I23>109%,H23*0.015,I23>104%,H23*0.0125,I23>99%,H23*0.01,I23<99%,H23*0)} -> 0
B24: 54 - CAÑETE DIEGO | C24: 33494055 | D24: =IFERROR(+VLOOKUP(B24,COMISIONES!A:E,5,FALSE),"0")*1 -> 855590.57 | F24: =+D24-E24 -> 855590.57 | G24: =+D24/C24 -> 0.02554455 | H24: =+D24/$N$3*$N$4 -> 20534174 | I24: =+H24/C24 -> 0.61306921 | J24: =+D24/$N$3 -> 855590.57 | K24: =+(C24-D24)/$N$2 -> 1419063.7 | L24: {=+_xlfn.IFS(I24>114%,H24*0.02,I24>109%,H24*0.015,I24>104%,H24*0.0125,I24>99%,H24*0.01,I24<99%,H24*0)} -> 0
B25: 56 - JUAN ANDRES SANCHEZ | C25: 54064953 | D25: =IFERROR(+VLOOKUP(B25,COMISIONES!A:E,5,FALSE),"0")*1 -> 0 | F25: =+D25-E25 -> 0 | G25: =+D25/C25 -> 0 | H25: =+D25/$N$3*$N$4 -> 0 | I25: =+H25/C25 -> 0 | J25: =+D25/$N$3 -> 0 | K25: =+(C25-D25)/$N$2 -> 2350650.1 | L25: {=+_xlfn.IFS(I25>109%,H25*0.015,I25>104%,H25*0.0125,I25>99%,H25*0.01,I25<99%,H25*0)} -> 0
C26: 2.8589866e+08 | D26: =+SUM(D17:D25) -> 8970730.7 | F26: =+D26-E26 -> 8970730.7 | G26: =+D26/C26 -> 0.03137731 | H26: =+D26/$N$3*$N$4 -> 2.1529754e+08 | I26: =+H26/C26 -> 0.75305543 | J26: =+D26/$N$3 -> 8970730.7 | K26: =+(C26-D26)/$N$2 -> 12040345
A27: GONZALO | B27: 32 - CABRAL GONZALO | C27: 81977700 | D27: =IFERROR(+VLOOKUP(B27,COMISIONES!A:E,5,FALSE),"0")*1 -> 2145545.3 | F27: =+D27-E27 -> 2145545.3 | G27: =+D27/C27 -> 0.026172304 | H27: =+D27/$N$3*$N$4 -> 51493087 | I27: =+H27/C27 -> 0.62813529 | J27: =+D27/$N$3 -> 2145545.3 | K27: =+(C27-D27)/$N$2 -> 3470963.2 | L27: {=+_xlfn.IFS(I27>114%,H27*0.0125,I27>109%,H27*0.01,I27>104%,H27*0.0075,I27>99%,H27*0.005,I27<99%,H27*0)} -> 0
B28: 36 - COSARINSKI DIEGO | C28: 21000000 | D28: =IFERROR(+VLOOKUP(B28,COMISIONES!A:E,5,FALSE),"0")*1 -> 682680.94 | F28: =+D28-E28 -> 682680.94 | G28: =+D28/C28 -> 0.032508616 | H28: =+D28/$N$3*$N$4 -> 16384342 | I28: =+H28/C28 -> 0.78020679 | J28: =+D28/$N$3 -> 682680.94 | K28: =+(C28-D28)/$N$2 -> 883361.7 | L28: {=+_xlfn.IFS(I28>114%,H28*0.02,I28>109%,H28*0.015,I28>104%,H28*0.0125,I28>99%,H28*0.01,I28<99%,H28*0)} -> 0
B29: 9 - ESTIGARRIBIA DAVID | C29: 25739700 | D29: =IFERROR(+VLOOKUP(B29,COMISIONES!A:E,5,FALSE),"0")*1 -> 560866.84 | F29: =+D29-E29 -> 560866.84 | G29: =+D29/C29 -> 0.021789952 | H29: =+D29/$N$3*$N$4 -> 13460804 | I29: =+H29/C29 -> 0.52295886 | J29: =+D29/$N$3 -> 560866.84 | K29: =+(C29-D29)/$N$2 -> 1094731.9 | L29: {=+_xlfn.IFS(I29>114%,H29*0.02,I29>109%,H29*0.015,I29>104%,H29*0.0125,I29>99%,H29*0.01,I29<99%,H29*0)} -> 0
B30: 40 - IBARROLA JORGE | C30: 38233205 | D30: =IFERROR(+VLOOKUP(B30,COMISIONES!A:E,5,FALSE),"0")*1 -> 1241096.8 | F30: =+D30-E30 -> 1241096.8 | G30: =+D30/C30 -> 0.032461229 | H30: =+D30/$N$3*$N$4 -> 29786324 | I30: =+H30/C30 -> 0.7790695 | J30: =+D30/$N$3 -> 1241096.8 | K30: =+(C30-D30)/$N$2 -> 1608352.5 | L30: {=+_xlfn.IFS(I30>114%,H30*0.02,I30>109%,H30*0.015,I30>104%,H30*0.0125,I30>99%,H30*0.01,I30<99%,H30*0)} -> 0
B31: 27 - GOMEZ ADRIÁN | C31: 25415250 | D31: =IFERROR(+VLOOKUP(B31,COMISIONES!A:E,5,FALSE),"0")*1 -> 967034.52 | F31: =+D31-E31 -> 967034.52 | G31: =+D31/C31 -> 0.038049381 | H31: =+D31/$N$3*$N$4 -> 23208829 | I31: =+H31/C31 -> 0.91318513 | J31: =+D31/$N$3 -> 967034.52 | K31: =+(C31-D31)/$N$2 -> 1062965.9 | L31: {=+_xlfn.IFS(I31>114%,H31*0.02,I31>109%,H31*0.015,I31>104%,H31*0.0125,I31>99%,H31*0.01,I31<99%,H31*0)} -> 0
B32: 10 - BRITEZ EMMANUEL | C32: 25200000 | D32: =IFERROR(+VLOOKUP(B32,COMISIONES!A:E,5,FALSE),"0")*1 -> 235546.28 | F32: =+D32-E32 -> 235546.28 | G32: =+D32/C32 -> 0.0093470746 | H32: =+D32/$N$3*$N$4 -> 5653110.7 | I32: =+H32/C32 -> 0.22432979 | J32: =+D32/$N$3 -> 235546.28 | K32: =+(C32-D32)/$N$2 -> 1085411 | L32: {=+_xlfn.IFS(I32>114%,H32*0.02,I32>109%,H32*0.015,I32>104%,H32*0.0125,I32>99%,H32*0.01,I32<99%,H32*0)} -> 0
B33: 28 - GOMEZ PABLO | C33: 26496750 | D33: =IFERROR(+VLOOKUP(B33,COMISIONES!A:E,5,FALSE),"0")*1 -> 370995.2 | F33: =+D33-E33 -> 370995.2 | G33: =+D33/C33 -> 0.014001536 | H33: =+D33/$N$3*$N$4 -> 8903884.8 | I33: =+H33/C33 -> 0.33603687 | J33: =+D33/$N$3 -> 370995.2 | K33: =+(C33-D33)/$N$2 -> 1135902.4 | L33: {=+_xlfn.IFS(I33>114%,H33*0.02,I33>109%,H33*0.015,I33>104%,H33*0.0125,I33>99%,H33*0.01,I33<99%,H33*0)} -> 0
B34: 33 - NICOLAS AZULA | C34: 21000000 | D34: =IFERROR(+VLOOKUP(B34,COMISIONES!A:E,5,FALSE),"0")*1 -> 602361.46 | F34: =+D34-E34 -> 602361.46 | G34: =+D34/C34 -> 0.028683879 | H34: =+D34/$N$3*$N$4 -> 14456675 | I34: =+H34/C34 -> 0.68841309 | J34: =+D34/$N$3 -> 602361.46 | K34: =+(C34-D34)/$N$2 -> 886853.85 | L34: {=+_xlfn.IFS(I34>114%,H34*0.02,I34>109%,H34*0.015,I34>104%,H34*0.0125,I34>99%,H34*0.01,I34<99%,H34*0)} -> 0
B35: 37 - PEREZ ESQUIVEL BRUNO NICOLAS | C35: 24658200 | D35: =IFERROR(+VLOOKUP(B35,COMISIONES!A:E,5,FALSE),"0")*1 -> 269184.14 | F35: =+D35-E35 -> 269184.14 | G35: =+D35/C35 -> 0.010916618 | H35: =+D35/$N$3*$N$4 -> 6460419.3 | I35: =+H35/C35 -> 0.26199882 | J35: =+D35/$N$3 -> 269184.14 | K35: =+(C35-D35)/$N$2 -> 1060392 | L35: {=+_xlfn.IFS(I35>114%,H35*0.02,I35>109%,H35*0.015,I35>104%,H35*0.0125,I35>99%,H35*0.01,I35<99%,H35*0)} -> 0
B36: 24 - MARTINEZ JORGE NICOLAS | C36: 25235000 | D36: =IFERROR(+VLOOKUP(B36,COMISIONES!A:E,5,FALSE),"0")*1 -> 1074255.4 | F36: =+D36-E36 -> 1074255.4 | G36: =+D36/C36 -> 0.042570058 | H36: =+D36/$N$3*$N$4 -> 25782130 | I36: =+H36/C36 -> 1.0216814 | J36: =+D36/$N$3 -> 1074255.4 | K36: =+(C36-D36)/$N$2 -> 1050467.2 | L36: {=+_xlfn.IFS(I36>114%,H36*0.02,I36>109%,H36*0.015,I36>104%,H36*0.0125,I36>99%,H36*0.01,I36<99%,H36*0)} -> 257821.3
B37: 7 - VALLEJOS EDUARDO | C37: 122011750 | D37: =IFERROR(+VLOOKUP(B37,COMISIONES!A:E,5,FALSE),"0")*1 -> -41520.786 | F37: =+D37-E37 -> -41520.786 | G37: =+D37/C37 -> -0.00034030153 | H37: =+D37/$N$3*$N$4 -> -996498.86 | I37: =+H37/C37 -> -0.0081672368 | J37: =+D37/$N$3 -> -41520.786 | K37: =+(C37-D37)/$N$2 -> 5306663.9 | L37: {=+_xlfn.IFS(I37>114%,H37*0.0125,I37>109%,H37*0.01,I37>104%,H37*0.0075,I37>99%,H37*0.005,I37<99%,H37*0)} -> 0
B38: 57 - ROUBINEAU SEBASTIAN | C38: 35700000 | D38: =IFERROR(+VLOOKUP(B38,COMISIONES!A:E,5,FALSE),"0")*1 -> 0 | F38: =+D38-E38 -> 0 | G38: =+D38/C38 -> 0 | H38: =+D38/$N$3*$N$4 -> 0 | I38: =+H38/C38 -> 0 | J38: =+D38/$N$3 -> 0 | K38: =+(C38-D38)/$N$2 -> 1552173.9 | L38: {=+_xlfn.IFS(I38>109%,H38*0.015,I38>104%,H38*0.0125,I38>99%,H38*0.01,I38<99%,H38*0)} -> 0
B39: 1 - VERA ERNESTO | C39: 36361428 | D39: =IFERROR(+VLOOKUP(B39,COMISIONES!A:E,5,FALSE),"0")*1 -> 2409808.7 | F39: =+D39-E39 -> 2409808.7 | G39: =+D39/C39 -> 0.066273764 | H39: =+D39/$N$3*$N$4 -> 57835408 | I39: =+H39/C39 -> 1.5905703 | J39: =+D39/$N$3 -> 2409808.7 | K39: =+(C39-D39)/$N$2 -> 1476157.4 | L39: {=+_xlfn.IFS(I39>114%,H39*0.02,I39>109%,H39*0.015,I39>104%,H39*0.0125,I39>99%,H39*0.01,I39<99%,H39*0)} -> 1156708.2
C40: 5.0902898e+08 | D40: =+SUM(D27:D39) -> 10517855 | F40: =+D40-E40 -> 10517855 | G40: =+D40/C40 -> 0.020662585 | H40: =+D40/$N$3*$N$4 -> 2.5242852e+08 | I40: =+H40/C40 -> 0.49590205 | J40: =+D40/$N$3 -> 10517855 | K40: =+(C40-D40)/$N$2 -> 21674397
...

Sheet COBERTURA
A1: SUPERVISOR | C1: VENDEDOR | D1: COBERTURA TOTAL | E1: DIA ANTERIOR | F1: INCREMENTO DIARIO | G1: CARTERA TOTAL | H1: CCC | I1: CCC FALTANTE 85% | P1: Cod vdor | R1: Cobertura x Un de negocio
A2: MARTIN (SUPERVISOR) | B2: 22 | C2: =+AVANCE!B11 -> 22 - ALMIRON NICOLAS | D2: =H2/G2 -> 0.79166667 | E2: 33 | F2: =+H2-E2 -> 24 | G2: =VLOOKUP(B2,'Base Cobertura'!$A:$C,3,FALSE) -> 72 | H2: =VLOOKUP(B2,'Base Cobertura'!$A:$C,2,FALSE) -> 57 | I2: =(+G2*$M$2)-H2 -> 4.2 | J2: bien | K2: bien | L2: OBJETIVO | M2: 0.85 | P2: 12 | Q2: =VLOOKUP(P2,$B:$C,2,FALSE) -> 12 - GUTIERREZ MARCOS DAVID | R2: =VLOOKUP(P2,$B:$C,2,FALSE) -> 12 - GUTIERREZ MARCOS DAVID | S2: CCC | T2: CARTERA TOTAL | U2: % ALCANZADO
B3: 49 | C3: =+AVANCE!B12 -> 49 - ESCOBAR RAÚL | D3: =H3/G3 -> 0.42259414 | E3: 1 | F3: =+H3-E3 -> 100 | G3: =VLOOKUP(B3,'Base Cobertura'!$A:$C,3,FALSE) -> 239 | H3: =VLOOKUP(B3,'Base Cobertura'!$A:$C,2,FALSE) -> 101 | I3: =(+G3*$M$2)-H3 -> 102.15 | J3: mal | K3: chaca | P3: {=+_xlfn._xlws.FILTER('Base Cobertura'!E:I,'Base Cobertura'!E:E=COBERTURA!P2)} -> 12 | Q3: 12 | R3: 148 - ALMACEN | S3: 66 | T3: 213 | U3: =+S3/T3 -> 0.30985915
B4: 20 | C4: =+AVANCE!B2 -> 20 - FLORES JAVIER | D4: =H4/G4 -> 0.92920354 | E4: 126 | F4: =+H4-E4 -> 84 | G4: =VLOOKUP(B4,'Base Cobertura'!$A:$C,3,FALSE) -> 226 | H4: =VLOOKUP(B4,'Base Cobertura'!$A:$C,2,FALSE) -> 210 | I4: =(+G4*$M$2)-H4 -> -17.9 | J4: re bien | K4: muy bien | P4: 12 | Q4: 0 | R4: 148 - Articulos Sin Asociar Agrupacion | S4: 58 | T4: 213 | U4: =+S4/T4 -> 0.27230047
B5: 15 | C5: =+AVANCE!B13 -> 15 - GALARZA GERARDO | D5: =H5/G5 -> 0.81538462 | E5: 21 | F5: =+H5-E5 -> 32 | G5: =VLOOKUP(B5,'Base Cobertura'!$A:$C,3,FALSE) -> 65 | H5: =VLOOKUP(B5,'Base Cobertura'!$A:$C,2,FALSE) -> 53 | I5: =(+G5*$M$2)-H5 -> 2.25 | K5: muy bien | P5: 12 | Q5: 0 | R5: 148 - BEBIDAS | S5: 90 | T5: 213 | U5: =+S5/T5 -> 0.42253521
B6: 19 | C6: =+AVANCE!B3 -> 19 - GONZALEZ MARCELO | D6: =H6/G6 -> 0.88405797 | E6: 100 | F6: =+H6-E6 -> 83 | G6: =VLOOKUP(B6,'Base Cobertura'!$A:$C,3,FALSE) -> 207 | H6: =VLOOKUP(B6,'Base Cobertura'!$A:$C,2,FALSE) -> 183 | I6: =(+G6*$M$2)-H6 -> -7.05 | J6: apretarlo | K6: apretarlo | P6: 12 | Q6: 0 | R6: 148 - CHOCOLATE | S6: 51 | T6: 213 | U6: =+S6/T6 -> 0.23943662
B7: 16 | C7: =+AVANCE!B4 -> 16 - GOMEZ MATÍAS | D7: =H7/G7 -> 0.85858586 | E7: 81 | F7: =+H7-E7 -> 89 | G7: =VLOOKUP(B7,'Base Cobertura'!$A:$C,3,FALSE) -> 198 | H7: =VLOOKUP(B7,'Base Cobertura'!$A:$C,2,FALSE) -> 170 | I7: =(+G7*$M$2)-H7 -> -1.7 | J7: apretarlo | K7: apretarlo | P7: 12 | Q7: 0 | R7: 148 - GALLETITAS | S7: 107 | T7: 213 | U7: =+S7/T7 -> 0.50234742
B8: 12 | C8: =+AVANCE!B5 -> 12 - GUTIERREZ MARCOS DAVID | D8: =H8/G8 -> 0.85915493 | E8: 89 | F8: =+H8-E8 -> 94 | G8: =VLOOKUP(B8,'Base Cobertura'!$A:$C,3,FALSE) -> 213 | H8: =VLOOKUP(B8,'Base Cobertura'!$A:$C,2,FALSE) -> 183 | I8: =(+G8*$M$2)-H8 -> -1.95 | J8: bien | K8: apretarlo | P8: 12 | Q8: 0 | R8: 148 - GOLOSINAS | S8: 83 | T8: 213 | U8: =+S8/T8 -> 0.38967136
B9: 11 | C9: =+AVANCE!B6 -> 11 - SANCHEZ RICARDO | D9: =H9/G9 -> 0.74074074 | E9: 92 | F9: =+H9-E9 -> 28 | G9: =VLOOKUP(B9,'Base Cobertura'!$A:$C,3,FALSE) -> 162 | H9: =VLOOKUP(B9,'Base Cobertura'!$A:$C,2,FALSE) -> 120 | I9: =(+G9*$M$2)-H9 -> 17.7 | J9: bien | K9: apretarlo con ema | P9: 12 | Q9: 0 | R9: 148 - MASCOTAS | S9: 22 | T9: 213 | U9: =+S9/T9 -> 0.10328638
B10: 8 | C10: =+AVANCE!B7 -> 8 - RAVAROTTO EMANUEL | D10: =H10/G10 -> 0.86597938 | E10: 64 | F10: =+H10-E10 -> 104 | G10: =VLOOKUP(B10,'Base Cobertura'!$A:$C,3,FALSE) -> 194 | H10: =VLOOKUP(B10,'Base Cobertura'!$A:$C,2,FALSE) -> 168 | I10: =(+G10*$M$2)-H10 -> -3.1 | J10: apretarlo | K10: apretarlo | P10: 12 | Q10: 0 | R10: 148 - NO PERECEDEROS | S10: 46 | T10: 213 | U10: =+S10/T10 -> 0.21596244
B11: 52 | C11: =+AVANCE!B14 -> 52 - MARSALL NICOLAS | D11: =H11/G11 -> 0.57425743 | E11: 19 | F11: =+H11-E11 -> 39 | G11: =VLOOKUP(B11,'Base Cobertura'!$A:$C,3,FALSE) -> 101 | H11: =VLOOKUP(B11,'Base Cobertura'!$A:$C,2,FALSE) -> 58 | I11: =(+G11*$M$2)-H11 -> 27.85 | J11: verlo | P11: 12 | Q11: 0 | R11: 148 - PILAS | S11: 51 | T11: 213 | U11: =+S11/T11 -> 0.23943662
B12: 53 | C12: =+AVANCE!B15 -> 53 - SANDOVAL RODRIGO | D12: =H12/G12 -> 0.64761905 | E12: 24 | F12: =+H12-E12 -> 44 | G12: =VLOOKUP(B12,'Base Cobertura'!$A:$C,3,FALSE) -> 105 | H12: =VLOOKUP(B12,'Base Cobertura'!$A:$C,2,FALSE) -> 68 | I12: =(+G12*$M$2)-H12 -> 21.25 | J12: verlo
B13: 5 | C13: =+AVANCE!B8 -> 5 - SCHELOVER RAUL | D13: =H13/G13 -> 0.90384615 | E13: 144 | F13: =+H13-E13 -> 91 | G13: =VLOOKUP(B13,'Base Cobertura'!$A:$C,3,FALSE) -> 260 | H13: =VLOOKUP(B13,'Base Cobertura'!$A:$C,2,FALSE) -> 235 | I13: =(+G13*$M$2)-H13 -> -14 | J13: re bien | K13: muy bien
B14: 4 | C14: =+AVANCE!B9 -> 4 - TUR SPRINGER FERNANDO | D14: =H14/G14 -> 0.87912088 | E14: 85 | F14: =+H14-E14 -> 75 | G14: =VLOOKUP(B14,'Base Cobertura'!$A:$C,3,FALSE) -> 182 | H14: =VLOOKUP(B14,'Base Cobertura'!$A:$C,2,FALSE) -> 160 | I14: =(+G14*$M$2)-H14 -> -5.3 | J14: bien | K14: muy bien
F15: =+SUM(F2:F14) -> 887 | G15: =+SUM(G2:G14) -> 2224 | H15: =+SUM(H2:H14) -> 1766
A16: CRISTIAN (SUPERVISOR) | B16: 31 | C16: =+AVANCE!B22 -> 31 - BARTSCHAT EMILIANO NAHUEL | D16: =H16/G16 -> 0.8757764 | E16: 90 | F16: =+H16-E16 -> 51 | G16: =VLOOKUP(B16,'Base Cobertura'!$A:$C,3,FALSE) -> 161 | H16: =VLOOKUP(B16,'Base Cobertura'!$A:$C,2,FALSE) -> 141 | I16: =(+G16*$M$2)-H16 -> -4.15 | J16: bien | K16: bien
B17: 54 | C17: =+AVANCE!B24 -> 54 - CAÑETE DIEGO | D17: =H17/G17 -> 0.74752475 | E17: 92 | F17: =+H17-E17 -> 59 | G17: =VLOOKUP(B17,'Base Cobertura'!$A:$C,3,FALSE) -> 202 | H17: =VLOOKUP(B17,'Base Cobertura'!$A:$C,2,FALSE) -> 151 | I17: =(+G17*$M$2)-H17 -> 20.7 | J17: bien | K17: chaca
B18: 21 | C18: =+AVANCE!B20 -> 21 - CATAN MATIAS | D18: =H18/G18 -> 0.8816568 | E18: 88 | F18: =+H18-E18 -> 61 | G18: =VLOOKUP(B18,'Base Cobertura'!$A:$C,3,FALSE) -> 169 | H18: =VLOOKUP(B18,'Base Cobertura'!$A:$C,2,FALSE) -> 149 | I18: =(+G18*$M$2)-H18 -> -5.35 | J18: apretarlo | K18: bien
B19: 23 | C19: =+AVANCE!B21 -> 23 - DELGADO JOSÉ | D19: =H19/G19 -> 0.86875 | E19: 95 | F19: =+H19-E19 -> 44 | G19: =VLOOKUP(B19,'Base Cobertura'!$A:$C,3,FALSE) -> 160 | H19: =VLOOKUP(B19,'Base Cobertura'!$A:$C,2,FALSE) -> 139 | I19: =(+G19*$M$2)-H19 -> -3 | J19: apretarlo | K19: muy bien
B20: 18 | C20: =+AVANCE!B19 -> 18 - HERRERA PABLO | D20: =H20/G20 -> 0.90340909 | E20: 83 | F20: =+H20-E20 -> 76 | G20: =VLOOKUP(B20,'Base Cobertura'!$A:$C,3,FALSE) -> 176 | H20: =VLOOKUP(B20,'Base Cobertura'!$A:$C,2,FALSE) -> 159 | I20: =(+G20*$M$2)-H20 -> -9.4 | J20: bien | K20: bien
B21: 44 | C21: =+AVANCE!B23 -> 44 - MONGES CESAR LUIS | D21: =H21/G21 -> 0.85798817 | E21: 64 | F21: =+H21-E21 -> 81 | G21: =VLOOKUP(B21,'Base Cobertura'!$A:$C,3,FALSE) -> 169 | H21: =VLOOKUP(B21,'Base Cobertura'!$A:$C,2,FALSE) -> 145 | I21: =(+G21*$M$2)-H21 -> -1.35 | J21: apretarlo | K21: muy bien
B22: 56 | C22: =+AVANCE!B25 -> 56 - JUAN ANDRES SANCHEZ | D22: =H22/G22 -> 0.51515152 | E22: 66 | F22: =+H22-E22 -> 36 | G22: =VLOOKUP(B22,'Base Cobertura'!$A:$C,3,FALSE) -> 198 | H22: =VLOOKUP(B22,'Base Cobertura'!$A:$C,2,FALSE) -> 102 | I22: =(+G22*$M$2)-H22 -> 66.3 | J22: apretarlo | K22: apretar/charlar
B23: 2 | C23: =+AVANCE!B17 -> 2 - OJEDA NORBERTO | D23: =H23/G23 -> 0.88405797 | E23: 70 | F23: =+H23-E23 -> 52 | G23: =VLOOKUP(B23,'Base Cobertura'!$A:$C,3,FALSE) -> 138 | H23: =VLOOKUP(B23,'Base Cobertura'!$A:$C,2,FALSE) -> 122 | I23: =(+G23*$M$2)-H23 -> -4.7 | J23: apretarlo | K23: apretar
B24: 3 | C24: =+AVANCE!B18 -> 3 - VIDAL NAHUEL | D24: =H24/G24 -> 0.91176471 | E24: 79 | F24: =+H24-E24 -> 76 | G24: =VLOOKUP(B24,'Base Cobertura'!$A:$C,3,FALSE) -> 170 | H24: =VLOOKUP(B24,'Base Cobertura'!$A:$C,2,FALSE) -> 155 | I24: =(+G24*$M$2)-H24 -> -10.5 | J24: abrazo | K24: muy bien
F25: =+SUM(F16:F24) -> 536 | G25: =+SUM(G16:G24) -> 1543 | H25: =+SUM(H16:H24) -> 1263
A26: GONZALO (SUPERVISOR) | B26: 32 | C26: =+AVANCE!B27 -> 32 - CABRAL GONZALO | D26: =H26/G26 -> 0.89285714 | E26: 20 | F26: =+H26-E26 -> 30 | G26: =VLOOKUP(B26,'Base Cobertura'!$A:$C,3,FALSE) -> 56 | H26: =VLOOKUP(B26,'Base Cobertura'!$A:$C,2,FALSE) -> 50 | I26: =(+G26*$M$2)-H26 -> -2.4 | J26: bien | K26: apretar
B27: 36 | C27: =+AVANCE!B28 -> 36 - COSARINSKI DIEGO | D27: =H27/G27 -> 0.60897436 | E27: 68 | F27: =+H27-E27 -> 27 | G27: =VLOOKUP(B27,'Base Cobertura'!$A:$C,3,FALSE) -> 156 | H27: =VLOOKUP(B27,'Base Cobertura'!$A:$C,2,FALSE) -> 95 | I27: =(+G27*$M$2)-H27 -> 37.6 | J27: apretarlo | K27: apretar
B28: 9 | C28: =+AVANCE!B29 -> 9 - ESTIGARRIBIA DAVID | D28: =H28/G28 -> 0.86335404 | E28: 80 | F28: =+H28-E28 -> 59 | G28: =VLOOKUP(B28,'Base Cobertura'!$A:$C,3,FALSE) -> 161 | H28: =VLOOKUP(B28,'Base Cobertura'!$A:$C,2,FALSE) -> 139 | I28: =(+G28*$M$2)-H28 -> -2.15 | J28: apretarlo | K28: bien
B29: 40 | C29: =+AVANCE!B30 -> 40 - IBARROLA JORGE | D29: =H29/G29 -> 0.5060241 | E29: 68 | F29: =+H29-E29 -> 58 | G29: =VLOOKUP(B29,'Base Cobertura'!$A:$C,3,FALSE) -> 249 | H29: =VLOOKUP(B29,'Base Cobertura'!$A:$C,2,FALSE) -> 126 | I29: =(+G29*$M$2)-H29 -> 85.65 | J29: apretarlo | K29: apretar
B30: 27 | C30: =+AVANCE!B31 -> 27 - GOMEZ ADRIÁN | D30: =H30/G30 -> 0.89285714 | E30: 73 | F30: =+H30-E30 -> 52 | G30: =VLOOKUP(B30,'Base Cobertura'!$A:$C,3,FALSE) -> 140 | H30: =VLOOKUP(B30,'Base Cobertura'!$A:$C,2,FALSE) -> 125 | I30: =(+G30*$M$2)-H30 -> -6 | J30: bien | K30: apretar
B31: 10 | C31: =+AVANCE!B32 -> 10 - BRITEZ EMMANUEL | D31: =H31/G31 -> 0.72928177 | E31: 40 | F31: =+H31-E31 -> 92 | G31: =VLOOKUP(B31,'Base Cobertura'!$A:$C,3,FALSE) -> 181 | H31: =VLOOKUP(B31,'Base Cobertura'!$A:$C,2,FALSE) -> 132 | I31: =(+G31*$M$2)-H31 -> 21.85 | J31: apretarlo | K31: apretar
B32: 28 | C32: =+AVANCE!B33 -> 28 - GOMEZ PABLO | D32: =H32/G32 -> 0.875 | E32: 67 | F32: =+H32-E32 -> 80 | G32: =VLOOKUP(B32,'Base Cobertura'!$A:$C,3,FALSE) -> 168 | H32: =VLOOKUP(B32,'Base Cobertura'!$A:$C,2,FALSE) -> 147 | I32: =(+G32*$M$2)-H32 -> -4.2 | J32: apretarlo | K32: apretar
B33: 33 | C33: =+AVANCE!B34 -> 33 - NICOLAS AZULA | D33: =H33/G33 -> 0.79069767 | E33: 66 | F33: =+H33-E33 -> 70 | G33: =VLOOKUP(B33,'Base Cobertura'!$A:$C,3,FALSE) -> 172 | H33: =VLOOKUP(B33,'Base Cobertura'!$A:$C,2,FALSE) -> 136 | I33: =(+G33*$M$2)-H33 -> 10.2 | J33: apretarlo | K33: apretar
B34: 37 | C34: =+AVANCE!B35 -> 37 - PEREZ ESQUIVEL BRUNO NICOLAS | D34: =H34/G34 -> 0.72340426 | E34: 82 | F34: =+H34-E34 -> 20 | G34: =VLOOKUP(B34,'Base Cobertura'!$A:$C,3,FALSE) -> 141 | H34: =VLOOKUP(B34,'Base Cobertura'!$A:$C,2,FALSE) -> 102 | I34: =(+G34*$M$2)-H34 -> 17.85 | J34: bien | K34: apretar
B35: 24 | C35: =+AVANCE!B36 -> 24 - MARTINEZ JORGE NICOLAS | D35: =H35/G35 -> 0.7247191 | E35: 81 | F35: =+H35-E35 -> 48 | G35: =VLOOKUP(B35,'Base Cobertura'!$A:$C,3,FALSE) -> 178 | H35: =VLOOKUP(B35,'Base Cobertura'!$A:$C,2,FALSE) -> 129 | I35: =(+G35*$M$2)-H35 -> 22.3 | J35: apretarlo | K35: apretar
B36: 7 | C36: =+AVANCE!B37 -> 7 - VALLEJOS EDUARDO | D36: =H36/G36 -> 0.25663717 | E36: 0 | F36: =+H36-E36 -> 29 | G36: =VLOOKUP(B36,'Base Cobertura'!$A:$C,3,FALSE) -> 113 | H36: =VLOOKUP(B36,'Base Cobertura'!$A:$C,2,FALSE) -> 29 | I36: =(+G36*$M$2)-H36 -> 67.05 | J36: apretarlo
B37: 57 | C37: =+AVANCE!B38 -> 57 - ROUBINEAU SEBASTIAN | D37: =H37/G37 -> 0.22330097 | E37: 17 | F37: =+H37-E37 -> 6 | G37: =VLOOKUP(B37,'Base Cobertura'!$A:$C,3,FALSE) -> 103 | H37: =VLOOKUP(B37,'Base Cobertura'!$A:$C,2,FALSE) -> 23 | I37: =(+G37*$M$2)-H37 -> 64.55 | J37: verlo
B38: 1 | C38: =+AVANCE!B39 -> 1 - VERA ERNESTO | D38: =H38/G38 -> 0.88976378 | E38: 60 | F38: =+H38-E38 -> 53 | G38: =VLOOKUP(B38,'Base Cobertura'!$A:$C,3,FALSE) -> 127 | H38: =VLOOKUP(B38,'Base Cobertura'!$A:$C,2,FALSE) -> 113 | I38: =(+G38*$M$2)-H38 -> -5.05 | J38: bien | K38: bien
F39: =+SUM(F26:F38) -> 624 | G39: =+SUM(G26:G38) -> 1945 | H39: =+SUM(H26:H38) -> 1346 | L39: TOTAL CANALES
A40: LOPEZ ENZO | F40: =+SUM(F39+F25+F15) -> 2047 | G40: =+G15+G25+G39 -> 5712 | H40: =+H15+H25+H39 -> 4375 | L40: =+H40/G40 -> 0.76593137
...

Sheet Venta C
B1: VENDEDOR/ SUPERVISOR | C1: Venta NETA ARTICULOS C
A2: 20 | B2: 20 - FLORES JAVIER | C2: =IFERROR(VLOOKUP(A2,'Base venta C'!$E:$P,12,FALSE),"0")*1 -> 343887.46
A3: 19 | B3: 19 - GONZALEZ MARCELO | C3: =IFERROR(VLOOKUP(A3,'Base venta C'!$E:$P,12,FALSE),"0")*1 -> 365262.82
A4: 16 | B4: 16 - GOMEZ MATÍAS | C4: =IFERROR(VLOOKUP(A4,'Base venta C'!$E:$P,12,FALSE),"0")*1 -> 271002.4
A5: 12 | B5: 12 - GUTIERREZ MARCOS DAVID | C5: =IFERROR(VLOOKUP(A5,'Base venta C'!$E:$P,12,FALSE),"0")*1 -> 284624.48
A6: 11 | B6: 11 - ZACARIAS DAVID | C6: =IFERROR(VLOOKUP(A6,'Base venta C'!$E:$P,12,FALSE),"0")*1 -> 166886.05
A7: 8 | B7: 8 - RAVAROTTO EMANUEL | C7: =IFERROR(VLOOKUP(A7,'Base venta C'!$E:$P,12,FALSE),"0")*1 -> 284846.64
A8: 5 | B8: 5 - SCHELOVER RAUL | C8: =IFERROR(VLOOKUP(A8,'Base venta C'!$E:$P,12,FALSE),"0")*1 -> 322216.7
A9: 4 | B9: 4 - TUR SPRINGER FERNANDO | C9: =IFERROR(VLOOKUP(A9,'Base venta C'!$E:$P,12,FALSE),"0")*1 -> 875228.78
B10: MARTIN (SUPERVISOR) PREVENTA
A11: 22 | B11: 22 - ALMIRON NICOLAS | C11: =IFERROR(VLOOKUP(A11,'Base venta C'!$E:$P,12,FALSE),"0")*1 -> 270784.37
A12: 49 | B12: 49 - ESCOBAR RAÚL | C12: =IFERROR(VLOOKUP(A12,'Base venta C'!$E:$P,12,FALSE),"0")*1 -> 76349.44
A13: 15 | B13: 15 - GALARZA GERARDO | C13: =IFERROR(VLOOKUP(A13,'Base venta C'!$E:$P,12,FALSE),"0")*1 -> 1329007.3
A14: 52 | B14: 52 - MARSALL NICOLAS | C14: =IFERROR(VLOOKUP(A14,'Base venta C'!$E:$P,12,FALSE),"0")*1 -> 155315.73
A15: 53 | B15: 53 - SANDOVAL RODRIGO | C15: =IFERROR(VLOOKUP(A15,'Base venta C'!$E:$P,12,FALSE),"0")*1 -> 833691.44
B16: MARTIN (SUPERVISOR)
A17: 2 | B17: 2 - OJEDA NORBERTO | C17: =IFERROR(VLOOKUP(A17,'Base venta C'!$E:$P,12,FALSE),"0")*1 -> 355809.05
A18: 3 | B18: 3 - VIDAL NAHUEL | C18: =IFERROR(VLOOKUP(A18,'Base venta C'!$E:$P,12,FALSE),"0")*1 -> 461503.95
A19: 18 | B19: 18 - HERRERA PABLO | C19: =IFERROR(VLOOKUP(A19,'Base venta C'!$E:$P,12,FALSE),"0")*1 -> 465462.81
A20: 21 | B20: 21 - CATAN MATIAS | C20: =IFERROR(VLOOKUP(A20,'Base venta C'!$E:$P,12,FALSE),"0")*1 -> 300786.17
A21: 23 | B21: 23 - DELGADO JOSÉ | C21: =IFERROR(VLOOKUP(A21,'Base venta C'!$E:$P,12,FALSE),"0")*1 -> 517438.51
A22: 31 | B22: 31 - BARTSCHAT EMILIANO NAHUEL | C22: =IFERROR(VLOOKUP(A22,'Base venta C'!$E:$P,12,FALSE),"0")*1 -> 346898.23
A23: 44 | B23: 44 - MONGE CÉSAR LUIS | C23: =IFERROR(VLOOKUP(A23,'Base venta C'!$E:$P,12,FALSE),"0")*1 -> 475747.4
A24: 54 | B24: 54 - CAÑETE DIEGO | C24: =IFERROR(VLOOKUP(A24,'Base venta C'!$E:$P,12,FALSE),"0")*1 -> 394891.73
A25: 56 | B25: 56 - JUAN ANDRES SANCHEZ | C25: =IFERROR(VLOOKUP(A25,'Base venta C'!$E:$P,12,FALSE),"0")*1 -> 254599.35
B26: CRISTIAN (SUPERVISOR)
A27: 32 | B27: 32 - BLANCO FERNANDO | C27: =IFERROR(VLOOKUP(A27,'Base venta C'!$E:$P,12,FALSE),"0")*1 -> 357064.39
A28: 36 | B28: 36 - STELLA MARIS CANO | C28: =IFERROR(VLOOKUP(A28,'Base venta C'!$E:$P,12,FALSE),"0")*1 -> 228911.14
A29: 9 | B29: 9 - ESTIGARRIBIA DAVID | C29: =IFERROR(VLOOKUP(A29,'Base venta C'!$E:$P,12,FALSE),"0")*1 -> 449396.93
A30: 40 | B30: 40 - GARCIA BOGARIN SANTIAGO | C30: =IFERROR(VLOOKUP(A30,'Base venta C'!$E:$P,12,FALSE),"0")*1 -> 259074.86
A31: 27 | B31: 27 - GOMEZ ADRIÁN | C31: =IFERROR(VLOOKUP(A31,'Base venta C'!$E:$P,12,FALSE),"0")*1 -> 315929.47
A32: 10 | B32: 10 - SEGOVIA JUAN CRUZ | C32: =IFERROR(VLOOKUP(A32,'Base venta C'!$E:$P,12,FALSE),"0")*1 -> 385757.33
A33: 28 | B33: 28 - GOMEZ PABLO | C33: =IFERROR(VLOOKUP(A33,'Base venta C'!$E:$P,12,FALSE),"0")*1 -> 216785.26
A34: 33 | B34: 33 - NICOLAS AZULA | C34: =IFERROR(VLOOKUP(A34,'Base venta C'!$E:$P,12,FALSE),"0")*1 -> 218111.24
A35: 37 | B35: 37 - PEREZ ESQUIVEL BRUNO NICOLAS | C35: =IFERROR(VLOOKUP(A35,'Base venta C'!$E:$P,12,FALSE),"0")*1 -> 160532.76
A36: 24 | B36: 24 - DELGADO HERNAN GABRIEL | C36: =IFERROR(VLOOKUP(A36,'Base venta C'!$E:$P,12,FALSE),"0")*1 -> 294217.66
A37: 7 | B37: 7 - VALLEJOS EDUARDO | C37: =IFERROR(VLOOKUP(A37,'Base venta C'!$E:$P,12,FALSE),"0")*1 -> 264122.85
A38: 57 | B38: 57 - ZARATE NICOLAS | C38: =IFERROR(VLOOKUP(A38,'Base venta C'!$E:$P,12,FALSE),"0")*1 -> 62179.29
A39: 1 | B39: 1 - VERA ERNESTO | C39: =IFERROR(VLOOKUP(A39,'Base venta C'!$E:$P,12,FALSE),"0")*1 -> 1671221.4
B40: GONZALO (SUPERVISOR)
...

Sheet Base Cobertura
A1: COBERTURAMESENCURSO | F1: COBERTURAUNIDADDENEGOCIO
A2: Nro Vendedor | B2: CCC x Bultos | C2: Cartera Clientes | F2: Nro Vendedor | G2: Agrupacion | H2: CCC x Bultos | I2: Cartera Clientes
B3: 6 | C3: 3408 | G3: 148 - ALMACEN | H3: 3 | I3: 3408
A4: 1 | B4: 113 | C4: 127 | G4: 148 - Articulos Sin Asociar Agrupacion | H4: 1 | I4: 3408
A5: 10 | B5: 132 | C5: 181 | G5: 148 - BEBIDAS | H5: 2 | I5: 3408
A6: 100 | B6: 40 | C6: 2024 | G6: 148 - CHOCOLATE | H6: 2 | I6: 3408
A7: 11 | B7: 120 | C7: 162 | G7: 148 - GALLETITAS | H7: 4 | I7: 3408
A8: 12 | B8: 183 | C8: 213 | G8: 148 - GOLOSINAS | H8: 2 | I8: 3408
A9: 123 | B9: 36 | C9: 489 | G9: 148 - MASCOTAS | H9: 3 | I9: 3408
A10: 15 | B10: 53 | C10: 65 | G10: 148 - NO PERECEDEROS | I10: 3408
A11: 16 | B11: 170 | C11: 198 | G11: 148 - PILAS | I11: 3408
A12: 18 | B12: 159 | C12: 176 | E12: =+F12 -> 1 | F12: 1 | G12: 148 - ALMACEN | H12: 48 | I12: 127
A13: 19 | B13: 183 | C13: 207 | E13: =+$E$12 -> 1 | G13: 148 - Articulos Sin Asociar Agrupacion | H13: 50 | I13: 127
A14: 2 | B14: 122 | C14: 138 | E14: =+$E$12 -> 1 | G14: 148 - BEBIDAS | H14: 55 | I14: 127
A15: 20 | B15: 210 | C15: 226 | E15: =+$E$12 -> 1 | G15: 148 - CHOCOLATE | H15: 51 | I15: 127
A16: 21 | B16: 149 | C16: 169 | E16: =+$E$12 -> 1 | G16: 148 - GALLETITAS | H16: 77 | I16: 127
A17: 22 | B17: 57 | C17: 72 | E17: =+$E$12 -> 1 | G17: 148 - GOLOSINAS | H17: 66 | I17: 127
A18: 23 | B18: 139 | C18: 160 | E18: =+$E$12 -> 1 | G18: 148 - MASCOTAS | H18: 29 | I18: 127
A19: 24 | B19: 129 | C19: 178 | E19: =+$E$12 -> 1 | G19: 148 - NO PERECEDEROS | H19: 46 | I19: 127
A20: 25 | B20: 85 | C20: 172 | E20: =+$E$12 -> 1 | G20: 148 - PILAS | H20: 51 | I20: 127
A21: 26 | B21: 67 | C21: 162 | E21: =+$F$21 -> 10 | F21: 10 | G21: 148 - ALMACEN | H21: 32 | I21: 181
A22: 27 | B22: 125 | C22: 140 | E22: =+$F$21 -> 10 | G22: 148 - Articulos Sin Asociar Agrupacion | H22: 24 | I22: 181
A23: 28 | B23: 147 | C23: 168 | E23: =+$F$21 -> 10 | G23: 148 - BEBIDAS | H23: 74 | I23: 181
A24: 3 | B24: 155 | C24: 170 | E24: =+$F$21 -> 10 | G24: 148 - CHOCOLATE | H24: 56 | I24: 181
A25: 30 | B25: 31 | C25: 138 | E25: =+$F$21 -> 10 | G25: 148 - GALLETITAS | H25: 86 | I25: 181
A26: 31 | B26: 141 | C26: 161 | E26: =+$F$21 -> 10 | G26: 148 - GOLOSINAS | H26: 50 | I26: 181
A27: 32 | B27: 50 | C27: 56 | E27: =+$F$21 -> 10 | G27: 148 - MASCOTAS | H27: 21 | I27: 181
A28: 33 | B28: 136 | C28: 172 | E28: =+$F$21 -> 10 | G28: 148 - NO PERECEDEROS | H28: 31 | I28: 181
A29: 36 | B29: 95 | C29: 156 | E29: =+$F$21 -> 10 | G29: 148 - PILAS | H29: 27 | I29: 181
A30: 37 | B30: 102 | C30: 141 | E30: =+$F$30 -> 100 | F30: 100 | G30: 148 - ALMACEN | H30: 27 | I30: 2024
A31: 4 | B31: 160 | C31: 182 | E31: =+$F$30 -> 100 | G31: 148 - Articulos Sin Asociar Agrupacion | H31: 22 | I31: 2024
A32: 40 | B32: 126 | C32: 249 | E32: =+$F$30 -> 100 | G32: 148 - BEBIDAS | H32: 22 | I32: 2024
A33: 42 | B33: 12 | C33: 52 | E33: =+$F$30 -> 100 | G33: 148 - CHOCOLATE | H33: 9 | I33: 2024
A34: 43 | B34: 22 | C34: 93 | E34: =+$F$30 -> 100 | G34: 148 - GALLETITAS | H34: 27 | I34: 2024
A35: 44 | B35: 145 | C35: 169 | E35: =+$F$30 -> 100 | G35: 148 - GOLOSINAS | H35: 20 | I35: 2024
A36: 49 | B36: 101 | C36: 239 | E36: =+$F$30 -> 100 | G36: 148 - MASCOTAS | H36: 15 | I36: 2024
A37: 5 | B37: 235 | C37: 260 | E37: =+$F$30 -> 100 | G37: 148 - NO PERECEDEROS | H37: 13 | I37: 2024
A38: 52 | B38: 58 | C38: 101 | E38: =+$F$30 -> 100 | G38: 148 - PILAS | H38: 6 | I38: 2024
A39: 53 | B39: 68 | C39: 105 | E39: =+$F$39 -> 11 | F39: 11 | G39: 148 - ALMACEN | H39: 46 | I39: 162
A40: 54 | B40: 151 | C40: 202 | E40: =+$F$39 -> 11 | G40: 148 - Articulos Sin Asociar Agrupacion | H40: 22 | I40: 162
...

Sheet Base venta C
A1: Periodos | B1: Cod. Período | C1: Descripción Período | D1: Vendedor según comprobante | E1: Código | F1: Descripción | G1: Rotacion a-b-c | H1: Código | I1: Descripción | J1: P.P.P. Neto | K1: P.P.P. Final | L1: Cantidades CON Cargo | M1: Cantidades SIN Cargo | N1: Cantidades Totales | O1: Pesos Totales | P1: Importes Netos | Q1: Importes Finales | R1: Cantidad de Facturas | S1: Bultos Promedio | T1: Cantidades en Combos
A2: (001) MAR 2026 | B2: 1 | C2: 46082 | D2: Suc: 001 (000001) VERA ERNESTO | E2: 1 | F2: VERA ERNESTO | G2: (1382) ROTACION C INCENTIVO | H2: 1382 | I2: ROTACION C INCENTIVO | J2: 98746.145 | K2: 122432.8 | L2: 14.2607 | M2: 2.6637 | N2: 16.9244 | O2: 0 | P2: 1671221.4 | Q2: 2072104.4 | R2: 128 | S2: 0.13 | T2: 0
A3: (001) MAR 2026 | B3: 1 | C3: 46082 | D3: Suc: 001 (000002) OJEDA NORBERTO | E3: 2 | F3: OJEDA NORBERTO | G3: (1382) ROTACION C INCENTIVO | H3: 1382 | I3: ROTACION C INCENTIVO | J3: 11815.421 | K3: 14554.453 | L3: 25.5498 | M3: 4.5642 | N3: 30.114 | O3: 0 | P3: 355809.05 | Q3: 438292.15 | R3: 73 | S3: 0.41 | T3: 0
A4: (001) MAR 2026 | B4: 1 | C4: 46082 | D4: Suc: 001 (000003) VIDAL NAHUEL | E4: 3 | F4: VIDAL NAHUEL | G4: (1382) ROTACION C INCENTIVO | H4: 1382 | I4: ROTACION C INCENTIVO | J4: 12029.634 | K4: 14825.838 | L4: 27.3731 | M4: 10.9908 | N4: 38.3639 | O4: 0 | P4: 461503.95 | Q4: 568777.28 | R4: 79 | S4: 0.49 | T4: 0
A5: (001) MAR 2026 | B5: 1 | C5: 46082 | D5: Suc: 001 (000004) TUR SPRINGER FERNANDO | E5: 4 | F5: TUR SPRINGER FERNANDO | G5: (1382) ROTACION C INCENTIVO | H5: 1382 | I5: ROTACION C INCENTIVO | J5: 17624.902 | K5: 21774.702 | L5: 44.3529 | M5: 5.3058 | N5: 49.6586 | O5: 0 | P5: 875228.78 | Q5: 1081302.2 | R5: 100 | S5: 0.5 | T5: 0
A6: (001) MAR 2026 | B6: 1 | C6: 46082 | D6: Suc: 001 (000005) SCHELOVER RAUL | E6: 5 | F6: SCHELOVER RAUL | G6: (1382) ROTACION C INCENTIVO | H6: 1382 | I6: ROTACION C INCENTIVO | J6: 26707.909 | K6: 32656.222 | L6: 7.0172 | M6: 5.0472 | N6: 12.0645 | O6: 0 | P6: 322216.7 | Q6: 393979.93 | R6: 70 | S6: 0.17 | T6: 0
A7: (001) MAR 2026 | B7: 1 | C7: 46082 | D7: Suc: 001 (000007) VALLEJOS EDUARDO | E7: 7 | F7: VALLEJOS EDUARDO | G7: (1382) ROTACION C INCENTIVO | H7: 1382 | I7: ROTACION C INCENTIVO | J7: 6772.381 | K7: 8382.717 | L7: 39 | M7: 0 | N7: 39 | O7: 0 | P7: 264122.85 | Q7: 326925.97 | R7: 1 | S7: 39 | T7: 0
A8: (001) MAR 2026 | B8: 1 | C8: 46082 | D8: Suc: 001 (000008) RAVAROTTO EMANUEL | E8: 8 | F8: RAVAROTTO EMANUEL | G8: (1382) ROTACION C INCENTIVO | H8: 1382 | I8: ROTACION C INCENTIVO | J8: 18047.967 | K8: 22290.443 | L8: 8.0508 | M8: 7.7319 | N8: 15.7828 | O8: 0 | P8: 284846.64 | Q8: 351804.59 | R8: 61 | S8: 0.26 | T8: 0
A9: (001) MAR 2026 | B9: 1 | C9: 46082 | D9: Suc: 001 (000009) ESTIGARRIBIA DAVID | E9: 9 | F9: ESTIGARRIBIA DAVID | G9: (1382) ROTACION C INCENTIVO | H9: 1382 | I9: ROTACION C INCENTIVO | J9: 9288.078 | K9: 11426.613 | L9: 40.549 | M9: 7.8353 | N9: 48.3843 | O9: 0 | P9: 449396.93 | Q9: 552868.39 | R9: 85 | S9: 0.57 | T9: 0
A10: (001) MAR 2026 | B10: 1 | C10: 46082 | D10: Suc: 001 (000010) SEGOVIA JUAN CRUZ | E10: 10 | F10: SEGOVIA JUAN CRUZ | G10: (1382) ROTACION C INCENTIVO | H10: 1382 | I10: ROTACION C INCENTIVO | J10: 19423.102 | K10: 23755.08 | L10: 16.26 | M10: 3.6008 | N10: 19.8607 | O10: 0 | P10: 385757.33 | Q10: 471793.64 | R10: 61 | S10: 0.33 | T10: 0
A11: (001) MAR 2026 | B11: 1 | C11: 46082 | D11: Suc: 001 (000011) ZACARIAS DAVID | E11: 11 | F11: ZACARIAS DAVID | G11: (1382) ROTACION C INCENTIVO | H11: 1382 | I11: ROTACION C INCENTIVO | J11: 19880.77 | K11: 24580.662 | L11: 6.225 | M11: 2.1693 | N11: 8.3943 | O11: 0 | P11: 166886.05 | Q11: 206338.57 | R11: 53 | S11: 0.16 | T11: 0
A12: (001) MAR 2026 | B12: 1 | C12: 46082 | D12: Suc: 001 (000012) GUTIERREZ MARCOS DAVID | E12: 12 | F12: GUTIERREZ MARCOS DAVID | G12: (1382) ROTACION C INCENTIVO | H12: 1382 | I12: ROTACION C INCENTIVO | J12: 21003.651 | K12: 25910.202 | L12: 6.2833 | M12: 7.2679 | N12: 13.5512 | O12: 0 | P12: 284624.48 | Q12: 351114.08 | R12: 65 | S12: 0.21 | T12: 0
A13: (001) MAR 2026 | B13: 1 | C13: 46082 | D13: Suc: 001 (000015) GALARZA GERARDO | E13: 15 | F13: GALARZA GERARDO | G13: (1382) ROTACION C INCENTIVO | H13: 1382 | I13: ROTACION C INCENTIVO | J13: 39203.754 | K13: 49427.271 | L13: 33.6667 | M13: 0.2333 | N13: 33.9 | O13: 0 | P13: 1329007.3 | Q13: 1675584.5 | R13: 10 | S13: 3.39 | T13: 0
... A45: (001) MAR 2026 | B45: 1 | C45: 46082 | D45: Suc: 001 (000123) TORRES ROLANDO | E45: 123 | F45: TORRES ROLANDO | G45: (1382) ROTACION C INCENTIVO | H45: 1382 | I45: ROTACION C INCENTIVO | J45: 52587.592 | K45: 64949.011 | L45: 26.325 | M45: 0.1667 | N45: 26.4917 | O45: 0 | P45: 1393132.9 | Q45: 1720607.6 | R45: 13 | S45: 2.04 | T45: 0
